Workbook

Sheet Schedule
A1: Job # | B1: Job Name | C1: GC | D1: Units | E1: Project Start Date | F1: RI Foreman | G1: Trim Foreman | H1: Address | I1: 41913 | J1: 42767 | K1: 41944 | M1: 41974 | N1: 42856 | O1: 42005 | P1: 42767 | Q1: 42036 | S1: 42064 | T1: 42856 | U1: 42095 | V1: 42125 | W1: 42156 | X1: 42186 | Z1: 42217 | AB1: 42248 | AD1: 42278 | AF1: 42309 | AH1: 42339 | AJ1: 42370 | AL1: 42401 | AN1: 42430 | AP1: 42461 | AR1: 42491 | AT1: 42522 | AU1: 42552 | AV1: 42552 | AW1: 42614 | AX1: 42583 | AZ1: 42614 | BA1: 42705 | BB1: 42644 | BC1: 42767 | BD1: 42675 | BF1: 42705 | BG1: 42856 | BH1: 42736 | BI1: 42917 | BJ1: 42767 | BL1: 42795 | BM1: 43009 | BN1: 42826 | BO1: 43070 | BP1: 42856 | BR1: 42887 | BS1: 43160 | BT1: 42917 | BU1: 43221 | BV1: 42948 | BX1: 42979 | BY1: 43313 | BZ1: 43009 | CA1: 43374 | CB1: 43040 | CC1: 43070 | CD1: 43070 | CF1: 43101 | CH1: 43132 | CJ1: 43160 | CL1: 43191 | CN1: 43221 | CP1: 43252 | CR1: 43282 | CT1: 43313 | CV1: 43344 | CX1: 43374 | CZ1: 43405 | DB1: 43435 | DD1: 43466 | DF1: 43497 | DH1: 43525 | DJ1: 43556 | DL1: 43586 | DN1: 43617 | DP1: 43647 | DR1: 43678 | DT1: 43709 | DV1: 43739 | DX1: 43770 | DZ1: 43800 | EB1: 43831 | ED1: 43862 | EF1: 43891 | EH1: 43922 | EJ1: 43952 | EL1: 43983 | EN1: 44013 | EP1: 44044 | ER1: 44075 | ET1: 44105 | EV1: 44136 | EX1: 44166 | EZ1: 44197 | FB1: 44228 | FD1: 44256 | FF1: 44287 | FH1: 44317 | FJ1: 44348 | FL1: 44378 | FN1: 44409 | FP1: 44440 | FR1: 44470 | FT1: 44501 | FV1: 44531 | FX1: 44562 | FZ1: 44593 | GB1: 44621 | GD1: 44652 | GF1: 44682 | GH1: 44713 | GJ1: 44743 | GL1: 44774 | GN1: 44805 | GP1: 44835 | GR1: 44866 | GT1: 44896 | GV1: 44927 | GX1: 44958 | GZ1: 44986 | HB1: 45017 | HD1: 45047 | HF1: 45078 | HH1: 45108 | HJ1: 45139 | HL1: 45170 | HN1: 45200 | HP1: 45231 | HR1: 45261 | HT1: 45292 | HV1: 45323 | HX1: 45352 | HZ1: 45383 | IB1: 45413 | ID1: 45444 | IF1: 45474 | IH1: 45505 | IJ1: 45536 | IL1: 45566 | IN1: 45597 | IP1: 45627 | IR1: 45658 | IT1: 45689 | IV1: 45717 | IX1: 45748 | IZ1: 45778 | JB1: 45809 | JD1: 45839 | JF1: 45870 | JH1: 45901 | JJ1: 45931 | JL1: 45962 | JN1: 45992 | JP1: 46023 | JR1: 46054 | JT1: 46082 | JV1: 46113 | JX1: 46143 | JZ1: 46174 | KB1: 46204 | KD1: 46235 | KF1: 46266 | KH1: 46296 | KJ1: 46327 | KL1: 46357 | KN1: 46388 | KP1: 46419 | KR1: 46447 | KT1: 46478 | KV1: 46508 | KX1: 46539 | KZ1: 46569 | LB1: 46600
A2: 2001 | B2: 230 Broadway | C2: SRM | D2: 234
A3: 2002 | B3: Wedgewood | C3: Exxel Pacific | D3: 91
A4: 2003 | B4: Evanston Space | C4: Exxel Pacific | D4: 28
A5: 2005 | B5: Indigo/Kavela | C5: Chinn | D5: 66
A6: 2006 | B6: Bella Lago | C6: ICC | D6: 319
A7: 2008 | B7: 101 Taylor | C7: SRM | D7: 258 | F7: Bob | G7: Al
A8: 2009 | B8: Greenwood | C8: Chinn | D8: 56
A9: 2010 | B9: Old Town | C9: Chinn | D9: 149
A10: 2011 | B10: Barrett Park | C10: Chinn | D10: 117
A11: 2012 | B11: 8th Ave | C11: Exxel Pacific | D11: 162
A12: 2013 | B12: NE 63rd | C12: Exxel Pacific | D12: 112
A13: 2016 | B13: Sedona | C13: Natural & Built | D13: 85
A14: 2018 | B14: Astro | C14: SRM | D14: 211 | F14: Bob | G14: Al | I14: TRIM | K14: TRIM | M14: TRIM | O14: TRIM | Q14: TRIM | S14: TRIM
A15: 2017 | B15: 36 Stone | C15: Exxel Pacific | D15: 119 | F15: Esteban | G15: Al | I15: RI | K15: RI | M15: TRIM | O15: TRIM | Q15: TRIM | S15: TRIM
A16: 2022 | B16: Interlake | C16: Exxel Pacific | D16: 18 | F16: Al | G16: Al | M16: GW | O16: GW | S16: RI | U16: RI | W16: TRIM
A17: 2015 | B17: Rooster | C17: Exxel Pacific | D17: 197 | F17: Al - Trim | G17: Al | I17: RI | K17: RI | M17: RI | O17: RI | Q17: RI | S17: RI | U17: RI | V17: RI | W17: TRIM | X17: TRIM | Z17: TRIM | AB17: TRIM
A18: 2014 | B18: Pike Motorworks | C18: Exxel Pacific | D18: 258 | F18: Joe | G18: Joe | H18: 714 E Pike Street, Seattle, WA 98122 | I18: RI | K18: RI | M18: RI | O18: RI | Q18: RI | S18: RI | U18: RI | V18: RI | W18: TRIM | X18: TRIM | Z18: TRIM | AB18: TRIM | AD18: TRIM | AF18: TRIM | AH18: TRIM | AJ18: TRIM
A19: 2020 | B19: Bellevue Main | C19: SRM | D19: 256 | F19: Nate (Al trim) | G19: Al | H19: 15 Bellevue Way SE, Bellevue, WA 98004 | I19: RI | K19: RI | M19: RI | O19: RI | Q19: RI | S19: RI | U19: RI | V19: RI | W19: RI | X19: RI | Z19: RI | AB19: TRIM | AD19: TRIM | AF19: TRIM | AH19: TRIM | AJ19: TRIM | AL19: TRIM
A20: 2019 | B20: 8th Republic | C20: Exxel Pacific | D20: 211 | F20: Thaddeus (Al trim) | G20: Al/Rick | H20: 430 8th Ave North, Seattle, WA 98109 | I20: GW | K20: GW | M20: PT | O20: PT | Q20: PT | S20: PT | U20: RI | V20: RI | W20: RI | X20: RI | Z20: RI | AB20: RI | AD20: TRIM | AF20: TRIM | AH20: TRIM | AJ20: TRIM | AL20: TRIM
A21: 2024 | B21: Merrill Gardens | C21: SRM | D21: 117 | F21: Gustavo | G21: Al | H21: 5601 24th Ave NW, Seattle, WA 98107 | S21: GW | U21: GW | V21: PT | W21: PT | X21: RI | Z21: RI | AB21: RI | AD21: RI | AF21: RI | AH21: RI | AJ21: RI | AL21: RI | AN21: TRIM | AP21: TRIM | AR21: TRIM | AT21: TRIM
A22: 2021 | B22: Admiral | C22: Exxel Pacific | D22: 136 | F22: Esteban | G22: Al | H22: 3210 California Ave SW, Seattle, WA 98116 | S22: GW | U22: GW | V22: GW | W22: GW | X22: PT | Z22: PT | AB22: RI | AD22: RI | AF22: RI | AH22: RI | AJ22: RI | AL22: RI | AN22: RI | AP22: TRIM | AR22: TRIM | AT22: TRIM
A23: 2023 | B23: Hadley | C23: Chinn | D23: 209 | F23: Joe | G23: Al | H23: 2601 76th Ave SE, Mercer Island, WA 98040 | O23: GW | Q23: GW | S23: GW | U23: PT | V23: PT | W23: PT | X23: RI | Z23: RI | AB23: RI | AD23: RI | AF23: RI | AH23: RI | AJ23: RI | AL23: RI | AN23: RI | AP23: TRIM | AR23: TRIM | AT23: TRIM | AV23: TRIM | AX23: TRIM | AZ23: TRIM
A24: 2028 | B24: Reserve @ Lynnwood | C24: Exxel Pacific | D24: 296 | H24: 19815 Scriber Lake Road, Lynnwood, WA 98036 | AO24: GW | AP24: PT | AR24: PT | AS24: RI | AT24: PT | AU24: RI | AV24: RI | AX24: RI | AZ24: RI | BB24: RI | BD24: RI | BF24: RI | BH24: TUBS | BJ24: BURN
A25: 2025 | B25: The Cora | C25: Exxel Pacific | D25: 75 | F25: Thaddeus | H25: 19 W Harrison, Seattle, WA 98119 | AU25: GW | AV25: GW | AX25: PT | AZ25: PT | BB25: PT | BC25: RI | BD25: RI | BF25: RI | BH25: RI | BJ25: RI | BL25: PICKUP | BN25: PICKUP | BP25: TRIM | BR25: TRIM
A26: 2026 | B26: Boren | C26: Synnergy | D26: 49 | F26: Gustavo | H26: 525 Boren Ave N, Seattle, WA 98109 | AR26: GW | AT26: GW | AV26: PT | AX26: PT | AZ26: PT | BA26: RI | BB26: RI | BD26: RI | BF26: RI | BH26: RI | BJ26: RI | BL26: PICKUP | BN26: PICKUP | BP26: TRIM | BR26: TRIM | BT26: TRIM
A27: 2029 | B27: Parsonage | C27: Exxel Pacific | D27: 83 | F27: Rick | H27: 4132 Brooklyn Ave NE, Seattle, WA 98105 | AX27: GW | AZ27: GW | BB27: GW | BC27: PT | BD27: PT | BF27: PT | BG27: RI | BH27: RI | BJ27: RI | BL27: RI | BN27: PICKUP | BP27: TRIM | BR27: TRIM | BT27: TRIM
A28: 2027 | B28: 550 Broadway | C28: Exxel Pacific | D28: 170 | F28: Joe | H28: 550 Broadway, Seattle, WA 98122 | AP28: GW | AR28: GW | AS28: PT | AT28: PT | AV28: PT | AX28: PT | AZ28: PT | BB28: RI | BD28: RI | BF28: RI | BH28: RI | BJ28: RI | BL28: PICKUP | BN28: PICKUP | BP28: TRIM | BR28: TRIM | BT28: TRIM | BV28: TRIM
A29: 2035 | B29: 162 Ten | C29: Natural & Built | D29: 92 | E29: 42598 | F29: Reuben | H29: 16210 NE 80th St, Redmond, WA 98052 | BB29: GW | BD29: GW | BF29: PT | BH29: PT | BJ29: PT | BL29: RI | BN29: RI | BP29: RI | BR29: RI | BT29: RI | BV29: RI | BX29: PICKUP | BZ29: PICKUP | CB29: TRIM | CD29: TRIM | CF29: TRIM | CH29: TRIM
A30: 2034 | B30: Park Lane | C30: Compass | D30: 128 | E30: 42587 | F30: Thaddeus | H30: 207 Park Lane, Kirkland, WA 98033 | BF30: GW | BH30: PT | BJ30: PT | BL30: RI | BN30: RI | BP30: RI | BR30: RI | BT30: RI | BV30: RI | BX30: PICKUP | BZ30: PICKUP | CB30: PICKUP | CD30: TRIM | CF30: TRIM | CH30: TRIM
A31: 2032 | B31: Luna | C31: Blueprint | D31: 71 | E31: 42675 | F31: Rick | H31: 6921 Roosevelt Way NE, Seattle, WA 98115 | BK31: GW | BL31: GW | BN31: GW | BO31: RI | BP31: RI | BR31: RI | BT31: RI | BV31: RI | BX31: RI | BZ31: RI | CB31: RI | CD31: TRIM | CF31: TRIM | CH31: TRIM | CJ31: TRIM | CL31: TRIM | CN31: TRIM
A32: 2036 | B32: Westridge | C32: Exxel Pacific | D32: 31 | E32: 42644 | F32: Gustavo | H32: 512 121st Place NE, Bellevue, WA | BI32: GW | BK32: GW | BM32: GW | BN32: GW | BP32: GW | BR32: GW | BT32: RI | BV32: RI | BX32: RI | BZ32: RI | CB32: RI | CD32: PICKUP | CF32: PICKUP | CH32: TRIM | CJ32: TRIM | CL32: TRIM | CN32: TRIM | CP32: TRIM | CR32: TRIM
A33: 2048 | B33: Ballinger | C33: GRE | D33: 72 | E33: 43025 | F33: Esteban | BZ33: RI | CB33: RI | CD33: RI | CF33: RI | CH33: PICKUP | CJ33: TRIM | CL33: TRIM | CN33: TRIM | CP33: TRIM
A34: 2047 | B34: Greenlake | C34: GRE | D34: 70 | E34: 43025 | F34: Reuben | BZ34: RI | CB34: RI | CD34: RI | CF34: RI | CH34: PICKUP | CJ34: PICKUP | CL34: TRIM | CN34: TRIM | CP34: TRIM
A35: 2033 | B35: Vuecrest | C35: Compass | D35: 139 | E35: 42614 | F35: Victor | H35: 1000 100th Ave NE, Bellevue, WA | BG35: GW | BH35: GW | BJ35: GW | BK35: PT | BL35: PT | BM35: RI | BN35: RI | BP35: RI | BR35: RI | BT35: RI | BV35: RI | BX35: RI | BZ35: RI | CB35: RI | CD35: PICKUP | CF35: PICKUP | CH35: TRIM | CJ35: TRIM | CL35: TRIM | CN35: TRIM | CP35: TRIM | CR35: TRIM
A36: 2030 | B36: East Union | C36: Exxel Pacific | D36: 144 | E36: 42675 | F36: Joe | H36: 2220 E. Union Street, Seattle WA | BL36: GW | BN36: GW | BO36: PT | BP36: PT | BR36: PT | BT36: RI | BV36: RI | BX36: RI | BZ36: RI | CB36: RI | CD36: RI | CF36: RI | CH36: PICKUP | CJ36: PICKUP | CL36: TRIM | CN36: TRIM | CP36: TRIM | CR36: TRIM
A37: 2038 | B37: 2nd & John | C37: Compass | D37: 80 | E37: 42783 | F37: Thaddeus / Joe | H37: 200 2nd Ave West, Seattle, WA | BT37: GW | BV37: GW | BX37: PT | BZ37: PT | CB37: PT | CD37: PT | CE37: RI | CF37: RI | CH37: RI | CJ37: RI | CL37: RI | CN37: RI | CP37: PICKUP | CR37: PICKUP | CT37: TRIM | CV37: TRIM | CX37: TRIM | CZ37: TRIM | DB37: TRIM
A38: 2040 | B38: Roosevelt 65th | C38: Blueprint | D38: 55 | E38: 42795 | F38: Garrett / Joe | H38: 1222 NE 65th Street, Seattle, WA 98115 | BX38: GW | BZ38: PT | CB38: PT | CD38: PT | CE38: RI | CF38: RI | CH38: RI | CJ38: RI | CL38: RI | CN38: RI | CP38: RI | CR38: RI | CT38: PICKUP | CV38: TRIM | CX38: TRIM | CZ38: TRIM | DB38: TRIM
A39: 2037 | B39: University Apartments | C39: Marpac | D39: 122 | E39: 42744 | F39: Rick / Joe | H39: 3025 NE 130th Street, Seattle WA | BT39: GW | BV39: GW | BX39: PT | BZ39: PT | CB39: PT | CD39: PT | CF39: PT | CH39: PT | CJ39: RI | CL39: RI | CN39: RI | CP39: RI | CR39: RI | CT39: PICKUP | CV39: PICKUP | CX39: TRIM | CZ39: TRIM | DB39: TRIM
A40: 2042 | B40: Metro Flats | C40: Shelter Holdings | D40: 75 | E40: AUGUST, 17 | F40: Reuben / Bob | CE40: GW | CF40: PT | CH40: PT | CJ40: RI | CL40: RI | CN40: RI | CP40: RI | CR40: RI | CT40: PICKUP | CV40: TRIM | CX40: TRIM | CZ40: TRIM | DB40: TRIM | DD40: TRIM | DF40: TRIM | DH40: TRIM
...

Sheet Job Info
B1: =Schedule!B1 -> Job Name | C1: =Schedule!C1 -> GC | D1: Units | E1: Original Contract | G1: Contract w/ CO's | I1: Franklin Costs to date | J1: As-Bid Eng Budget | K1: Frank Cost/unit | L1: Insurance Type | M1: GC PM | N1: GC Sup | O1: GC PE | P1: Developer | Q1: Architect | R1: Structural | S1: Acoustical | T1: ADA Consultant | U1: Interior Design | V1: Engineer | W1: Levels Above | X1: Levels Below | Y1: Concrete | Z1: Wood
E2: Total | F2: Per unit | G2: Total | H2: Per Unit
A3: =Schedule!A2 -> 2001 | B3: =Schedule!B2 -> 230 Broadway | C3: =Schedule!C2 -> SRM | D3: 234 | E3: 2026045.6 | F3: =E3/D3 -> 8658.3147 | G3: 2121873.5 | H3: =G3/D3 -> 9067.8355 | I3: 21979 | J3: 30000 | K3: =I3/Schedule!D2 -> 93.92735 | Q3: Runberg
A4: =Schedule!A3 -> 2002 | B4: =Schedule!B3 -> Wedgewood | C4: =Schedule!C3 -> Exxel Pacific | D4: 91 | E4: 879530 | F4: =E4/D4 -> 9665.1648 | G4: 864597 | H4: =G4/D4 -> 9501.0659 | I4: 10520 | J4: 25000 | K4: =I4/Schedule!D3 -> 115.6044
A5: =Schedule!A4 -> 2003 | B5: =Schedule!B4 -> Evanston Space | C5: =Schedule!C4 -> Exxel Pacific | D5: 5 | F5: =E5/D5 -> 0 | H5: =G5/D5 -> 0 | I5: 8475 | K5: =I5/Schedule!D4 -> 302.67857
A6: =Schedule!A5 -> 2005 | B6: =Schedule!B5 -> Indigo/Kavela | C6: =Schedule!C5 -> Chinn | D6: 66 | E6: 501500 | F6: =E6/D6 -> 7598.4848 | G6: 499368 | H6: =G6/D6 -> 7566.1818 | I6: 13668 | J6: 18000 | K6: =I6/Schedule!D5 -> 207.09091 | Q6: Johnson Architecture and Planning | V6: Rushing
A7: =Schedule!A6 -> 2006 | B7: =Schedule!B6 -> Bella Lago | C7: =Schedule!C6 -> ICC | D7: 319 | F7: =E7/D7 -> 0 | H7: =G7/D7 -> 0 | I7: 30611 | K7: =I7/Schedule!D6 -> 95.959248
A8: =Schedule!A7 -> 2008 | B8: =Schedule!B7 -> 101 Taylor | C8: =Schedule!C7 -> SRM | D8: 258 | F8: =E8/D8 -> 0 | H8: =G8/D8 -> 0 | I8: 56506 | K8: =I8/Schedule!D7 -> 219.0155 | O8: A.J. Haviland | Q8: Runberg | V8: Rushing
A9: =Schedule!A8 -> 2009 | B9: =Schedule!B8 -> Greenwood | C9: =Schedule!C8 -> Chinn | D9: 56 | E9: 384900 | F9: =E9/D9 -> 6873.2143 | G9: 392855 | H9: =G9/D9 -> 7015.2679 | I9: 4895 | J9: 5000 | K9: =I9/Schedule!D8 -> 87.410714 | Q9: Studio Meng Strazzara
A10: =Schedule!A9 -> 2010 | B10: =Schedule!B9 -> Old Town | C10: =Schedule!C9 -> Chinn | D10: 149 | E10: 1469800 | F10: =E10/D10 -> 9864.4295 | G10: 1386419 | H10: =G10/D10 -> 9304.8255 | I10: 10463 | J10: 20000 | K10: =I10/Schedule!D9 -> 70.221477 | Q10: Weber Thompson | W10: 8
A11: =Schedule!A10 -> 2011 | B11: =Schedule!B10 -> Barrett Park | C11: =Schedule!C10 -> Chinn | D11: 117 | E11: 813050 | F11: =E11/D11 -> 6949.1453 | G11: 869823.5 | H11: =G11/D11 -> 7434.3889 | I11: 12487 | J11: 25000 | K11: =I11/Schedule!D10 -> 106.7265 | Q11: Studio Meng Strazzara | V11: Rushing
A12: =Schedule!A11 -> 2012 | B12: =Schedule!B11 -> 8th Ave | C12: =Schedule!C11 -> Exxel Pacific | D12: 162 | E12: 1394655 | F12: =E12/D12 -> 8608.9815 | G12: 1393316 | H12: =G12/D12 -> 8600.716 | I12: 15613 | K12: =I12/Schedule!D11 -> 96.376543 | Q12: NK | V12: Pressler
A13: =Schedule!A12 -> 2013 | B13: =Schedule!B12 -> NE 63rd | C13: =Schedule!C12 -> Exxel Pacific | D13: 112 | E13: 959780 | F13: =E13/D13 -> 8569.4643 | G13: 966156 | H13: =G13/D13 -> 8626.3929 | I13: 18532 | J13: 25000 | K13: =I13/Schedule!D12 -> 165.46429 | P13: Intra-Corp | Q13: Runberg | V13: Pressler | W13: 6 | X13: 1 | Y13: 2 | Z13: 5
A14: =Schedule!A14 -> 2018 | B14: =Schedule!B14 -> Astro | C14: =Schedule!C14 -> SRM | D14: 211 | E14: 2499585 | F14: =E14/D14 -> 11846.374 | G14: 2524038.5 | H14: =G14/D14 -> 11962.268 | I14: 24000 | K14: =I14/Schedule!D14 -> 113.74408 | M14: Eric Petersen | N14: John Schwab / James Wilkins | O14: Andrew Withnell | P14: SRM | Q14: Runberg | R14: DCI Engineers | S14: SSA Acoustics | V14: Pressler | W14: 6 | X14: 2 | Y14: 3 | Z14: 5
A15: =Schedule!A15 -> 2017 | B15: =Schedule!B15 -> 36 Stone | C15: =Schedule!C15 -> Exxel Pacific | D15: 119 | E15: 1373148 | F15: =E15/D15 -> 11539.059 | G15: 1365227 | H15: =G15/D15 -> 11472.496 | I15: 18000 | K15: =I15/Schedule!D15 -> 151.2605 | M15: Tyson Scheenstra / Tommy Booth | N15: Brad Carpenter | O15: Tommy Booth | P15: Mack Urban | Q15: Baylis | R15: CPL | S15: SSA Acoustics | T15: Karen Braitmayer | U15: ObjectSpace | V15: Rushing | W15: 4 | X15: 1 | Y15: 1 | Z15: 4
A16: =Schedule!A16 -> 2022 | B16: =Schedule!B16 -> Interlake | C16: =Schedule!C16 -> Exxel Pacific | D16: 18 | E16: 232454 | F16: =E16/D16 -> 12914.111 | G16: 242637 | H16: =G16/D16 -> 13479.833 | I16: 4757 | K16: =I16/Schedule!D16 -> 264.27778 | M16: Tommy Booth | N16: Brad Carpenter | O16: Garret Olsen | P16: Mack Urban | Q16: Nicholson Kovalchick | R16: Michael Nouwens | W16: 3 | X16: 0 | Y16: 0 | Z16: 3
A17: =Schedule!A17 -> 2015 | B17: =Schedule!B17 -> Rooster | C17: =Schedule!C17 -> Exxel Pacific | D17: 197 | E17: 1935285 | F17: =E17/D17 -> 9823.7817 | G17: 2045883 | H17: =G17/D17 -> 10385.193 | I17: 48000 | K17: =I17/Schedule!D17 -> 243.65482 | L17: Not Wrap | M17: John Hughes | N17: Nick Amaya | O17: Ben Prigmore / Mason Seto | P17: Lake Union Partners | Q17: Weinstein AU | R17: CPL | S17: SSA Acoustics | T17: Endelman & Associates | V17: Rushing | W17: 7 | X17: 2 | Y17: 4 | Z17: 5
A18: =Schedule!A18 -> 2014 | B18: =Schedule!B18 -> Pike Motorworks | C18: =Schedule!C18 -> Exxel Pacific | D18: 241 | E18: 2661895 | F18: =E18/D18 -> 11045.207 | H18: =G18/D18 -> 0 | I18: 65000 | J18: 70000 | K18: =I18/Schedule!D18 -> 251.93798 | L18: Wrap | M18: Dave Biasini / Josh Purefoy | N18: Jeff Christiansen / Bill Armstrong | O18: Brett Johnston / Ben McCarty | P18: The Wolff Company | Q18: Weber Thompson | R18: CPL | T18: theACCESSpartnership | U18: Weber Thompson / Graham Baba | V18: Ecotope | W18: 7 | X18: 3 | Y18: 5 | Z18: 5
A19: =Schedule!A19 -> 2020 | B19: =Schedule!B19 -> Bellevue Main | C19: =Schedule!C19 -> SRM | D19: 256 | E19: 3415305 | F19: =E19/D19 -> 13341.035 | H19: =G19/D19 -> 0 | I19: NA | K19: NA | L19: Not Wrap | M19: Todd Rankin / Erik Benzel | N19: Bill Robinson / Jared Osborn | O19: Renay Luzama | P19: Pillar Properties / SRM | Q19: Benson & Bohl | R19: DCI Engineers | S19: SSA Acoustics | V19: Pressler | W19: 5 | X19: 2 | Y19: 3 | Z19: 4
A20: =Schedule!A20 -> 2019 | B20: =Schedule!B20 -> 8th Republic | C20: =Schedule!C20 -> Exxel Pacific | D20: 211 | E20: 2721210 | F20: =E20/D20 -> 12896.73 | H20: =G20/D20 -> 0 | I20: 70000 | K20: =I20/Schedule!D20 -> 331.75355 | L20: Wrap | M20: Dave Biasini / Brian Christensen | N20: Dan Phillips / Todd Tradal | O20: Joel Palmer / Sam Bernoski | P20: The Wolff Company | Q20: Runberg - Interior Miller Hull - Exterior | R20: CPL | S20: SSA Acoustics | T20: theACCESSpartnership | U20: Lair Design | V20: Rushing | W20: 8 | X20: 2 | Y20: 10 | Z20: 0
A21: =Schedule!A21 -> 2024 | B21: =Schedule!B21 -> Merrill Gardens | C21: =Schedule!C21 -> SRM | D21: 104 | E21: 1763480 | F21: =E21/D21 -> 16956.538 | H21: =G21/D21 -> 0 | I21: NA | K21: =I21/Schedule!D21 -> #VALUE! | L21: Not Wrap | M21: Bill Robinson | N21: James Wilkins | O21: Ben Robles | P21: Merrill Gardens / Pillar Properties | Q21: Urbal Architecture | R21: DCI Engineers | S21: SSA Acoustics | U21: NAC Architecture | V21: Abossein | W21: 7 | X21: 1 | Y21: 3 | Z21: 5
A22: =Schedule!A22 -> 2021 | B22: =Schedule!B22 -> Admiral | C22: =Schedule!C22 -> Exxel Pacific | D22: 136 | E22: 1558650 | F22: =E22/D22 -> 11460.662 | H22: =G22/D22 -> 0 | I22: 53260 | K22: =I22/Schedule!D22 -> 391.61765 | L22: Wrap | M22: Victor Vo / Justin Ripkin | N22: Scott Weston / Nic Christoffer | O22: Justin Ripkin | P22: Intra-Corp | Q22: Nicholson Kovalchick | R22: Panos (Yu & Troch..) | S22: SSA Acoustics | T22: Karen Braitmayer | U22: ObjectSpace | V22: Pressler | W22: 5 | X22: 1 | Y22: 2 | Z22: 4
A23: =Schedule!A23 -> 2023 | B23: =Schedule!B23 -> Hadley | C23: =Schedule!C23 -> Chinn | D23: 209 | E23: 2469500 | F23: =E23/D23 -> 11815.789 | H23: =G23/D23 -> 0 | I23: 28144 | K23: =I23/Schedule!D23 -> 134.66029 | L23: Not Wrap | M23: Charlie Poggemann | N23: Mark Pesanti / Sim Mooers | O23: Lauren Bjorndahl | P23: Legacy Partners | Q23: VIA Architecture | R23: Panos (Yu & Troch..) | S23: JGL Acoustics | T23: Karen Braitmayer | U23: Robin Chell Design | V23: Rushing | W23: 6 | X23: 1 | Y23: 3 | Z23: 4
A24: =Schedule!A24 -> 2028 | B24: =Schedule!B24 -> Reserve @ Lynnwood | C24: =Schedule!C24 -> Exxel Pacific | D24: 296 | E24: 2979880 | F24: =E24/D24 -> 10067.162 | H24: =G24/D24 -> 0 | I24: 20233 | K24: =I24/Schedule!D24 -> 68.35473 | L24: Not Wrap | M24: TJ Mellema / Coby Jones | N24: Brad Holz | P24: AVS Communities | Q24: Charles Morgan & Associates, LLC | V24: N/A | W24: 5 | X24: 1 | Y24: 1 | Z24: 5
A25: =Schedule!A28 -> 2027 | B25: =Schedule!B28 -> 550 Broadway | C25: =Schedule!C28 -> Exxel Pacific | D25: 170 | E25: 2230810 | F25: =E25/D25 -> 13122.412 | G25: 2275444 | H25: =G25/D25 -> 13384.965 | I25: 39854 | K25: =I25/Schedule!D28 -> 234.43529 | L25: Wrap | M25: Justin Gotcher / Chris Austin | N25: Brian Proctor | O25: Chris Austin | P25: Intra-Corp | Q25: Nicholson Kovalchick | V25: Pressler
A26: =Schedule!A26 -> 2026 | B26: Boren (Fox & Finch) | C26: =Schedule!C26 -> Synnergy | D26: 49 | E26: 825370 | F26: =E26/D26 -> 16844.286 | H26: =G26/D26 -> 0 | I26: 17344 | K26: =I26/Schedule!D26 -> 353.95918 | L26: Not Wrap | M26: Matt Stewart / Ron Auld / Jamie Creek | N26: Aaron Steinke | O26: Michele Lee
A27: =Schedule!A25 -> 2025 | B27: =Schedule!B25 -> The Cora | C27: =Schedule!C25 -> Exxel Pacific | D27: 75 | E27: 1179300 | F27: =E27/D27 -> 15724 | G27: 1202633 | H27: =G27/D27 -> 16035.107 | I27: 27970 | K27: =I27/Schedule!D25 -> 372.93333 | L27: Not Wrap | M27: Victor Vo / Ben Prigmore | N27: Tim Conner | O27: Jola Bielecki | P27: Barrientos, LLC
A28: =Schedule!A27 -> 2029 | B28: =Schedule!B27 -> Parsonage | C28: =Schedule!C27 -> Exxel Pacific | D28: 83 | E28: 1113220 | F28: =E28/D28 -> 13412.289 | G28: 1129452 | H28: =G28/D28 -> 13607.855 | I28: 20121 | K28: =I28/Schedule!D27 -> 242.42169 | L28: Not Wrap | M28: Victor Vo / Ben Prigmore | N28: Bill Armstrong | O28: Mason Seto
A29: =Schedule!A36 -> 2030 | B29: =Schedule!B36 -> East Union | C29: =Schedule!C36 -> Exxel Pacific | D29: 144 | E29: 2135080 | F29: =E29/D29 -> 14826.944 | G29: 2322781 | H29: =G29/D29 -> 16130.424 | K29: =I29/Schedule!D29 -> 0 | L29: Not Wrap | M29: Coby Jones | N29: Steve Booth | O29: Matt Anderson | P29: Lake Union Partners
A30: 2031 | B30: Issaquah Gateway (Anthology) | C30: Exxel Pacific | D30: 398 | E30: 5051600 | F30: =E30/D30 -> 12692.462 | G30: 5187754 | H30: =G30/D30 -> 13034.558 | L30: Not Wrap | M30: Ben McCarty/Tim Spink | N30: Dennis Schlosser | O30: Connor Jungkuntz | P30: Wolff | Q30: Weinstein AU
A31: 2032 | B31: Luna | C31: Blueprint | D31: 71 | E31: 685300 | F31: =E31/D31 -> 9652.1127 | G31: 726903 | H31: =G31/D31 -> 10238.07 | L31: Not Wrap | M31: Andrew Withnell | N31: Scott McSpadden
A32: 2033 | B32: Vuecrest (LUX) | C32: Compass | D32: 137 | E32: 2447600 | F32: =E32/D32 -> 17865.693 | G32: 2286188 | H32: =G32/D32 -> 16687.504 | K32: =I32/Schedule!D42 -> 0 | L32: Wrap | M32: Ryan Ames/Vince Dennison | N32: Todd Mortenson | O32: Dan Peck | P32: Continental
A33: 2034 | B33: Park Lane (VODA) | C33: Compass | D33: 128 | E33: 1784000 | F33: =E33/D33 -> 13937.5 | G33: 1842651 | H33: =G33/D33 -> 14395.711 | K33: =I33/Schedule!D35 -> 0 | L33: Wrap | M33: Frank Weaver | N33: Mike Horgan | O33: Kait O'Neill | P33: Continental | Q33: Johnson Braund | R33: Yu & Trochalakis | U33: Sechrist Design
A34: 2035 | B34: 162 Ten | C34: Natural & Built | D34: 97 | E34: 717400 | F34: =E34/D34 -> 7395.8763 | G34: =E34+5500 -> 722900 | H34: =G34/D34 -> 7452.5773 | K34: =I34/Schedule!D30 -> 0 | L34: Not Wrap | M34: Tyson Cornett
A35: 2036 | B35: Westridge | C35: Exxel Pacific | D35: 31 | E35: 388515 | F35: =E35/D35 -> 12532.742 | G35: 418677 | H35: =G35/D35 -> 13505.71 | K35: =I35/Schedule!D36 -> 0 | L35: Not Wrap | M35: David Strid | N35: Shon Geer | O35: Jose Tapia
A36: 2037 | B36: University Apartments (MYSA) | C36: Marpac | D36: 122 | E36: 1920850 | F36: =E36/D36 -> 15744.672 | G36: 2076783 | H36: =G36/D36 -> 17022.811 | K36: =I36/Schedule!D32 -> 0 | L36: Not Wrap | M36: Evan Chan | N36: Doyle Gustafson
A37: 2038 | B37: 2nd & John | C37: Compass | D37: 80 | E37: 1175378 | F37: =E37/D37 -> 14692.225 | G37: 1195660 | H37: =G37/D37 -> 14945.75 | L37: Wrap | M37: Justin Anderson | N37: Kurt Weagant | O37: Karl Clocksin | P37: Continental
A38: 2039 | B38: Ravello Gas Piping | C38: Shelter Holdings | D38: na | E38: 54900 | L38: Not Wrap | M38: Renay Luzama | N38: Bill Robinson
A39: 2040 | B39: Brooklyn 65 | C39: Blueprint | D39: 55 | E39: 604000 | F39: =E39/D39 -> 10981.818 | G39: 624171 | H39: =G39/D39 -> 11348.564 | L39: Not Wrap | M39: Andrew Withnell | N39: Mike Sanderson | O39: Kyle Stenson
A40: 2041 | B40: Luna | C40: Chinn | D40: 108 | E40: 1766205 | F40: =E40/D40 -> 16353.75 | G40: 1878824 | H40: =G40/D40 -> 17396.519 | L40: Not Wrap | M40: Joe Hanley | N40: James Casal | O40: Amir Molavi
...

Sheet Projects Bid
A1: Job # | B1: Job Name | C1: OWP Bid Date | D1: GC | E1: Units | F1: Base Bid | G1: Price/unit | H1: Owner | I1: Architect | J1: Engineer | K1: Area | L1: Start Date | M1: General Schedule | N1: Competitor | O1: Competitor Bid? | P1: Competitor | Q1: Competitor Bid? | R1: Competitor | S1: Competitor Bid? | T1: Notes
A2: BID | B2: Block 11 | C2: 42391 | D2: Exxel Pacific | E2: 386 | F2: 6599000 | G2: =F2/E2 -> 17095.855 | H2: Vulcan | I2: Runberg | J2: Ecotope | K2: South Lake Union | L2: 42613 | M2: 22 Months | N2: Wolfe Plumbing | P2: Ocean Park | R2: PSF Mechanical
A3: BID | B3: 44th Ave SW Apartments | C3: 42396 | D3: Blueprint | E3: 58 | F3: 569000 | G3: =F3/E3 -> 9810.3448 | H3: Blueprint | I3: Cone | J3: N/A | K3: West Seattle | L3: Spring 2016 | M3: ~16 Months | N3: DK Plumbing? | O3: Think it was $412,000 | T3: Mike Burdo sent Exh B on the following project that was put out to bid. On it there was the $412,000, which we think was for this project.
A4: BID | B4: East Union | C4: 42391 | D4: Exxel Pacific | E4: 144 | F4: 2063000 | G4: =F4/E4 -> 14326.389 | H4: Lake Union Partners | I4: Weinstein A+U | J4: Rushing | K4: Madrona | L4: Summer 2016 | M4: 18 Months | N4: Wolfe Plumbing | O4: Approx $2,013,000 | P4: Atlas Plumbing | Q4: Don't know
A5: BID | B5: Boylston Flats | C5: 42419 | D5: W.G. Clark | E5: 107 | F5: 1025000 | G5: =F5/E5 -> 9579.4393 | H5: Johnson-Carr | I5: S+H Works | J5: N/A | K5: Capitol Hill | L5: 42491 | M5: 15 Months
A6: BID | B6: Issaquah Gateway (SEE 2ND BID) | C6: 42426 | D6: Exxel Pacific | E6: 398 | F6: 4919200 | G6: =F6/E6 -> 12359.799 | H6: Wolff Company | I6: VIA | J6: Glumac | K6: Issaquah | L6: Summer 2016 | M6: 27 Months
A7: BID | B7: 66th & Roosevelt | C7: 42444 | D7: Exxel Pacific | E7: 206 | F7: 2996000 | G7: =F7/E7 -> 14543.689 | H7: HB Management | I7: Weinstein A+U | K7: Roosevelt
A8: BID | B8: 6505 15th Ave NE | C8: 42444 | D8: Exxel Pacific | E8: 222 | F8: 3343000 | G8: =F8/E8 -> 15058.559 | H8: Roosevelt Development Group | I8: GGLO | J8: PAE | K8: Roosevelt
A9: BID | B9: 103rd Avenue Apartments | C9: 42465 | D9: Chinn | E9: 162 | F9: 2867000 | G9: =F9/E9 -> 17697.531 | H9: Shintex Global Holdings, LLC | I9: GGLO | J9: Rushing | K9: Downtown Bellevue | N9: SJS Mechanical | O9: 2650000 | P9: Transit | Q9: Even less than SJS, but Chinn went with SJS
A10: BID | B10: Ravelo Apartments | C10: 42486 | D10: Shelter Holdings | E10: 102 | F10: 1465800 | G10: =F10/E10 -> 14370.588 | H10: Shelter Holdings | I10: SMR Architects | J10: Sider+Byers | K10: Redmond | L10: 42552 | M10: ~16 Months | N10: Sunrise Plumbing? | P10: Peltram | Q10: ~$160k lower
A11: BID | B11: Lake City Apartments | C11: 42496 | D11: Marpac | E11: 122 | F11: 1793000 | G11: =F11/E11 -> 14696.721 | I11: Studio19 Architects | J11: N/A | K11: Lake City | L11: 42705
A12: BID | B12: Vuecrest Apartments | C12: 42507 | D12: Compass | E12: 139 | F12: 2419000 | G12: =F12/E12 -> 17402.878 | H12: Continental Properties | I12: Encore Architects | J12: Emerald City | K12: Downtown Bellevue | L12: 42567 | M12: ~23 Months | N12: Aloisio Plumbing | O12: Don't know yet, but we are low so far. Update 5/17/16, Dan Peck told me Alosio was 5% low.
A13: BID | B13: 6921 Roosevelt Way NE | C13: 42508 | D13: Blueprint | E13: 71 | F13: 662800 | G13: =F13/E13 -> 9335.2113 | H13: Blueprint | I13: Cone | J13: N/A | K13: Roosevelt | L13: 42675 | N13: Tri-State | O13: Mike said the bids were so close they were almost matching
A14: BID | B14: Capitol Hill Lofts | C14: 42514 | D14: Marpac | E14: 55 | F14: 891000 | G14: =F14/E14 -> 16200 | H14: Vestus | I14: NK Architects | J14: N/A | K14: Capitol Hill | L14: Late 2016/early 17 | N14: Wolfe Plumbing originally bid it but pulled their number, so no competition | R14: Transit | S14: Within $60k | T14: Put bid in, he said we got it, then called back two weeks later and said that Transit got it. Classic case of us giving them a number and then they turn it over to Transit.
A15: BID | B15: Issaquah Gateway 2nd Time | C15: 42523 | D15: Exxel Pacific | E15: 398 | F15: 5049100 | G15: =F15/E15 -> 12686.181 | H15: Wolff Company | I15: VIA | J15: Glumac | K15: Issaquah | L15: Summer 2016 | M15: 27 Months | N15: Wolfe & Bigfoot possibly bid the mid-rise buildings, but sounds like no bidders on walk ups
A16: BID | B16: Park Lane Apartments | C16: 42534 | D16: Compass | E16: 128 | F16: 1839000 | G16: =F16/E16 -> 14367.188 | H16: Continental Properties | I16: Johnson Braund | J16: Emerald City | K16: Kirkland | L16: 42583 | M16: 21 Months | N16: SJS Mechanical | O16: "Very close" | P16: JD Plumbing
A17: BID | B17: Issaquah Senior Housing | C17: 42534 | D17: Exxel Pacific | E17: 146 | F17: 2249000 | G17: =F17/E17 -> 15404.11 | H17: Wolff Company | I17: VIA | J17: N/A | K17: Issaquah | L17: ? | M17: ? | N17: Bulldog | O17: 2055000 | T17: Bid to Halvorson, EP and Chinn
A18: BID | B18: 2nd & John | C18: 42565 | D18: Compass | E18: 80 | F18: 1179000 | G18: =F18/E18 -> 14737.5 | H18: Continental Properties | I18: Baylis | J18: Emerald City | K18: Capitol Hill | L18: 42614 | M18: ~16 Months
A19: BID | B19: 162 Ten | C19: 42576 | D19: Natural&Built | E19: 96 | F19: 698400 | G19: =F19/E19 -> 7275 | H19: Natural & Built | I19: Milbrandt Architects | J19: Pressler | K19: Redmond
A20: BID | B20: Cannery | C20: 42607 | D20: Exxel Pacific | E20: 54 | F20: 916400 | G20: =F20/E20 -> 16970.37 | H20: Barrientos | I20: Hewitt | J20: Rushing Narrative | K20: Pioneer Square | L20: Summer 2017
A21: BID | B21: Jefferson Park Apartments | C21: 42662 | D21: Marpac | E21: 49 | F21: 822000 | G21: =F21/E21 -> 16775.51 | I21: Encore Architects | K21: International District | L21: Not Sure | M21: Not sure | N21: Bulldog (got it) | O21: 700000 | P21: Tri-State (pulled) | Q21: 586000 | R21: Transit | S21: 930000
A22: BID | B22: Aegis Mercer Island | C22: 42682 | D22: Compass | E22: 89 | F22: 1481800 | G22: =F22/E22 -> 16649.438 | H22: Aegis | I22: Ankrom Moisan | J22: Coffman | K22: Mercer Island
A23: BID | B23: NE 65th Street | C23: 42690 | D23: Blueprint | E23: 55 | F23: 604000 | G23: =F23/E23 -> 10981.818 | H23: Blueprint | I23: Cone | J23: N/A | K23: Roosevelt | L23: Summer 2017
A24: BID | B24: NE 66th Street | C24: 42690 | D24: Blueprint | E24: 78 | F24: 839500 | G24: =F24/E24 -> 10762.821 | H24: Blueprint | I24: Cone | J24: N/A | K24: Roosevelt | L24: Summer 2017 | T24: Per conversation with Andrew on 11/30, he is probably giving us this job, but the 65th will probably go to the same plumber that did the west seattle job
A25: BID | B25: Issaquah Senior Housing | C25: 42704 | D25: Exxel Pacific | E25: 146 | F25: 2369000 | G25: =F25/E25 -> 16226.027 | H25: Wolff Company | I25: VIA | J25: Glumac | K25: Issaquah | L25: 42705 | M25: ? | N25: Aloisio Plumbing | O25: 2150000 | P25: Transit | Q25: 2350000 | R25: Wolff ended up getting this one | T25: Glumac had drawings this time
A26: BID | B26: 403 Dexter | C26: 42717 | D26: Synnergy | E26: 98 | F26: 1542000 | G26: =F26/E26 -> 15734.694 | H26: Wilshire | I26: VIA | J26: Glumac | K26: South Lake Union | L26: ? | M26: ?
A27: BID | B27: Issaquah Apartments | C27: 42726 | D27: Exxel Pacific | E27: 110 | F27: 1809400 | G27: =F27/E27 -> 16449.091 | H27: American Classic Homes | I27: Group Architect | J27: Ecotope | K27: Issaquah | L27: ?? | M27: ?? | N27: Edmonds Plumbing | O27: 1388500 | P27: United Plumbing | Q27: Not sure. Was told that Owner wants to work with United, and they have a relationship. They were cheaper too.
A28: BID | B28: Greenwood Apartments | C28: 42754 | D28: Rush Commerical | E28: 85 | F28: 1817800 | G28: =F28/E28 -> 21385.882 | H28: Greenwood Ave Investors | I28: Encore Architects | J28: Rushing | K28: Greenwood | L28: March, 2017 | M28: 14 months | N28: Dave Anderson provided a list of plumbing bidders, it was very long and very commercial
A29: BID | B29: Maple Leaf Flats Greenlake | C29: 42769 | D29: Charter | E29: 42 | F29: 724400 | G29: =F29/E29 -> 17247.619 | H29: Flatiron Properties | I29: Johnston Architects | J29: Sider+Byers | K29: Greenlake | L29: July, 2017 | M29: 13 months
A30: FYI | B30: Harbor Avenue | C30: NA | D30: Chinn | E30: 15 | F30: NA | G30: NA | K30: West Seattle | N30: SJS Mechanical | O30: 921000 | T30: Charlie asked us to look at it but hadn't realized that it was already committed to SJS. Would have been a good job.
A31: BID | B31: 4218 Roosevelt | C31: 42824 | D31: Chinn | E31: 110 | F31: 1485200 | G31: =F31/E31 -> 13501.818 | H31: G&K Brothers, Inc. | I31: Studio19 | J31: Coffman? | K31: University District | L31: ??? | M31: ???
A32: BID | B32: Bear Creek Apartments | C32: 42832 | D32: Fairfield | E32: 360 | F32: 5430700 | G32: =F32/E32 -> 15085.278 | H32: Fairfield Residential | I32: ARK Architects | J32: Interface Engineering | K32: Redmond | L32: Summer 17 | M32: Long time | N32: SJS Mechanical | P32: LOST TO JET INDUSTRIES BY 5 OR 6% | T32: I thought that Ocean Park and Allied Plumbing had submitted bids, but according to Justin with Fiarfield, they did not.
A33: BID | B33: 4218 Roosevelt | C33: 42863 | D33: Marpac | E33: 110 | F33: 1648500 | G33: =F33/E33 -> 14986.364 | H33: G&K Brothers, Inc. | I33: Studio19 | J33: Coffman? | K33: University District | L33: Late August 17 | M33: ??? | N33: SJS Mechanical | T33: Originally bid to Chinn. Owner re-bid it to Marpac. Chinn told us we were 20% low, so we raised our number to Marpac.
A34: BID | B34: Aegis Overlake | C34: 42873 | D34: Compass | E34: 118 | F34: 3210500 | G34: =F34/E34 -> 27207.627 | H34: Aegis | I34: Ankrom Moisan | J34: Coffman | K34: Bellevue | N34: Compass turned this project down. Exxel Pacific picked it up. Wolff got it for around $23k to $24k per unit.
A35: BID | B35: Metro Flats | C35: 42885 | D35: Shelter Holdings | E35: 72 | F35: 934800 | G35: =F35/E35 -> 12983.333 | H35: Shelter Holdings | I35: Johnston Architects | J35: N/A | K35: First Hill | L35: ? | M35: ?
A36: BID | B36: Auburn Town Center Apartments | C36: 42892 | D36: Compass | E36: 205 | F36: 3209000 | G36: =F36/E36 -> 15653.659 | H36: Merrill Gardens | I36: Urbal Architecture | J36: N/A | K36: Auburn | L36: ? | M36: ? | T36: BUDGET PRICING ONLY
A37: BID | B37: Bellevue Parkside | C37: 42908 | D37: Compass | E37: 136 | F37: 2592500 | G37: =F37/E37 -> 19062.5 | H37: Continental Properties | I37: Encore Architects | J37: Emerald City | K37: Bellevue | L37: Q1 2018 | M37: ? | N37: Tri-State | P37: SJS
A38: BID | B38: Bellevue Parkside Rebid | C38: 43126 | D38: Compass | E38: 136 | F38: =2623500-321000 -> 2302500 | G38: =F38/E38 -> 16930.147 | H38: Continental Properties | I38: Encore Architects | J38: Emerald City | K38: Bellevue | L38: Q1 2018 | M38: ? | N38: Tri-State | P38: SJS
A39: BID | B39: Columbia City Apartments | C39: 42912 | D39: Exxel Pacific | E39: 242 | F39: 3974000 | G39: =F39/E39 -> 16421.488 | H39: Lake Union Partners | I39: Weinstein A+U | J39: Rushing | K39: Columbia City | L39: ? | M39: ?
A40: NO BID | B40: 23rd & Jackson | C40: na | D40: Exxel Pacific | E40: 532 | H40: Vulcan | J40: Ecotope | N40: Hawk Mechanical got it, per Steve Sharrat
...

Sheet BbQuantityLink
A1: <?xml version="1.0" encoding="utf-8"?>_x000D_ <QuantityLinks Version="3">_x000D_ <Links />_x000D_ <Filesets />_x000D_ <Guids />_x000D_ </QuantityLinks> | B1: 1

Sheet Projects NOT Bid
A1: Job Name | B1: Invite Date | C1: GC | D1: Units | E1: Owner | F1: Area | G1: Reason Did Not Bid | H1: Competitor | I1: Competitor Bid? | J1: Notes
A2: Bothell Commons Phase II | B2: 44876 | C2: Avalon Bay | D2: 400 | E2: Avalon Bay | F2: Bothell | G2: Too busy to get around to
A3: Market Square | B3: 44831 | C3: Pavilion | D3: 176 | E3: Heron Properties | F3: Tacoma | G3: Been hearing bad things about Pavilion, south end job so competition will be cheap
A4: KOZ Lynnwood Apartments | B4: 44887 | C4: Kirtley-Cole | D4: 200 | E4: Koz | F4: Lynnwood | G4: Too busy to get around to, messy spec, and I imagine competition would be cheap. I found on mybuildingpermit.com that their plumbing budget is $4,220,000, which is $21,100 per unit
A5: 2501 Market Street | B5: 44894 | C5: Chinn | D5: 110 | E5: Jordan Selig Real Estate | F5: Ballard | G5: Typical Chinn asking for budgets. Job will rebid competitively in future.
A6: SRM Bellevue Way | B6: 44943 | C6: SRM | D6: 376 | E6: SRM | F6: Bellevue | G6: Very early budgeting. Will be asked to bid again in future. See notes in email I sent to myself.
A7: Apollo Apartments | B7: 44936 | C7: Exxel Pacific | D7: 255 | E7: Blackfish Capital | F7: Edmonds | G7: See email for explanation.
A8: Seatac Hyatt Hotel | B8: 44957 | C8: Chinn | D8: 198 | F8: Seatac | G8: See email for explanation.
A9: 3831 Stone Way | B9: 44965 | C9: Exxel Pacific | D9: 230 | E9: Prometheus Real Estate Group | F9: Wallingford | G9: Told Exxel Pacific that I would bid it if the senior PM called me. It's a schematic bid, and way too early, so this is probably just budget pricing. Exxel never called me. Jens said that Eric would call me, but he never did. Just going to wait until it's further along, i should get a bid invite later.
A10: Spruce Project | B10: 45071 | C10: Marpac | D10: 400 | E10: T Property Investments | F10: South seattle | G10: See email for explanation.
A11: St Lukes | B11: 45085 | C11: Venture | D11: 206 | E11: Security Properties | F11: Ballard | G11: See email for explanation.
A12: Ardea at Totem Lake | B12: 45100 | C12: Venture | D12: 170 | E12: TWG Development | F12: Totem Lake | G12: Venture project, busy with other bidding, Abossein design
A13: 1013 E Republican St | B13: 45121 | C13: Petra | D13: 75 | E13: Mike Martin? | F13: Capitol Hill | G13: Messy spec, Petra, probably a bunch of shitty plumbers bidding on it, etc
A14: Overlake Square | B14: 45120 | C14: Carmel Partners | D14: 569 | E14: Carmel Partners | F14: Redmond (Overlake) | G14: Too big. CP is big and there's a lot of risk here
A15: iVista Apartments | B15: 45133 | C15: Rush/Venture/Petra | D15: 256 | E15: Cosmos Group | F15: Lynnwood | G15: Don't have enough time before 2nd baby is due. Rush Commerical is GC. Nasty looking spec. Just got an invite to bid on Intracorp Lacey, so would like to concentrate on that. Also was invited to bid on this again in Feb/March 2024
A16: Modera Bridle Trails | B16: 45139 | C16: Mill Creek | D16: 372 | E16: Mill Creek | F16: Kirkland | G16: Atlas and JD bid it, so it's already going to be cheap. The Modera ID project was bid very cheaply, so they're going to have a very cheap expectation. Also, it's big and complicated, and I don't have time to deal with this bid. Have a baby coming in a week.
A17: 12th Place Apartments | B17: 45135 | C17: Compass | D17: 274 | E17: Gables Residential | F17: Bellevue | G17: Very messy fixture spec. Bid invite says there will be future rounds of bidding, so we will have another chance. I have a baby due in a week, and there are other projects to bid, so need to prioritize. Also, bid invite says the project won't go if it doesn't meet owners budget, so isn't very promising.
A18: Lacey Apartments | B18: 45134 | C18: Intracorp | D18: 216 | E18: Intracorp | F18: Lacey | G18: See email for explanation.
A19: AAA Management Renton | B19: 45163 | C19: Compass | D19: 343 | E19: AAA Management | F19: Renton | G19: AAA Management is shitty owner, requires a lot of time/effort. They wanted pricing on tear down, rebuild, and conversion from office to apartment. Too much time to think about. Too many other things to bid right now.
A20: Village at 47th | B20: 45187 | C20: ACG | D20: 272 | E20: Vintage Housing | F20: Tukwila | G20: Cannot find any info about permits online. Cannot figure out who bid it. Was a low level PE that called me about it, with little info. ACG is GC, which is probably a waste of time. Not sure if we want to work for them. There is other better stuff to bid on right now.
... A46: 185th Transit Center Apartments | B46: 45518 | C46: Redhawk | D46: 26 | E46: ? | F46: Shoreline | G46: Thought about doing this one, but I searched the lien records for Redhawk and it came up with several pages. Don't think it's worth even throwing my number out there.
A47: Sunrise 12 Apartments | B47: 45523 | C47: High Country | D47: 12 | F47: Shoreline | G47: Only 12 units, and I have plenty of other bids to concentrate on right now
A48: 165 Washington | B48: 45527 | C48: WG Clark | D48: 77 | E48: Johnson Carr | F48: Pioneer Square | G48: Feel like a project of this size is going to get a lot of bidders, and I've never been able to get a WG Clark job, so it's kind of pointless, and there's a ton of other jobs to bid on. Someone is going to come in stupid low.
A49: 149th Shoreline | B49: 45559 | C49: Rush | D49: 252 | E49: AAA Management | F49: Shoreline | G49: Job has been around for years, waste of time since it's AAA management and Rush. Lots to bid on, not going to waste my time on this one.
A50: Tacoma Holiday Inn Express | C50: Petra/Rmiller | D50: 127 | F50: Tacoma | G50: Too much to bid on right now, would require a lot of effort, and it's for GC's that I haven't worked for.
A51: Overlake Mixed Use | C51: WG Clark | D51: 233 | E51: Johnson Carr | F51: Overlake Redmond | G51: Too much to bid on right now, and didn't have time to get around to this one. Seems like Johnson Carr is struggling to get jobs going right now and I doubt this one is starting very soon.
A52: Uptown Apartments | B52: 45581 | C52: Compass | D52: 215 | E52: Kamiak | F52: Queen Anne | G52: Budgeting only. Kamiak can't get any jobs to start right now. Waste of time. If compass wants me to bid it, they'll call me.
A53: Bell 10 | B53: 45581 | C53: WG Clark | D53: 102 | E53: Guntower Capital | F53: Bellevue | G53: Alpine/Atlas has already done plumbing engineering, so they have a cheap price. Waste of time.
A54: 4742 Apartments | B54: 45636 | C54: WGClark, Rmiller, Chinn | D54: 89 | E54: Campus U Development | F54: U District | G54: Too much to bid right now, they have 3 GC's looking at it, seems like a waste of time.
A55: Astor Townhomes | B55: 45667 | C55: Fullwiler Construction | D55: 39 | E55: Fullwiler Construction, Shelter Homes? | F55: Roosevelt | G55: Never worked for these guys, seems like a messy job, townhomes, etc.
A56: Pixel Apartments | B56: 45665 | C56: Gencap | D56: 179 | E56: McCraken Properties | F56: Overlake Redmond | G56: Gencap is a waste of time, always gives their jobs to JD
A57: 12th & Olive | B57: 45671 | C57: Rush | D57: 134 | E57: Mack Real Estate (not the Mack that we've worked for before, this is a big one out of New York) | F57: Capitol Hill | G57: Wanted it back within a week. Seems unlikely to actually go because he's asking me for prices to add units, revise major parts of building. Rush uses super cheap numbers that I don't feel like working for.
A58: Acer House | B58: 45672 | C58: Rush | D58: 121 | E58: Great Expectations | F58: Central District | G58: Atlas has job. Trademark is bidding too. I bid on it the first time around, but it's very apparent that it's a waste of my time and is going to go for a stupid low number.
A59: 2nd & Bell | B59: 45674 | C59: Rush | D59: 175 | E59: HB Management / Paragon Real Estate | F59: Belltown | G59: Wolfe did design on job. Rush is used to stupid low numbers, and Trademark will probably be bidding. No point in wasting my time on this. Note that I bid this to Exxel I February 2021
A60: Tacoma Trax | B60: 45679 | C60: Gencap | D60: 202 | E60: Parkview Financial of Los Angeles (used to be a GIS International job) | F60: Tacoma | G60: Gencap is a waste of time. They are calling it "budgetary" pricing.
A61: Proctor 4 | B61: 45684 | C61: Rush | D61: 98 | E61: Rush | F61: Tacoma | G61: Rush is a waste of time. Going to be competing with Trademark and Atlas prices. They make you do finanical pre-quals and list your OH&P, etc.
A62: 124 Tacoma | B62: 45688 | C62: Rush | D62: 147 | E62: Rush | F62: Tacoma | G62: Rush is a waste of time. Going to be competing with Trademark and Atlas prices. They make you do finanical pre-quals and list your OH&P, etc.
A63: Milano Issaquah | B63: 45742 | C63: R Miller | D63: 65 | E63: Not sure | F63: Issaquah | G63: Too much to bid right now. Rush was looking at this a year ago. Doesn't seem like a good project.
... A79: Burl Apartments | B79: 46059 | C79: Compass | D79: 171 | E79: Spectrum | F79: Shoreline | G79: Was not able to get around to this bid because of hawaii trip and too busy. It had a lot of bidders on it including LJM, Wolfe, Atlas, Artemis and Western Mech, Trademark.
A80: 1661 East Olive Way | C80: Compass | G80: Too busy. Budget only at this time. Will probably be invited again.
...
