Workbook

Sheet Overview
B2: Job #2010 · Chinn Old Town Mixed Use
B3: Cortex JCR Summary • Chinn Construction, LLC • Seattle, WA • 165-unit mixed-use multifamily apartments + ground-floor retail • Sep 2012 – Sep 2014 (~24 months)
B5: PROJECT OVERVIEW
B6: Project Job # | C6: 2010
B7: Project Name: | C7: Chinn Old Town Mixed Use
B8: General Contractor | C8: Chinn Construction, LLC
B9: Location | C9: Seattle, WA
B10: Project Duration | C10: Sep 2012 – Sep 2014 (~24 months)
B11: Total Unique Documents | C11: Old Town folder: Contract, Billing (aggregate + 19 SOVs), PO_s (73), Permits, Plans, Submittals
B13: CONTRACT VALUE | D13: NET PROFIT | F13: DIRECT COST | H13: LABOR HOURS
B14: $1,386,419 | D14: $800,420 | F14: $585,999 | H14: 9,992
B15: Original $1,469,800 + $-83,381 COs | D15: 57.7% margin | F15: 42.3% of revenue | H15: 22 workers
B18: COST BREAKDOWN
B19: Category | C19: Budget | D19: Actual | E19: Variance | F19: % Budget | G19: % of Cost
B20: Labor | C20: 303565 | D20: 196271.13 | E20: =C20-D20 -> 107293.87 | F20: =IF(C20=0,0,D20/C20) -> 0.64655388 | G20: =IF($D$24=0,0,D20/$D$24) -> 0.33493448
B21: Material | C21: 504680 | D21: 282662.77 | E21: =C21-D21 -> 222017.23 | F21: =IF(C21=0,0,D21/C21) -> 0.56008316 | G21: =IF($D$24=0,0,D21/$D$24) -> 0.48236084
B22: Overhead | C22: 8000 | D22: 3650.67 | E22: =C22-D22 -> 4349.33 | F22: =IF(C22=0,0,D22/C22) -> 0.45633375 | G22: =IF($D$24=0,0,D22/$D$24) -> 0.0062298274
B23: Burden | C23: 161672.55 | D23: 103414.01 | E23: =C23-D23 -> 58258.54 | F23: =IF(C23=0,0,D23/C23) -> 0.63965101 | G23: =IF($D$24=0,0,D23/$D$24) -> 0.17647485
B24: TOTAL | C24: =SUM(C20:C23) -> 977917.55 | D24: =SUM(D20:D23) -> 585998.58 | E24: =C24-D24 -> 391918.97 | F24: =IF(C24=0,0,D24/C24) -> 0.59923107 | G24: 1
B27: PROJECT PROFILE
B28: Metric | C28: Value | D28: Metric | E28: Value | F28: Metric | G28: Value
B29: Plumbing Units | C29: 165 | D29: Water Closets | E29: 165 | F29: Kitchen Sinks | G29: 150
B30: Total Fixtures | C30: 803 | D30: Lavatories | E30: 175 | F30: Showers | G30: 15
B31: Fixtures / Unit | C31: 4.87 | D31: Tubs | E31: 149 | F31: Auto Washers | G31: 149
B32: Stacks | C32: 30 | D32: Duration | E32: 24 mo | F32: Cost Codes | G32: 28
B36: SOURCES
B37: Job #2010 — Chinn Old Town Mixed Use • GC: Chinn Construction, LLC • Seattle, WA
B38: Canonical source: 2010 Job Detail Report.pdf (123 pages, OWP Sage Timberline export)
B39: Cost codes parsed: 28
B40: Unit count (165) and fixture count (803) confirmed from existing project data
B41: Mixed-use: 165 plumbing units, 175 lavatories (suggests 10 powder-room units) + 15 shower-only units
B42: Billing: OLD TOWN AGGREGATE BILLING.xlsx (18 pay apps Sep 2012 – Sep 2014)
B43: Final contract $1,386,419 (original $1,469,800 + $-83,381 COs)

Sheet Budget vs Actual
B2: Budget vs Actual — All Cost Codes
B4: Code | C4: Description | D4: Orig Budget | E4: Rev Budget | F4: Actual | G4: Variance | H4: % Used
B5: LABOR
B6: 011 | C6: DS & RD Labor | D6: 7590 | E6: 7590 | F6: 2137 | G6: =E6-F6 -> 5453 | H6: =IF(E6=0,0,F6/E6) -> 0.28155468
B7: 100 | C7: Supervision | D7: 10430 | E7: 10430 | F7: 4944 | G7: =E7-F7 -> 5486 | H7: =IF(E7=0,0,F7/E7) -> 0.47401726
B8: 101 | C8: Takeoff & Purchase Labor | D8: 7450 | E8: 7450 | F8: 4286 | G8: =E8-F8 -> 3164 | H8: =IF(E8=0,0,F8/E8) -> 0.57530201
B9: 110 | C9: Underground Labor | D9: 3820 | E9: 3820 | F9: 959 | G9: =E9-F9 -> 2861 | H9: =IF(E9=0,0,F9/E9) -> 0.25104712
B10: 111 | C10: Garage Labor | D10: 39100 | E10: 39100 | F10: 28821.5 | G10: =E10-F10 -> 10278.5 | H10: =IF(E10=0,0,F10/E10) -> 0.73712276
B11: 112 | C11: Canout Labor | D11: 6650 | E11: 6650 | F11: 2982.25 | G11: =E11-F11 -> 3667.75 | H11: =IF(E11=0,0,F11/E11) -> 0.44845865
B12: 120 | C12: Roughin Labor | D12: 204925 | E12: 159525 | F12: 114688.38 | G12: =E12-F12 -> 44836.62 | H12: =IF(E12=0,0,F12/E12) -> 0.71893672
B13: 130 | C13: Finish Labor | D13: 31000 | E13: 31500 | F13: 29825 | G13: =E13-F13 -> 1675 | H13: =IF(E13=0,0,F13/E13) -> 0.9468254
B14: 140 | C14: Gas Labor | D14: 3600 | E14: 3600 | F14: 1712 | G14: =E14-F14 -> 1888 | H14: =IF(E14=0,0,F14/E14) -> 0.47555556
B15: 141 | C15: Water Main/Insulation Lab | D15: 14900 | E15: 33900 | F15: 3672 | G15: =E15-F15 -> 30228 | H15: =IF(E15=0,0,F15/E15) -> 0.10831858
B16: 142 | C16: Mech Room Labor | D16: 0 | E16: 0 | F16: 1871 | G16: =E16-F16 -> -1871 | H16: =IF(E16=0,0,F16/E16) -> 0
B17: 145 | C17: Tub/Shower Labor | D17: 0 | E17: 0 | F17: 373 | G17: =E17-F17 -> -373 | H17: =IF(E17=0,0,F17/E17) -> 0
B18: MATERIAL
B19: 039 | C19: DS & RD Material | D19: 11500 | E19: 11500 | F19: 1188.86 | G19: =E19-F19 -> 10311.14 | H19: =IF(E19=0,0,F19/E19) -> 0.10337913
B20: 210 | C20: Underground Material | D20: 3000 | E20: 3000 | F20: 1514.24 | G20: =E20-F20 -> 1485.76 | H20: =IF(E20=0,0,F20/E20) -> 0.50474667
B21: 211 | C21: Garage Material | D21: 63370 | E21: 63370 | F21: 11302.9 | G21: =E21-F21 -> 52067.1 | H21: =IF(E21=0,0,F21/E21) -> 0.17836358
B22: 212 | C22: Canout Material | D22: 7980 | E22: 7980 | F22: 5720.08 | G22: =E22-F22 -> 2259.92 | H22: =IF(E22=0,0,F22/E22) -> 0.71680201
B23: 220 | C23: Roughin Material | D23: 204925 | E23: 130025 | F23: 66457.52 | G23: =E23-F23 -> 63567.48 | H23: =IF(E23=0,0,F23/E23) -> 0.5111134
B24: 230 | C24: Finish Material | D24: 261700 | E24: 251305 | F24: 173652.72 | G24: =E24-F24 -> 77652.28 | H24: =IF(E24=0,0,F24/E24) -> 0.69100384
B25: 240 | C25: Gas Material | D25: 3600 | E25: 3600 | F25: 1080.05 | G25: =E25-F25 -> 2519.95 | H25: =IF(E25=0,0,F25/E25) -> 0.30001389
B26: 241 | C26: Water Main/Insulation Mat | D26: 14900 | E26: 33900 | F26: 20000.49 | G26: =E26-F26 -> 13899.51 | H26: =IF(E26=0,0,F26/E26) -> 0.58998496
B27: 242 | C27: Mech Room Material | D27: 0 | E27: 0 | F27: 1098.46 | G27: =E27-F27 -> -1098.46 | H27: =IF(E27=0,0,F27/E27) -> 0
B28: 245 | C28: Tub/Shower Material | D28: 0 | E28: 0 | F28: 647.45 | G28: =E28-F28 -> -647.45 | H28: =IF(E28=0,0,F28/E28) -> 0
B29: OVERHEAD
B30: 600 | C30: Subcontractor | D30: 1000 | E30: 1000 | F30: 1212 | G30: =E30-F30 -> -212 | H30: =IF(E30=0,0,F30/E30) -> 1.212
B31: 601 | C31: Engineering/Plans | D31: 4000 | E31: 4000 | F31: 2404.21 | G31: =E31-F31 -> 1595.79 | H31: =IF(E31=0,0,F31/E31) -> 0.6010525
B32: 603 | C32: Permits & Licenses | D32: 3000 | E32: 3000 | F32: 34.46 | G32: =E32-F32 -> 2965.54 | H32: =IF(E32=0,0,F32/E32) -> 0.011486667
B33: BURDEN
B34: 995 | C34: Payroll Burden | D34: 145220.27 | E34: 137421.67 | F34: 87883.44 | G34: =E34-F34 -> 49538.23 | H34: =IF(E34=0,0,F34/E34) -> 0.63951661
B35: 998 | C35: Payroll Taxes | D35: 26232.23 | E35: 24250.88 | F35: 15530.57 | G35: =E35-F35 -> 8720.31 | H35: =IF(E35=0,0,F35/E35) -> 0.64041264
B36: TOTAL | C36: Direct Cost | D36: 1079892.5 | E36: 977917.55 | F36: 585998.58 | G36: =E36-F36 -> 391918.97 | H36: =IF(E36=0,0,F36/E36) -> 0.59923107
B39: SOURCES
B40: Job #2010 — Chinn Old Town Mixed Use • GC: Chinn Construction, LLC • Seattle, WA
B41: Canonical source: 2010 Job Detail Report.pdf (123 pages, OWP Sage Timberline export)
B42: Cost codes parsed: 28
B43: Unit count (165) and fixture count (803) confirmed from existing project data
B44: Mixed-use: 165 plumbing units, 175 lavatories (suggests 10 powder-room units) + 15 shower-only units
...

Sheet Cost Breakdown
B2: Cost Breakdown — Category Deep Dive
B4: A. CATEGORY SHARE OF DIRECT COST
B5: Category | C5: # Codes | D5: Budget | E5: Actual | F5: Variance | G5: % Budget | H5: % of Cost | I5: Per Unit
B6: Labor | C6: 12 | D6: 303565 | E6: 196271.13 | F6: =D6-E6 -> 107293.87 | G6: =IF(D6=0,0,E6/D6) -> 0.64655388 | H6: =IF(585998.58=0,0,E6/585998.58) -> 0.33493448 | I6: =IF(165=0,0,E6/165) -> 1189.522
B7: Material | C7: 10 | D7: 504680 | E7: 282662.77 | F7: =D7-E7 -> 222017.23 | G7: =IF(D7=0,0,E7/D7) -> 0.56008316 | H7: =IF(585998.58=0,0,E7/585998.58) -> 0.48236084 | I7: =IF(165=0,0,E7/165) -> 1713.1077
B8: Overhead | C8: 3 | D8: 8000 | E8: 3650.67 | F8: =D8-E8 -> 4349.33 | G8: =IF(D8=0,0,E8/D8) -> 0.45633375 | H8: =IF(585998.58=0,0,E8/585998.58) -> 0.0062298274 | I8: =IF(165=0,0,E8/165) -> 22.125273
B9: Burden | C9: 2 | D9: 161672.55 | E9: 103414.01 | F9: =D9-E9 -> 58258.54 | G9: =IF(D9=0,0,E9/D9) -> 0.63965101 | H9: =IF(585998.58=0,0,E9/585998.58) -> 0.17647485 | I9: =IF(165=0,0,E9/165) -> 626.75158
B12: B. LARGEST OVERRUNS (Actual > Revised Budget)
B13: Code | C13: Description | D13: Rev Budget | E13: Actual | F13: Overrun | G13: % Over
B14: 142 | C14: Mech Room Labor | D14: 0 | E14: 1871 | F14: =E14-D14 -> 1871 | G14: =IF(D14=0,0,F14/D14) -> 0
B15: 242 | C15: Mech Room Material | D15: 0 | E15: 1098.46 | F15: =E15-D15 -> 1098.46 | G15: =IF(D15=0,0,F15/D15) -> 0
B16: 245 | C16: Tub/Shower Material | D16: 0 | E16: 647.45 | F16: =E16-D16 -> 647.45 | G16: =IF(D16=0,0,F16/D16) -> 0
B17: 145 | C17: Tub/Shower Labor | D17: 0 | E17: 373 | F17: =E17-D17 -> 373 | G17: =IF(D17=0,0,F17/D17) -> 0
B18: 600 | C18: Subcontractor | D18: 1000 | E18: 1212 | F18: =E18-D18 -> 212 | G18: =IF(D18=0,0,F18/D18) -> 0.212
B21: C. LARGEST SAVINGS (Actual < Revised Budget)
B22: Code | C22: Description | D22: Rev Budget | E22: Actual | F22: Savings | G22: % Under
B23: 230 | C23: Finish Material | D23: 251305 | E23: 173652.72 | F23: =D23-E23 -> 77652.28 | G23: =IF(D23=0,0,F23/D23) -> 0.30899616
B24: 220 | C24: Roughin Material | D24: 130025 | E24: 66457.52 | F24: =D24-E24 -> 63567.48 | G24: =IF(D24=0,0,F24/D24) -> 0.4888866
B25: 211 | C25: Garage Material | D25: 63370 | E25: 11302.9 | F25: =D25-E25 -> 52067.1 | G25: =IF(D25=0,0,F25/D25) -> 0.82163642
B26: 995 | C26: Payroll Burden | D26: 137421.67 | E26: 87883.44 | F26: =D26-E26 -> 49538.23 | G26: =IF(D26=0,0,F26/D26) -> 0.36048339
B27: 120 | C27: Roughin Labor | D27: 159525 | E27: 114688.38 | F27: =D27-E27 -> 44836.62 | G27: =IF(D27=0,0,F27/D27) -> 0.28106328
B28: 141 | C28: Water Main/Insulation Lab | D28: 33900 | E28: 3672 | F28: =D28-E28 -> 30228 | G28: =IF(D28=0,0,F28/D28) -> 0.89168142
B29: 241 | C29: Water Main/Insulation Mat | D29: 33900 | E29: 20000.49 | F29: =D29-E29 -> 13899.51 | G29: =IF(D29=0,0,F29/D29) -> 0.41001504
B30: 039 | C30: DS & RD Material | D30: 11500 | E30: 1188.86 | F30: =D30-E30 -> 10311.14 | G30: =IF(D30=0,0,F30/D30) -> 0.89662087
B31: 111 | C31: Garage Labor | D31: 39100 | E31: 28821.5 | F31: =D31-E31 -> 10278.5 | G31: =IF(D31=0,0,F31/D31) -> 0.26287724
B32: 998 | C32: Payroll Taxes | D32: 24250.88 | E32: 15530.57 | F32: =D32-E32 -> 8720.31 | G32: =IF(D32=0,0,F32/D32) -> 0.35958736
B35: SOURCES
B36: Job #2010 — Chinn Old Town Mixed Use • GC: Chinn Construction, LLC • Seattle, WA
B37: Canonical source: 2010 Job Detail Report.pdf (123 pages, OWP Sage Timberline export)
B38: Cost codes parsed: 28
B39: Unit count (165) and fixture count (803) confirmed from existing project data
B40: Mixed-use: 165 plumbing units, 175 lavatories (suggests 10 powder-room units) + 15 shower-only units
B41: Billing: OLD TOWN AGGREGATE BILLING.xlsx (18 pay apps Sep 2012 – Sep 2014)
B42: Final contract $1,386,419 (original $1,469,800 + $-83,381 COs)

Sheet Material
B2: Material Spend Analysis
B3: 10 material cost codes • $282,663 JDR material • 18 AP vendors • $362,722 total AP
B5: A. MATERIAL BY COST CODE
B6: Code | C6: Description | D6: Rev Budget | E6: Actual | F6: Variance | G6: % Used | H6: % of Mat | I6: Per Unit
B7: 039 | C7: DS & RD Material | D7: 11500 | E7: 1188.86 | F7: =D7-E7 -> 10311.14 | G7: =IF(D7=0,0,E7/D7) -> 0.10337913 | H7: =IF(282662.77=0,0,E7/282662.77) -> 0.0042059306 | I7: =IF(165=0,0,E7/165) -> 7.2052121
B8: 210 | C8: Underground Material | D8: 3000 | E8: 1514.24 | F8: =D8-E8 -> 1485.76 | G8: =IF(D8=0,0,E8/D8) -> 0.50474667 | H8: =IF(282662.77=0,0,E8/282662.77) -> 0.005357055 | I8: =IF(165=0,0,E8/165) -> 9.1772121
B9: 211 | C9: Garage Material | D9: 63370 | E9: 11302.9 | F9: =D9-E9 -> 52067.1 | G9: =IF(D9=0,0,E9/D9) -> 0.17836358 | H9: =IF(282662.77=0,0,E9/282662.77) -> 0.039987226 | I9: =IF(165=0,0,E9/165) -> 68.502424
B10: 212 | C10: Canout Material | D10: 7980 | E10: 5720.08 | F10: =D10-E10 -> 2259.92 | G10: =IF(D10=0,0,E10/D10) -> 0.71680201 | H10: =IF(282662.77=0,0,E10/282662.77) -> 0.020236411 | I10: =IF(165=0,0,E10/165) -> 34.667152
B11: 220 | C11: Roughin Material | D11: 130025 | E11: 66457.52 | F11: =D11-E11 -> 63567.48 | G11: =IF(D11=0,0,E11/D11) -> 0.5111134 | H11: =IF(282662.77=0,0,E11/282662.77) -> 0.23511239 | I11: =IF(165=0,0,E11/165) -> 402.77285
B12: 230 | C12: Finish Material | D12: 251305 | E12: 173652.72 | F12: =D12-E12 -> 77652.28 | G12: =IF(D12=0,0,E12/D12) -> 0.69100384 | H12: =IF(282662.77=0,0,E12/282662.77) -> 0.61434592 | I12: =IF(165=0,0,E12/165) -> 1052.4407
B13: 240 | C13: Gas Material | D13: 3600 | E13: 1080.05 | F13: =D13-E13 -> 2519.95 | G13: =IF(D13=0,0,E13/D13) -> 0.30001389 | H13: =IF(282662.77=0,0,E13/282662.77) -> 0.0038209843 | I13: =IF(165=0,0,E13/165) -> 6.5457576
B14: 241 | C14: Water Main/Insulation Mat | D14: 33900 | E14: 20000.49 | F14: =D14-E14 -> 13899.51 | G14: =IF(D14=0,0,E14/D14) -> 0.58998496 | H14: =IF(282662.77=0,0,E14/282662.77) -> 0.070757426 | I14: =IF(165=0,0,E14/165) -> 121.21509
B15: 242 | C15: Mech Room Material | D15: 0 | E15: 1098.46 | F15: =D15-E15 -> -1098.46 | G15: =IF(D15=0,0,E15/D15) -> 0 | H15: =IF(282662.77=0,0,E15/282662.77) -> 0.0038861149 | I15: =IF(165=0,0,E15/165) -> 6.6573333
B16: 245 | C16: Tub/Shower Material | D16: 0 | E16: 647.45 | F16: =D16-E16 -> -647.45 | G16: =IF(D16=0,0,E16/D16) -> 0 | H16: =IF(282662.77=0,0,E16/282662.77) -> 0.0022905387 | I16: =IF(165=0,0,E16/165) -> 3.9239394
B17: TOTAL | C17: All Material | D17: =SUM(D7:D16) -> 504680 | E17: =SUM(E7:E16) -> 282662.77 | F17: =D17-E17 -> 222017.23 | G17: =IF(D17=0,0,E17/D17) -> 0.56008316 | H17: 1 | I17: =IF(165=0,0,E17/165) -> 1713.1077
B20: B. VENDORS BY SPEND (AP)
B21: Vendor | C21: # Invoices | D21: Total Spend | E21: % of AP | I21: Avg Invoice
B22: Rosen Supply Company, Inc. | C22: 73 | D22: 215859.94 | E22: =IF(362721.85=0,0,D22/362721.85) -> 0.59511149 | I22: =IF(C22=0,0,D22/C22) -> 2956.9855
B23: Ferguson Enterprises, Inc. | C23: 58 | D23: 84342.57 | E23: =IF(362721.85=0,0,D23/362721.85) -> 0.23252685 | I23: =IF(C23=0,0,D23/C23) -> 1454.1822
B24: Bank of America CC | C24: 3 | D24: 30892.62 | E24: =IF(362721.85=0,0,D24/362721.85) -> 0.085168897 | I24: =IF(C24=0,0,D24/C24) -> 10297.54
B25: Franklin Engineering | C25: 4 | D25: 10463 | E25: =IF(362721.85=0,0,D25/362721.85) -> 0.028845795 | I25: =IF(C25=0,0,D25/C25) -> 2615.75
B26: Keller Supply Company | C26: 7 | D26: 10106.67 | E26: =IF(362721.85=0,0,D26/362721.85) -> 0.027863417 | I26: =IF(C26=0,0,D26/C26) -> 1443.81
B27: Quality Concrete Products, Inc. | C27: 2 | D27: 2414 | E27: =IF(362721.85=0,0,D27/362721.85) -> 0.0066552373 | I27: =IF(C27=0,0,D27/C27) -> 1207
B28: United Rentals, Inc. | C28: 6 | D28: 2404.21 | E28: =IF(362721.85=0,0,D28/362721.85) -> 0.006628247 | I28: =IF(C28=0,0,D28/C28) -> 400.70167
B29: Ferguson Enterprises, Inc. #3007 | C29: 7 | D29: 2271.7 | E29: =IF(362721.85=0,0,D29/362721.85) -> 0.0062629257 | I29: =IF(C29=0,0,D29/C29) -> 324.52857
B30: Rosen Supply Kirkland | C30: 3 | D30: 1831.58 | E30: =IF(362721.85=0,0,D30/362721.85) -> 0.0050495442 | I30: =IF(C30=0,0,D30/C30) -> 610.52667
B31: Duraseal, Inc. | C31: 1 | D31: 950 | E31: =IF(362721.85=0,0,D31/362721.85) -> 0.0026190868 | I31: =IF(C31=0,0,D31/C31) -> 950
B32: DRSi | C32: 2 | D32: 265.36 | E32: =IF(362721.85=0,0,D32/362721.85) -> 0.00073157986 | I32: =IF(C32=0,0,D32/C32) -> 132.68
B33: R.A. Brown Backflow Testing | C33: 1 | D33: 212 | E33: =IF(362721.85=0,0,D33/362721.85) -> 0.00058446989 | I33: =IF(C33=0,0,D33/C33) -> 212
... B39: C.M. Hoskins Company | C39: 1 | D39: 54.4 | E39: =IF(362721.85=0,0,D39/362721.85) -> 0.00014997718 | I39: =IF(C39=0,0,D39/C39) -> 54.4
B40: TOTAL | C40: =SUM(C22:C39) -> 175 | D40: =SUM(D22:D39) -> 362721.85 | E40: 1
B43: SOURCES
B44: Job #2010 — Chinn Old Town Mixed Use • GC: Chinn Construction, LLC • Seattle, WA
B45: Canonical source: 2010 Job Detail Report.pdf (123 pages, OWP Sage Timberline export)
B46: Cost codes parsed: 28
B47: Unit count (165) and fixture count (803) confirmed from existing project data
B48: Mixed-use: 165 plumbing units, 175 lavatories (suggests 10 powder-room units) + 15 shower-only units
B49: Billing: OLD TOWN AGGREGATE BILLING.xlsx (18 pay apps Sep 2012 – Sep 2014)
B50: Final contract $1,386,419 (original $1,469,800 + $-83,381 COs)
B51: Vendor AP ties to JDR 'by Source: AP' line (362,721.85)

Sheet Crew & Labor
B2: Crew & Labor — Per-Worker Breakdown
B4: Worker | C4: Hours | D4: Gross Pay | E4: $/Hour | F4: Tier
B5: Anderson, Richard P | C5: 1681 | D5: 42050 | E5: =IF(C5=0,0,D5/C5) -> 25.014872 | F5: Mid
B6: Barnhart, Joseph N | C6: 1588 | D6: 46498.5 | E6: =IF(C6=0,0,D6/C6) -> 29.281171 | F6: Mid
B7: Hayton, Evan R | C7: 1465 | D7: 19207 | E7: =IF(C7=0,0,D7/C7) -> 13.11058 | F7: Apprentice
B8: Garcia, Jordan X | C8: 1192 | D8: 15781 | E8: =IF(C8=0,0,D8/C8) -> 13.239094 | F8: Apprentice
B9: Wilson, Garret A | C9: 833.5 | D9: 11129.5 | E9: =IF(C9=0,0,D9/C9) -> 13.352729 | F9: Apprentice
B10: Kinssies, Jr, John E | C10: 727.5 | D10: 9796.5 | E10: =IF(C10=0,0,D10/C10) -> 13.465979 | F10: Apprentice
B11: Waites, Thaddeus Z | C11: 680 | D11: 18200 | E11: =IF(C11=0,0,D11/C11) -> 26.764706 | F11: Mid
B12: Mayfield, Elijah S | C12: 366 | D12: 4758 | E12: =IF(C12=0,0,D12/C12) -> 13 | F12: Apprentice
B13: Soto Serna, Cesar E | C13: 366 | D13: 4114 | E13: =IF(C13=0,0,D13/C13) -> 11.240437 | F13: Apprentice
B14: Gerard, Jeffrey S | C14: 314.5 | D14: 10992.5 | E14: =IF(C14=0,0,D14/C14) -> 34.952305 | F14: Senior
B15: Holmes, Anthony R | C15: 301 | D15: 3660 | E15: =IF(C15=0,0,D15/C15) -> 12.159468 | F15: Apprentice
B16: Nabbefeld, Maxwell B | C16: 112 | D16: 1344 | E16: =IF(C16=0,0,D16/C16) -> 12 | F16: Apprentice
... B26: Arreola, Israel A | C26: 2 | D26: 24 | E26: =IF(C26=0,0,D26/C26) -> 12 | F26: Apprentice
B27: TOTAL (22 workers) | C27: =SUM(C5:C26) -> 9923.5 | D27: =SUM(D5:D26) -> 191760.25 | E27: =IF(C27=0,0,D27/C27) -> 19.323852
B30: SOURCES
B31: Job #2010 — Chinn Old Town Mixed Use • GC: Chinn Construction, LLC • Seattle, WA
B32: Canonical source: 2010 Job Detail Report.pdf (123 pages, OWP Sage Timberline export)
B33: Cost codes parsed: 28
B34: Unit count (165) and fixture count (803) confirmed from existing project data
B35: Mixed-use: 165 plumbing units, 175 lavatories (suggests 10 powder-room units) + 15 shower-only units
B36: Billing: OLD TOWN AGGREGATE BILLING.xlsx (18 pay apps Sep 2012 – Sep 2014)
B37: Final contract $1,386,419 (original $1,469,800 + $-83,381 COs)
B38: Tier: Apprentice <$18/hr, Mid $18–30, Senior >$30

Sheet Crew Analytics
B2: Crew Analytics
B4: A. TIER DISTRIBUTION
B5: Tier | C5: # Workers | D5: Hours | E5: Gross Pay | F5: % of Hours
B6: Senior | C6: 2 | D6: 325.5 | E6: 11350.5 | F6: =IF(9923.5=0,0,D6/9923.5) -> 0.032800927
B7: Mid | C7: 4 | D7: 3956 | E7: 106951.5 | F7: =IF(9923.5=0,0,D7/9923.5) -> 0.39864967
B8: Apprentice | C8: 16 | D8: 5642 | E8: 73458.25 | F8: =IF(9923.5=0,0,D8/9923.5) -> 0.5685494
B11: B. WAGE STATISTICS
B12: Blended Gross Wage | C12: 19.323852 | F12: Payroll $ ÷ payroll hours (pre-burden)
B13: Fully-Loaded Wage | C13: 30.19954 | F13: (Labor + Burden) ÷ total hours
B14: Burden Multiplier | C14: 1.5628116 | F14: Fully loaded ÷ gross wage
B15: Min Worker Rate | C15: 11.170213 | F15: Cheapest apprentice hour
B16: Max Worker Rate | C16: 34.952305 | F16: Most expensive foreman hour
B17: Avg Hours / Worker | C17: 451.06818 | F17: Crew continuity indicator
B20: SOURCES
B21: Job #2010 — Chinn Old Town Mixed Use • GC: Chinn Construction, LLC • Seattle, WA
B22: Canonical source: 2010 Job Detail Report.pdf (123 pages, OWP Sage Timberline export)
B23: Cost codes parsed: 28
B24: Unit count (165) and fixture count (803) confirmed from existing project data
B25: Mixed-use: 165 plumbing units, 175 lavatories (suggests 10 powder-room units) + 15 shower-only units
B26: Billing: OLD TOWN AGGREGATE BILLING.xlsx (18 pay apps Sep 2012 – Sep 2014)
B27: Final contract $1,386,419 (original $1,469,800 + $-83,381 COs)

Sheet Productivity
B2: Productivity — Phase & Unit Metrics
B4: A. LABOR HOURS BY PHASE
B5: Phase | C5: Labor Code | D5: Hours | E5: % of Total | F5: Hours / Unit
B6: DS & RD | C6: 011 | D6: 90 | E6: =IF(9992.25=0,0,D6/9992.25) -> 0.0090069804 | F6: =IF(165=0,0,D6/165) -> 0.54545455
B7: Supervision | C7: 100 | D7: 138 | E7: =IF(9992.25=0,0,D7/9992.25) -> 0.013810703 | F7: =IF(165=0,0,D7/165) -> 0.83636364
B8: Takeoff & Purchasing | C8: 101 | D8: 124 | E8: =IF(9992.25=0,0,D8/9992.25) -> 0.012409617 | F8: =IF(165=0,0,D8/165) -> 0.75151515
B9: Underground | C9: 110 | D9: 30 | E9: =IF(9992.25=0,0,D9/9992.25) -> 0.0030023268 | F9: =IF(165=0,0,D9/165) -> 0.18181818
B10: Garage | C10: 111 | D10: 1345 | E10: =IF(9992.25=0,0,D10/9992.25) -> 0.13460432 | F10: =IF(165=0,0,D10/165) -> 8.1515152
B11: Canout | C11: 112 | D11: 122.5 | E11: =IF(9992.25=0,0,D11/9992.25) -> 0.012259501 | F11: =IF(165=0,0,D11/165) -> 0.74242424
B12: Roughin | C12: 120 | D12: 6202.25 | E12: =IF(9992.25=0,0,D12/9992.25) -> 0.62070605 | F12: =IF(165=0,0,D12/165) -> 37.589394
B13: Finish | C13: 130 | D13: 1569 | E13: =IF(9992.25=0,0,D13/9992.25) -> 0.15702169 | F13: =IF(165=0,0,D13/165) -> 9.5090909
B14: Gas | C14: 140 | D14: 79 | E14: =IF(9992.25=0,0,D14/9992.25) -> 0.0079061272 | F14: =IF(165=0,0,D14/165) -> 0.47878788
B15: Water Main / Insulation | C15: 141 | D15: 189.5 | E15: =IF(9992.25=0,0,D15/9992.25) -> 0.018964698 | F15: =IF(165=0,0,D15/165) -> 1.1484848
B16: Mech Room | C16: 142 | D16: 89 | E16: =IF(9992.25=0,0,D16/9992.25) -> 0.0089069028 | F16: =IF(165=0,0,D16/165) -> 0.53939394
B17: Tub / Shower | C17: 145 | D17: 14 | E17: =IF(9992.25=0,0,D17/9992.25) -> 0.0014010858 | F17: =IF(165=0,0,D17/165) -> 0.084848485
B18: TOTAL | D18: =SUM(D6:D17) -> 9992.25 | E18: 1 | F18: =IF(165=0,0,D18/165) -> 60.559091
B21: B. PRODUCTIVITY RATIOS
B22: Metric | C22: Value | D22: Units | F22: Notes
B23: Hours / Unit | C23: 60.559091 | D23: hrs | F23: Labor hours per residential unit
B24: Hours / Fixture | C24: 12.443649 | D24: hrs | F24: Labor hours per plumbing fixture
B25: Revenue / Hour | C25: 138.74943 | D25: $ | F25: Top-line per labor hour
B26: Profit / Hour | C26: 80.104123 | D26: $ | F26: Bottom-line per labor hour
B27: Units / Month | C27: 6.875 | D27: units | F27: Build velocity
B28: Fixtures / Month | C28: 33.458333 | D28: fix | F28: Fixture install pace
B29: Hours / Month | C29: 416.34375 | D29: hrs | F29: Monthly labor burn
B30: Revenue / Month | C30: 57767.458 | D30: $ | F30: Monthly billing rate
B33: SOURCES
B34: Job #2010 — Chinn Old Town Mixed Use • GC: Chinn Construction, LLC • Seattle, WA
B35: Canonical source: 2010 Job Detail Report.pdf (123 pages, OWP Sage Timberline export)
B36: Cost codes parsed: 28
B37: Unit count (165) and fixture count (803) confirmed from existing project data
B38: Mixed-use: 165 plumbing units, 175 lavatories (suggests 10 powder-room units) + 15 shower-only units
B39: Billing: OLD TOWN AGGREGATE BILLING.xlsx (18 pay apps Sep 2012 – Sep 2014)
B40: Final contract $1,386,419 (original $1,469,800 + $-83,381 COs)

Sheet PO Commitments
B2: Purchase Order Commitments
B3: 73 unique POs • PO amounts not dollar-parsed from individual PDFs • JDR material $282,663
B5: A. COMMITMENTS BY COST CODE
B6: OWP Code | C6: Description → JDR | D6: PO Count | E6: % of POs | F6: JDR Material
B7: 30 | C7: 110+210 Underground | D7: 12 | E7: =IF(73=0,0,D7/73) -> 0.16438356
B8: 31 | C8: 120+220 Roughin | D8: 17 | E8: =IF(73=0,0,D8/73) -> 0.23287671
B9: 32 | C9: 130+230 Trim/Finish | D9: 13 | E9: =IF(73=0,0,D9/73) -> 0.17808219
B10: 40 | C10: 141+241 Water Main/Ins | D10: 1 | E10: =IF(73=0,0,D10/73) -> 0.01369863
B11: 41 | C11: 140+240 Gas | D11: 3 | E11: =IF(73=0,0,D11/73) -> 0.04109589
B12: OTHER | C12: Unclassified | D12: 27 | E12: =IF(73=0,0,D12/73) -> 0.36986301
B13: TOTAL | D13: =SUM(D7:D12) -> 73 | E13: 1 | F13: 282662.77
B16: B. COMMITMENTS BY VENDOR
B17: Vendor | C17: PO Count | D17: % of POs
B18: OTHER | C18: 60 | D18: =IF(73=0,0,C18/73) -> 0.82191781
B19: ROSEN | C19: 8 | D19: =IF(73=0,0,C19/73) -> 0.10958904
B20: FEI | C20: 3 | D20: =IF(73=0,0,C20/73) -> 0.04109589
B21: CONSOLIDATED | C21: 1 | D21: =IF(73=0,0,C21/73) -> 0.01369863
B22: SIOUX CHIEF | C22: 1 | D22: =IF(73=0,0,C22/73) -> 0.01369863
B25: C. PO COVERAGE NOTES
B26: Total Material Actual (JDR) | E26: 282662.77
B27: Unique PO Count | E27: 73
B28: (Dollar PO commitment not extracted — requires per-PDF parse)
B31: SOURCES
B32: Job #2010 — Chinn Old Town Mixed Use • GC: Chinn Construction, LLC • Seattle, WA
B33: Canonical source: 2010 Job Detail Report.pdf (123 pages, OWP Sage Timberline export)
B34: Cost codes parsed: 28
B35: Unit count (165) and fixture count (803) confirmed from existing project data
B36: Mixed-use: 165 plumbing units, 175 lavatories (suggests 10 powder-room units) + 15 shower-only units
B37: Billing: OLD TOWN AGGREGATE BILLING.xlsx (18 pay apps Sep 2012 – Sep 2014)
B38: Final contract $1,386,419 (original $1,469,800 + $-83,381 COs)
B39: PO count is deduplicated by 5-digit PO number extracted from filenames
B40: Vendor/code classification is heuristic (filename keyword match)

Sheet Billing & SOV
B2: Revenue & Billing Reconciliation
B3: 18 pay applications • Sep 2012 – Sep 2014 • $1,386,419 final
B5: A. CONTRACT SUMMARY
B6: Original Contract | G6: 1469800
B7: Change Orders (net) | G7: -83381
B8: Final Contract Value | G8: 1386419
B9: Retainage (5%) | G9: 69321
B10: Net Paid to OWP | G10: 1317098
B12: B. PAY APPLICATION TIMELINE
B13: App# | C13: Date | D13: Period Billing | E13: Retention | F13: Net This Period | G13: Aggregate | H13: % Complete
B14: 1 | C14: 2012-09-20 | D14: 24000 | E14: 1200 | F14: =D14-E14 -> 22800 | G14: 22800 | H14: =IF(1386419=0,0,G14/1386419) -> 0.016445245
B15: 2 | C15: 2012-10-18 | D15: 48000 | E15: 2400 | F15: =D15-E15 -> 45600 | G15: 68400 | H15: =IF(1386419=0,0,G15/1386419) -> 0.049335735
B16: 3 | C16: 2012-12-20 | D16: 15400 | E16: 770 | F16: =D16-E16 -> 14630 | G16: 83030 | H16: =IF(1386419=0,0,G16/1386419) -> 0.0598881
B17: 4 | C17: 2013-02-19 | D17: 10100 | E17: 505 | F17: =D17-E17 -> 9595 | G17: 92625 | H17: =IF(1386419=0,0,G17/1386419) -> 0.066808807
B18: 5 | C18: 2013-04-18 | D18: 6300 | E18: 315 | F18: =D18-E18 -> 5985 | G18: 98610 | H18: =IF(1386419=0,0,G18/1386419) -> 0.071125684
B19: 6 | C19: 2013-05-19 | D19: 20400 | E19: 1020 | F19: =D19-E19 -> 19380 | G19: 117990 | H19: =IF(1386419=0,0,G19/1386419) -> 0.085104142
B20: 7 | C20: 2013-06-20 | D20: 70200 | E20: 3510 | F20: =D20-E20 -> 66690 | G20: 184680 | H20: =IF(1386419=0,0,G20/1386419) -> 0.13320648
B21: 8 | C21: 2013-07-20 | D21: 160800 | E21: 8040 | F21: =D21-E21 -> 152760 | G21: 337440 | H21: =IF(1386419=0,0,G21/1386419) -> 0.24338962
B22: 9 | C22: 2013-08-20 | D22: 143247 | E22: 7162.35 | F22: =D22-E22 -> 136084.65 | G22: 473524.65 | H22: =IF(1386419=0,0,G22/1386419) -> 0.34154512
B23: 10 | C23: 2013-09-20 | D23: 292950 | E23: 14647.5 | F23: =D23-E23 -> 278302.5 | G23: 751827.15 | H23: =IF(1386419=0,0,G23/1386419) -> 0.5422799
B24: 11 | C24: 2013-10-17 | D24: 204800 | E24: 10240 | F24: =D24-E24 -> 194560 | G24: 946387.15 | H24: =IF(1386419=0,0,G24/1386419) -> 0.68261265
B25: 12 | C25: 2013-11-12 | D25: 40600 | E25: 2030 | F25: =D25-E25 -> 38570 | G25: 984957.15 | H25: =IF(1386419=0,0,G25/1386419) -> 0.71043252
... B31: 18 | C31: 2014-09-20 | D31: 1848 | E31: 92.4 | F31: =D31-E31 -> 1755.6 | G31: 1317098.1 | H31: =IF(1386419=0,0,G31/1386419) -> 0.95
B33: C. BILLING ↔ JDR TIE-OUT
B34: Metric | C34: SOV | D34: JDR | E34: Δ | F34: Status
B35: Final Contract Value | C35: 1386419 | D35: 1386419 | E35: =C35-D35 -> 0 | F35: =IF(ABS(E35)<=1,"TIES",IF(ABS(E35)<=ABS(D35)*0.05,"WITHIN","OFF")) -> TIES
B36: Retainage | C36: 69321 | D36: 69321 | E36: =C36-D36 -> 0 | F36: =IF(ABS(E36)<=1,"TIES",IF(ABS(E36)<=ABS(D36)*0.05,"WITHIN","OFF")) -> TIES
B37: Direct Cost | C37: 585999 | D37: 585999 | E37: =C37-D37 -> 0 | F37: =IF(ABS(E37)<=1,"TIES",IF(ABS(E37)<=ABS(D37)*0.05,"WITHIN","OFF")) -> TIES
B41: SOURCES
B42: Job #2010 — Chinn Old Town Mixed Use • GC: Chinn Construction, LLC • Seattle, WA
B43: Canonical source: 2010 Job Detail Report.pdf (123 pages, OWP Sage Timberline export)
B44: Cost codes parsed: 28
B45: Unit count (165) and fixture count (803) confirmed from existing project data
B46: Mixed-use: 165 plumbing units, 175 lavatories (suggests 10 powder-room units) + 15 shower-only units
B47: Billing: OLD TOWN AGGREGATE BILLING.xlsx (18 pay apps Sep 2012 – Sep 2014)
B48: Final contract $1,386,419 (original $1,469,800 + $-83,381 COs)

Sheet Insights
B2: Key Insights — Job #2010 Chinn Old Town Mixed Use
B3: Narrative observations distilled from the full JDR analysis
B5: MARGIN PROFILE | C5: Net profit of $800,420 on $1,386,419 revenue = 57.7% gross margin. Direct cost $585,999 absorbs 42.3% of revenue.
B6: VENDOR CONCENTRATION | C6: Rosen Supply Company, Inc. alone = $215,860 (60% of all AP) across 73 invoices. Total 18 AP vendors, $362,722 total AP spend.
B7: CREW PROFILE | C7: 22 workers for 9,992 hours = 454 avg hrs/worker. Top 3 workers logged 4,734 hrs combined (47% of all labor).
B8: ROUGHIN DOMINANCE | C8: Code 120 Roughin Labor = 6,202 hrs (62% of all labor) and $114,688 actual. Code 230 Finish Material = $173,653 — 30% of total direct cost.
B9: BUDGET DELIVERY | C9: Revised budget was $977,918; actual direct cost $585,999 → $391,919 variance (40.1% under revised budget).
B10: CONTRACT GROWTH | C10: Contract grew from $1,469,800 to $1,386,419 — net +$-83,381 (-5.7%). Retainage of $69,321 (5%) withheld until closeout.
B11: BURDEN RATIO | C11: Burden codes 995 + 998 = $103,414 on $196,271 labor base = 52.7%. In line with OWP's typical 48–50% labor burden.
B12: PROJECT SCALE | C12: 165 units · 803 fixtures · 24 months. Revenue/unit $8,403, hours/unit 60.6, profit/unit $4,851.
B13: PRODUCTIVITY | C13: Blended labor rate $19.64/hr. Revenue/hour $139. Profit/hour $80. 416 hrs/month burn rate.
B14: FIXTURE DENSITY | C14: 803 fixtures ÷ 165 units = 4.87 fixtures/unit. Material/fixture $352, labor/fixture $244.
B16: BIGGEST QUESTION
B17: How does this job's 57.7% margin compare across similar projects in the OWP portfolio, and what operational levers drove the result — estimating accuracy, vendor pricing, or labor productivity?
B20: SOURCES
B21: Job #2010 — Chinn Old Town Mixed Use • GC: Chinn Construction, LLC • Seattle, WA
B22: Canonical source: 2010 Job Detail Report.pdf (123 pages, OWP Sage Timberline export)
B23: Cost codes parsed: 28
B24: Unit count (165) and fixture count (803) confirmed from existing project data
B25: Mixed-use: 165 plumbing units, 175 lavatories (suggests 10 powder-room units) + 15 shower-only units
B26: Billing: OLD TOWN AGGREGATE BILLING.xlsx (18 pay apps Sep 2012 – Sep 2014)
B27: Final contract $1,386,419 (original $1,469,800 + $-83,381 COs)

Sheet Benchmark KPIs
B2: Benchmark KPIs
B3: Normalized metrics designed for apples-to-apples comparison across all OWP projects
B5: KPI | C5: Data Name | D5: Value | E5: Category | F5: Notes | G5: Confidence | H5: Source Document
B6: Job Number | C6: job_number | D6: 2010 | E6: Profile | F6: OWP job ID | G6: Verified | H6: Benchmark KPIs / Metric Registry — see source tabs
B7: Job Name | C7: job_name | D7: Chinn Old Town Mixed Use | E7: Profile | G7: Verified | H7: Benchmark KPIs / Metric Registry — see source tabs
B8: General Contractor | C8: general_contractor | D8: Chinn Construction, LLC | E8: Profile | G8: Verified | H8: Benchmark KPIs / Metric Registry — see source tabs
B9: Location | C9: location | D9: Seattle, WA | E9: Profile | G9: Verified | H9: Benchmark KPIs / Metric Registry — see source tabs
B10: Project Type | C10: project_type | D10: 165-unit mixed-use multifamily apartments + ground-floor retail | E10: Profile | G10: Verified | H10: Benchmark KPIs / Metric Registry — see source tabs
B11: Duration (months) | C11: duration_months | D11: 24 | E11: Profile | F11: Sep 2012 – Sep 2014 (~24 months) | G11: Verified | H11: Benchmark KPIs / Metric Registry — see source tabs
B12: Unit Count | C12: unit_count | D12: 165 | E12: Profile | G12: Verified | H12: Benchmark KPIs / Metric Registry — see source tabs
B13: Total Fixtures | C13: total_fixtures | D13: 803 | E13: Profile | G13: Verified | H13: Benchmark KPIs / Metric Registry — see source tabs
B14: Fixtures per Unit | C14: fixtures_per_unit | D14: 4.8666667 | E14: Profile | G14: Verified | H14: Benchmark KPIs / Metric Registry — see source tabs
B15: Contract Value (Orig) | C15: contract_original | D15: 1469800 | E15: Financial | G15: Verified | H15: Benchmark KPIs / Metric Registry — see source tabs
B16: Contract Value (Final) | C16: contract_final | D16: 1386419 | E16: Financial | F16: After change orders | G16: Verified | H16: Benchmark KPIs / Metric Registry — see source tabs
B17: Change Orders ($) | C17: change_orders | D17: -83381 | E17: Financial | G17: Verified | H17: Benchmark KPIs / Metric Registry — see source tabs
B18: Revenue | C18: revenue | D18: 1386419 | E18: Financial | G18: Verified | H18: Benchmark KPIs / Metric Registry — see source tabs
B19: Net Profit | C19: net_profit | D19: 800420.42 | E19: Financial | G19: Verified | H19: Benchmark KPIs / Metric Registry — see source tabs
B20: Gross Margin | C20: gross_margin | D20: 0.57732938 | E20: Financial | G20: Verified | H20: Benchmark KPIs / Metric Registry — see source tabs
B21: Direct Cost | C21: direct_cost | D21: 585998.58 | E21: Financial | G21: Verified | H21: Benchmark KPIs / Metric Registry — see source tabs
B22: Labor Cost | C22: labor_cost | D22: 196271.13 | E22: Labor | F22: Sum of 12 labor codes | G22: Verified | H22: Benchmark KPIs / Metric Registry — see source tabs
B23: Material Cost | C23: material_cost | D23: 282662.77 | E23: Material | F23: Sum of 10 material codes | G23: Verified | H23: Benchmark KPIs / Metric Registry — see source tabs
B24: Overhead Cost | C24: overhead_cost | D24: 3650.67 | E24: Financial | F24: Sub+Eng+Permits | G24: Verified | H24: Benchmark KPIs / Metric Registry — see source tabs
B25: Burden Cost | C25: burden_cost | D25: 103414.01 | E25: Financial | F25: Codes 995+998 | G25: Verified | H25: Benchmark KPIs / Metric Registry — see source tabs
B26: Retainage | C26: retainage | D26: 69320.95 | E26: Financial | F26: 5% withheld | G26: Verified | H26: Benchmark KPIs / Metric Registry — see source tabs
B27: Revenue per Unit | C27: revenue_per_unit | D27: 8402.5394 | E27: Financial | G27: Verified | H27: Benchmark KPIs / Metric Registry — see source tabs
B28: Profit per Unit | C28: profit_per_unit | D28: 4851.0328 | E28: Financial | G28: Verified | H28: Benchmark KPIs / Metric Registry — see source tabs
B29: Direct Cost per Unit | C29: cost_per_unit | D29: 3551.5065 | E29: Financial | G29: Verified | H29: Benchmark KPIs / Metric Registry — see source tabs
B30: Labor Cost per Unit | C30: labor_per_unit | D30: 1189.522 | E30: Labor | G30: Verified | H30: Benchmark KPIs / Metric Registry — see source tabs
B31: Material Cost per Unit | C31: material_per_unit | D31: 1713.1077 | E31: Material | G31: Verified | H31: Benchmark KPIs / Metric Registry — see source tabs
B32: Revenue per Fixture | C32: revenue_per_fixture | D32: 1726.5492 | E32: Financial | G32: Verified | H32: Benchmark KPIs / Metric Registry — see source tabs
B33: Profit per Fixture | C33: profit_per_fixture | D33: 996.78757 | E33: Financial | G33: Verified | H33: Benchmark KPIs / Metric Registry — see source tabs
B34: Cost per Fixture | C34: cost_per_fixture | D34: 729.76162 | E34: Financial | G34: Verified | H34: Benchmark KPIs / Metric Registry — see source tabs
B35: Labor per Fixture | C35: labor_per_fixture | D35: 244.42233 | E35: Labor | G35: Verified | H35: Benchmark KPIs / Metric Registry — see source tabs
B36: Material per Fixture | C36: material_per_fixture | D36: 352.00843 | E36: Material | G36: Verified | H36: Benchmark KPIs / Metric Registry — see source tabs
B37: Total Labor Hours | C37: total_hours | D37: 9992.25 | E37: Labor | F37: Sum of JDR cost code hours | G37: Verified | H37: Benchmark KPIs / Metric Registry — see source tabs
B38: Total Workers | C38: total_workers | D38: 22 | E38: Labor | F38: Unique payroll IDs | G38: Verified | H38: Benchmark KPIs / Metric Registry — see source tabs
B39: Blended Gross Wage | C39: blended_gross_wage | D39: 19.190898 | E39: Labor | F39: Pre-burden | G39: Verified | H39: Benchmark KPIs / Metric Registry — see source tabs
B40: Fully-Loaded Wage | C40: fully_loaded_wage | D40: 29.991758 | E40: Labor | F40: Post-burden | G40: Verified | H40: Benchmark KPIs / Metric Registry — see source tabs
B41: Burden Multiplier | C41: burden_multiplier | D41: 1.5628116 | E41: Labor | G41: Verified | H41: Benchmark KPIs / Metric Registry — see source tabs
B42: Hours per Unit | C42: hours_per_unit | D42: 60.559091 | E42: Labor | F42: Key benchmark | G42: Verified | H42: Benchmark KPIs / Metric Registry — see source tabs
...

Sheet Vendors
A1: Vendor Detail — Job #2010
A3: Vendors | B3: 18 | D3: Top vendor | E3: Rosen Supply Company, Inc.
A4: Invoices | B4: 175 | D4: Top 3 share | E4: =331095.13/362721.85 -> 0.91280724
A5: Total AP | B5: 362721.85 | D5: Source | E5: Job Detail Report (Sage Timberline AP export)
A6: Avg Inv | B6: =B5/B4 -> 2072.6963
A8: Rank | B8: Vendor | C8: Vendor Code | D8: Invoices | E8: Total Spend | F8: % of AP | G8: Avg / Invoice
A9: 1 | B9: Rosen Supply Company, Inc. | D9: 73 | E9: 215859.94 | F9: =E9/E$27 -> 0.59511149 | G9: =IF(D9=0,0,E9/D9) -> 2956.9855
A10: 2 | B10: Ferguson Enterprises, Inc. | D10: 58 | E10: 84342.57 | F10: =E10/E$27 -> 0.23252685 | G10: =IF(D10=0,0,E10/D10) -> 1454.1822
A11: 3 | B11: Bank of America CC | D11: 3 | E11: 30892.62 | F11: =E11/E$27 -> 0.085168897 | G11: =IF(D11=0,0,E11/D11) -> 10297.54
A12: 4 | B12: Franklin Engineering | D12: 4 | E12: 10463 | F12: =E12/E$27 -> 0.028845795 | G12: =IF(D12=0,0,E12/D12) -> 2615.75
A13: 5 | B13: Keller Supply Company | D13: 7 | E13: 10106.67 | F13: =E13/E$27 -> 0.027863417 | G13: =IF(D13=0,0,E13/D13) -> 1443.81
A14: 6 | B14: Quality Concrete Products, Inc. | D14: 2 | E14: 2414 | F14: =E14/E$27 -> 0.0066552373 | G14: =IF(D14=0,0,E14/D14) -> 1207
A15: 7 | B15: United Rentals, Inc. | D15: 6 | E15: 2404.21 | F15: =E15/E$27 -> 0.006628247 | G15: =IF(D15=0,0,E15/D15) -> 400.70167
A16: 8 | B16: Ferguson Enterprises, Inc. #3007 | D16: 7 | E16: 2271.7 | F16: =E16/E$27 -> 0.0062629257 | G16: =IF(D16=0,0,E16/D16) -> 324.52857
A17: 9 | B17: Rosen Supply Kirkland | D17: 3 | E17: 1831.58 | F17: =E17/E$27 -> 0.0050495442 | G17: =IF(D17=0,0,E17/D17) -> 610.52667
A18: 10 | B18: Duraseal, Inc. | D18: 1 | E18: 950 | F18: =E18/E$27 -> 0.0026190868 | G18: =IF(D18=0,0,E18/D18) -> 950
A19: 11 | B19: DRSi | D19: 2 | E19: 265.36 | F19: =E19/E$27 -> 0.00073157986 | G19: =IF(D19=0,0,E19/D19) -> 132.68
A20: 12 | B20: R.A. Brown Backflow Testing | D20: 1 | E20: 212 | F20: =E20/E$27 -> 0.00058446989 | G20: =IF(D20=0,0,E20/D20) -> 212
... A26: 18 | B26: C.M. Hoskins Company | D26: 1 | E26: 54.4 | F26: =E26/E$27 -> 0.00014997718 | G26: =IF(D26=0,0,E26/D26) -> 54.4
B27: TOTAL | D27: =SUM(D9:D26) -> 175 | E27: =SUM(E9:E26) -> 362721.85 | F27: =SUM(F9:F26) -> 1 | G27: =IF(D27=0,0,E27/D27) -> 2072.6963

Sheet Change Log
B2: Change Log — Master Register
B3: Unified change-event ledger: RFIs, ASIs, COPs, COs, Backcharges, T&M (23 events)
B5: Event ID | C5: Type | D5: Date | E5: Subject | F5: Originator | G5: Linked Event(s) | H5: Cost Impact ($) | I5: Schedule (days) | J5: Status | K5: Source Document
B6: CO-003 | C6: CO | D6: 2013-12-12 | E6: Change Order #3 — embedded in schedule of values | F6: GC (WPM) | H6: 0 | I6: 0 | J6: Active | K6: 2010-Chinn, Old Town/Oldtown billing/Chinn Old Town schedule of values- 13 -12-12-13 co#3.xlsx
B7: CO-004 | C7: CO | D7: 2014-05-20 | E7: Change Order #4 — embedded in schedule of values | F7: GC (WPM) | H7: 0 | I7: 0 | J7: Active | K7: 2010-Chinn, Old Town/Oldtown billing/Chinn Old Town schedule of values- 17 -5-20-14 co#4.xlsx
B8: ASI-001 | C8: ASI | D8: 2012-05-31 | E8: Landscape for construction drawings | F8: Architect (Weber Thompson) | H8: 0 | I8: 0 | J8: Closed | K8: 2010-Chinn, Old Town/ASI-RFI/ASI No 1 Narrative.pdf
B9: ASI-002 | C9: ASI | D9: 2012-06-19 | E9: Structural Drawings Revision 7 — transformer cable room, wall replacement 8→6, dimensions, column repositioning | F9: Architect (Weber Thompson) | H9: 0 | I9: 0 | J9: Closed | K9: 2010-Chinn, Old Town/ASI-RFI/ASI No 2 Narratives.pdf
B10: ASI-006 | C10: ASI | D10: 2012-Q3 | E10: Architectural revisions — Level L011 | F10: Architect (Weber Thompson) | H10: 0 | I10: 0 | J10: Closed | K10: 2010-Chinn, Old Town/ASI-RFI/old town RFI-ASI/ASI 6 Architectural Revisions Level L011.pdf
B11: ASI-008 | C11: ASI | D11: 2012-Q4 | E11: Courtyard & street level irrigation plan details | F11: Landscape Architect | H11: 0 | I11: 0 | J11: Closed | K11: 2010-Chinn, Old Town/ASI-RFI/old town RFI-ASI/Old Town ASI#8.pdf
B12: ASI-023.R1 | C12: ASI | D12: 2013 | E12: ASI 23 Revision 1 — resubmission | F12: Architect (Weber Thompson) | H12: 0 | I12: 0 | J12: Closed | K12: 2010-Chinn, Old Town/ASI-RFI/ASI No 23R1 Complete.pdf
B13: ASI-024 | C13: ASI | D13: 2013 | E13: ASI 24 — design clarification | F13: Architect (Weber Thompson) | H13: 0 | I13: 0 | J13: Closed | K13: 2010-Chinn, Old Town/ASI-RFI/ASI No 24 Complete.pdf
B14: ASI-NARR | C14: ASI | D14: 2013 | E14: ID Revisions Narrative — design revisions summary | F14: Architect (Weber Thompson) | H14: 0 | I14: 0 | J14: Closed | K14: 2010-Chinn, Old Town/ASI-RFI/Narrative for ID Revisions.pdf
B15: RFI-004 | C15: RFI | D15: 2012 | E15: PSE Transformer Relocation | F15: GC (OTMU) | H15: 0 | I15: 0 | J15: Closed | K15: 2010-Chinn, Old Town/ASI-RFI/old town RFI-ASI/RFI 4 PSE Transformer Relocation_Response.pdf
B16: RFI-016 | C16: RFI | D16: 2012 | E16: Oil/water separator relocation | F16: GC (OTMU) | H16: 0 | I16: 0 | J16: Closed | K16: 2010-Chinn, Old Town/ASI-RFI/old town RFI-ASI/Response - OTMU RFI #016 - oil water location relocation_.pdf
B17: RFI-026 | C17: RFI | D17: 2012 | E17: Vault room wall and footing details | F17: GC (OTMU) | H17: 0 | I17: 0 | J17: Closed | K17: 2010-Chinn, Old Town/ASI-RFI/old town RFI-ASI/RFI 026 - Response - Vault room wall and footing details.pdf
... B28: RFI-115 | C28: RFI | D28: 2013 | E28: Water repeater | F28: GC (OTMU) | H28: 0 | I28: 0 | J28: Closed | K28: 2010-Chinn, Old Town/ASI-RFI/old town RFI-ASI/OTMU RFI 115 - Water repeater_Response.pdf
B30: TOTAL | H30: =SUM(H6:H28) -> 0 | I30: =SUM(I6:I28) -> 0

Sheet Root Cause Analysis
B2: Root Cause Analysis — Change Driver Taxonomy
B3: Categorized change events with responsible-party attribution — feeds bid-risk intelligence
B5: CATEGORY ROLLUP
B6: Root Cause Category | C6: # Events | D6: Net Cost Impact ($) | E6: % of Events | F6: Predominant Responsibility | G6: Notes
B7: Design error | C7: 3 | D7: 0 | E7: =C7/23 -> 0.13043478 | F7: Designer | G7: Structural Drawings Revision 7 — transformer cable room, wal
B8: Design substitution | C8: 1 | D8: 0 | E8: =C8/23 -> 0.043478261 | F8: Owner/GC | G8: Water vault pump change (equipment substitution)
B9: Design clarification | C9: 9 | D9: 0 | E9: =C9/23 -> 0.39130435 | F9: Designer | G9: Landscape for construction drawings
B10: Field condition | C10: 2 | D10: 0 | E10: =C10/23 -> 0.086956522 | F10: Owner/GC | G10: Oil/water separator relocation
B11: Coordination conflict | C11: 5 | D11: 0 | E11: =C11/23 -> 0.2173913 | F11: Owner/GC | G11: PSE Transformer Relocation
B12: Scope gap | C12: 1 | D12: 0 | E12: =C12/23 -> 0.043478261 | F12: Owner/GC | G12: Warning horn or light at garage exits
B13: Combined/multi-cause | C13: 2 | D13: 0 | E13: =C13/23 -> 0.086956522 | F13: Mixed | G13: Change Order #3 — embedded in schedule of values
B14: TOTAL | C14: =SUM(C7:C13) -> 23 | D14: =SUM(D7:D13) -> 0
B17: RESPONSIBILITY ATTRIBUTION
B18: Responsible Party | C18: # Events | D18: Net $ Impact | E18: Bid-Risk Signal
B19: Owner/GC | C19: 11 | D19: 0 | E19: NEUTRAL
B20: Designer | C20: 9 | D20: 0 | E20: NEUTRAL
B21: Mixed | C21: 3 | D21: 0 | E21: NEUTRAL

Sheet Predictive Signals
B2: Predictive Signals — Leading Indicators
B3: Forward-looking metrics that predict CO waves, schedule slips, and margin erosion
B5: CURRENT-STATE SIGNALS
B6: Indicator | C6: Current Value | D6: Benchmark | E6: Status | F6: Predictive Meaning
B7: RFI Total (closed) | C7: 14 | D7: <50 for mid-size | E7: INFO | F7: Volume proxy for design doc quality
B8: RFI Velocity (per month, derived) | C8: See KPIs D50 | D8: <3.0/wk | E8: INFO | F8: >3/wk = CO wave in 4-8 wks
B9: RFI Avg Cycle Time (days) | C9: Unknown | D9: <14 | E9: N/A | F9: >30 avg signals schedule slip
B10: ASI / OCD Count | C10: 7 | D10: <5 | E10: ELEVATED | F10: High ASI = owner scope churn
B11: Backcharge Count | C11: 0 | D11: <3 | E11: HEALTHY | F11: BC clusters = coordination weakness
B12: Change Order Count | C12: 2 | D12: <3 | E12: HEALTHY | F12: CO count signals scope definition
B13: T&M Event Count | C13: 0 | D13: <2 | E13: HEALTHY | F13: T&M = directed work pipeline
B14: Submittal resubmission count | C14: 0 | D14: <10 | E14: HEALTHY | F14: Repeats = coord issues incubating
B15: Net $ Impact (all events) | C15: 0 | D15: Near $0 | E15: NEUTRAL | F15: Net recoverable vs absorbed
B18: FORECAST MODELS (closed-project — actuals)
B19: Forecast | C19: Current Estimate | D19: Confidence | E19: Driver | F19: Model Note
B20: Projected final CO % of contract | C20: ='Benchmark KPIs'!D55 -> -0.056729487 | D20: Actual | E20: Closed project | F20: CO$ / orig contract
B21: Projected EAC (direct cost) | C21: ='Benchmark KPIs'!D21 -> 585998.58 | D21: Actual | E21: Closed project | F21: Sum of L+M+OH+Burden
B22: Projected final margin | C22: ='Benchmark KPIs'!D20 -> 0.57732938 | D22: Actual | E22: Closed project | F22: (Rev - DC) / Rev
B23: Composite risk score (0-100) | C23: 24 | D23: Medium | E23: 0 BCs + 7 ASI/OCDs | F23: Custom Cortex scoring

Sheet Metric Registry
B2: Metric Registry — Cortex Data Catalog
B3: Every metric with data_label, confidence_level, and source_document — the machine-readable JCR index
B5: # | C5: Data Label | D5: Human Label | E5: Value | F5: Unit | G5: Source Tab | H5: Confidence | I5: Source Document(s) | J5: Formula / Derivation
B6: 1 | C6: job_number | D6: Job Number | E6: ='Benchmark KPIs'!D6 -> 2010 | F6: id | G6: Benchmark KPIs | H6: Verified | I6: JDR header | J6: See Benchmark KPIs tab
B7: 2 | C7: job_name | D7: Job Name | E7: ='Benchmark KPIs'!D7 -> Chinn Old Town Mixed Use | F7: text | G7: Benchmark KPIs | H7: Verified | I7: Contract folder | J7: See Benchmark KPIs tab
B8: 3 | C8: general_contractor | D8: General Contractor | E8: ='Benchmark KPIs'!D8 -> Chinn Construction, LLC | F8: text | G8: Benchmark KPIs | H8: Verified | I8: Contract folder | J8: See Benchmark KPIs tab
B9: 4 | C9: location | D9: Location | E9: ='Benchmark KPIs'!D9 -> Seattle, WA | F9: text | G9: Benchmark KPIs | H9: Verified | I9: Permit/Plans | J9: See Benchmark KPIs tab
B10: 5 | C10: project_type | D10: Project Type | E10: ='Benchmark KPIs'!D10 -> 165-unit mixed-use multifamily apartments + ground-floor retail | F10: text | G10: Benchmark KPIs | H10: Verified | I10: Plans | J10: See Benchmark KPIs tab
B11: 6 | C11: duration_months | D11: Duration (months) | E11: ='Benchmark KPIs'!D11 -> 24 | F11: months | G11: Benchmark KPIs | H11: Verified | I11: First-to-last invoice | J11: See Benchmark KPIs tab
B12: 7 | C12: unit_count | D12: Unit Count | E12: ='Benchmark KPIs'!D12 -> 165 | F12: units | G12: Benchmark KPIs | H12: Verified | I12: Plumbing permit + P-tag list | J12: See Benchmark KPIs tab
B13: 8 | C13: total_fixtures | D13: Total Fixtures | E13: ='Benchmark KPIs'!D13 -> 803 | F13: count | G13: Benchmark KPIs | H13: Verified | I13: Permit detail | J13: See Benchmark KPIs tab
B14: 9 | C14: contract_original | D14: Contract Original | E14: ='Benchmark KPIs'!D15 -> 1469800 | F14: USD | G14: Benchmark KPIs | H14: Verified | I14: Contract SOV | J14: See Benchmark KPIs tab
B15: 10 | C15: contract_final | D15: Contract Final | E15: ='Benchmark KPIs'!D16 -> 1386419 | F15: USD | G15: Benchmark KPIs | H15: Verified | I15: Final billing SOV | J15: See Benchmark KPIs tab
B16: 11 | C16: change_orders | D16: Change Orders ($) | E16: ='Benchmark KPIs'!D17 -> -83381 | F16: USD | G16: Benchmark KPIs | H16: Verified | I16: JDR revised - original | J16: See Benchmark KPIs tab
B17: 12 | C17: revenue | D17: Revenue | E17: ='Benchmark KPIs'!D18 -> 1386419 | F17: USD | G17: Benchmark KPIs | H17: Verified | I17: Aggregate billing | J17: See Benchmark KPIs tab
B18: 13 | C18: net_profit | D18: Net Profit | E18: ='Benchmark KPIs'!D19 -> 800420.42 | F18: USD | G18: Benchmark KPIs | H18: Verified | I18: Revenue - Direct Cost | J18: See Benchmark KPIs tab
B19: 14 | C19: gross_margin | D19: Gross Margin % | E19: ='Benchmark KPIs'!D20 -> 0.57732938 | F19: % | G19: Benchmark KPIs | H19: Verified | I19: Derived | J19: See Benchmark KPIs tab
B20: 15 | C20: direct_cost | D20: Direct Cost | E20: ='Benchmark KPIs'!D21 -> 585998.58 | F20: USD | G20: Benchmark KPIs | H20: Verified | I20: JDR cost codes | J20: See Benchmark KPIs tab
B21: 16 | C21: labor_cost | D21: Labor Cost | E21: ='Benchmark KPIs'!D22 -> 196271.13 | F21: USD | G21: Benchmark KPIs | H21: Verified | I21: JDR labor codes | J21: See Benchmark KPIs tab
B22: 17 | C22: material_cost | D22: Material Cost | E22: ='Benchmark KPIs'!D23 -> 282662.77 | F22: USD | G22: Benchmark KPIs | H22: Verified | I22: JDR material codes | J22: See Benchmark KPIs tab
B23: 18 | C23: overhead_cost | D23: Overhead Cost | E23: ='Benchmark KPIs'!D24 -> 3650.67 | F23: USD | G23: Benchmark KPIs | H23: Verified | I23: JDR overhead codes | J23: See Benchmark KPIs tab
B24: 19 | C24: burden_cost | D24: Burden Cost | E24: ='Benchmark KPIs'!D25 -> 103414.01 | F24: USD | G24: Benchmark KPIs | H24: Verified | I24: JDR burden codes | J24: See Benchmark KPIs tab
B25: 20 | C25: retainage | D25: Retainage | E25: ='Benchmark KPIs'!D26 -> 69320.95 | F25: USD | G25: Benchmark KPIs | H25: Verified | I25: Aggregate billing row | J25: See Benchmark KPIs tab
B26: 21 | C26: total_hours | D26: Total Labor Hours | E26: ='Benchmark KPIs'!D37 -> 9992.25 | F26: hours | G26: Benchmark KPIs | H26: Verified | I26: JDR payroll | J26: See Benchmark KPIs tab
B27: 22 | C27: total_workers | D27: Total Workers | E27: ='Benchmark KPIs'!D38 -> 22 | F27: count | G27: Benchmark KPIs | H27: Verified | I27: JDR unique workers | J27: See Benchmark KPIs tab
B28: 23 | C28: blended_gross_wage | D28: Blended Gross Wage | E28: ='Benchmark KPIs'!D39 -> 19.190898 | F28: USD/hr | G28: Benchmark KPIs | H28: Verified | I28: Labor $ / Hours | J28: See Benchmark KPIs tab
B29: 24 | C29: total_vendors | D29: Total Vendors | E29: ='Benchmark KPIs'!D51 -> 18 | F29: count | G29: Benchmark KPIs | H29: Verified | I29: JDR AP unique | J29: See Benchmark KPIs tab
B30: 25 | C30: total_pos | D30: Total POs | E30: ='Benchmark KPIs'!D54 -> 73 | F30: count | G30: Benchmark KPIs | H30: Verified | I30: PO folder count | J30: See Benchmark KPIs tab
B31: 26 | C31: co_pct | D31: CO % of Original | E31: ='Benchmark KPIs'!D55 -> -0.056729487 | F31: % | G31: Benchmark KPIs | H31: Verified | I31: Derived | J31: See Benchmark KPIs tab
B32: 27 | C32: rfi_total_count | D32: RFIs Total | E32: 14 | F32: count | G32: Predictive Signals | H32: Verified | I32: ASI-RFI folder count | J32: See Predictive Signals tab
B33: 28 | C33: asi_ocd_count | D33: ASI + OCD Count | E33: 7 | F33: count | G33: Change Log | H33: Verified | I33: ASI-RFI folder + Change Orders | J33: See Change Log tab
B34: 29 | C34: co_count_total | D34: Change Order Count | E34: 2 | F34: count | G34: Change Log | H34: Verified | I34: Change Orders folder | J34: See Change Log tab
B35: 30 | C35: backcharge_count | D35: Backcharge Count | E35: 0 | F35: count | G35: Change Log | H35: Verified | I35: Invoices/Backcharges | J35: See Change Log tab
B36: 31 | C36: tm_event_count | D36: T&M Event Count | E36: 0 | F36: count | G36: Change Log | H36: Verified | I36: Change Orders / JDR 038 | J36: See Change Log tab
B37: 32 | C37: submittal_resub_count | D37: Submittal Resubmissions | E37: 0 | F37: count | G37: Predictive Signals | H37: Verified | I37: Submittals folder | J37: See Predictive Signals tab
B38: 33 | C38: change_event_total | D38: Total Tracked Events | E38: 23 | F38: count | G38: Change Log | H38: Verified | I38: Change Log tab | J38: See Change Log tab
B39: 34 | C39: change_net_impact | D39: Change Net $ Impact | E39: ='Change Log'!H30 -> 0 | F39: USD | G39: Change Log | H39: Verified | I39: SUM H col | J39: See Change Log tab

Sheet Reconciliation
B2: Reconciliation — Cross-Tab Tie-out Proofs
B3: Live cross-sheet formulas verify data consistency across all 17 tabs
B4: Check | C4: Tab A | D4: Tab B | E4: Δ | F4: Status | G4: Tabs
B5: A. OVERVIEW ↔ BENCHMARK KPIS
B6: Direct Cost Total | C6: =Overview!D24 -> 585998.58 | D6: ='Benchmark KPIs'!D21 -> 585998.58 | E6: =C6-D6 -> 0 | F6: =IF(ABS(E6)<=1,"TIES",IF(ABS(E6)<=ABS(D6)*0.05,"WITHIN","OFF")) -> TIES | G6: 1↔2↔11
B7: Contract Final Value | C7: 1386419 | D7: ='Benchmark KPIs'!D16 -> 1386419 | E7: =C7-D7 -> 0 | F7: =IF(ABS(E7)<=1,"TIES",IF(ABS(E7)<=ABS(D7)*0.05,"WITHIN","OFF")) -> TIES | G7: JDR↔11
B8: Net Profit | C8: 800420.42 | D8: ='Benchmark KPIs'!D19 -> 800420.42 | E8: =C8-D8 -> 0 | F8: =IF(ABS(E8)<=1,"TIES",IF(ABS(E8)<=ABS(D8)*0.05,"WITHIN","OFF")) -> TIES | G8: JDR↔11
B9: Gross Margin | C9: 0.57732938 | D9: ='Benchmark KPIs'!D20 -> 0.57732938 | E9: =C9-D9 -> 0 | F9: =IF(ABS(E9)<=1,"TIES",IF(ABS(E9)<=ABS(D9)*0.05,"WITHIN","OFF")) -> TIES | G9: JDR↔11
B11: B. OVERVIEW ↔ COST BREAKDOWN (Category Actuals)
B12: Labor Actual | C12: =Overview!D20 -> 196271.13 | D12: ='Cost Breakdown'!E6 -> 196271.13 | E12: =C12-D12 -> 0 | F12: =IF(ABS(E12)<=1,"TIES",IF(ABS(E12)<=ABS(D12)*0.05,"WITHIN","OFF")) -> TIES | G12: 1↔3
B13: Material Actual | C13: =Overview!D21 -> 282662.77 | D13: ='Cost Breakdown'!E7 -> 282662.77 | E13: =C13-D13 -> 0 | F13: =IF(ABS(E13)<=1,"TIES",IF(ABS(E13)<=ABS(D13)*0.05,"WITHIN","OFF")) -> TIES | G13: 1↔3
B14: Overhead Actual | C14: =Overview!D22 -> 3650.67 | D14: ='Cost Breakdown'!E8 -> 3650.67 | E14: =C14-D14 -> 0 | F14: =IF(ABS(E14)<=1,"TIES",IF(ABS(E14)<=ABS(D14)*0.05,"WITHIN","OFF")) -> TIES | G14: 1↔3
B15: Burden Actual | C15: =Overview!D23 -> 103414.01 | D15: ='Cost Breakdown'!E9 -> 103414.01 | E15: =C15-D15 -> 0 | F15: =IF(ABS(E15)<=1,"TIES",IF(ABS(E15)<=ABS(D15)*0.05,"WITHIN","OFF")) -> TIES | G15: 1↔3
B17: C. BUDGET vs ACTUAL ↔ OVERVIEW
B18: Actual Direct Cost | C18: ='Budget vs Actual'!F36 -> 585998.58 | D18: =Overview!D24 -> 585998.58 | E18: =C18-D18 -> 0 | F18: =IF(ABS(E18)<=1,"TIES",IF(ABS(E18)<=ABS(D18)*0.05,"WITHIN","OFF")) -> TIES | G18: 2↔1
B19: Revised Budget Total | C19: ='Budget vs Actual'!E36 -> 977917.55 | D19: =Overview!C24 -> 977917.55 | E19: =C19-D19 -> 0 | F19: =IF(ABS(E19)<=1,"TIES",IF(ABS(E19)<=ABS(D19)*0.05,"WITHIN","OFF")) -> TIES | G19: 2↔1
B21: D. MATERIAL ↔ COST BREAKDOWN ↔ KPIS
B22: Material Actual (Material tab) | C22: =Material!E17 -> 282662.77 | D22: ='Cost Breakdown'!E7 -> 282662.77 | E22: =C22-D22 -> 0 | F22: =IF(ABS(E22)<=1,"TIES",IF(ABS(E22)<=ABS(D22)*0.05,"WITHIN","OFF")) -> TIES | G22: 4↔3
B23: Material Actual (KPIs) | C23: ='Benchmark KPIs'!D23 -> 282662.77 | D23: ='Cost Breakdown'!E7 -> 282662.77 | E23: =C23-D23 -> 0 | F23: =IF(ABS(E23)<=1,"TIES",IF(ABS(E23)<=ABS(D23)*0.05,"WITHIN","OFF")) -> TIES | G23: 11↔3
B25: E. CREW & LABOR ↔ PRODUCTIVITY ↔ KPIS (Hours)
B26: Total Hours (Crew tab) | C26: ='Crew & Labor'!C27 -> 9923.5 | D26: ='Benchmark KPIs'!D37 -> 9992.25 | E26: =C26-D26 -> -68.75 | F26: =IF(ABS(E26)<=5,"TIES",IF(ABS(E26)<=ABS(D26)*0.05,"WITHIN","OFF")) -> WITHIN | G26: 5↔11
B27: Total Hours (Productivity tab) | C27: =Productivity!D18 -> 9992.25 | D27: ='Benchmark KPIs'!D37 -> 9992.25 | E27: =C27-D27 -> 0 | F27: =IF(ABS(E27)<=5,"TIES",IF(ABS(E27)<=ABS(D27)*0.05,"WITHIN","OFF")) -> TIES | G27: 7↔11
B28: Total Workers | C28: 22 | D28: ='Benchmark KPIs'!D38 -> 22 | E28: =C28-D28 -> 0 | F28: =IF(E28=0,"TIES",IF(ABS(E28)<=1,"WITHIN","OFF")) -> TIES | G28: JDR↔11
B30: F. CREW ANALYTICS ↔ KPIS (Wage Statistics)
B31: Blended Gross Wage | C31: ='Crew Analytics'!C12 -> 19.323852 | D31: ='Benchmark KPIs'!D39 -> 19.190898 | E31: =C31-D31 -> 0.13295453 | F31: =IF(ABS(E31)<=1,"TIES",IF(ABS(E31)<=ABS(D31)*0.05,"WITHIN","OFF")) -> TIES | G31: 6↔11
B32: Fully-Loaded Wage | C32: ='Crew Analytics'!C13 -> 30.19954 | D32: ='Benchmark KPIs'!D40 -> 29.991758 | E32: =C32-D32 -> 0.20778287 | F32: =IF(ABS(E32)<=1,"TIES",IF(ABS(E32)<=ABS(D32)*0.05,"WITHIN","OFF")) -> TIES | G32: 6↔11
B34: G. PO COMMITMENTS ↔ KPIS
B35: PO Count | C35: ='PO Commitments'!D13 -> 73 | D35: ='Benchmark KPIs'!D54 -> 73 | E35: =C35-D35 -> 0 | F35: =IF(E35=0,"TIES",IF(ABS(E35)<=1,"WITHIN","OFF")) -> TIES | G35: 8↔11
B37: H. BILLING & SOV ↔ JDR
B38: Final Contract Value | C38: 1386419 | D38: 1386419 | E38: =C38-D38 -> 0 | F38: =IF(ABS(E38)<=1,"TIES",IF(ABS(E38)<=ABS(D38)*0.05,"WITHIN","OFF")) -> TIES | G38: 9↔JDR
B39: Retainage | C39: 69321 | D39: 69321 | E39: =C39-D39 -> 0 | F39: =IF(ABS(E39)<=1,"TIES",IF(ABS(E39)<=ABS(D39)*0.05,"WITHIN","OFF")) -> TIES | G39: 9↔JDR
B40: Direct Cost | C40: 585999 | D40: 585999 | E40: =C40-D40 -> 0 | F40: =IF(ABS(E40)<=1,"TIES",IF(ABS(E40)<=ABS(D40)*0.05,"WITHIN","OFF")) -> TIES | G40: 9↔JDR
B42: I. VENDORS ↔ KPIS
B43: Vendor Count | C43: =Vendors!B3 -> 18 | D43: ='Benchmark KPIs'!D51 -> 18 | E43: =C43-D43 -> 0 | F43: =IF(E43=0,"TIES",IF(ABS(E43)<=1,"WITHIN","OFF")) -> TIES | G43: 12↔11
B44: Total AP Spend | C44: =Vendors!E27 -> 362721.85 | D44: 362722 | E44: =C44-D44 -> -0.15 | F44: =IF(ABS(E44)<=1,"TIES",IF(ABS(E44)<=ABS(D44)*0.05,"WITHIN","OFF")) -> TIES | G44: 12↔JDR
B46: J. INSIGHTS (Narrative Review)
B47: 10 insight cards — narrative text verified at generation time, no formula check applicable
B48: K. CHANGE LOG ↔ ROOT CAUSE ANALYSIS
B49: Total Event Count | C49: 23 | D49: ='Root Cause Analysis'!C14 -> 23 | E49: =C49-D49 -> 0 | F49: =IF(ABS(E49)<=1,"TIES",IF(ABS(E49)<=ABS(D49)*0.05,"WITHIN","OFF")) -> TIES | G49: 13↔14
B50: Net $ Impact (all events) | C50: ='Change Log'!H30 -> 0 | D50: ='Root Cause Analysis'!D14 -> 0 | E50: =C50-D50 -> 0 | F50: =IF(ABS(E50)<=1,"TIES",IF(ABS(E50)<=ABS(D50)*0.05,"WITHIN","OFF")) -> TIES | G50: 13↔14
...
