Workbook

Sheet Overview
B2: Job #2011 · Chinn Barrett Park Apartments
B3: Cortex JCR Summary • Chinn Construction, LLC • Seattle, WA (Capitol Hill) • 117-unit 4-story multifamily apartments • Nov 2012 – Mar 2014 (~17 months)
B5: PROJECT OVERVIEW
B6: Project Job # | C6: 2011
B7: Project Name: | C7: Chinn Barrett Park Apartments
B8: General Contractor | C8: Chinn Construction, LLC
B9: Location | C9: Seattle, WA (Capitol Hill)
B10: Project Duration | C10: Nov 2012 – Mar 2014 (~17 months)
B11: Total Unique Documents | C11: Barrett Park folder: Contract, Billing (aggregate + 13 SOVs), PO_s, Progress Payments, Change Orders
B13: CONTRACT VALUE | D13: NET PROFIT | F13: DIRECT COST | H13: LABOR HOURS
B14: $869,824 | D14: $332,960 | F14: $536,863 | H14: 6,944
B15: Original $813,050 + $56,774 COs | D15: 38.3% margin | F15: 61.7% of revenue | H15: 31 workers
B18: COST BREAKDOWN
B19: Category | C19: Budget | D19: Actual | E19: Variance | F19: % Budget | G19: % of Cost
B20: Labor | C20: 174655 | D20: 142882.75 | E20: =C20-D20 -> 31772.25 | F20: =IF(C20=0,0,D20/C20) -> 0.81808565 | G20: =IF($D$24=0,0,D20/$D$24) -> 0.26614356
B21: Material | C21: 393359 | D21: 295005.88 | E21: =C21-D21 -> 98353.12 | F21: =IF(C21=0,0,D21/C21) -> 0.74996601 | G21: =IF($D$24=0,0,D21/$D$24) -> 0.54949891
B22: Overhead | C22: 45725 | D22: 26210.1 | E22: =C22-D22 -> 19514.9 | F22: =IF(C22=0,0,D22/C22) -> 0.57321159 | G22: =IF($D$24=0,0,D22/$D$24) -> 0.048820794
B23: Burden | C23: 89051.11 | D23: 72764.72 | E23: =C23-D23 -> 16286.39 | F23: =IF(C23=0,0,D23/C23) -> 0.81711188 | G23: =IF($D$24=0,0,D23/$D$24) -> 0.13553674
B24: TOTAL | C24: =SUM(C20:C23) -> 702790.11 | D24: =SUM(D20:D23) -> 536863.45 | E24: =C24-D24 -> 165926.66 | F24: =IF(C24=0,0,D24/C24) -> 0.76390297 | G24: 1
B27: PROJECT PROFILE
B28: Metric | C28: Value | D28: Metric | E28: Value | F28: Metric | G28: Value
B29: Plumbing Units | C29: 117 | D29: Water Closets | E29: 117 | F29: Kitchen Sinks | G29: 119
B30: Total Fixtures | C30: 841 | D30: Lavatories | E30: 117 | F30: Dishwashers | G30: 3
B31: Fixtures / Unit | C31: 7.18 | D31: Tubs/Showers | E31: 117 | F31: Auto Washers | G31: 117
B32: Stacks | C32: 30 | D32: Floors | E32: 4 | F32: Duration | G32: 17 mo
B36: SOURCES
B37: Job #2011 — Chinn Barrett Park Apartments • GC: Chinn Construction, LLC • Seattle, WA (Capitol Hill)
B38: Canonical source: 2011 Job Detail Report.pdf (69 pages, OWP Sage Timberline export)
B39: Cost codes parsed: 29
B40: Unit count: 117 units confirmed
B41: Fixture count: 841 from permit SR1224327
B42: Billing: BARRETT AGGREGATE BILLING.xlsx (13 pay apps Nov 2012 – Mar 2014)

Sheet Budget vs Actual
B2: Budget vs Actual — All Cost Codes
B4: Code | C4: Description | D4: Orig Budget | E4: Rev Budget | F4: Actual | G4: Variance | H4: % Used
B5: LABOR
B6: 011 | C6: DS & RD Labor | D6: 3250 | E6: 3250 | F6: 1008 | G6: =E6-F6 -> 2242 | H6: =IF(E6=0,0,F6/E6) -> 0.31015385
B7: 100 | C7: Supervision | D7: 8190 | E7: 8190 | F7: 4164 | G7: =E7-F7 -> 4026 | H7: =IF(E7=0,0,F7/E7) -> 0.50842491
B8: 101 | C8: Takeoff & Purchase Labor | D8: 5850 | E8: 5850 | F8: 3513 | G8: =E8-F8 -> 2337 | H8: =IF(E8=0,0,F8/E8) -> 0.60051282
B9: 110 | C9: Underground Labor | D9: 13150 | E9: 13150 | F9: 6703 | G9: =E9-F9 -> 6447 | H9: =IF(E9=0,0,F9/E9) -> 0.50973384
B10: 111 | C10: Garage Labor | D10: 16200 | E10: 16200 | F10: 10199 | G10: =E10-F10 -> 6001 | H10: =IF(E10=0,0,F10/E10) -> 0.6295679
B11: 112 | C11: Canout Labor | D11: 3640 | E11: 3640 | F11: 2062 | G11: =E11-F11 -> 1578 | H11: =IF(E11=0,0,F11/E11) -> 0.56648352
B12: 113 | C12: Foundation Drain Labor | D12: 0 | E12: 5650 | F12: 2115 | G12: =E12-F12 -> 3535 | H12: =IF(E12=0,0,F12/E12) -> 0.37433628
B13: 120 | C13: Roughin Labor | D13: 82535 | E13: 82835 | F13: 81010.75 | G13: =E13-F13 -> 1824.25 | H13: =IF(E13=0,0,F13/E13) -> 0.9779773
B14: 130 | C14: Finish Labor | D14: 24770 | E14: 24770 | F14: 21869 | G14: =E14-F14 -> 2901 | H14: =IF(E14=0,0,F14/E14) -> 0.88288252
B15: 141 | C15: Water Main/Insulation Lab | D15: 0 | E15: 0 | F15: 208 | G15: =E15-F15 -> -208 | H15: =IF(E15=0,0,F15/E15) -> 0
B16: 142 | C16: Mech Room Labor | D16: 1760 | E16: 1760 | F16: 1007 | G16: =E16-F16 -> 753 | H16: =IF(E16=0,0,F16/E16) -> 0.57215909
B17: 145 | C17: Tub/Shower Labor | D17: 9360 | E17: 9360 | F17: 9024 | G17: =E17-F17 -> 336 | H17: =IF(E17=0,0,F17/E17) -> 0.96410256
B18: MATERIAL
B19: 039 | C19: DS & RD Material | D19: 4725 | E19: 4725 | F19: 1134.76 | G19: =E19-F19 -> 3590.24 | H19: =IF(E19=0,0,F19/E19) -> 0.24016085
B20: 210 | C20: Underground Material | D20: 10300 | E20: 10300 | F20: 5311 | G20: =E20-F20 -> 4989 | H20: =IF(E20=0,0,F20/E20) -> 0.51563107
B21: 211 | C21: Garage Material | D21: 14000 | E21: 14000 | F21: 6465.89 | G21: =E21-F21 -> 7534.11 | H21: =IF(E21=0,0,F21/E21) -> 0.46184929
B22: 212 | C22: Canout Material | D22: 5460 | E22: 5460 | F22: 5222.75 | G22: =E22-F22 -> 237.25 | H22: =IF(E22=0,0,F22/E22) -> 0.95654762
B23: 213 | C23: Foundation Material | D23: 0 | E23: 6000 | F23: 3664.54 | G23: =E23-F23 -> 2335.46 | H23: =IF(E23=0,0,F23/E23) -> 0.61075667
B24: 220 | C24: Roughin Material | D24: 82540 | E24: 82840 | F24: 48840.52 | G24: =E24-F24 -> 33999.48 | H24: =IF(E24=0,0,F24/E24) -> 0.58957653
B25: 230 | C25: Finish Material | D25: 231620 | E25: 259734 | F25: 207101.2 | G25: =E25-F25 -> 52632.8 | H25: =IF(E25=0,0,F25/E25) -> 0.79735884
B26: 241 | C26: Water Main/Insulation Mat | D26: 7800 | E26: 7800 | F26: 15147.02 | G26: =E26-F26 -> -7347.02 | H26: =IF(E26=0,0,F26/E26) -> 1.9419256
B27: 242 | C27: Mech Room Material | D27: 2500 | E27: 2500 | F27: 1233.58 | G27: =E27-F27 -> 1266.42 | H27: =IF(E27=0,0,F27/E27) -> 0.493432
B28: 244 | C28: Fire Caulking Material | D28: 0 | E28: 0 | F28: 0 | G28: =E28-F28 -> 0 | H28: =IF(E28=0,0,F28/E28) -> 0
B29: 245 | C29: Tub/Shower Material | D29: 0 | E29: 0 | F29: 884.62 | G29: =E29-F29 -> -884.62 | H29: =IF(E29=0,0,F29/E29) -> 0
B30: OVERHEAD
B31: 600 | C31: Subcontractor | D31: 10000 | E31: 13085 | F31: 6346.07 | G31: =E31-F31 -> 6738.93 | H31: =IF(E31=0,0,F31/E31) -> 0.48498815
B32: 601 | C32: Engineering/Plans | D32: 25000 | E32: 25000 | F32: 12573.03 | G32: =E32-F32 -> 12426.97 | H32: =IF(E32=0,0,F32/E32) -> 0.5029212
B33: 603 | C33: Permits & Licenses | D33: 7630 | E33: 7640 | F33: 7291 | G33: =E33-F33 -> 349 | H33: =IF(E33=0,0,F33/E33) -> 0.95431937
B34: BURDEN
B35: 995 | C35: Payroll Burden | D35: 73133.62 | E35: 75712.95 | F35: 61834.11 | G35: =E35-F35 -> 13878.84 | H35: =IF(E35=0,0,F35/E35) -> 0.81669133
B36: 998 | C36: Payroll Taxes | D36: 12905.93 | E36: 13338.16 | F36: 10930.61 | G36: =E36-F36 -> 2407.55 | H36: =IF(E36=0,0,F36/E36) -> 0.81949909
B37: TOTAL | C37: Direct Cost | D37: 656319.55 | E37: 702790.11 | F37: 536863.45 | G37: =E37-F37 -> 165926.66 | H37: =IF(E37=0,0,F37/E37) -> 0.76390297
B40: SOURCES
B41: Job #2011 — Chinn Barrett Park Apartments • GC: Chinn Construction, LLC • Seattle, WA (Capitol Hill)
B42: Canonical source: 2011 Job Detail Report.pdf (69 pages, OWP Sage Timberline export)
B43: Cost codes parsed: 29
B44: Unit count: 117 units confirmed
...

Sheet Cost Breakdown
B2: Cost Breakdown — Category Deep Dive
B4: A. CATEGORY SHARE OF DIRECT COST
B5: Category | C5: # Codes | D5: Budget | E5: Actual | F5: Variance | G5: % Budget | H5: % of Cost | I5: Per Unit
B6: Labor | C6: 12 | D6: 174655 | E6: 142882.75 | F6: =D6-E6 -> 31772.25 | G6: =IF(D6=0,0,E6/D6) -> 0.81808565 | H6: =IF(536863.45=0,0,E6/536863.45) -> 0.26614356 | I6: =IF(117=0,0,E6/117) -> 1221.2201
B7: Material | C7: 11 | D7: 393359 | E7: 295005.88 | F7: =D7-E7 -> 98353.12 | G7: =IF(D7=0,0,E7/D7) -> 0.74996601 | H7: =IF(536863.45=0,0,E7/536863.45) -> 0.54949891 | I7: =IF(117=0,0,E7/117) -> 2521.4178
B8: Overhead | C8: 3 | D8: 45725 | E8: 26210.1 | F8: =D8-E8 -> 19514.9 | G8: =IF(D8=0,0,E8/D8) -> 0.57321159 | H8: =IF(536863.45=0,0,E8/536863.45) -> 0.048820794 | I8: =IF(117=0,0,E8/117) -> 224.01795
B9: Burden | C9: 2 | D9: 89051.11 | E9: 72764.72 | F9: =D9-E9 -> 16286.39 | G9: =IF(D9=0,0,E9/D9) -> 0.81711188 | H9: =IF(536863.45=0,0,E9/536863.45) -> 0.13553674 | I9: =IF(117=0,0,E9/117) -> 621.92068
B12: B. LARGEST OVERRUNS (Actual > Revised Budget)
B13: Code | C13: Description | D13: Rev Budget | E13: Actual | F13: Overrun | G13: % Over
B14: 241 | C14: Water Main/Insulation Mat | D14: 7800 | E14: 15147.02 | F14: =E14-D14 -> 7347.02 | G14: =IF(D14=0,0,F14/D14) -> 0.94192564
B15: 245 | C15: Tub/Shower Material | D15: 0 | E15: 884.62 | F15: =E15-D15 -> 884.62 | G15: =IF(D15=0,0,F15/D15) -> 0
B16: 141 | C16: Water Main/Insulation Lab | D16: 0 | E16: 208 | F16: =E16-D16 -> 208 | G16: =IF(D16=0,0,F16/D16) -> 0
B19: C. LARGEST SAVINGS (Actual < Revised Budget)
B20: Code | C20: Description | D20: Rev Budget | E20: Actual | F20: Savings | G20: % Under
B21: 230 | C21: Finish Material | D21: 259734 | E21: 207101.2 | F21: =D21-E21 -> 52632.8 | G21: =IF(D21=0,0,F21/D21) -> 0.20264116
B22: 220 | C22: Roughin Material | D22: 82840 | E22: 48840.52 | F22: =D22-E22 -> 33999.48 | G22: =IF(D22=0,0,F22/D22) -> 0.41042347
B23: 995 | C23: Payroll Burden | D23: 75712.95 | E23: 61834.11 | F23: =D23-E23 -> 13878.84 | G23: =IF(D23=0,0,F23/D23) -> 0.18330867
B24: 601 | C24: Engineering/Plans | D24: 25000 | E24: 12573.03 | F24: =D24-E24 -> 12426.97 | G24: =IF(D24=0,0,F24/D24) -> 0.4970788
B25: 211 | C25: Garage Material | D25: 14000 | E25: 6465.89 | F25: =D25-E25 -> 7534.11 | G25: =IF(D25=0,0,F25/D25) -> 0.53815071
B26: 600 | C26: Subcontractor | D26: 13085 | E26: 6346.07 | F26: =D26-E26 -> 6738.93 | G26: =IF(D26=0,0,F26/D26) -> 0.51501185
B27: 110 | C27: Underground Labor | D27: 13150 | E27: 6703 | F27: =D27-E27 -> 6447 | G27: =IF(D27=0,0,F27/D27) -> 0.49026616
B28: 111 | C28: Garage Labor | D28: 16200 | E28: 10199 | F28: =D28-E28 -> 6001 | G28: =IF(D28=0,0,F28/D28) -> 0.3704321
B29: 210 | C29: Underground Material | D29: 10300 | E29: 5311 | F29: =D29-E29 -> 4989 | G29: =IF(D29=0,0,F29/D29) -> 0.48436893
B30: 100 | C30: Supervision | D30: 8190 | E30: 4164 | F30: =D30-E30 -> 4026 | G30: =IF(D30=0,0,F30/D30) -> 0.49157509
B33: SOURCES
B34: Job #2011 — Chinn Barrett Park Apartments • GC: Chinn Construction, LLC • Seattle, WA (Capitol Hill)
B35: Canonical source: 2011 Job Detail Report.pdf (69 pages, OWP Sage Timberline export)
B36: Cost codes parsed: 29
B37: Unit count: 117 units confirmed
B38: Fixture count: 841 from permit SR1224327
B39: Billing: BARRETT AGGREGATE BILLING.xlsx (13 pay apps Nov 2012 – Mar 2014)

Sheet Material
B2: Material Spend Analysis
B3: 11 material cost codes • $295,006 JDR material • 14 AP vendors • $387,379 total AP
B5: A. MATERIAL BY COST CODE
B6: Code | C6: Description | D6: Rev Budget | E6: Actual | F6: Variance | G6: % Used | H6: % of Mat | I6: Per Unit
B7: 039 | C7: DS & RD Material | D7: 4725 | E7: 1134.76 | F7: =D7-E7 -> 3590.24 | G7: =IF(D7=0,0,E7/D7) -> 0.24016085 | H7: =IF(295005.88=0,0,E7/295005.88) -> 0.0038465674 | I7: =IF(117=0,0,E7/117) -> 9.6988034
B8: 210 | C8: Underground Material | D8: 10300 | E8: 5311 | F8: =D8-E8 -> 4989 | G8: =IF(D8=0,0,E8/D8) -> 0.51563107 | H8: =IF(295005.88=0,0,E8/295005.88) -> 0.018003031 | I8: =IF(117=0,0,E8/117) -> 45.393162
B9: 211 | C9: Garage Material | D9: 14000 | E9: 6465.89 | F9: =D9-E9 -> 7534.11 | G9: =IF(D9=0,0,E9/D9) -> 0.46184929 | H9: =IF(295005.88=0,0,E9/295005.88) -> 0.021917834 | I9: =IF(117=0,0,E9/117) -> 55.264017
B10: 212 | C10: Canout Material | D10: 5460 | E10: 5222.75 | F10: =D10-E10 -> 237.25 | G10: =IF(D10=0,0,E10/D10) -> 0.95654762 | H10: =IF(295005.88=0,0,E10/295005.88) -> 0.017703884 | I10: =IF(117=0,0,E10/117) -> 44.638889
B11: 213 | C11: Foundation Material | D11: 6000 | E11: 3664.54 | F11: =D11-E11 -> 2335.46 | G11: =IF(D11=0,0,E11/D11) -> 0.61075667 | H11: =IF(295005.88=0,0,E11/295005.88) -> 0.012421922 | I11: =IF(117=0,0,E11/117) -> 31.320855
B12: 220 | C12: Roughin Material | D12: 82840 | E12: 48840.52 | F12: =D12-E12 -> 33999.48 | G12: =IF(D12=0,0,E12/D12) -> 0.58957653 | H12: =IF(295005.88=0,0,E12/295005.88) -> 0.16555778 | I12: =IF(117=0,0,E12/117) -> 417.44034
B13: 230 | C13: Finish Material | D13: 259734 | E13: 207101.2 | F13: =D13-E13 -> 52632.8 | G13: =IF(D13=0,0,E13/D13) -> 0.79735884 | H13: =IF(295005.88=0,0,E13/295005.88) -> 0.70202397 | I13: =IF(117=0,0,E13/117) -> 1770.0957
B14: 241 | C14: Water Main/Insulation Mat | D14: 7800 | E14: 15147.02 | F14: =D14-E14 -> -7347.02 | G14: =IF(D14=0,0,E14/D14) -> 1.9419256 | H14: =IF(295005.88=0,0,E14/295005.88) -> 0.051344807 | I14: =IF(117=0,0,E14/117) -> 129.46171
B15: 242 | C15: Mech Room Material | D15: 2500 | E15: 1233.58 | F15: =D15-E15 -> 1266.42 | G15: =IF(D15=0,0,E15/D15) -> 0.493432 | H15: =IF(295005.88=0,0,E15/295005.88) -> 0.0041815438 | I15: =IF(117=0,0,E15/117) -> 10.543419
B16: 244 | C16: Fire Caulking Material | D16: 0 | E16: 0 | F16: =D16-E16 -> 0 | G16: =IF(D16=0,0,E16/D16) -> 0 | H16: =IF(295005.88=0,0,E16/295005.88) -> 0 | I16: =IF(117=0,0,E16/117) -> 0
B17: 245 | C17: Tub/Shower Material | D17: 0 | E17: 884.62 | F17: =D17-E17 -> -884.62 | G17: =IF(D17=0,0,E17/D17) -> 0 | H17: =IF(295005.88=0,0,E17/295005.88) -> 0.0029986521 | I17: =IF(117=0,0,E17/117) -> 7.5608547
B18: TOTAL | C18: All Material | D18: =SUM(D7:D17) -> 393359 | E18: =SUM(E7:E17) -> 295005.88 | F18: =D18-E18 -> 98353.12 | G18: =IF(D18=0,0,E18/D18) -> 0.74996601 | H18: 1 | I18: =IF(117=0,0,E18/117) -> 2521.4178
B21: B. VENDORS BY SPEND (AP)
B22: Vendor | C22: # Invoices | D22: Total Spend | E22: % of AP | I22: Avg Invoice
B23: Ferguson Enterprises, Inc. | C23: 56 | D23: 302211.38 | E23: =IF(387378.94=0,0,D23/387378.94) -> 0.78014406 | I23: =IF(C23=0,0,D23/C23) -> 5396.6318
B24: Rosen Supply Company, Inc. | C24: 30 | D24: 35755.01 | E24: =IF(387378.94=0,0,D24/387378.94) -> 0.092299829 | I24: =IF(C24=0,0,D24/C24) -> 1191.8337
B25: Franklin Engineering | C25: 5 | D25: 12487 | E25: =IF(387378.94=0,0,D25/387378.94) -> 0.032234587 | I25: =IF(C25=0,0,D25/C25) -> 2497.4
B26: Keller Supply Company | C26: 13 | D26: 10651.28 | E26: =IF(387378.94=0,0,D26/387378.94) -> 0.027495764 | I26: =IF(C26=0,0,D26/C26) -> 819.32923
B27: Fastenal Company | C27: 4 | D27: 8107.96 | E27: =IF(387378.94=0,0,D27/387378.94) -> 0.020930307 | I27: =IF(C27=0,0,D27/C27) -> 2026.99
B28: Bank of America CC | C28: 3 | D28: 7291 | E28: =IF(387378.94=0,0,D28/387378.94) -> 0.018821364 | I28: =IF(C28=0,0,D28/C28) -> 2430.3333
B29: Mickelo Construction LLC | C29: 2 | D29: 6217.07 | E29: =IF(387378.94=0,0,D29/387378.94) -> 0.016049066 | I29: =IF(C29=0,0,D29/C29) -> 3108.535
B30: Quality Concrete Products, Inc. | C30: 2 | D30: 2598 | E30: =IF(387378.94=0,0,D30/387378.94) -> 0.0067066114 | I30: =IF(C30=0,0,D30/C30) -> 1299
B31: Manor Hardware & Construction Supply | C31: 2 | D31: 870 | E31: =IF(387378.94=0,0,D31/387378.94) -> 0.0022458629 | I31: =IF(C31=0,0,D31/C31) -> 435
B32: Core & Main LP | C32: 1 | D32: 810 | E32: =IF(387378.94=0,0,D32/387378.94) -> 0.0020909758 | I32: =IF(C32=0,0,D32/C32) -> 810
B33: R.A. Brown Backflow Testing | C33: 1 | D33: 129 | E33: =IF(387378.94=0,0,D33/387378.94) -> 0.00033300726 | I33: =IF(C33=0,0,D33/C33) -> 129
B34: C.M. Hoskins Company | C34: 1 | D34: 102 | E34: =IF(387378.94=0,0,D34/387378.94) -> 0.00026330807 | I34: =IF(C34=0,0,D34/C34) -> 102
... B36: Capital One Credit Card | C36: 2 | D36: 63.21 | E36: =IF(387378.94=0,0,D36/387378.94) -> 0.00016317356 | I36: =IF(C36=0,0,D36/C36) -> 31.605
B37: TOTAL | C37: =SUM(C23:C36) -> 123 | D37: =SUM(D23:D36) -> 387378.94 | E37: 1
B40: SOURCES
B41: Job #2011 — Chinn Barrett Park Apartments • GC: Chinn Construction, LLC • Seattle, WA (Capitol Hill)
B42: Canonical source: 2011 Job Detail Report.pdf (69 pages, OWP Sage Timberline export)
B43: Cost codes parsed: 29
B44: Unit count: 117 units confirmed
B45: Fixture count: 841 from permit SR1224327
B46: Billing: BARRETT AGGREGATE BILLING.xlsx (13 pay apps Nov 2012 – Mar 2014)
B47: Vendor AP ties to JDR 'by Source: AP' line (387,378.94)

Sheet Crew & Labor
B2: Crew & Labor — Per-Worker Breakdown
B4: Worker | C4: Hours | D4: Gross Pay | E4: $/Hour | F4: Tier
B5: Quintanilla, Esteban R | C5: 804.5 | D5: 24669 | E5: =IF(C5=0,0,D5/C5) -> 30.663766 | F5: Senior
B6: Castro Hernandez, Jose A | C6: 785.5 | D6: 11541 | E6: =IF(C6=0,0,D6/C6) -> 14.692553 | F6: Apprentice
B7: Monico Brambila, Jesus S | C7: 640 | D7: 7792 | E7: =IF(C7=0,0,D7/C7) -> 12.175 | F7: Apprentice
B8: Garcia, Jordan X | C8: 607 | D8: 7748 | E8: =IF(C8=0,0,D8/C8) -> 12.764415 | F8: Apprentice
B9: Lima Romero, Melvin A | C9: 523.5 | D9: 9941.5 | E9: =IF(C9=0,0,D9/C9) -> 18.990449 | F9: Mid
B10: Castaneda Martinez, Gustavo | C10: 449 | D10: 11691 | E10: =IF(C10=0,0,D10/C10) -> 26.037862 | F10: Mid
B11: Palma Vides, Hugo | C11: 384 | D11: 9984 | E11: =IF(C11=0,0,D11/C11) -> 26 | F11: Mid
B12: Anderson, Richard P | C12: 341 | D12: 8866 | E12: =IF(C12=0,0,D12/C12) -> 26 | F12: Mid
B13: Wilson, Garret A | C13: 320 | D13: 4296 | E13: =IF(C13=0,0,D13/C13) -> 13.425 | F13: Apprentice
B14: Gerard, Jeffrey S | C14: 254 | D14: 8779 | E14: =IF(C14=0,0,D14/C14) -> 34.562992 | F14: Senior
B15: McCabe, Thomas C | C15: 196 | D15: 3504 | E15: =IF(C15=0,0,D15/C15) -> 17.877551 | F15: Apprentice
B16: Ross, Kelli M | C16: 189 | D16: 5292 | E16: =IF(C16=0,0,D16/C16) -> 28 | F16: Mid
... B35: Vaughan, Tyler J | C35: 8 | D35: 104 | E35: =IF(C35=0,0,D35/C35) -> 13 | F35: Apprentice
B36: TOTAL (31 workers) | C36: =SUM(C5:C35) -> 6803 | D36: =SUM(D5:D35) -> 138693.5 | E36: =IF(C36=0,0,D36/C36) -> 20.387109
B39: SOURCES
B40: Job #2011 — Chinn Barrett Park Apartments • GC: Chinn Construction, LLC • Seattle, WA (Capitol Hill)
B41: Canonical source: 2011 Job Detail Report.pdf (69 pages, OWP Sage Timberline export)
B42: Cost codes parsed: 29
B43: Unit count: 117 units confirmed
B44: Fixture count: 841 from permit SR1224327
B45: Billing: BARRETT AGGREGATE BILLING.xlsx (13 pay apps Nov 2012 – Mar 2014)
B46: Tier: Apprentice <$18/hr, Mid $18–30, Senior >$30

Sheet Crew Analytics
B2: Crew Analytics
B4: A. TIER DISTRIBUTION
B5: Tier | C5: # Workers | D5: Hours | E5: Gross Pay | F5: % of Hours
B6: Senior | C6: 3 | D6: 1180.5 | E6: 37230 | F6: =IF(6803=0,0,D6/6803) -> 0.17352639
B7: Mid | C7: 12 | D7: 2401.5 | E7: 57652.5 | F7: =IF(6803=0,0,D7/6803) -> 0.35300603
B8: Apprentice | C8: 16 | D8: 3221 | E8: 43811 | F8: =IF(6803=0,0,D8/6803) -> 0.47346759
B11: B. WAGE STATISTICS
B12: Blended Gross Wage | C12: 20.387109 | F12: Payroll $ ÷ payroll hours (pre-burden)
B13: Fully-Loaded Wage | C13: 31.698878 | F13: (Labor + Burden) ÷ total hours
B14: Burden Multiplier | C14: 1.5548491 | F14: Fully loaded ÷ gross wage
B15: Min Worker Rate | C15: 11.882353 | F15: Cheapest apprentice hour
B16: Max Worker Rate | C16: 34.562992 | F16: Most expensive foreman hour
B17: Avg Hours / Worker | C17: 219.45161 | F17: Crew continuity indicator
B20: SOURCES
B21: Job #2011 — Chinn Barrett Park Apartments • GC: Chinn Construction, LLC • Seattle, WA (Capitol Hill)
B22: Canonical source: 2011 Job Detail Report.pdf (69 pages, OWP Sage Timberline export)
B23: Cost codes parsed: 29
B24: Unit count: 117 units confirmed
B25: Fixture count: 841 from permit SR1224327
B26: Billing: BARRETT AGGREGATE BILLING.xlsx (13 pay apps Nov 2012 – Mar 2014)

Sheet Productivity
B2: Productivity — Phase & Unit Metrics
B4: A. LABOR HOURS BY PHASE
B5: Phase | C5: Labor Code | D5: Hours | E5: % of Total | F5: Hours / Unit
B6: DS & RD | C6: 011 | D6: 56 | E6: =IF(6943.5=0,0,D6/6943.5) -> 0.0080650969 | F6: =IF(117=0,0,D6/117) -> 0.47863248
B7: Supervision | C7: 100 | D7: 117 | E7: =IF(6943.5=0,0,D7/6943.5) -> 0.016850292 | F7: =IF(117=0,0,D7/117) -> 1
B8: Takeoff & Purchasing | C8: 101 | D8: 104 | E8: =IF(6943.5=0,0,D8/6943.5) -> 0.014978037 | F8: =IF(117=0,0,D8/117) -> 0.88888889
B9: Underground | C9: 110 | D9: 298.5 | E9: =IF(6943.5=0,0,D9/6943.5) -> 0.042989847 | F9: =IF(117=0,0,D9/117) -> 2.5512821
B10: Garage | C10: 111 | D10: 553 | E10: =IF(6943.5=0,0,D10/6943.5) -> 0.079642831 | F10: =IF(117=0,0,D10/117) -> 4.7264957
B11: Canout | C11: 112 | D11: 96 | E11: =IF(6943.5=0,0,D11/6943.5) -> 0.01382588 | F11: =IF(117=0,0,D11/117) -> 0.82051282
B12: Foundation Drain | C12: 113 | D12: 96.5 | E12: =IF(6943.5=0,0,D12/6943.5) -> 0.01389789 | F12: =IF(117=0,0,D12/117) -> 0.82478632
B13: Roughin | C13: 120 | D13: 3984 | E13: =IF(6943.5=0,0,D13/6943.5) -> 0.57377403 | F13: =IF(117=0,0,D13/117) -> 34.051282
B14: Finish | C14: 130 | D14: 1173 | E14: =IF(6943.5=0,0,D14/6943.5) -> 0.16893498 | F14: =IF(117=0,0,D14/117) -> 10.025641
B15: Water Main / Insulation | C15: 141 | D15: 16 | E15: =IF(6943.5=0,0,D15/6943.5) -> 0.0023043134 | F15: =IF(117=0,0,D15/117) -> 0.13675214
B16: Mech Room | C16: 142 | D16: 44 | E16: =IF(6943.5=0,0,D16/6943.5) -> 0.0063368618 | F16: =IF(117=0,0,D16/117) -> 0.37606838
B17: Tub / Shower | C17: 145 | D17: 405.5 | E17: =IF(6943.5=0,0,D17/6943.5) -> 0.058399942 | F17: =IF(117=0,0,D17/117) -> 3.465812
B18: TOTAL | D18: =SUM(D6:D17) -> 6943.5 | E18: 1 | F18: =IF(117=0,0,D18/117) -> 59.346154
B21: B. PRODUCTIVITY RATIOS
B22: Metric | C22: Value | D22: Units | F22: Notes
B23: Hours / Unit | C23: 59.346154 | D23: hrs | F23: Labor hours per residential unit
B24: Hours / Fixture | C24: 8.2562426 | D24: hrs | F24: Labor hours per plumbing fixture
B25: Revenue / Hour | C25: 125.27162 | D25: $ | F25: Top-line per labor hour
B26: Profit / Hour | C26: 47.952769 | D26: $ | F26: Bottom-line per labor hour
B27: Units / Month | C27: 6.8823529 | D27: units | F27: Build velocity
B28: Fixtures / Month | C28: 49.470588 | D28: fix | F28: Fixture install pace
B29: Hours / Month | C29: 408.44118 | D29: hrs | F29: Monthly labor burn
B30: Revenue / Month | C30: 51166.088 | D30: $ | F30: Monthly billing rate
B33: SOURCES
B34: Job #2011 — Chinn Barrett Park Apartments • GC: Chinn Construction, LLC • Seattle, WA (Capitol Hill)
B35: Canonical source: 2011 Job Detail Report.pdf (69 pages, OWP Sage Timberline export)
B36: Cost codes parsed: 29
B37: Unit count: 117 units confirmed
B38: Fixture count: 841 from permit SR1224327
B39: Billing: BARRETT AGGREGATE BILLING.xlsx (13 pay apps Nov 2012 – Mar 2014)

Sheet PO Commitments
B2: Purchase Order Commitments
B3: 0 unique POs • PO amounts not dollar-parsed from individual PDFs • JDR material $295,006
B5: A. COMMITMENTS BY COST CODE
B6: OWP Code | C6: Description → JDR | D6: PO Count | E6: % of POs | F6: JDR Material
B7: TOTAL | D7: =SUM(D7:D6) -> #VALUE! | E7: 1 | F7: 295005.88
B10: B. COMMITMENTS BY VENDOR
B11: Vendor | C11: PO Count | D11: % of POs
B14: C. PO COVERAGE NOTES
B15: Total Material Actual (JDR) | E15: 295005.88
B16: Unique PO Count | E16: 0
B17: (Dollar PO commitment not extracted — requires per-PDF parse)
B20: SOURCES
B21: Job #2011 — Chinn Barrett Park Apartments • GC: Chinn Construction, LLC • Seattle, WA (Capitol Hill)
B22: Canonical source: 2011 Job Detail Report.pdf (69 pages, OWP Sage Timberline export)
B23: Cost codes parsed: 29
B24: Unit count: 117 units confirmed
B25: Fixture count: 841 from permit SR1224327
B26: Billing: BARRETT AGGREGATE BILLING.xlsx (13 pay apps Nov 2012 – Mar 2014)
B27: PO count is deduplicated by 5-digit PO number extracted from filenames
B28: Vendor/code classification is heuristic (filename keyword match)

Sheet Billing & SOV
B2: Revenue & Billing Reconciliation
B3: 13 pay applications • Nov 2012 – Mar 2014 • $869,824 final
B5: A. CONTRACT SUMMARY
B6: Original Contract | G6: 813050
B7: Change Orders (net) | G7: 56774
B8: Final Contract Value | G8: 869824
B9: Retainage (5%) | G9: 43491
B10: Net Paid to OWP | G10: 826333
B12: B. PAY APPLICATION TIMELINE
B13: App# | C13: Date | D13: Period Billing | E13: Retention | F13: Net This Period | G13: Aggregate | H13: % Complete
B14: 1 | C14: 2012-11-15 | D14: 9500 | E14: 475 | F14: =D14-E14 -> 9025 | G14: 9025 | H14: =IF(869823.5=0,0,G14/869823.5) -> 0.010375668
B15: 2 | C15: 2013-01-15 | D15: 32700 | E15: 1635 | F15: =D15-E15 -> 31065 | G15: 40090 | H15: =IF(869823.5=0,0,G15/869823.5) -> 0.04608981
B16: 3 | C16: 2013-02-15 | D16: 33000 | E16: 1650 | F16: =D16-E16 -> 31350 | G16: 71440 | H16: =IF(869823.5=0,0,G16/869823.5) -> 0.082131605
B17: 4 | C17: 2013-03-15 | D17: 38800 | E17: 1940 | F17: =D17-E17 -> 36860 | G17: 108300 | H17: =IF(869823.5=0,0,G17/869823.5) -> 0.12450802
B18: 5 | C18: 2013-04-09 | D18: 18700 | E18: 935 | F18: =D18-E18 -> 17765 | G18: 126065 | H18: =IF(869823.5=0,0,G18/869823.5) -> 0.1449317
B19: 6 | C19: 2013-05-09 | D19: 63000 | E19: 3150 | F19: =D19-E19 -> 59850 | G19: 185915 | H19: =IF(869823.5=0,0,G19/869823.5) -> 0.21373876
B20: 7 | C20: 2013-06-11 | D20: 235300 | E20: 11765 | F20: =D20-E20 -> 223535 | G20: 409450 | H20: =IF(869823.5=0,0,G20/869823.5) -> 0.47072768
B21: 8 | C21: 2013-07-11 | D21: 183000 | E21: 9150 | F21: =D21-E21 -> 173850 | G21: 583300 | H21: =IF(869823.5=0,0,G21/869823.5) -> 0.67059582
B22: 9 | C22: 2013-08-09 | D22: 41009 | E22: 2050.45 | F22: =D22-E22 -> 38958.55 | G22: 622258.55 | H22: =IF(869823.5=0,0,G22/869823.5) -> 0.71538485
B23: 10 | C23: 2013-09-10 | D23: 5400 | E23: 270 | F23: =D23-E23 -> 5130 | G23: 627388.55 | H23: =IF(869823.5=0,0,G23/869823.5) -> 0.72128259
B24: 11 | C24: 2013-10-10 | D24: 5100 | E24: 255 | F24: =D24-E24 -> 4845 | G24: 632233.55 | H24: =IF(869823.5=0,0,G24/869823.5) -> 0.72685269
B25: 12 | C25: 2014-02-10 | D25: 103997 | E25: 5199.85 | F25: =D25-E25 -> 98797.15 | G25: 731030.7 | H25: =IF(869823.5=0,0,G25/869823.5) -> 0.84043567
... B27: 14 | C27: 2014-11-13 | D27: 43491.18 | E27: 0 | F27: =D27-E27 -> 43491.18 | G27: 869823.5 | H27: =IF(869823.5=0,0,G27/869823.5) -> 1
B29: C. BILLING ↔ JDR TIE-OUT
B30: Metric | C30: SOV | D30: JDR | E30: Δ | F30: Status
B31: Final Contract Value | C31: 869824 | D31: 869824 | E31: =C31-D31 -> 0 | F31: =IF(ABS(E31)<=1,"TIES",IF(ABS(E31)<=ABS(D31)*0.05,"WITHIN","OFF")) -> TIES
B32: Retainage | C32: 43491 | D32: 43491 | E32: =C32-D32 -> 0 | F32: =IF(ABS(E32)<=1,"TIES",IF(ABS(E32)<=ABS(D32)*0.05,"WITHIN","OFF")) -> TIES
B33: Direct Cost | C33: 536863.45 | D33: 536863.45 | E33: =C33-D33 -> 0 | F33: =IF(ABS(E33)<=1,"TIES",IF(ABS(E33)<=ABS(D33)*0.05,"WITHIN","OFF")) -> TIES
B37: SOURCES
B38: Job #2011 — Chinn Barrett Park Apartments • GC: Chinn Construction, LLC • Seattle, WA (Capitol Hill)
B39: Canonical source: 2011 Job Detail Report.pdf (69 pages, OWP Sage Timberline export)
B40: Cost codes parsed: 29
B41: Unit count: 117 units confirmed
B42: Fixture count: 841 from permit SR1224327
B43: Billing: BARRETT AGGREGATE BILLING.xlsx (13 pay apps Nov 2012 – Mar 2014)

Sheet Insights
B2: Key Insights — Job #2011 Chinn Barrett Park Apartments
B3: Narrative observations distilled from the full JDR analysis
B5: MARGIN PROFILE | C5: Net profit of $332,960 on $869,824 revenue = 38.3% gross margin. Direct cost $536,863 absorbs 61.7% of revenue.
B6: VENDOR CONCENTRATION | C6: Ferguson Enterprises, Inc. alone = $302,211 (78% of all AP) across 56 invoices. Total 14 AP vendors, $387,379 total AP spend.
B7: CREW PROFILE | C7: 31 workers for 6,944 hours = 224 avg hrs/worker. Top 3 workers logged 2,230 hrs combined (32% of all labor).
B8: ROUGHIN DOMINANCE | C8: Code 120 Roughin Labor = 3,984 hrs (57% of all labor) and $81,011 actual. Code 230 Finish Material = $207,101 — 39% of total direct cost.
B9: BUDGET DELIVERY | C9: Revised budget was $702,790; actual direct cost $536,863 → $165,927 variance (23.6% under revised budget).
B10: CONTRACT GROWTH | C10: Contract grew from $813,050 to $869,824 — net +$56,774 (7.0%). Retainage of $43,491 (5%) withheld until closeout.
B11: BURDEN RATIO | C11: Burden codes 995 + 998 = $72,765 on $142,883 labor base = 50.9%. In line with OWP's typical 48–50% labor burden.
B12: PROJECT SCALE | C12: 117 units · 841 fixtures · 17 months. Revenue/unit $7,434, hours/unit 59.3, profit/unit $2,846.
B13: PRODUCTIVITY | C13: Blended labor rate $20.58/hr. Revenue/hour $125. Profit/hour $48. 408 hrs/month burn rate.
B14: FIXTURE DENSITY | C14: 841 fixtures ÷ 117 units = 7.19 fixtures/unit. Material/fixture $351, labor/fixture $170.
B16: BIGGEST QUESTION
B17: How does this job's 38.3% margin compare across similar projects in the OWP portfolio, and what operational levers drove the result — estimating accuracy, vendor pricing, or labor productivity?
B20: SOURCES
B21: Job #2011 — Chinn Barrett Park Apartments • GC: Chinn Construction, LLC • Seattle, WA (Capitol Hill)
B22: Canonical source: 2011 Job Detail Report.pdf (69 pages, OWP Sage Timberline export)
B23: Cost codes parsed: 29
B24: Unit count: 117 units confirmed
B25: Fixture count: 841 from permit SR1224327
B26: Billing: BARRETT AGGREGATE BILLING.xlsx (13 pay apps Nov 2012 – Mar 2014)

Sheet Benchmark KPIs
B2: Benchmark KPIs
B3: Normalized metrics designed for apples-to-apples comparison across all OWP projects
B5: KPI | C5: Data Name | D5: Value | E5: Category | F5: Notes | G5: Confidence | H5: Source Document
B6: Job Number | C6: job_number | D6: 2011 | E6: Profile | F6: OWP job ID | G6: Verified | H6: Benchmark KPIs / Metric Registry — see source tabs
B7: Job Name | C7: job_name | D7: Chinn Barrett Park Apartments | E7: Profile | G7: Verified | H7: Benchmark KPIs / Metric Registry — see source tabs
B8: General Contractor | C8: general_contractor | D8: Chinn Construction, LLC | E8: Profile | G8: Verified | H8: Benchmark KPIs / Metric Registry — see source tabs
B9: Location | C9: location | D9: Seattle, WA (Capitol Hill) | E9: Profile | G9: Verified | H9: Benchmark KPIs / Metric Registry — see source tabs
B10: Project Type | C10: project_type | D10: 117-unit 4-story multifamily apartments | E10: Profile | G10: Verified | H10: Benchmark KPIs / Metric Registry — see source tabs
B11: Duration (months) | C11: duration_months | D11: 17 | E11: Profile | F11: Nov 2012 – Mar 2014 (~17 months) | G11: Verified | H11: Benchmark KPIs / Metric Registry — see source tabs
B12: Unit Count | C12: unit_count | D12: 117 | E12: Profile | G12: Verified | H12: Benchmark KPIs / Metric Registry — see source tabs
B13: Total Fixtures | C13: total_fixtures | D13: 841 | E13: Profile | G13: Verified | H13: Benchmark KPIs / Metric Registry — see source tabs
B14: Fixtures per Unit | C14: fixtures_per_unit | D14: 7.1880342 | E14: Profile | G14: Verified | H14: Benchmark KPIs / Metric Registry — see source tabs
B15: Contract Value (Orig) | C15: contract_original | D15: 813050 | E15: Financial | G15: Verified | H15: Benchmark KPIs / Metric Registry — see source tabs
B16: Contract Value (Final) | C16: contract_final | D16: 869823.5 | E16: Financial | F16: After change orders | G16: Verified | H16: Benchmark KPIs / Metric Registry — see source tabs
B17: Change Orders ($) | C17: change_orders | D17: 56773.5 | E17: Financial | G17: Verified | H17: Benchmark KPIs / Metric Registry — see source tabs
B18: Revenue | C18: revenue | D18: 869823.5 | E18: Financial | G18: Verified | H18: Benchmark KPIs / Metric Registry — see source tabs
B19: Net Profit | C19: net_profit | D19: 332960.05 | E19: Financial | G19: Verified | H19: Benchmark KPIs / Metric Registry — see source tabs
B20: Gross Margin | C20: gross_margin | D20: 0.38279036 | E20: Financial | G20: Verified | H20: Benchmark KPIs / Metric Registry — see source tabs
B21: Direct Cost | C21: direct_cost | D21: 536863.45 | E21: Financial | G21: Verified | H21: Benchmark KPIs / Metric Registry — see source tabs
B22: Labor Cost | C22: labor_cost | D22: 142882.75 | E22: Labor | F22: Sum of 12 labor codes | G22: Verified | H22: Benchmark KPIs / Metric Registry — see source tabs
B23: Material Cost | C23: material_cost | D23: 295005.88 | E23: Material | F23: Sum of 11 material codes | G23: Verified | H23: Benchmark KPIs / Metric Registry — see source tabs
B24: Overhead Cost | C24: overhead_cost | D24: 26210.1 | E24: Financial | F24: Sub+Eng+Permits | G24: Verified | H24: Benchmark KPIs / Metric Registry — see source tabs
B25: Burden Cost | C25: burden_cost | D25: 72764.72 | E25: Financial | F25: Codes 995+998 | G25: Verified | H25: Benchmark KPIs / Metric Registry — see source tabs
B26: Retainage | C26: retainage | D26: 43491 | E26: Financial | F26: 5% withheld | G26: Verified | H26: Benchmark KPIs / Metric Registry — see source tabs
B27: Revenue per Unit | C27: revenue_per_unit | D27: 7434.3889 | E27: Financial | G27: Verified | H27: Benchmark KPIs / Metric Registry — see source tabs
B28: Profit per Unit | C28: profit_per_unit | D28: 2845.8124 | E28: Financial | G28: Verified | H28: Benchmark KPIs / Metric Registry — see source tabs
B29: Direct Cost per Unit | C29: cost_per_unit | D29: 4588.5765 | E29: Financial | G29: Verified | H29: Benchmark KPIs / Metric Registry — see source tabs
B30: Labor Cost per Unit | C30: labor_per_unit | D30: 1221.2201 | E30: Labor | G30: Verified | H30: Benchmark KPIs / Metric Registry — see source tabs
B31: Material Cost per Unit | C31: material_per_unit | D31: 2521.4178 | E31: Material | G31: Verified | H31: Benchmark KPIs / Metric Registry — see source tabs
B32: Revenue per Fixture | C32: revenue_per_fixture | D32: 1034.2729 | E32: Financial | G32: Verified | H32: Benchmark KPIs / Metric Registry — see source tabs
B33: Profit per Fixture | C33: profit_per_fixture | D33: 395.90969 | E33: Financial | G33: Verified | H33: Benchmark KPIs / Metric Registry — see source tabs
B34: Cost per Fixture | C34: cost_per_fixture | D34: 638.3632 | E34: Financial | G34: Verified | H34: Benchmark KPIs / Metric Registry — see source tabs
B35: Labor per Fixture | C35: labor_per_fixture | D35: 169.89625 | E35: Labor | G35: Verified | H35: Benchmark KPIs / Metric Registry — see source tabs
B36: Material per Fixture | C36: material_per_fixture | D36: 350.77988 | E36: Material | G36: Verified | H36: Benchmark KPIs / Metric Registry — see source tabs
B37: Total Labor Hours | C37: total_hours | D37: 6943.5 | E37: Labor | F37: Sum of JDR cost code hours | G37: Verified | H37: Benchmark KPIs / Metric Registry — see source tabs
B38: Total Workers | C38: total_workers | D38: 31 | E38: Labor | F38: Unique payroll IDs | G38: Verified | H38: Benchmark KPIs / Metric Registry — see source tabs
B39: Blended Gross Wage | C39: blended_gross_wage | D39: 19.974581 | E39: Labor | F39: Pre-burden | G39: Verified | H39: Benchmark KPIs / Metric Registry — see source tabs
B40: Fully-Loaded Wage | C40: fully_loaded_wage | D40: 31.057459 | E40: Labor | F40: Post-burden | G40: Verified | H40: Benchmark KPIs / Metric Registry — see source tabs
B41: Burden Multiplier | C41: burden_multiplier | D41: 1.5548491 | E41: Labor | G41: Verified | H41: Benchmark KPIs / Metric Registry — see source tabs
B42: Hours per Unit | C42: hours_per_unit | D42: 59.346154 | E42: Labor | F42: Key benchmark | G42: Verified | H42: Benchmark KPIs / Metric Registry — see source tabs
...

Sheet Change Log
B2: Change Log — Master Register
B3: Unified change-event ledger: RFIs, ASIs, COPs, COs, Backcharges, T&M (29 events)
B5: Event ID | C5: Type | D5: Date | E5: Subject | F5: Originator | G5: Linked Event(s) | H5: Cost Impact ($) | I5: Schedule (days) | J5: Status | K5: Source Document
B6: CO-001 | C6: CO | D6: 2013-04-11 | E6: Furnish and install footing + sub-slab drains (field condition discovered during excavation) | F6: Field (OWP) | H6: 25400 | I6: 0 | J6: Approved | K6: 2011-Chinn, Barrett Park/Barrett billing/Chinn Barrett Park schedule of values 1
B7: CO-002 | C7: CO | D7: 2013-05-09 | E7: Add trash chute wash down | F7: Architect | H7: 959 | I7: 0 | J7: Approved | K7: 2011-Chinn, Barrett Park/Barrett billing/Chinn Barrett Park schedule of values 5
B8: CO-003 | C8: CO | D8: 2014-02-10 | E8: Change plumbing fixtures — ADA + standard alternatives | F8: Architect | G8: SUB-P11-R1,SUB-P13-R1,SUB-PRV-R1 | H8: 30415 | I8: 0 | J8: Partial (billed $15,597 of $30,415) | K8: 2011-Chinn, Barrett Park/Barrett billing/Chinn Barrett Park schedule of values 12
B9: ASI-002 | C9: ASI | D9: 2013-04-11 | E9: Revised Unit A-2 layout | F9: Architect | H9: 0 | I9: 0 | J9: Closed | K9: 2011-Chinn, Barrett Park/Barrett RFI-ASI/Barrett ASI 02
B10: ASI-003 | C10: ASI | D10: 2013-04-12 | E10: Revised Unit A-1 layout | F10: Architect | H10: 0 | I10: 0 | J10: Closed | K10: 2011-Chinn, Barrett Park/Barrett RFI-ASI/Barrett ASI 03
B11: ASI-004 | C11: ASI | D11: 2013-04-16 | E11: Live/Work Units ABC dimension clarification | F11: Architect | H11: 0 | I11: 0 | J11: Closed | K11: 2011-Chinn, Barrett Park/Barrett RFI-ASI/Barrett ASI 04
B12: ASI-006 | C12: ASI | D12: 2013-06-04 | E12: Soffit above upper cabinet clarification | F12: Architect | H12: 0 | I12: 0 | J12: Closed | K12: 2011-Chinn, Barrett Park/Barrett RFI-ASI/Barrett ASI 06
B13: ASI-008 | C13: ASI | D13: 2013-09-23 | E13: Unit A2 island counter revision | F13: Architect | H13: 0 | I13: 0 | J13: Closed | K13: 2011-Chinn, Barrett Park/Barrett RFI-ASI/ASI 008
B14: RFI-033 | C14: RFI | D14: 2013-04-11 | E14: Siding detail clarifications | F14: GC (SMS) | H14: 0 | I14: 0 | J14: Closed | K14: 2011-Chinn, Barrett Park/Barrett RFI-ASI/12-0806 Barrett Park RFI 033
B15: RFI-034 | C15: RFI | D15: 2013-04-18 | E15: RSIC clip in ceiling below roof | F15: GC (SMS) | H15: 0 | I15: 0 | J15: Closed | K15: 2011-Chinn, Barrett Park/Barrett RFI-ASI/12-0806 Barret Park RFI 034
B16: RFI-037 | C16: RFI | D16: 2013-04-16 | E16: Wall elevation — copy storage + amenity rooms | F16: GC (SMS) | H16: 0 | I16: 0 | J16: Closed | K16: 2011-Chinn, Barrett Park/Barrett RFI-ASI/RFI 037 - Response
B17: RFI-038 | C17: RFI | D17: 2013-04-12 | E17: Elevation of island kitchen (A-2) | F17: GC (SMS) | H17: 0 | I17: 0 | J17: Closed | K17: 2011-Chinn, Barrett Park/Barrett RFI-ASI/RFI 038 Response
B18: RFI-039 | C18: RFI | D18: 2013-04-16 | E18: Lobby + mgmt office offset from Grid B | F18: GC (SMS) | H18: 0 | I18: 0 | J18: Closed | K18: 2011-Chinn, Barrett Park/Barrett RFI-ASI/RFI 039
B19: RFI-040 | C19: RFI | D19: 2013-05-03 | E19: Wood stair details | F19: GC (SMS) | H19: 0 | I19: 0 | J19: Closed | K19: 2011-Chinn, Barrett Park/Barrett RFI-ASI/12-0806 Barret Park RFI 040
B20: RFI-043 | C20: RFI | D20: 2013-07-02 | E20: Patio at Unit 104 too short | F20: Owner | H20: 0 | I20: 0 | J20: Closed | K20: 2011-Chinn, Barrett Park/Barrett RFI-ASI/12-0806 Barret Park RFI 043
... B25: RFI-055 | C25: RFI | D25: 2013-06-14 | E25: Coping detail at metal siding | F25: GC (SMS) | H25: 0 | I25: 0 | J25: Closed | K25: 2011-Chinn, Barrett Park/Barrett RFI-ASI/12-0806 Barret Park RFI 055
B26: RFI-057 | C26: RFI | D26: 2013-06-14 | E26: ADA clearances at kitchens | F26: GC (SMS) | G26: CO-003 | H26: 0 | I26: 0 | J26: Closed | K26: 2011-Chinn, Barrett Park/Barrett RFI-ASI/12-0806 Barrett Park RFI 057
B27: RFI-058 | C27: RFI | D27: 2013-06-14 | E27: Energy factor for hot water tank | F27: GC (SMS) | H27: 0 | I27: 0 | J27: Closed | K27: 2011-Chinn, Barrett Park/Barrett RFI-ASI/12-0806 Barret Park RFI 058
B28: RFI-059 | C28: RFI | D28: 2013-06-18 | E28: FEC location and types | F28: GC (SMS) | H28: 0 | I28: 0 | J28: Closed | K28: 2011-Chinn, Barrett Park/Barrett RFI-ASI/RFI 059
B29: RFI-074 | C29: RFI | D29: 2013-09-11 | E29: Storefront S1/S2/S3 clarifications | F29: GC (SMS) | H29: 0 | I29: 0 | J29: Closed | K29: 2011-Chinn, Barrett Park/Barrett RFI-ASI/RFI 074
B30: RFI-076 | C30: RFI | D30: 2013-09-11 | E30: Live/Work units accessibility compliance | F30: GC (SMS) | H30: 0 | I30: 0 | J30: Closed | K30: 2011-Chinn, Barrett Park/Barrett RFI-ASI/RFI 076
B31: RFI-079 | C31: RFI | D31: 2013-11-08 | E31: Water heater at amenity kitchen | F31: GC (SMS) | H31: 0 | I31: 0 | J31: Closed | K31: 2011-Chinn, Barrett Park/Barrett RFI-ASI/12-0806 Barret Park RFI 079
B32: SUB-P11-R1 | C32: Submittal-resub | D32: 2013 | E32: P11 tankless heater — revised submittal | F32: Sub (OWP) | G32: CO-003 | H32: 0 | I32: 0 | J32: Approved | K32: 2011-Chinn, Barrett Park/Submittals/MIKE_S FILES/
B33: SUB-P13-R1 | C33: Submittal-resub | D33: 2013 | E33: P13 amenity room water heater — revised submittal | F33: Sub (OWP) | G33: CO-003 | H33: 0 | I33: 0 | J33: Approved | K33: 2011-Chinn, Barrett Park/Submittals/MIKE_S FILES/
B34: SUB-PRV-R1 | C34: Submittal-resub | D34: 2013 | E34: PRV-2 pressure regulating valve — revised submittal | F34: Sub (OWP) | G34: CO-003 | H34: 0 | I34: 0 | J34: Approved | K34: 2011-Chinn, Barrett Park/Submittals/MIKE_S FILES/
B36: TOTAL | H36: =SUM(H6:H34) -> 56774 | I36: =SUM(I6:I34) -> 0

Sheet Root Cause Analysis
B2: Root Cause Analysis — Change Driver Taxonomy
B3: Categorized change events with responsible-party attribution — feeds bid-risk intelligence
B5: CATEGORY ROLLUP
B6: Root Cause Category | C6: # Events | D6: Net Cost Impact ($) | E6: % of Events | F6: Predominant Responsibility | G6: Notes
B7: Design substitution | C7: 4 | D7: 30415 | E7: =C7/29 -> 0.13793103 | F7: Designer | G7: Change plumbing fixtures — ADA + standard alternatives
B8: Design clarification | C8: 22 | D8: 959 | E8: =C8/29 -> 0.75862069 | F8: Designer | G8: Add trash chute wash down
B9: Owner directive | C9: 1 | D9: 0 | E9: =C9/29 -> 0.034482759 | F9: Owner/GC | G9: Patio at Unit 104 too short
B10: Field condition | C10: 1 | D10: 25400 | E10: =C10/29 -> 0.034482759 | F10: Sub (OWP) | G10: Furnish and install footing + sub-slab drains (field conditi
B11: Scope gap | C11: 1 | D11: 0 | E11: =C11/29 -> 0.034482759 | F11: Designer | G11: ADA clearances at kitchens
B12: TOTAL | C12: =SUM(C7:C11) -> 29 | D12: =SUM(D7:D11) -> 56774
B15: RESPONSIBILITY ATTRIBUTION
B16: Responsible Party | C16: # Events | D16: Net $ Impact | E16: Bid-Risk Signal
B17: Designer | C17: 27 | D17: 31374 | E17: POSITIVE — recoverable
B18: Sub (OWP) | C18: 1 | D18: 25400 | E18: POSITIVE — recoverable
B19: Owner/GC | C19: 1 | D19: 0 | E19: NEUTRAL

Sheet Predictive Signals
B2: Predictive Signals — Leading Indicators
B3: Forward-looking metrics that predict CO waves, schedule slips, and margin erosion
B5: CURRENT-STATE SIGNALS
B6: Indicator | C6: Current Value | D6: Benchmark | E6: Status | F6: Predictive Meaning
B7: RFI Total (closed) | C7: 19 | D7: <50 for mid-size | E7: INFO | F7: Volume proxy for design doc quality
B8: RFI Velocity (per month, derived) | C8: See KPIs D50 | D8: <3.0/wk | E8: INFO | F8: >3/wk = CO wave in 4-8 wks
B9: RFI Avg Cycle Time (days) | C9: Unknown | D9: <14 | E9: N/A | F9: >30 avg signals schedule slip
B10: ASI / OCD Count | C10: 5 | D10: <5 | E10: HEALTHY | F10: High ASI = owner scope churn
B11: Backcharge Count | C11: 0 | D11: <3 | E11: HEALTHY | F11: BC clusters = coordination weakness
B12: Change Order Count | C12: 3 | D12: <3 | E12: HEALTHY | F12: CO count signals scope definition
B13: T&M Event Count | C13: 0 | D13: <2 | E13: HEALTHY | F13: T&M = directed work pipeline
B14: Submittal resubmission count | C14: 7 | D14: <10 | E14: HEALTHY | F14: Repeats = coord issues incubating
B15: Net $ Impact (all events) | C15: 56774 | D15: Near $0 | E15: POSITIVE | F15: Net recoverable vs absorbed
B18: FORECAST MODELS (closed-project — actuals)
B19: Forecast | C19: Current Estimate | D19: Confidence | E19: Driver | F19: Model Note
B20: Projected final CO % of contract | C20: ='Benchmark KPIs'!D55 -> 0.069827809 | D20: Actual | E20: Closed project | F20: CO$ / orig contract
B21: Projected EAC (direct cost) | C21: ='Benchmark KPIs'!D21 -> 536863.45 | D21: Actual | E21: Closed project | F21: Sum of L+M+OH+Burden
B22: Projected final margin | C22: ='Benchmark KPIs'!D20 -> 0.38279036 | D22: Actual | E22: Closed project | F22: (Rev - DC) / Rev
B23: Composite risk score (0-100) | C23: 20 | D23: Medium | E23: 0 BCs + 5 ASI/OCDs | F23: Custom Cortex scoring

Sheet Metric Registry
B2: Metric Registry — Cortex Data Catalog
B3: Every metric with data_label, confidence_level, and source_document — the machine-readable JCR index
B5: # | C5: Data Label | D5: Human Label | E5: Value | F5: Unit | G5: Source Tab | H5: Confidence | I5: Source Document(s) | J5: Formula / Derivation
B6: 1 | C6: job_number | D6: Job Number | E6: ='Benchmark KPIs'!D6 -> 2011 | F6: id | G6: Benchmark KPIs | H6: Verified | I6: JDR header | J6: See Benchmark KPIs tab
B7: 2 | C7: job_name | D7: Job Name | E7: ='Benchmark KPIs'!D7 -> Chinn Barrett Park Apartments | F7: text | G7: Benchmark KPIs | H7: Verified | I7: Contract folder | J7: See Benchmark KPIs tab
B8: 3 | C8: general_contractor | D8: General Contractor | E8: ='Benchmark KPIs'!D8 -> Chinn Construction, LLC | F8: text | G8: Benchmark KPIs | H8: Verified | I8: Contract folder | J8: See Benchmark KPIs tab
B9: 4 | C9: location | D9: Location | E9: ='Benchmark KPIs'!D9 -> Seattle, WA (Capitol Hill) | F9: text | G9: Benchmark KPIs | H9: Verified | I9: Permit/Plans | J9: See Benchmark KPIs tab
B10: 5 | C10: project_type | D10: Project Type | E10: ='Benchmark KPIs'!D10 -> 117-unit 4-story multifamily apartments | F10: text | G10: Benchmark KPIs | H10: Verified | I10: Plans | J10: See Benchmark KPIs tab
B11: 6 | C11: duration_months | D11: Duration (months) | E11: ='Benchmark KPIs'!D11 -> 17 | F11: months | G11: Benchmark KPIs | H11: Verified | I11: First-to-last invoice | J11: See Benchmark KPIs tab
B12: 7 | C12: unit_count | D12: Unit Count | E12: ='Benchmark KPIs'!D12 -> 117 | F12: units | G12: Benchmark KPIs | H12: Verified | I12: Plumbing permit + P-tag list | J12: See Benchmark KPIs tab
B13: 8 | C13: total_fixtures | D13: Total Fixtures | E13: ='Benchmark KPIs'!D13 -> 841 | F13: count | G13: Benchmark KPIs | H13: Verified | I13: Permit detail | J13: See Benchmark KPIs tab
B14: 9 | C14: contract_original | D14: Contract Original | E14: ='Benchmark KPIs'!D15 -> 813050 | F14: USD | G14: Benchmark KPIs | H14: Verified | I14: Contract SOV | J14: See Benchmark KPIs tab
B15: 10 | C15: contract_final | D15: Contract Final | E15: ='Benchmark KPIs'!D16 -> 869823.5 | F15: USD | G15: Benchmark KPIs | H15: Verified | I15: Final billing SOV | J15: See Benchmark KPIs tab
B16: 11 | C16: change_orders | D16: Change Orders ($) | E16: ='Benchmark KPIs'!D17 -> 56773.5 | F16: USD | G16: Benchmark KPIs | H16: Verified | I16: JDR revised - original | J16: See Benchmark KPIs tab
B17: 12 | C17: revenue | D17: Revenue | E17: ='Benchmark KPIs'!D18 -> 869823.5 | F17: USD | G17: Benchmark KPIs | H17: Verified | I17: Aggregate billing | J17: See Benchmark KPIs tab
B18: 13 | C18: net_profit | D18: Net Profit | E18: ='Benchmark KPIs'!D19 -> 332960.05 | F18: USD | G18: Benchmark KPIs | H18: Verified | I18: Revenue - Direct Cost | J18: See Benchmark KPIs tab
B19: 14 | C19: gross_margin | D19: Gross Margin % | E19: ='Benchmark KPIs'!D20 -> 0.38279036 | F19: % | G19: Benchmark KPIs | H19: Verified | I19: Derived | J19: See Benchmark KPIs tab
B20: 15 | C20: direct_cost | D20: Direct Cost | E20: ='Benchmark KPIs'!D21 -> 536863.45 | F20: USD | G20: Benchmark KPIs | H20: Verified | I20: JDR cost codes | J20: See Benchmark KPIs tab
B21: 16 | C21: labor_cost | D21: Labor Cost | E21: ='Benchmark KPIs'!D22 -> 142882.75 | F21: USD | G21: Benchmark KPIs | H21: Verified | I21: JDR labor codes | J21: See Benchmark KPIs tab
B22: 17 | C22: material_cost | D22: Material Cost | E22: ='Benchmark KPIs'!D23 -> 295005.88 | F22: USD | G22: Benchmark KPIs | H22: Verified | I22: JDR material codes | J22: See Benchmark KPIs tab
B23: 18 | C23: overhead_cost | D23: Overhead Cost | E23: ='Benchmark KPIs'!D24 -> 26210.1 | F23: USD | G23: Benchmark KPIs | H23: Verified | I23: JDR overhead codes | J23: See Benchmark KPIs tab
B24: 19 | C24: burden_cost | D24: Burden Cost | E24: ='Benchmark KPIs'!D25 -> 72764.72 | F24: USD | G24: Benchmark KPIs | H24: Verified | I24: JDR burden codes | J24: See Benchmark KPIs tab
B25: 20 | C25: retainage | D25: Retainage | E25: ='Benchmark KPIs'!D26 -> 43491 | F25: USD | G25: Benchmark KPIs | H25: Verified | I25: Aggregate billing row | J25: See Benchmark KPIs tab
B26: 21 | C26: total_hours | D26: Total Labor Hours | E26: ='Benchmark KPIs'!D37 -> 6943.5 | F26: hours | G26: Benchmark KPIs | H26: Verified | I26: JDR payroll | J26: See Benchmark KPIs tab
B27: 22 | C27: total_workers | D27: Total Workers | E27: ='Benchmark KPIs'!D38 -> 31 | F27: count | G27: Benchmark KPIs | H27: Verified | I27: JDR unique workers | J27: See Benchmark KPIs tab
B28: 23 | C28: blended_gross_wage | D28: Blended Gross Wage | E28: ='Benchmark KPIs'!D39 -> 19.974581 | F28: USD/hr | G28: Benchmark KPIs | H28: Verified | I28: Labor $ / Hours | J28: See Benchmark KPIs tab
B29: 24 | C29: total_vendors | D29: Total Vendors | E29: ='Benchmark KPIs'!D51 -> 14 | F29: count | G29: Benchmark KPIs | H29: Verified | I29: JDR AP unique | J29: See Benchmark KPIs tab
B30: 25 | C30: total_pos | D30: Total POs | E30: ='Benchmark KPIs'!D54 -> 0 | F30: count | G30: Benchmark KPIs | H30: Verified | I30: PO folder count | J30: See Benchmark KPIs tab
B31: 26 | C31: co_pct | D31: CO % of Original | E31: ='Benchmark KPIs'!D55 -> 0.069827809 | F31: % | G31: Benchmark KPIs | H31: Verified | I31: Derived | J31: See Benchmark KPIs tab
B32: 27 | C32: rfi_total_count | D32: RFIs Total | E32: 19 | F32: count | G32: Predictive Signals | H32: Verified | I32: ASI-RFI folder count | J32: See Predictive Signals tab
B33: 28 | C33: asi_ocd_count | D33: ASI + OCD Count | E33: 5 | F33: count | G33: Change Log | H33: Verified | I33: ASI-RFI folder + Change Orders | J33: See Change Log tab
B34: 29 | C34: co_count_total | D34: Change Order Count | E34: 3 | F34: count | G34: Change Log | H34: Verified | I34: Change Orders folder | J34: See Change Log tab
B35: 30 | C35: backcharge_count | D35: Backcharge Count | E35: 0 | F35: count | G35: Change Log | H35: Verified | I35: Invoices/Backcharges | J35: See Change Log tab
B36: 31 | C36: tm_event_count | D36: T&M Event Count | E36: 0 | F36: count | G36: Change Log | H36: Verified | I36: Change Orders / JDR 038 | J36: See Change Log tab
B37: 32 | C37: submittal_resub_count | D37: Submittal Resubmissions | E37: 7 | F37: count | G37: Predictive Signals | H37: Verified | I37: Submittals folder | J37: See Predictive Signals tab
B38: 33 | C38: change_event_total | D38: Total Tracked Events | E38: 29 | F38: count | G38: Change Log | H38: Verified | I38: Change Log tab | J38: See Change Log tab
B39: 34 | C39: change_net_impact | D39: Change Net $ Impact | E39: ='Change Log'!H36 -> 56774 | F39: USD | G39: Change Log | H39: Verified | I39: SUM H col | J39: See Change Log tab

Sheet Reconciliation
B2: Reconciliation — Tie-out Proofs
B3: Live cross-sheet formulas verify data consistency across all 17 tabs
B4: Check | C4: Computed | D4: Expected | E4: Δ | F4: Status
B5: A. JDR COST CODE ROLLUP
B6: Labor subtotal (12 codes) | C6: 142882.75 | D6: 142882.75 | E6: =C6-D6 -> 0 | F6: =IF(ABS(E6)<=1,"TIES",IF(ABS(E6)<=ABS(D6)*0.05,"WITHIN","OFF")) -> TIES
B7: Material subtotal (11 codes) | C7: 295005.88 | D7: 295005.88 | E7: =C7-D7 -> 0 | F7: =IF(ABS(E7)<=1,"TIES",IF(ABS(E7)<=ABS(D7)*0.05,"WITHIN","OFF")) -> TIES
B8: Overhead subtotal (3 codes) | C8: 26210.1 | D8: 26210.1 | E8: =C8-D8 -> 0 | F8: =IF(ABS(E8)<=1,"TIES",IF(ABS(E8)<=ABS(D8)*0.05,"WITHIN","OFF")) -> TIES
B9: Burden subtotal (2 codes) | C9: 72764.72 | D9: 72764.72 | E9: =C9-D9 -> 0 | F9: =IF(ABS(E9)<=1,"TIES",IF(ABS(E9)<=ABS(D9)*0.05,"WITHIN","OFF")) -> TIES
B10: Direct Cost (all categories) | C10: 536863.45 | D10: 536863.45 | E10: =C10-D10 -> 0 | F10: =IF(ABS(E10)<=1,"TIES",IF(ABS(E10)<=ABS(D10)*0.05,"WITHIN","OFF")) -> TIES
B11: Revenue (code 999) | C11: 869823.5 | D11: 869823.5 | E11: =C11-D11 -> 0 | F11: =IF(ABS(E11)<=1,"TIES",IF(ABS(E11)<=ABS(D11)*0.05,"WITHIN","OFF")) -> TIES
B12: Net Profit (Revenue - Expenses) | C12: 332960.05 | D12: 332960.05 | E12: =C12-D12 -> 0 | F12: =IF(ABS(E12)<=1,"TIES",IF(ABS(E12)<=ABS(D12)*0.05,"WITHIN","OFF")) -> TIES
B14: B. LABOR HOURS ROLLUP
B15: JDR Cost Code hours (Payroll Hours lines) | C15: 6943.5 | D15: 6943.5 | E15: =C15-D15 -> 0 | F15: =IF(ABS(E15)<=5,"TIES",IF(ABS(E15)<=ABS(D15)*0.05,"WITHIN","OFF")) -> TIES
B16: Per-worker hours (sum of PR Regular) | C16: 6803 | D16: 6943.5 | E16: =C16-D16 -> -140.5 | F16: =IF(ABS(E16)<=5,"TIES",IF(ABS(E16)<=ABS(D16)*0.05,"WITHIN","OFF")) -> WITHIN
B18: C. BILLING (SOV) ↔ JDR
B19: Final Contract Value | C19: 869824 | D19: 869824 | E19: =C19-D19 -> 0 | F19: =IF(ABS(E19)<=1,"TIES",IF(ABS(E19)<=ABS(D19)*0.05,"WITHIN","OFF")) -> TIES
B20: Retainage | C20: 43491 | D20: 43491 | E20: =C20-D20 -> 0 | F20: =IF(ABS(E20)<=1,"TIES",IF(ABS(E20)<=ABS(D20)*0.05,"WITHIN","OFF")) -> TIES
B21: Direct Cost | C21: 536863.45 | D21: 536863.45 | E21: =C21-D21 -> 0 | F21: =IF(ABS(E21)<=1,"TIES",IF(ABS(E21)<=ABS(D21)*0.05,"WITHIN","OFF")) -> TIES
B23: D. VENDOR AP ↔ JDR
B24: Vendor AP total (sum of invoices) | C24: 387378.94 | D24: 387379 | E24: =C24-D24 -> -0.06 | F24: =IF(ABS(E24)<=5,"TIES",IF(ABS(E24)<=ABS(D24)*0.05,"WITHIN","OFF")) -> TIES
B28: SOURCES
B29: Job #2011 — Chinn Barrett Park Apartments • GC: Chinn Construction, LLC • Seattle, WA (Capitol Hill)
B30: Canonical source: 2011 Job Detail Report.pdf (69 pages, OWP Sage Timberline export)
B31: Cost codes parsed: 29
B32: Unit count: 117 units confirmed
B33: Fixture count: 841 from permit SR1224327
B34: Billing: BARRETT AGGREGATE BILLING.xlsx (13 pay apps Nov 2012 – Mar 2014)
B35: TIES = within $1 or 5 hrs • WITHIN = within 5% • OFF = investigate
B48: K. CHANGE LOG ↔ ROOT CAUSE ANALYSIS
B49: Total Event Count | C49: 29 | D49: ='Root Cause Analysis'!C12 -> 29 | E49: =C49-D49 -> 0 | F49: =IF(ABS(E49)<=1,"TIES",IF(ABS(E49)<=ABS(D49)*0.05,"WITHIN","OFF")) -> TIES | G49: 13↔14
B50: Net $ Impact (all events) | C50: ='Change Log'!H36 -> 56774 | D50: ='Root Cause Analysis'!D12 -> 56774 | E50: =C50-D50 -> 0 | F50: =IF(ABS(E50)<=1,"TIES",IF(ABS(E50)<=ABS(D50)*0.05,"WITHIN","OFF")) -> TIES | G50: 13↔14
B52: L. PREDICTIVE SIGNALS ↔ CHANGE LOG
B53: Backcharge Count signal | C53: 0 | D53: =COUNTIF('Change Log'!C6:C35,"Backcharge") -> 0 | E53: =C53-D53 -> 0 | F53: =IF(ABS(E53)<=1,"TIES",IF(ABS(E53)<=ABS(D53)*0.05,"WITHIN","OFF")) -> TIES | G53: 15↔13
B55: M. METRIC REGISTRY ↔ BENCHMARK KPIs
B56: revenue (row 17) | C56: ='Metric Registry'!E17 -> 869823.5 | D56: ='Benchmark KPIs'!D18 -> 869823.5 | E56: =C56-D56 -> 0 | F56: =IF(ABS(E56)<=1,"TIES",IF(ABS(E56)<=ABS(D56)*0.05,"WITHIN","OFF")) -> TIES | G56: 16↔11
B57: unit_count (row 12) | C57: ='Metric Registry'!E12 -> 117 | D57: ='Benchmark KPIs'!D12 -> 117 | E57: =C57-D57 -> 0 | F57: =IF(ABS(E57)<=1,"TIES",IF(ABS(E57)<=ABS(D57)*0.05,"WITHIN","OFF")) -> TIES | G57: 16↔11
B58: total_fixtures (row 13) | C58: ='Metric Registry'!E13 -> 841 | D58: ='Benchmark KPIs'!D13 -> 841 | E58: =C58-D58 -> 0 | F58: =IF(ABS(E58)<=1,"TIES",IF(ABS(E58)<=ABS(D58)*0.05,"WITHIN","OFF")) -> TIES | G58: 16↔11
B59: direct_cost (row 19) | C59: ='Metric Registry'!E19 -> 0.38279036 | D59: ='Benchmark KPIs'!D21 -> 536863.45 | E59: =C59-D59 -> -536863.07 | F59: =IF(ABS(E59)<=1,"TIES",IF(ABS(E59)<=ABS(D59)*0.05,"WITHIN","OFF")) -> OFF | G59: 16↔11
B60: total_pos (row 30) | C60: ='Metric Registry'!E30 -> 0 | D60: ='Benchmark KPIs'!D54 -> 0 | E60: =C60-D60 -> 0 | F60: =IF(ABS(E60)<=1,"TIES",IF(ABS(E60)<=ABS(D60)*0.05,"WITHIN","OFF")) -> TIES | G60: 16↔11
B62: N. CHANGE LOG ↔ METRIC REGISTRY (event counts)
...

Sheet Vendors
A1: Vendor Detail — Job #2011
A3: Vendors | B3: 14 | D3: Top vendor | E3: Ferguson Enterprises, Inc.
A4: Invoices | B4: 123 | D4: Top 3 share | E4: =350453.39/387378.94 -> 0.90467848
A5: Total AP | B5: 387378.94 | D5: Source | E5: 2011 Job Detail Report.pdf (Sage Timberline AP export)
A6: Avg Inv | B6: =B5/B4 -> 3149.4223
A8: Rank | B8: Vendor | C8: Vendor Code | D8: Invoices | E8: Total Spend | F8: % of AP | G8: Avg / Invoice
A9: 1 | B9: Ferguson Enterprises, Inc. | D9: 56 | E9: 302211.38 | F9: =E9/E$23 -> 0.78014406 | G9: =E9/D9 -> 5396.6318
A10: 2 | B10: Rosen Supply Company, Inc. | D10: 30 | E10: 35755.01 | F10: =E10/E$23 -> 0.092299829 | G10: =E10/D10 -> 1191.8337
A11: 3 | B11: Franklin Engineering | D11: 5 | E11: 12487 | F11: =E11/E$23 -> 0.032234587 | G11: =E11/D11 -> 2497.4
A12: 4 | B12: Keller Supply Company | D12: 13 | E12: 10651.28 | F12: =E12/E$23 -> 0.027495764 | G12: =E12/D12 -> 819.32923
A13: 5 | B13: Fastenal Company | D13: 4 | E13: 8107.96 | F13: =E13/E$23 -> 0.020930307 | G13: =E13/D13 -> 2026.99
A14: 6 | B14: Bank of America CC | D14: 3 | E14: 7291 | F14: =E14/E$23 -> 0.018821364 | G14: =E14/D14 -> 2430.3333
A15: 7 | B15: Mickelo Construction LLC | D15: 2 | E15: 6217.07 | F15: =E15/E$23 -> 0.016049066 | G15: =E15/D15 -> 3108.535
A16: 8 | B16: Quality Concrete Products, Inc. | D16: 2 | E16: 2598 | F16: =E16/E$23 -> 0.0067066114 | G16: =E16/D16 -> 1299
A17: 9 | B17: Manor Hardware & Construction Supply | D17: 2 | E17: 870 | F17: =E17/E$23 -> 0.0022458629 | G17: =E17/D17 -> 435
A18: 10 | B18: Core & Main LP | D18: 1 | E18: 810 | F18: =E18/E$23 -> 0.0020909758 | G18: =E18/D18 -> 810
A19: 11 | B19: R.A. Brown Backflow Testing | D19: 1 | E19: 129 | F19: =E19/E$23 -> 0.00033300726 | G19: =E19/D19 -> 129
A20: 12 | B20: C.M. Hoskins Company | D20: 1 | E20: 102 | F20: =E20/E$23 -> 0.00026330807 | G20: =E20/D20 -> 102
... A22: 14 | B22: Capital One Credit Card | D22: 2 | E22: 63.21 | F22: =E22/E$23 -> 0.00016317356 | G22: =E22/D22 -> 31.605
B23: TOTAL | D23: =SUM(D9:D22) -> 123 | E23: =SUM(E9:E22) -> 387378.94 | F23: =SUM(F9:F22) -> 1 | G23: =E23/D23 -> 3149.4223
