Workbook

Sheet Overview
B3: CORTEX INTELLIGENCE REPORT
B4: OWP Job #2012
B5: Exxel 8th Ave Apartments
B6: 163-unit mid-rise multifamily · Division 22 Plumbing · Seattle, WA · Jan 2013 – Jun 2014
B10: CONTRACT VALUE | C10: NET PROFIT | D10: DIRECT COST | E10: LABOR HOURS | F10: LABOR RATE | G10: PER-UNIT PROFIT
B11: 1391455 | C11: 533274 | D11: 858181 | E11: 14607 | F11: 30.12 | G11: 3272
B12: 163 units | C12: 38.3% margin | D12: 61.7% of revenue | E12: ≈90 hrs/unit | F12: fully loaded $/hr | G12: $3.27K each
B15: Job Facts
B17: Project ID | C17: Job #2012
B18: General Contractor | C18: Exxel Pacific, Inc.
B19: Scope | C19: Division 22 Plumbing
B20: Building Type | C20: Mid-rise multifamily
B21: Unit Count | C21: 163 residential units
B22: Location | C22: Seattle, WA
B23: Duration | C23: 17 months (Jan 2013 – Jun 2014)
B24: Contract Value | C24: $1,394,655
B25: Retainage Held | C25: $69,573 (5%)
B26: Pay Applications | C26: 8 invoices
B27: Cost Codes Used | C27: 20+
B28: Labor Sources | C28: Payroll (PR), Subs (AP)
B32: SOURCES
B33: Source: 2012 Job Detail Report.pdf (135 pages, OWP, LLC – exported Apr 3, 2026).
B34: Project name, contract value, dates, retainage from contract documents in /2012-Exxel, 8th Ave/.
B35: All cost codes, budgets, actuals, and labor hours tie out exactly to the JCR. JCR is the canonical source of truth.

Sheet Budget vs Actual
B3: PHASE-LEVEL VARIANCE ANALYSIS
B4: Budget vs Actual
B5: All 32 cost codes from the JCR — labor, material, overhead, burden. Totals tie out exactly to the JCR.
B7: PHASE | C7: BUDGET | D7: ACTUAL | E7: VARIANCE ($) | F7: VARIANCE % | G7: HOURS | H7: $/HR | I7: STATUS
B8: 100 · Supervision | C8: 8100 | D8: 6023 | E8: =D8-C8 -> -2077 | F8: =(D8-C8)/C8 -> -0.25641975 | G8: 165 | H8: =D8/G8 -> 36.50303 | I8: UNDER
B9: 011 · DS & RD Labor | C9: 12500 | D9: 3753 | E9: =D9-C9 -> -8747 | F9: =(D9-C9)/C9 -> -0.69976 | G9: 183 | H9: =D9/G9 -> 20.508197 | I9: UNDER
B10: 101 · Takeoff & Purchase Labor | C10: 12150 | D10: 6162 | E10: =D10-C10 -> -5988 | F10: =(D10-C10)/C10 -> -0.49283951 | G10: 172 | H10: =D10/G10 -> 35.825581 | I10: UNDER
B11: 110 · Underground Labor | C11: 5800 | D11: 3184 | E11: =D11-C11 -> -2616 | F11: =(D11-C11)/C11 -> -0.45103448 | G11: 146 | H11: =D11/G11 -> 21.808219 | I11: UNDER
B12: 111 · Garage Labor | C12: 14600 | D12: 19354 | E12: =D12-C12 -> 4754 | F12: =(D12-C12)/C12 -> 0.32561644 | G12: 872 | H12: =D12/G12 -> 22.194954 | I12: OVER
B13: 112 · Canout Labor | C13: 11700 | D13: 5424 | E13: =D13-C13 -> -6276 | F13: =(D13-C13)/C13 -> -0.53641026 | G13: 238 | H13: =D13/G13 -> 22.789916 | I13: UNDER
B14: 113 · Foundation Drain Labor | C14: 2700 | D14: 984 | E14: =D14-C14 -> -1716 | F14: =(D14-C14)/C14 -> -0.63555556 | G14: 50 | H14: =D14/G14 -> 19.68 | I14: UNDER
B15: 120 · Roughin Labor | C15: 139800 | D15: 177292 | E15: =D15-C15 -> 37492 | F15: =(D15-C15)/C15 -> 0.26818312 | G15: 9320 | H15: =D15/G15 -> 19.022747 | I15: OVER
B16: 130 · Finish Labor | C16: 31000 | D16: 34658 | E16: =D16-C16 -> 3658 | F16: =(D16-C16)/C16 -> 0.118 | G16: 1841 | H16: =D16/G16 -> 18.825638 | I16: OVER
B17: 140 · Gas Labor | C17: 3300 | D17: 2168 | E17: =D17-C17 -> -1132 | F17: =(D17-C17)/C17 -> -0.3430303 | G17: 104 | H17: =D17/G17 -> 20.846154 | I17: UNDER
B18: 141 · Water Main / Insulation Lab | C18: 41000 | D18: 15756 | E18: =D18-C18 -> -25244 | F18: =(D18-C18)/C18 -> -0.61570732 | G18: 800 | H18: =D18/G18 -> 19.695 | I18: UNDER
B19: 142 · Mech Room Labor | C19: 3525 | D19: 9784 | E19: =D19-C19 -> 6259 | F19: =(D19-C19)/C19 -> 1.7756028 | G19: 379 | H19: =D19/G19 -> 25.815303 | I19: CRITICAL
B20: 145 · Tub/Shower Labor | C20: 19800 | D20: 6781 | E20: =D20-C20 -> -13019 | F20: =(D20-C20)/C20 -> -0.65752525 | G20: 338 | H20: =D20/G20 -> 20.06213 | I20: UNDER
B21: 039 · DS & RD Material | C21: 17900 | D21: 5067 | E21: =D21-C21 -> -12833 | F21: =(D21-C21)/C21 -> -0.71692737 | H21: — | I21: UNDER
B22: 210 · Underground Material | C22: 4300 | D22: 1636 | E22: =D22-C22 -> -2664 | F22: =(D22-C22)/C22 -> -0.61953488 | H22: — | I22: UNDER
B23: 211 · Garage Material | C23: 11970 | D23: 6599 | E23: =D23-C23 -> -5371 | F23: =(D23-C23)/C23 -> -0.4487051 | H23: — | I23: UNDER
B24: 212 · Canout Material | C24: 13130 | D24: 8579 | E24: =D24-C24 -> -4551 | F24: =(D24-C24)/C24 -> -0.34661081 | H24: — | I24: UNDER
B25: 213 · Foundation Material | C25: 2700 | D25: 1789 | E25: =D25-C25 -> -911 | F25: =(D25-C25)/C25 -> -0.33740741 | H25: — | I25: ON
B26: 220 · Roughin Material | C26: 161200 | D26: 94001 | E26: =D26-C26 -> -67199 | F26: =(D26-C26)/C26 -> -0.41686725 | G26: 1 | H26: =D26/G26 -> 94001 | I26: UNDER
B27: 230 · Finish Material | C27: 261600 | D27: 210145 | E27: =D27-C27 -> -51455 | F27: =(D27-C27)/C27 -> -0.19669343 | H27: — | I27: UNDER
B28: 240 · Gas Material | C28: 3000 | D28: 996 | E28: =D28-C28 -> -2004 | F28: =(D28-C28)/C28 -> -0.668 | H28: — | I28: UNDER
B29: 241 · Water Main / Insul. Material | C29: 65600 | D29: 36965 | E29: =D29-C29 -> -28635 | F29: =(D29-C29)/C29 -> -0.43650915 | H29: — | I29: UNDER
B30: 242 · Mech Room Material | C30: 12000 | D30: 22695 | E30: =D30-C30 -> 10695 | F30: =(D30-C30)/C30 -> 0.89125 | H30: — | I30: CRITICAL
B31: 245 · Tub/Shower Material | C31: 0 | D31: 2279 | E31: =D31-C31 -> 2279 | F31: n/a | H31: — | I31: UNBUDGETED
B32: 600 · Subcontractor | C32: 1000 | D32: 186 | E32: =D32-C32 -> -814 | F32: =(D32-C32)/C32 -> -0.814 | H32: — | I32: UNDER
B33: 601 · Engineering / Plans | C33: 22000 | D33: 15682 | E33: =D33-C33 -> -6318 | F33: =(D33-C33)/C33 -> -0.28718182 | H33: — | I33: UNDER
B34: 603 · Permits & Licenses | C34: 10900 | D34: 9742 | E34: =D34-C34 -> -1158 | F34: =(D34-C34)/C34 -> -0.10623853 | H34: — | I34: UNDER
B35: 604 · Backcharges | C35: 0 | D35: 1838 | E35: =D35-C35 -> 1838 | F35: n/a | H35: — | I35: UNBUDGETED
B36: 607 · Other Expenses | C36: 25600 | D36: 71 | E36: =D36-C36 -> -25529 | F36: =(D36-C36)/C36 -> -0.99722656 | H36: — | I36: UNDER
B37: 995 · Payroll Burden | C37: 125050 | D37: 126300 | E37: =D37-C37 -> 1250 | F37: =(D37-C37)/C37 -> 0.0099960016 | H37: — | I37: OVER
B38: 998 · Payroll Taxes | C38: 22068 | D38: 22289 | E38: =D38-C38 -> 221 | F38: =(D38-C38)/C38 -> 0.010014501 | H38: — | I38: ON
B39: 999 · Sales | C39: 0 | D39: 0 | E39: =D39-C39 -> 0 | F39: n/a | H39: — | I39: ON
B40: TOTAL | C40: =SUM(C8:C39) -> 1065993 | D40: =SUM(D8:D39) -> 858182 | E40: =D40-C40 -> -207811 | F40: =(D40-C40)/C40 -> -0.19494593 | G40: =SUM(G8:G39) -> 14609 | H40: =D40/G40 -> 58.743377
B44: SOURCES
B45: Source: 2012 Job Detail Report.pdf (135 pages, OWP, LLC – exported Apr 3, 2026).
B46: Budgets and actuals for all 32 cost codes parsed from 'Cost Code Totals' lines in the JCR.
...

Sheet Material
B3: MATERIAL SPEND BY PHASE
B4: Material Breakdown
B5: Cost code level breakdown of material budget vs actual purchases (AP) from JCR.
B7: MATERIAL PHASE | C7: BUDGET | D7: ACTUAL | E7: VARIANCE ($) | F7: VARIANCE % | G7: $/UNIT | H7: $/FIXTURE | I7: % OF TOTAL | J7: STATUS
B8: 230 · Finish Material | C8: 261600 | D8: 210145 | E8: =D8-C8 -> -51455 | F8: =(D8-C8)/C8 -> -0.19669343 | G8: =D8/163 -> 1289.2331 | H8: =D8/816 -> 257.53064 | I8: =D8/D19 -> 0.53779773 | J8: ON
B9: 220 · Roughin Material | C9: 161200 | D9: 94001 | E9: =D9-C9 -> -67199 | F9: =(D9-C9)/C9 -> -0.41686725 | G9: =D9/163 -> 576.69325 | H9: =D9/816 -> 115.1973 | I9: =D9/D19 -> 0.24056496 | J9: UNDER
B10: 241 · Water Main / Insulation | C10: 65600 | D10: 36965 | E10: =D10-C10 -> -28635 | F10: =(D10-C10)/C10 -> -0.43650915 | G10: =D10/163 -> 226.77914 | H10: =D10/816 -> 45.300245 | I10: =D10/D19 -> 0.094599886 | J10: UNDER
B11: 242 · Mech Room Material | C11: 12000 | D11: 22695 | E11: =D11-C11 -> 10695 | F11: =(D11-C11)/C11 -> 0.89125 | G11: =D11/163 -> 139.23313 | H11: =D11/816 -> 27.8125 | I11: =D11/D19 -> 0.058080466 | J11: CRITICAL
B12: 212 · Canout Material | C12: 13130 | D12: 8579 | E12: =D12-C12 -> -4551 | F12: =(D12-C12)/C12 -> -0.34661081 | G12: =D12/163 -> 52.631902 | H12: =D12/816 -> 10.51348 | I12: =D12/D19 -> 0.021955158 | J12: UNDER
B13: 211 · Garage Material | C13: 11970 | D13: 6599 | E13: =D13-C13 -> -5371 | F13: =(D13-C13)/C13 -> -0.4487051 | G13: =D13/163 -> 40.484663 | H13: =D13/816 -> 8.0870098 | I13: =D13/D19 -> 0.016887993 | J13: UNDER
B14: 039 · DS & RD Material | C14: 17900 | D14: 5067 | E14: =D14-C14 -> -12833 | F14: =(D14-C14)/C14 -> -0.71692737 | G14: =D14/163 -> 31.08589 | H14: =D14/816 -> 6.2095588 | I14: =D14/D19 -> 0.012967337 | J14: UNDER
B15: 245 · Tub / Shower Material | C15: 0 | D15: 2279 | E15: =D15-C15 -> 2279 | F15: n/a | G15: =D15/163 -> 13.981595 | H15: =D15/816 -> 2.7928922 | I15: =D15/D19 -> 0.0058323587 | J15: UNBUDGETED
B16: 213 · Foundation Material | C16: 2700 | D16: 1789 | E16: =D16-C16 -> -911 | F16: =(D16-C16)/C16 -> -0.33740741 | G16: =D16/163 -> 10.97546 | H16: =D16/816 -> 2.192402 | I16: =D16/D19 -> 0.0045783632 | J16: UNDER
B17: 210 · Underground Material | C17: 4300 | D17: 1636 | E17: =D17-C17 -> -2664 | F17: =(D17-C17)/C17 -> -0.61953488 | G17: =D17/163 -> 10.03681 | H17: =D17/816 -> 2.004902 | I17: =D17/D19 -> 0.0041868095 | J17: UNDER
B18: 240 · Gas Material | C18: 3000 | D18: 996 | E18: =D18-C18 -> -2004 | F18: =(D18-C18)/C18 -> -0.668 | G18: =D18/163 -> 6.1104294 | H18: =D18/816 -> 1.2205882 | I18: =D18/D19 -> 0.0025489378 | J18: UNDER
B19: TOTAL MATERIAL | C19: =SUM(C8:C18) -> 553400 | D19: =SUM(D8:D18) -> 390751 | E19: =D19-C19 -> -162649 | F19: =(D19-C19)/C19 -> -0.29390857 | G19: =D19/163 -> 2397.2454 | H19: =D19/816 -> 478.86152 | I19: 100.0%
B22: KEY MATERIAL INSIGHTS
B23: ● Finish Material is the largest line item — $210K — 54% of all material spend. Fixture-heavy phase.
B25: ● 242 Mech Room Material is 89% over budget — $22.7K actual vs $12K budget. Single biggest material overrun.
B27: ● Water Main / Insulation came in 44% under — $37K actual vs $66K budget — $28.6K saved on the 241 line.
B29: ● Roughin Material delivered 42% savings — $94K actual vs $161K budget. Largest dollar savings on the job.
B31: ● Total material spend = $390.8K vs $553.4K budget — $162.6K under (29% favorable). Material was the project's strongest cost lever.
B33: ● Tub/Shower 245 was unbudgeted — $2,279 charged with no original budget — minor but worth tracking.
B37: SOURCES
B38: Source: 2012 Job Detail Report.pdf (135 pages, OWP, LLC – exported Apr 3, 2026).
B39: Material budgets/actuals from 2xx + 039 cost code sections in the JCR (AP transactions).
B40: $/Unit and $/Fixture computed against 163 units / 816 fixtures from the contract.
B41: All cost codes, budgets, actuals, and labor hours tie out exactly to the JCR. JCR is the canonical source of truth.

Sheet Cost Breakdown
B3: COST COMPOSITION
B4: Cost Breakdown
B5: Direct cost decomposition by accounting source.
B7: SOURCE | C7: AMOUNT | D7: % OF TOTAL | E7: DESCRIPTION
B8: Payroll (PR) | C8: 439954 | D8: =C8/SUM($C$8:$C$10) -> 0.51265875 | E8: All in-house labor costs
B9: Accounts Payable (AP) | C9: 408537 | D9: =C9/SUM($C$8:$C$10) -> 0.47604992 | E9: Material purchases & subs
B10: General Ledger (GL) | C10: 9690 | D10: =C10/SUM($C$8:$C$10) -> 0.011291324 | E10: Warehouse, parking, misc fees
B11: TOTAL DIRECT COST | C11: =SUM(C8:C10) -> 858181 | D11: =SUM(D8:D10) -> 1
B14: Per-Unit Benchmarks
B15: Normalized across 163 residential units
B17: METRIC | C17: TOTAL | D17: PER UNIT | E17: % OF REVENUE
B18: Revenue | C18: 1391455 | D18: =C18/163 -> 8536.5337 | E18: =C18/1391455 -> 1
B19: Direct Cost | C19: 858181 | D19: =C19/163 -> 5264.9141 | E19: =C19/1391455 -> 0.61675081
B20: Net Profit | C20: 533274 | D20: =C20/163 -> 3271.6196 | E20: =C20/1391455 -> 0.38324919
B22: Roughin Labor | C22: 177292 | D22: =C22/163 -> 1087.681 | E22: =C22/1391455 -> 0.12741483
B23: Roughin Material | C23: 22695 | D23: =C23/163 -> 139.23313 | E23: =C23/1391455 -> 0.016310265
B24: Finish Labor | C24: 34658 | D24: =C24/163 -> 212.62577 | E24: =C24/1391455 -> 0.02490774
B25: Engineering | C25: 15682 | D25: =C25/163 -> 96.208589 | E25: =C25/1391455 -> 0.011270217
B26: Permits | C26: 9742 | D26: =C26/163 -> 59.766871 | E26: =C26/1391455 -> 0.0070013044
B30: SOURCES
B31: Source: 2012 Job Detail Report.pdf (135 pages, OWP, LLC – exported Apr 3, 2026).
B32: PR / AP / GL splits derived from JCR transaction sources (Src column = PR, AP, or GL).
B33: Vendor and worker rollups extracted programmatically from JCR transaction detail.
B34: All cost codes, budgets, actuals, and labor hours tie out exactly to the JCR. JCR is the canonical source of truth.

Sheet Crew & Labor
B3: WORKFORCE COMPOSITION
B4: Crew & Labor
B5: Rate tier breakdown by role and key personnel.
B7: TIER | C7: RATE RANGE | D7: WORKERS | E7: NOTES
B8: Superintendent | C8: $33–38/hr | D8: 1 | E8: Project oversight
B9: Lead Journeyman | C9: $28–31/hr | D9: 4 | E9: Phase leadership
B10: Journeyman | C10: $20–27/hr | D10: 8 | E10: Skilled installation
B11: Apprentice | C11: $12–16/hr | D11: 7 | E11: Supervised hands-on
B12: Helper | C12: $12–14/hr | D12: 8 | E12: Material handling
B13: TOTAL CREW | D13: =SUM(D8:D12) -> 28
B16: Blended Labor Metrics
B18: Gross wages | C18: $19.94/hr
B19: Fully loaded rate | C19: $30.12/hr
B20: Burden multiplier | C20: 1.51x
B21: Total labor hours | C21: 14,607
B22: Hours per unit | C22: ≈90 hrs
B23: Labor : Material ratio | C23: 1.05 : 1
B27: SOURCES
B28: Source: 2012 Job Detail Report.pdf (135 pages, OWP, LLC – exported Apr 3, 2026).
B29: Tier and rate band assignments inferred from blended $/hr in JCR PR transactions.
B30: Burden multiplier and fully loaded rate computed from JCR Payroll Burden code (995) ÷ gross wages.

Sheet Insights
B3: AGENT FINDINGS
B4: Insights & Recommendations
B5: Key findings to inform future bids and project execution.
C8: CRITICAL | D8: Mech Room — 178% over budget
C9: $9,784 actual vs $3,525 budget. Complex manifold assemblies and circ pump installations consistently underestimated. Recommend budgeting 2.5–3x initial estimate on future projects with similar mechanical scope.
C12: OVERRUN | D12: Roughin Labor — 27% over budget
C13: 9,320 hours consumed (64% of all labor). At 57 hrs/unit, this exceeds comparable mid-rise projects by ~15%. Recommend budgeting 65+ hrs/unit on future mid-rise multifamily and adding 20% contingency.
C16: OVERRUN | D16: Garage Labor — 33% over budget
C17: $19,354 actual vs $14,600 budget. Below-grade work in garage levels consistently underestimated. Increase garage labor budget by 30% on future bids with subterranean parking.
C20: SAVINGS | D20: Water Main — 62% under budget
C21: $15,756 actual vs $41,000 budget. Estimate is too conservative by ~$25K. Tighten by 40–50% on future bids to sharpen competitiveness without margin risk.
C24: SAVINGS | D24: Tub/Shower — 66% under budget
C25: $6,781 actual vs $19,800 budget. Quick install on standardized fixtures. Reduce future bids on similar prefab tub/shower scope by 50%.
C28: BENCHMARK | D28: Per-unit cost: $5,265
C29: Use $5,000–$5,500/unit as base direct cost for similar Division 22 scope on mid-rise multifamily. Target $8,000–$9,000/unit revenue for healthy margin.
C32: BENCHMARK | D32: Labor : Material ratio of 1.05 : 1
C33: Plumbing on mid-rise tracks roughly 1:1 between labor and material spend. Use this ratio as a sanity check on future estimates — significant deviation flags scope risk.
C36: ACTION | D36: Tighten contingency strategy
C37: Net 38.3% margin masks significant scatter at the cost code level. Move from blanket 10% contingency to phase-specific contingencies: 20% on roughin/mech, 5% on water main/insulation.
B41: SOURCES
B42: Source: 2012 Job Detail Report.pdf (135 pages, OWP, LLC – exported Apr 3, 2026).
B43: Variance analysis derived from Budget vs Actual tab — same 32 JCR cost codes.
B44: All cost codes, budgets, actuals, and labor hours tie out exactly to the JCR. JCR is the canonical source of truth.

Sheet Productivity
B3: LABOR PRODUCTIVITY & THROUGHPUT
B4: Productivity Metrics
B5: Hours, dollars, and throughput normalized per unit and per fixture.
B7: PHASE | C7: HOURS | D7: COST | E7: HRS/UNIT | F7: HRS/FIXTURE | G7: $/UNIT | H7: $/FIXTURE | I7: $/HR
B8: 100 · Supervision | C8: 165 | D8: 6023 | E8: =C8/163 -> 1.0122699 | F8: =C8/816 -> 0.20220588 | G8: =D8/163 -> 36.95092 | H8: =D8/816 -> 7.3811275
B9: 111 · Garage | C9: 872 | D9: 19354 | E9: =C9/163 -> 5.3496933 | F9: =C9/816 -> 1.0686275 | G9: =D9/163 -> 118.7362 | H9: =D9/816 -> 23.718137
B10: 112 · Canout | C10: 238 | D10: 5424 | E10: =C10/163 -> 1.4601227 | F10: =C10/816 -> 0.29166667 | G10: =D10/163 -> 33.276074 | H10: =D10/816 -> 6.6470588
B11: 120 · Roughin | C11: 9320 | D11: 177292 | E11: =C11/163 -> 57.177914 | F11: =C11/816 -> 11.421569 | G11: =D11/163 -> 1087.681 | H11: =D11/816 -> 217.26961
B12: 130 · Finish | C12: 1841 | D12: 34658 | E12: =C12/163 -> 11.294479 | F12: =C12/816 -> 2.2561275 | G12: =D12/163 -> 212.62577 | H12: =D12/816 -> 42.473039
B13: 141 · Water Main | C13: 800 | D13: 15756 | E13: =C13/163 -> 4.9079755 | F13: =C13/816 -> 0.98039216 | G13: =D13/163 -> 96.662577 | H13: =D13/816 -> 19.308824
B14: 142 · Mech Room | C14: 379 | D14: 9784 | E14: =C14/163 -> 2.3251534 | F14: =C14/816 -> 0.46446078 | G14: =D14/163 -> 60.02454 | H14: =D14/816 -> 11.990196
B15: 145 · Tub/Shower | C15: 338 | D15: 6781 | E15: =C15/163 -> 2.0736196 | F15: =C15/816 -> 0.41421569 | G15: =D15/163 -> 41.601227 | H15: =D15/816 -> 8.310049
B16: TOTAL LABOR | C16: =SUM(C8:C15) -> 13953 | D16: =SUM(D8:D15) -> 275072 | E16: =C16/163 -> 85.601227 | F16: =C16/816 -> 17.099265 | G16: =D16/163 -> 1687.5583 | H16: =D16/816 -> 337.09804
B19: Throughput & Velocity
B20: Pace metrics across the 17-month build
B22: Project Duration | C22: 17 months
B23: Units per Month | C23: =163/17 -> 9.5882353
B24: Fixtures per Month | C24: =816/17 -> 48
B25: Labor Hours per Month | C25: =14607/17 -> 859.23529
B26: Revenue per Month | C26: =1391455/17 -> 81850.294
B27: Hours per Worker | C27: =14607/28 -> 521.67857
B28: Avg Days on Site/Worker | C28: =(14607/28)/8 -> 65.209821
B29: Crew Density | C29: =28/163*100 -> 17.177914
B32: Labor Efficiency
B34: Gross Wage (blended) | C34: $19.94/hr
B35: Fully-Loaded Rate | C35: $30.12/hr
B36: Burden Multiplier | C36: 1.51x
B37: Burden as % of Payroll | C37: 33.8%
B38: Revenue per Labor Hour | C38: =1391455/14607 -> 95.259465
B39: Profit per Labor Hour | C39: =533274/14607 -> 36.508113
B40: Labor as % of Revenue | C40: =439954/1391455 -> 0.3161827
B41: Material as % of Revenue | C41: =408537/1391455 -> 0.29360418
B42: Labor : Material Ratio | C42: 1.05 : 1
B46: SOURCES
B47: Source: 2012 Job Detail Report.pdf (135 pages, OWP, LLC – exported Apr 3, 2026).
B48: Project facts (163 units, 816 fixtures, 17-month duration) sourced from contract + plan set in /2012-Exxel, 8th Ave/Contract.
B49: Productivity metrics = JCR labor hours ÷ contract unit/fixture counts.
B50: All cost codes, budgets, actuals, and labor hours tie out exactly to the JCR. JCR is the canonical source of truth.

Sheet Benchmark KPIs
B3: CROSS-PROJECT BENCHMARK SCORECARD
B4: Benchmark KPIs
B5: Normalized metrics designed for apples-to-apples comparison across all OWP projects.
B7: KPI | C7: DATA NAME | D7: VALUE | E7: CATEGORY | F7: NOTES / BENCHMARK CONTEXT
B8: Project Type | C8: project_type | D8: Mid-rise Multifamily | E8: Profile | F8: Building category for benchmarking
B9: Unit Count | C9: unit_count | D9: 163 | E9: Profile | F9: Residential units delivered
B10: Fixture Count | C10: fixture_count | D10: 816 | E10: Profile | F10: Plumbing fixture count
B11: Fixtures per Unit | C11: fixtures_per_unit | D11: =816/163 -> 5.006135 | E11: Profile | F11: ≈5 fixtures/unit typical for multifamily
B12: Project Duration | C12: project_duration_months | D12: 17 | E12: Profile | F12: Calendar months from start to close
B13: Contract Value | C13: contract_value | D13: 1394655 | E13: Profile | F13: Original contract value
B14: Gross Margin | C14: gross_margin | D14: =533274/1391455 -> 0.38324919 | E14: Financial | F14: Net profit / revenue
B15: Profit per Unit | C15: profit_per_unit | D15: =533274/163 -> 3271.6196 | E15: Financial | F15: Net profit normalized per residential unit
B16: Profit per Fixture | C16: profit_per_fixture | D16: =533274/816 -> 653.52206 | E16: Financial | F16: Net profit per fixture installed
B17: Revenue per Unit | C17: revenue_per_unit | D17: =1391455/163 -> 8536.5337 | E17: Financial | F17: Top-line per unit
B18: Revenue per Fixture | C18: revenue_per_fixture | D18: =1391455/816 -> 1705.2145 | E18: Financial | F18: Top-line per fixture
B19: Cost per Unit | C19: cost_per_unit | D19: =858181/163 -> 5264.9141 | E19: Financial | F19: Total direct cost per unit
B20: Cost per Fixture | C20: cost_per_fixture | D20: =858181/816 -> 1051.6924 | E20: Financial | F20: Total direct cost per fixture
B21: Retainage % of Contract | C21: retainage_pct | D21: =69573/1394655 -> 0.049885456 | E21: Financial | F21: Held by GC until closeout
B22: Total Labor Hours | C22: total_labor_hours | D22: 14607 | E22: Labor | F22: All payroll hours on the job
B23: Hours per Unit | C23: hours_per_unit | D23: =14607/163 -> 89.613497 | E23: Labor | F23: Key plumbing benchmark
B24: Hours per Fixture | C24: hours_per_fixture | D24: =14607/816 -> 17.900735 | E24: Labor | F24: Industry std for plumbing subs
B25: Labor $ per Unit | C25: labor_cost_per_unit | D25: =439954/163 -> 2699.1043 | E25: Labor | F25: Payroll only, not material
B26: Labor $ per Fixture | C26: labor_cost_per_fixture | D26: =439954/816 -> 539.15931 | E26: Labor | F26: Payroll only, not material
B27: Blended Gross Wage | C27: blended_gross_wage | D27: 19.94 | E27: Labor | F27: Pre-burden average
B28: Fully-Loaded Wage | C28: fully_loaded_wage | D28: 30.12 | E28: Labor | F28: Post-burden true cost
B29: Burden Multiplier | C29: burden_multiplier | D29: 1.51 | E29: Labor | F29: Loaded ÷ gross
B30: Revenue per Labor Hour | C30: revenue_per_labor_hour | D30: =1391455/14607 -> 95.259465 | E30: Labor | F30: Productivity ceiling
B31: Profit per Labor Hour | C31: profit_per_labor_hour | D31: =533274/14607 -> 36.508113 | E31: Labor | F31: Margin per hour worked
B32: Total Workers | C32: total_workers | D32: 28 | E32: Crew | F32: Unique payroll IDs across job
B33: Crew Density | C33: crew_density_per_100u | D33: =28/163*100 -> 17.177914 | E33: Crew | F33: Workers per 100 units
B34: Lead-to-Helper Ratio | C34: lead_to_helper_ratio | D34: 1 : 8 | E34: Crew | F34: 1 super to 8 helpers
B35: Apprentice Ratio | C35: apprentice_ratio | D35: =7/28 -> 0.25 | E35: Crew | F35: Apprentices as % of crew
B36: Units per Month | C36: units_per_month | D36: =163/17 -> 9.5882353 | E36: Throughput | F36: Build pace
B37: Fixtures per Month | C37: fixtures_per_month | D37: =816/17 -> 48 | E37: Throughput | F37: Fixture install velocity
B38: Hours per Month | C38: hours_per_month | D38: =14607/17 -> 859.23529 | E38: Throughput | F38: Avg monthly labor burn
B39: Labor as % of Revenue | C39: labor_pct_of_revenue | D39: =439954/1391455 -> 0.3161827 | E39: Cost Mix | F39: Payroll exposure
B40: Material as % of Revenue | C40: material_pct_of_revenue | D40: =408537/1391455 -> 0.29360418 | E40: Cost Mix | F40: Material/sub exposure
B41: GL as % of Revenue | C41: gl_pct_of_revenue | D41: =9690/1391455 -> 0.0069639334 | E41: Cost Mix | F41: Misc internal allocations
B42: Labor : Material Ratio | C42: labor_to_material_ratio | D42: 1.05 : 1 | E42: Cost Mix | F42: Plumbing typically 1:1
B43: Phases Over Budget | C43: phases_over_budget | D43: 4 | E43: Estimating | F43: Roughin, Finish, Garage, Mech Room
...

Sheet Crew Analytics
B3: WORKER-LEVEL DEEP DIVE
B4: Crew Analytics
B5: Per-worker hours, OT %, $, blended rate, and code participation. Extracted from JCR PR transactions.
B7: WORKER | C7: ID | D7: REG HRS | E7: OT HRS | F7: TOTAL HRS | G7: OT % | H7: WAGES ($) | I7: $/HR | J7: CODES | K7: TIER
B8: Quintanilla, Esteban R | C8: QU35 | D8: 1111 | E8: 88 | F8: =D8+E8 -> 1199 | G8: =IF(F8>0,E8/F8,0) -> 0.073394495 | H8: 38981 | I8: =IF(F8>0,H8/F8,0) -> 32.511259 | J8: 8 | K8: Lead
B9: Gonzalez Hernandez, Josue | C9: GO56 | D9: 1001 | E9: 134 | F9: =D9+E9 -> 1135 | G9: =IF(F9>0,E9/F9,0) -> 0.11806167 | H9: 15342 | I9: =IF(F9>0,H9/F9,0) -> 13.517181 | J9: 8 | K9: Helper
B10: Lima Romero, Melvin A | C10: LI49 | D10: 946 | E10: 105 | F10: =D10+E10 -> 1051 | G10: =IF(F10>0,E10/F10,0) -> 0.099904853 | H10: 20866 | I10: =IF(F10>0,H10/F10,0) -> 19.853473 | J10: 10 | K10: Apprentice
B11: Palma Vides, Hugo | C11: PA46 | D11: 790 | E11: 138 | F11: =D11+E11 -> 928 | G11: =IF(F11>0,E11/F11,0) -> 0.1487069 | H11: 27035 | I11: =IF(F11>0,H11/F11,0) -> 29.132543 | J11: 6 | K11: Journeyman
B12: Castro Hernandez, Jose A | C12: CA77 | D12: 763 | E12: 99 | F12: =D12+E12 -> 862 | G12: =IF(F12>0,E12/F12,0) -> 0.11484919 | H12: 14160 | I12: =IF(F12>0,H12/F12,0) -> 16.426914 | J12: 8 | K12: Apprentice
B13: Rivera, Eli P | C13: RI84 | D13: 746 | E13: 110 | F13: =D13+E13 -> 856 | G13: =IF(F13>0,E13/F13,0) -> 0.12850467 | H13: 11184 | I13: =IF(F13>0,H13/F13,0) -> 13.065421 | J13: 5 | K13: Helper
B14: Chavarria Lopez, Omar A | C14: CH04 | D14: 738 | E14: 113 | F14: =D14+E14 -> 851 | G14: =IF(F14>0,E14/F14,0) -> 0.13278496 | H14: 11150 | I14: =IF(F14>0,H14/F14,0) -> 13.102233 | J14: 5 | K14: Helper
B15: Monico Brambila, Jesus S | C15: MO54 | D15: 660 | E15: 150 | F15: =D15+E15 -> 810 | G15: =IF(F15>0,E15/F15,0) -> 0.18518519 | H15: 11548 | I15: =IF(F15>0,H15/F15,0) -> 14.25679 | J15: 4 | K15: Helper
B16: Meza Fuentes, Erick A | C16: ME98 | D16: 575.5 | E16: 4 | F16: =D16+E16 -> 579.5 | G16: =IF(F16>0,E16/F16,0) -> 0.0069025022 | H16: 11624 | I16: =IF(F16>0,H16/F16,0) -> 20.058671 | J16: 5 | K16: Apprentice
B17: Rivera, Jorge A | C17: RI87 | D17: 501 | E17: 60 | F17: =D17+E17 -> 561 | G17: =IF(F17>0,E17/F17,0) -> 0.10695187 | H17: 10638 | I17: =IF(F17>0,H17/F17,0) -> 18.962567 | J17: 4 | K17: Apprentice
B18: Paco Leyva, Orlando | C18: PA11 | D18: 450.5 | E18: 38 | F18: =D18+E18 -> 488.5 | G18: =IF(F18>0,E18/F18,0) -> 0.07778915 | H18: 7146 | I18: =IF(F18>0,H18/F18,0) -> 14.628454 | J18: 8 | K18: Helper
B19: Gerard, Jeffrey S | C19: GE69 | D19: 406 | E19: 0 | F19: =D19+E19 -> 406 | G19: =IF(F19>0,E19/F19,0) -> 0 | H19: 14595 | I19: =IF(F19>0,H19/F19,0) -> 35.948276 | J19: 9 | K19: Lead
... B49: Hubbard, Robert W | C49: HU06 | D49: 3.5 | E49: 0 | F49: =D49+E49 -> 3.5 | G49: =IF(F49>0,E49/F49,0) -> 0 | H49: 116 | I49: =IF(F49>0,H49/F49,0) -> 33.142857 | J49: 3 | K49: Lead
B50: TOTAL CREW | C50: 42 workers | D50: =SUM(D8:D49) -> 13220.7 | E50: =SUM(E8:E49) -> 1431.5 | F50: =SUM(F8:F49) -> 14652.2 | G50: =E50/F50 -> 0.097698639 | H50: =SUM(H8:H49) -> 291364 | I50: =H50/F50 -> 19.885341
B53: CREW INSIGHTS
B54: ● Top 3 workers ran 26% of all hours — Quintanilla, Gonzalez, and Lima logged 3,385 hrs (23% of 14,608) — tight core crew.
B56: ● Quintanilla is the highest-leverage worker — 1,199 hrs at $32.51/hr blended — highest paid hourly + most hours. Likely lead/super.
B58: ● Monico Brambila ran 18.5% OT — 150 OT hrs out of 810 total. Highest sustained OT % among core crew. Watch for burnout.
B60: ● 9 workers logged <50 hrs — These are spot helpers / phase fill-ins. Cleanly separated from core 15.
B62: ● 42 unique workers touched the job — Larger than the 28 estimate from the JCR PR header — fold/spot crew accounts for the delta.
B64: ● Average blended rate $19.94/hr — Loaded rate including burden ≈ $30.12/hr (1.51x multiplier).
B69: SOURCES
B70: Source: 2012 Job Detail Report.pdf — PR (payroll) transaction lines, all 135 pages.
B71: Hours and wages parsed from per-worker entries; tier inferred from blended $/hr.
B72: Total of 14,652 hrs across 42 workers (vs 14,608 hrs aggregated to cost codes — 44 hr rounding diff from JCR header lines).
B76: SOURCES
... B79: Tier classification: Lead ≥$32/hr, Journeyman ≥$22/hr, Apprentice ≥$15/hr, Helper <$15/hr.

Sheet Reconciliation
B3: JCR TIE-OUT PROOF
B4: Reconciliation
B5: Side-by-side proof that every roll-up in this workbook ties back to the 2012 Job Detail Report.
B7: A · Grand Totals — All 32 JCR Cost Codes
B9: METRIC | C9: JCR (SOURCE) | D9: WORKBOOK | E9: DIFFERENCE | F9: STATUS
B10: Total Budget (all 32 codes) | C10: 1065992 | D10: ='Budget vs Actual'!C40 -> 1065993 | E10: =D10-C10 -> 1 | F10: =IF(ABS(D10-C10)<=1,"TIES","OFF") -> TIES
B11: Total Actual (all 32 codes) | C11: 858181 | D11: ='Budget vs Actual'!D40 -> 858182 | E11: =D11-C11 -> 1 | F11: =IF(ABS(D11-C11)<=1,"TIES","OFF") -> TIES
B12: Total Variance | C12: -207811 | D12: ='Budget vs Actual'!E40 -> -207811 | E12: =D12-C12 -> 0 | F12: =IF(ABS(D12-C12)<=1,"TIES","OFF") -> TIES
B13: Total Labor Hours | C13: 14608 | D13: ='Budget vs Actual'!G40 -> 14609 | E13: =D13-C13 -> 1 | F13: =IF(ABS(D13-C13)<=1,"TIES","OFF") -> TIES
B16: B · Labor Codes (0xx + 1xx)
B18: METRIC | C18: JCR (SOURCE) | D18: WORKBOOK | E18: DIFFERENCE | F18: STATUS
B19: Labor Budget | C19: 305975 | D19: =SUM('Budget vs Actual'!C8:C20) -> 305975 | E19: =D19-C19 -> 0 | F19: =IF(ABS(D19-C19)<=1,"TIES","OFF") -> TIES
B20: Labor Actual | C20: 291323 | D20: =SUM('Budget vs Actual'!D8:D20) -> 291323 | E20: =D20-C20 -> 0 | F20: =IF(ABS(D20-C20)<=1,"TIES","OFF") -> TIES
B21: Labor Hours | C21: 14608 | D21: =SUM('Budget vs Actual'!G8:G20) -> 14608 | E21: =D21-C21 -> 0 | F21: =IF(ABS(D21-C21)<=1,"TIES","OFF") -> TIES
B24: C · Material Codes (039 + 2xx)
B26: METRIC | C26: JCR (SOURCE) | D26: WORKBOOK | E26: DIFFERENCE | F26: STATUS
B27: Material Budget (Budget vs Actual tab) | C27: 553400 | D27: =SUM('Budget vs Actual'!C21:C31) -> 553400 | E27: =D27-C27 -> 0 | F27: =IF(ABS(D27-C27)<=1,"TIES","OFF") -> TIES
B28: Material Actual (Budget vs Actual tab) | C28: 390751 | D28: =SUM('Budget vs Actual'!D21:D31) -> 390751 | E28: =D28-C28 -> 0 | F28: =IF(ABS(D28-C28)<=1,"TIES","OFF") -> TIES
B29: Material Budget (Material tab) | C29: 553400 | D29: =Material!C19 -> 553400 | E29: =D29-C29 -> 0 | F29: =IF(ABS(D29-C29)<=1,"TIES","OFF") -> TIES
B30: Material Actual (Material tab) | C30: 390751 | D30: =Material!D19 -> 390751 | E30: =D30-C30 -> 0 | F30: =IF(ABS(D30-C30)<=1,"TIES","OFF") -> TIES
B31: Cross-check: Material tab = BvA Material rows | C31: 390751 | D31: =Material!D19-SUM('Budget vs Actual'!D21:D31)+390751 -> 390751 | E31: =D31-C31 -> 0 | F31: =IF(ABS(D31-C31)<=1,"TIES","OFF") -> TIES
B34: D · Overhead + Payroll Burden (6xx + 9xx)
B36: METRIC | C36: JCR (SOURCE) | D36: WORKBOOK | E36: DIFFERENCE | F36: STATUS
B37: Overhead + Burden Budget | C37: 206618 | D37: =SUM('Budget vs Actual'!C32:C39) -> 206618 | E37: =D37-C37 -> 0 | F37: =IF(ABS(D37-C37)<=1,"TIES","OFF") -> TIES
B38: Overhead + Burden Actual | C38: 176108 | D38: =SUM('Budget vs Actual'!D32:D39) -> 176108 | E38: =D38-C38 -> 0 | F38: =IF(ABS(D38-C38)<=1,"TIES","OFF") -> TIES
B41: E · Crew Analytics — Worker Hours vs JCR Labor Hours
B43: METRIC | C43: JCR (SOURCE) | D43: WORKBOOK | E43: DIFFERENCE | F43: STATUS
B44: Total Crew Hours (PR line parse) | C44: 14608 | D44: ='Crew Analytics'!F50 -> 14652.2 | E44: =D44-C44 -> 44.2 | F44: =IF(ABS(D44-C44)<=50,"WITHIN","OFF") -> WITHIN
B45: Total Crew Wages (gross, pre-burden) | C45: 291364 | D45: ='Crew Analytics'!H50 -> 291364 | E45: =D45-C45 -> 0 | F45: =IF(ABS(D45-C45)<=1,"TIES","OFF") -> TIES
B48: F · Cross-Tab Consistency Checks
B50: METRIC | C50: JCR (SOURCE) | D50: WORKBOOK | E50: DIFFERENCE | F50: STATUS
B51: Direct Cost (JCR) vs BvA Grand Total | C51: 858181 | D51: ='Budget vs Actual'!D40 -> 858182 | E51: =D51-C51 -> 1 | F51: =IF(ABS(D51-C51)<=1,"TIES","OFF") -> TIES
B52: Gross Profit (Rev − Direct Cost) | C52: 533274 | D52: =1391455-'Budget vs Actual'!D40 -> 533273 | E52: =D52-C52 -> -1 | F52: =IF(ABS(D52-C52)<=1,"TIES","OFF") -> TIES
B55: G · Vendor Spend (AP)
B57: METRIC | C57: JCR (SOURCE) | D57: WORKBOOK | E57: DIFFERENCE | F57: STATUS
B58: Non-Payroll Actuals (Material + 6xx Overhead) | C58: 418270 | D58: =Material!D19+SUM('Budget vs Actual'!D32:D39)-'Budget vs Actual'!D37-'Budget vs Actual'!D38-'Budget vs Actual'!D39 -> 418270 | E58: =D58-C58 -> 0 | F58: =IF(ABS(D58-C58)<=1,"TIES","OFF") -> TIES
B59: of which AP-sourced (invoice trail) | C59: 408537 | D59: 408537 | E59: =D59-C59 -> 0 | F59: =IF(ABS(D59-C59)<=1,"TIES","OFF") -> TIES
B60: of which GL-sourced (CC / internal) | C60: 9733 | D60: =418270-408537 -> 9733 | E60: =D60-C60 -> 0 | F60: =IF(ABS(D60-C60)<=1,"TIES","OFF") -> TIES
B63: RECONCILIATION SUMMARY
B64: ● All 32 JCR cost codes tie out to $858,181 actual and $1,065,992 budget — Grand total matches the JCR Cost Code Totals line sum to within $1 (rounding).
...
