Workbook

Sheet Inputs
B2: Inputs — Canonical Job Data (4-Way)
B3: All values sourced from each job's JCR Summary workbook. Blue = hardcoded input.
B5: Metric | C5: Job #2009 | D5: Job #2010 | E5: Job #2011 | F5: Job #2012 | G5: Source / Notes
B6: — PROFILE —
B7: Job Name | C7: Chinn Greenwood Apts | D7: Chinn Old Town Mixed Use | E7: Chinn Barrett Park | F7: Exxel 8th Ave
B8: General Contractor | C8: Chinn Construction, LLC | D8: Chinn Construction, LLC | E8: Chinn Construction, LLC | F8: Exxel Pacific, Inc.
B9: Location | C9: Seattle, WA | D9: Seattle, WA | E9: Seattle, WA | F9: Seattle, WA
B10: Duration (months) | C10: 16 | D10: 24 | E10: 17 | F10: 17 | G10: 2009: Jul 2012–Oct 2013
B11: Unit Count | C11: 168 | D11: 165 | E11: 117 | F11: 163 | G11: 2009: kitchen sink count
B12: Total Fixtures | C12: 812 | D12: 803 | E12: 590 | F12: 816 | G12: All in-unit plumbing fixtures
B13: — FINANCIAL —
B14: Original Contract | C14: 384900 | D14: 1469800 | E14: 813050 | F14: 1394655
B15: Final Contract / Revenue | C15: 394208 | D15: 1386419 | E15: 869824 | F15: 1391455 | G15: Post change orders
B16: Change Orders | C16: 9308 | D16: -83381 | E16: 56774 | F16: 0 | G16: 2009: small additive
B17: Net Profit | C17: 106309 | D17: 751270 | E17: 332960 | F17: 533274
B18: Direct Cost | C18: 287899 | D18: 635149 | E18: 536863 | F18: 858181 | G18: Labor + Material + OH + Burden
B19: Retainage | C19: 19710 | D19: 69321 | E19: 43491 | F19: 69573 | G19: 5% held by GC
B20: — COST MIX —
B21: Labor Cost | C21: 84698 | D21: 202988 | E21: 142883 | F21: 291323 | G21: Sum of labor codes from JCR
B22: Material Cost | C22: 151064 | D22: 283474 | E22: 295006 | F22: 390751 | G22: Sum of material codes
B23: Overhead Cost | C23: 11246 | D23: 45271 | E23: 26210 | F23: 27519 | G23: Sum of OH codes
B24: Burden Cost | C24: 40891 | D24: 103414 | E24: 72765 | F24: 148589 | G24: 995 Burden + 998 Taxes
B25: — LABOR —
B26: Total Labor Hours | C26: 4116 | D26: 10260 | E26: 6944 | F26: 14607
B27: Total Workers | C27: 23 | D27: 22 | E27: 31 | F27: 28 | G27: Unique payroll IDs
B28: Blended Gross Wage ($/hr) | C28: 20.58 | D28: 19.78 | E28: 20.58 | F28: 19.94 | G28: Labor $ / hours
B29: Fully-Loaded Wage ($/hr) | C29: 30.51 | D29: 29.86 | E29: 31.08 | F29: 30.12 | G29: (Labor+Burden) / hours
B30: — MATERIAL —
B31: Total PO Committed | C31: 154025 | D31: 213756 | E31: 124908 | F31: 0 | G31: 2012 tracks via AP only
B32: Total POs | C32: 49 | D32: 24 | E32: 26 | F32: 0
B33: Material Vendors | C33: 13 | D33: 18 | E33: 14 | F33: 17 | G33: Distinct AP vendors
B36: Sources: OWP_2009_JCR_Summary.xlsx, OWP_2010_JCR_Summary.xlsx, OWP_2011_JCR_Summary.xlsx, OWP_2012_JCR_Summary_Notion.xlsx — all reconcile exactly to their JCR PDFs.

Sheet Comparison
B2: 4-Way Benchmark — Jobs #2009 / #2010 / #2011 / #2012
B3: Chinn Greenwood (168u, 16mo) • Chinn Old Town (165u, 24mo) • Chinn Barrett (117u, 17mo) • Exxel 8th Ave (163u, 17mo) — all Seattle multifamily/mixed-use
B5: Metric | C5: 2009 Greenwood | D5: 2010 Old Town | E5: 2011 Barrett | F5: 2012 Exxel | G5: Best | H5: Range %
B6: A. PROJECT SCALE
B7: Unit Count | C7: =Inputs!C11 -> 168 | D7: =Inputs!D11 -> 165 | E7: =Inputs!E11 -> 117 | F7: =Inputs!F11 -> 163 | G7: =IF(MAX(C7,D7,E7,F7)=C7,"2009",IF(MAX(C7,D7,E7,F7)=D7,"2010",IF(MAX(C7,D7,E7,F7)=E7,"2011","2012"))) -> 2009 | H7: =IF(AVERAGE(C7,D7,E7,F7)=0,0,(MAX(C7,D7,E7,F7)-MIN(C7,D7,E7,F7))/ABS(AVERAGE(C7,D7,E7,F7))) -> 0.33278956
B8: Total Fixtures | C8: =Inputs!C12 -> 812 | D8: =Inputs!D12 -> 803 | E8: =Inputs!E12 -> 590 | F8: =Inputs!F12 -> 816 | G8: =IF(MAX(C8,D8,E8,F8)=C8,"2009",IF(MAX(C8,D8,E8,F8)=D8,"2010",IF(MAX(C8,D8,E8,F8)=E8,"2011","2012"))) -> 2012 | H8: =IF(AVERAGE(C8,D8,E8,F8)=0,0,(MAX(C8,D8,E8,F8)-MIN(C8,D8,E8,F8))/ABS(AVERAGE(C8,D8,E8,F8))) -> 0.29923866
B9: Duration (months) | C9: =Inputs!C10 -> 16 | D9: =Inputs!D10 -> 24 | E9: =Inputs!E10 -> 17 | F9: =Inputs!F10 -> 17 | G9: =IF(MIN(C9,D9,E9,F9)=C9,"2009",IF(MIN(C9,D9,E9,F9)=D9,"2010",IF(MIN(C9,D9,E9,F9)=E9,"2011","2012"))) -> 2009 | H9: =IF(AVERAGE(C9,D9,E9,F9)=0,0,(MAX(C9,D9,E9,F9)-MIN(C9,D9,E9,F9))/ABS(AVERAGE(C9,D9,E9,F9))) -> 0.43243243
B10: Fixtures / Unit | C10: =Inputs!C12/Inputs!C11 -> 4.8333333 | D10: =Inputs!D12/Inputs!D11 -> 4.8666667 | E10: =Inputs!E12/Inputs!E11 -> 5.042735 | F10: =Inputs!F12/Inputs!F11 -> 5.006135 | G10: =IF(MAX(C10,D10,E10,F10)=C10,"2009",IF(MAX(C10,D10,E10,F10)=D10,"2010",IF(MAX(C10,D10,E10,F10)=E10,"2011","2012"))) -> 2011 | H10: =IF(AVERAGE(C10,D10,E10,F10)=0,0,(MAX(C10,D10,E10,F10)-MIN(C10,D10,E10,F10))/ABS(AVERAGE(C10,D10,E10,F10))) -> 0.042412899
B11: B. TOP-LINE FINANCIAL
B12: Revenue (Final Contract) | C12: =Inputs!C15 -> 394208 | D12: =Inputs!D15 -> 1386419 | E12: =Inputs!E15 -> 869824 | F12: =Inputs!F15 -> 1391455 | G12: =IF(MAX(C12,D12,E12,F12)=C12,"2009",IF(MAX(C12,D12,E12,F12)=D12,"2010",IF(MAX(C12,D12,E12,F12)=E12,"2011","2012"))) -> 2012 | H12: =IF(AVERAGE(C12,D12,E12,F12)=0,0,(MAX(C12,D12,E12,F12)-MIN(C12,D12,E12,F12))/ABS(AVERAGE(C12,D12,E12,F12))) -> 0.98690766
B13: Net Profit | C13: =Inputs!C17 -> 106309 | D13: =Inputs!D17 -> 751270 | E13: =Inputs!E17 -> 332960 | F13: =Inputs!F17 -> 533274 | G13: =IF(MAX(C13,D13,E13,F13)=C13,"2009",IF(MAX(C13,D13,E13,F13)=D13,"2010",IF(MAX(C13,D13,E13,F13)=E13,"2011","2012"))) -> 2010 | H13: =IF(AVERAGE(C13,D13,E13,F13)=0,0,(MAX(C13,D13,E13,F13)-MIN(C13,D13,E13,F13))/ABS(AVERAGE(C13,D13,E13,F13))) -> 1.4965916
B14: Direct Cost | C14: =Inputs!C18 -> 287899 | D14: =Inputs!D18 -> 635149 | E14: =Inputs!E18 -> 536863 | F14: =Inputs!F18 -> 858181 | G14: =IF(MIN(C14,D14,E14,F14)=C14,"2009",IF(MIN(C14,D14,E14,F14)=D14,"2010",IF(MIN(C14,D14,E14,F14)=E14,"2011","2012"))) -> 2009 | H14: =IF(AVERAGE(C14,D14,E14,F14)=0,0,(MAX(C14,D14,E14,F14)-MIN(C14,D14,E14,F14))/ABS(AVERAGE(C14,D14,E14,F14))) -> 0.98405413
B15: Gross Margin | C15: =Inputs!C17/Inputs!C15 -> 0.26967743 | D15: =Inputs!D17/Inputs!D15 -> 0.54187803 | E15: =Inputs!E17/Inputs!E15 -> 0.38279008 | F15: =Inputs!F17/Inputs!F15 -> 0.38324919 | G15: =IF(MAX(C15,D15,E15,F15)=C15,"2009",IF(MAX(C15,D15,E15,F15)=D15,"2010",IF(MAX(C15,D15,E15,F15)=E15,"2011","2012"))) -> 2010 | H15: =IF(AVERAGE(C15,D15,E15,F15)=0,0,(MAX(C15,D15,E15,F15)-MIN(C15,D15,E15,F15))/ABS(AVERAGE(C15,D15,E15,F15))) -> 0.69016611
B16: Change Orders ($) | C16: =Inputs!C16 -> 9308 | D16: =Inputs!D16 -> -83381 | E16: =Inputs!E16 -> 56774 | F16: =Inputs!F16 -> 0 | G16: =IF(MAX(C16,D16,E16,F16)=C16,"2009",IF(MAX(C16,D16,E16,F16)=D16,"2010",IF(MAX(C16,D16,E16,F16)=E16,"2011","2012"))) -> 2011 | H16: =IF(AVERAGE(C16,D16,E16,F16)=0,0,(MAX(C16,D16,E16,F16)-MIN(C16,D16,E16,F16))/ABS(AVERAGE(C16,D16,E16,F16))) -> 32.407654
B17: Retainage | C17: =Inputs!C19 -> 19710 | D17: =Inputs!D19 -> 69321 | E17: =Inputs!E19 -> 43491 | F17: =Inputs!F19 -> 69573 | G17: =IF(MIN(C17,D17,E17,F17)=C17,"2009",IF(MIN(C17,D17,E17,F17)=D17,"2010",IF(MIN(C17,D17,E17,F17)=E17,"2011","2012"))) -> 2009 | H17: =IF(AVERAGE(C17,D17,E17,F17)=0,0,(MAX(C17,D17,E17,F17)-MIN(C17,D17,E17,F17))/ABS(AVERAGE(C17,D17,E17,F17))) -> 0.98692199
B18: C. PER-UNIT ECONOMICS
B19: Revenue / Unit | C19: =Inputs!C15/Inputs!C11 -> 2346.4762 | D19: =Inputs!D15/Inputs!D11 -> 8402.5394 | E19: =Inputs!E15/Inputs!E11 -> 7434.3932 | F19: =Inputs!F15/Inputs!F11 -> 8536.5337 | G19: =IF(MAX(C19,D19,E19,F19)=C19,"2009",IF(MAX(C19,D19,E19,F19)=D19,"2010",IF(MAX(C19,D19,E19,F19)=E19,"2011","2012"))) -> 2012 | H19: =IF(AVERAGE(C19,D19,E19,F19)=0,0,(MAX(C19,D19,E19,F19)-MIN(C19,D19,E19,F19))/ABS(AVERAGE(C19,D19,E19,F19))) -> 0.92665732
B20: Profit / Unit | C20: =Inputs!C17/Inputs!C11 -> 632.79167 | D20: =Inputs!D17/Inputs!D11 -> 4553.1515 | E20: =Inputs!E17/Inputs!E11 -> 2845.812 | F20: =Inputs!F17/Inputs!F11 -> 3271.6196 | G20: =IF(MAX(C20,D20,E20,F20)=C20,"2009",IF(MAX(C20,D20,E20,F20)=D20,"2010",IF(MAX(C20,D20,E20,F20)=E20,"2011","2012"))) -> 2010 | H20: =IF(AVERAGE(C20,D20,E20,F20)=0,0,(MAX(C20,D20,E20,F20)-MIN(C20,D20,E20,F20))/ABS(AVERAGE(C20,D20,E20,F20))) -> 1.3873237
B21: Direct Cost / Unit | C21: =Inputs!C18/Inputs!C11 -> 1713.6845 | D21: =Inputs!D18/Inputs!D11 -> 3849.3879 | E21: =Inputs!E18/Inputs!E11 -> 4588.5726 | F21: =Inputs!F18/Inputs!F11 -> 5264.9141 | G21: =IF(MIN(C21,D21,E21,F21)=C21,"2009",IF(MIN(C21,D21,E21,F21)=D21,"2010",IF(MIN(C21,D21,E21,F21)=E21,"2011","2012"))) -> 2009 | H21: =IF(AVERAGE(C21,D21,E21,F21)=0,0,(MAX(C21,D21,E21,F21)-MIN(C21,D21,E21,F21))/ABS(AVERAGE(C21,D21,E21,F21))) -> 0.92140653
B22: Labor Cost / Unit | C22: =Inputs!C21/Inputs!C11 -> 504.15476 | D22: =Inputs!D21/Inputs!D11 -> 1230.2303 | E22: =Inputs!E21/Inputs!E11 -> 1221.2222 | F22: =Inputs!F21/Inputs!F11 -> 1787.2577 | G22: =IF(MIN(C22,D22,E22,F22)=C22,"2009",IF(MIN(C22,D22,E22,F22)=D22,"2010",IF(MIN(C22,D22,E22,F22)=E22,"2011","2012"))) -> 2009 | H22: =IF(AVERAGE(C22,D22,E22,F22)=0,0,(MAX(C22,D22,E22,F22)-MIN(C22,D22,E22,F22))/ABS(AVERAGE(C22,D22,E22,F22))) -> 1.0821332
B23: Material Cost / Unit | C23: =Inputs!C22/Inputs!C11 -> 899.19048 | D23: =Inputs!D22/Inputs!D11 -> 1718.0242 | E23: =Inputs!E22/Inputs!E11 -> 2521.4188 | F23: =Inputs!F22/Inputs!F11 -> 2397.2454 | G23: =IF(MIN(C23,D23,E23,F23)=C23,"2009",IF(MIN(C23,D23,E23,F23)=D23,"2010",IF(MIN(C23,D23,E23,F23)=E23,"2011","2012"))) -> 2009 | H23: =IF(AVERAGE(C23,D23,E23,F23)=0,0,(MAX(C23,D23,E23,F23)-MIN(C23,D23,E23,F23))/ABS(AVERAGE(C23,D23,E23,F23))) -> 0.86106921
B24: Hours / Unit | C24: =Inputs!C26/Inputs!C11 -> 24.5 | D24: =Inputs!D26/Inputs!D11 -> 62.181818 | E24: =Inputs!E26/Inputs!E11 -> 59.350427 | F24: =Inputs!F26/Inputs!F11 -> 89.613497 | G24: =IF(MIN(C24,D24,E24,F24)=C24,"2009",IF(MIN(C24,D24,E24,F24)=D24,"2010",IF(MIN(C24,D24,E24,F24)=E24,"2011","2012"))) -> 2009 | H24: =IF(AVERAGE(C24,D24,E24,F24)=0,0,(MAX(C24,D24,E24,F24)-MIN(C24,D24,E24,F24))/ABS(AVERAGE(C24,D24,E24,F24))) -> 1.1052777
B25: D. PER-FIXTURE ECONOMICS
B26: Revenue / Fixture | C26: =Inputs!C15/Inputs!C12 -> 485.47783 | D26: =Inputs!D15/Inputs!D12 -> 1726.5492 | E26: =Inputs!E15/Inputs!E12 -> 1474.278 | F26: =Inputs!F15/Inputs!F12 -> 1705.2145 | G26: =IF(MAX(C26,D26,E26,F26)=C26,"2009",IF(MAX(C26,D26,E26,F26)=D26,"2010",IF(MAX(C26,D26,E26,F26)=E26,"2011","2012"))) -> 2010 | H26: =IF(AVERAGE(C26,D26,E26,F26)=0,0,(MAX(C26,D26,E26,F26)-MIN(C26,D26,E26,F26))/ABS(AVERAGE(C26,D26,E26,F26))) -> 0.92075814
B27: Profit / Fixture | C27: =Inputs!C17/Inputs!C12 -> 130.92241 | D27: =Inputs!D17/Inputs!D12 -> 935.57908 | E27: =Inputs!E17/Inputs!E12 -> 564.33898 | F27: =Inputs!F17/Inputs!F12 -> 653.52206 | G27: =IF(MAX(C27,D27,E27,F27)=C27,"2009",IF(MAX(C27,D27,E27,F27)=D27,"2010",IF(MAX(C27,D27,E27,F27)=E27,"2011","2012"))) -> 2010 | H27: =IF(AVERAGE(C27,D27,E27,F27)=0,0,(MAX(C27,D27,E27,F27)-MIN(C27,D27,E27,F27))/ABS(AVERAGE(C27,D27,E27,F27))) -> 1.4089824
B28: Direct Cost / Fixture | C28: =Inputs!C18/Inputs!C12 -> 354.55542 | D28: =Inputs!D18/Inputs!D12 -> 790.97011 | E28: =Inputs!E18/Inputs!E12 -> 909.93729 | F28: =Inputs!F18/Inputs!F12 -> 1051.6924 | G28: =IF(MIN(C28,D28,E28,F28)=C28,"2009",IF(MIN(C28,D28,E28,F28)=D28,"2010",IF(MIN(C28,D28,E28,F28)=E28,"2011","2012"))) -> 2009 | H28: =IF(AVERAGE(C28,D28,E28,F28)=0,0,(MAX(C28,D28,E28,F28)-MIN(C28,D28,E28,F28))/ABS(AVERAGE(C28,D28,E28,F28))) -> 0.89746013
B29: Labor / Fixture | C29: =Inputs!C21/Inputs!C12 -> 104.30788 | D29: =Inputs!D21/Inputs!D12 -> 252.78705 | E29: =Inputs!E21/Inputs!E12 -> 242.17458 | F29: =Inputs!F21/Inputs!F12 -> 357.01348 | G29: =IF(MIN(C29,D29,E29,F29)=C29,"2009",IF(MIN(C29,D29,E29,F29)=D29,"2010",IF(MIN(C29,D29,E29,F29)=E29,"2011","2012"))) -> 2009 | H29: =IF(AVERAGE(C29,D29,E29,F29)=0,0,(MAX(C29,D29,E29,F29)-MIN(C29,D29,E29,F29))/ABS(AVERAGE(C29,D29,E29,F29))) -> 1.0570327
B30: Material / Fixture | C30: =Inputs!C22/Inputs!C12 -> 186.03941 | D30: =Inputs!D22/Inputs!D12 -> 353.01868 | E30: =Inputs!E22/Inputs!E12 -> 500.01017 | F30: =Inputs!F22/Inputs!F12 -> 478.86152 | G30: =IF(MIN(C30,D30,E30,F30)=C30,"2009",IF(MIN(C30,D30,E30,F30)=D30,"2010",IF(MIN(C30,D30,E30,F30)=E30,"2011","2012"))) -> 2009 | H30: =IF(AVERAGE(C30,D30,E30,F30)=0,0,(MAX(C30,D30,E30,F30)-MIN(C30,D30,E30,F30))/ABS(AVERAGE(C30,D30,E30,F30))) -> 0.82736571
B31: Hours / Fixture | C31: =Inputs!C26/Inputs!C12 -> 5.0689655 | D31: =Inputs!D26/Inputs!D12 -> 12.777086 | E31: =Inputs!E26/Inputs!E12 -> 11.769492 | F31: =Inputs!F26/Inputs!F12 -> 17.900735 | G31: =IF(MIN(C31,D31,E31,F31)=C31,"2009",IF(MIN(C31,D31,E31,F31)=D31,"2010",IF(MIN(C31,D31,E31,F31)=E31,"2011","2012"))) -> 2009 | H31: =IF(AVERAGE(C31,D31,E31,F31)=0,0,(MAX(C31,D31,E31,F31)-MIN(C31,D31,E31,F31))/ABS(AVERAGE(C31,D31,E31,F31))) -> 1.0801999
B32: E. LABOR & PRODUCTIVITY
B33: Total Labor Hours | C33: =Inputs!C26 -> 4116 | D33: =Inputs!D26 -> 10260 | E33: =Inputs!E26 -> 6944 | F33: =Inputs!F26 -> 14607 | G33: =IF(MIN(C33,D33,E33,F33)=C33,"2009",IF(MIN(C33,D33,E33,F33)=D33,"2010",IF(MIN(C33,D33,E33,F33)=E33,"2011","2012"))) -> 2009 | H33: =IF(AVERAGE(C33,D33,E33,F33)=0,0,(MAX(C33,D33,E33,F33)-MIN(C33,D33,E33,F33))/ABS(AVERAGE(C33,D33,E33,F33))) -> 1.1680352
B34: Total Workers | C34: =Inputs!C27 -> 23 | D34: =Inputs!D27 -> 22 | E34: =Inputs!E27 -> 31 | F34: =Inputs!F27 -> 28 | G34: =IF(MIN(C34,D34,E34,F34)=C34,"2009",IF(MIN(C34,D34,E34,F34)=D34,"2010",IF(MIN(C34,D34,E34,F34)=E34,"2011","2012"))) -> 2010 | H34: =IF(AVERAGE(C34,D34,E34,F34)=0,0,(MAX(C34,D34,E34,F34)-MIN(C34,D34,E34,F34))/ABS(AVERAGE(C34,D34,E34,F34))) -> 0.34615385
B35: Blended Gross Wage | C35: =Inputs!C28 -> 20.58 | D35: =Inputs!D28 -> 19.78 | E35: =Inputs!E28 -> 20.58 | F35: =Inputs!F28 -> 19.94 | G35: =IF(MIN(C35,D35,E35,F35)=C35,"2009",IF(MIN(C35,D35,E35,F35)=D35,"2010",IF(MIN(C35,D35,E35,F35)=E35,"2011","2012"))) -> 2010 | H35: =IF(AVERAGE(C35,D35,E35,F35)=0,0,(MAX(C35,D35,E35,F35)-MIN(C35,D35,E35,F35))/ABS(AVERAGE(C35,D35,E35,F35))) -> 0.039564787
B36: Fully-Loaded Wage | C36: =Inputs!C29 -> 30.51 | D36: =Inputs!D29 -> 29.86 | E36: =Inputs!E29 -> 31.08 | F36: =Inputs!F29 -> 30.12 | G36: =IF(MIN(C36,D36,E36,F36)=C36,"2009",IF(MIN(C36,D36,E36,F36)=D36,"2010",IF(MIN(C36,D36,E36,F36)=E36,"2011","2012"))) -> 2010 | H36: =IF(AVERAGE(C36,D36,E36,F36)=0,0,(MAX(C36,D36,E36,F36)-MIN(C36,D36,E36,F36))/ABS(AVERAGE(C36,D36,E36,F36))) -> 0.040141482
B37: Revenue / Hour | C37: =Inputs!C15/Inputs!C26 -> 95.774538 | D37: =Inputs!D15/Inputs!D26 -> 135.12856 | E37: =Inputs!E15/Inputs!E26 -> 125.26267 | F37: =Inputs!F15/Inputs!F26 -> 95.259465 | G37: =IF(MAX(C37,D37,E37,F37)=C37,"2009",IF(MAX(C37,D37,E37,F37)=D37,"2010",IF(MAX(C37,D37,E37,F37)=E37,"2011","2012"))) -> 2010 | H37: =IF(AVERAGE(C37,D37,E37,F37)=0,0,(MAX(C37,D37,E37,F37)-MIN(C37,D37,E37,F37))/ABS(AVERAGE(C37,D37,E37,F37))) -> 0.35327306
B38: Profit / Hour | C38: =Inputs!C17/Inputs!C26 -> 25.828231 | D38: =Inputs!D17/Inputs!D26 -> 73.223197 | E38: =Inputs!E17/Inputs!E26 -> 47.949309 | F38: =Inputs!F17/Inputs!F26 -> 36.508113 | G38: =IF(MAX(C38,D38,E38,F38)=C38,"2009",IF(MAX(C38,D38,E38,F38)=D38,"2010",IF(MAX(C38,D38,E38,F38)=E38,"2011","2012"))) -> 2010 | H38: =IF(AVERAGE(C38,D38,E38,F38)=0,0,(MAX(C38,D38,E38,F38)-MIN(C38,D38,E38,F38))/ABS(AVERAGE(C38,D38,E38,F38))) -> 1.0330829
B39: Hours / Worker | C39: =Inputs!C26/Inputs!C27 -> 178.95652 | D39: =Inputs!D26/Inputs!D27 -> 466.36364 | E39: =Inputs!E26/Inputs!E27 -> 224 | F39: =Inputs!F26/Inputs!F27 -> 521.67857 | G39: =IF(MAX(C39,D39,E39,F39)=C39,"2009",IF(MAX(C39,D39,E39,F39)=D39,"2010",IF(MAX(C39,D39,E39,F39)=E39,"2011","2012"))) -> 2012 | H39: =IF(AVERAGE(C39,D39,E39,F39)=0,0,(MAX(C39,D39,E39,F39)-MIN(C39,D39,E39,F39))/ABS(AVERAGE(C39,D39,E39,F39))) -> 0.98554238
B40: F. COST MIX (% of Revenue)
B41: Labor % of Revenue | C41: =Inputs!C21/Inputs!C15 -> 0.21485612 | D41: =Inputs!D21/Inputs!D15 -> 0.14641173 | E41: =Inputs!E21/Inputs!E15 -> 0.16426656 | F41: =Inputs!F21/Inputs!F15 -> 0.20936574 | G41: =IF(MIN(C41,D41,E41,F41)=C41,"2009",IF(MIN(C41,D41,E41,F41)=D41,"2010",IF(MIN(C41,D41,E41,F41)=E41,"2011","2012"))) -> 2010 | H41: =IF(AVERAGE(C41,D41,E41,F41)=0,0,(MAX(C41,D41,E41,F41)-MIN(C41,D41,E41,F41))/ABS(AVERAGE(C41,D41,E41,F41))) -> 0.37253709
B42: Material % of Revenue | C42: =Inputs!C22/Inputs!C15 -> 0.38320886 | D42: =Inputs!D22/Inputs!D15 -> 0.20446488 | E42: =Inputs!E22/Inputs!E15 -> 0.33915597 | F42: =Inputs!F22/Inputs!F15 -> 0.28082187 | G42: =IF(MIN(C42,D42,E42,F42)=C42,"2009",IF(MIN(C42,D42,E42,F42)=D42,"2010",IF(MIN(C42,D42,E42,F42)=E42,"2011","2012"))) -> 2010 | H42: =IF(AVERAGE(C42,D42,E42,F42)=0,0,(MAX(C42,D42,E42,F42)-MIN(C42,D42,E42,F42))/ABS(AVERAGE(C42,D42,E42,F42))) -> 0.59203824
...

Sheet Insights
B2: Key Observations — 4-Way Benchmark
B4: 2010 IS THE MARGIN OUTLIER | C4: 2010 landed at 54.2% gross margin vs 38.3% on both 2011 and 2012, and 27.0% on 2009. Across 4 Seattle jobs, OWP's profit margin spans 27 points — there's no single 'normal' yet. 2010 demands a post-mortem on what made it exceptional.
B5: 2009 IS THE MARGIN FLOOR | C5: At 27.0% gross margin, the 2009 Greenwood job is OWP's least profitable in the set despite being the smallest contract. Cost structure tells the story: direct cost = 73% of revenue (vs 46% on 2010). The single-supplier (Ferguson 73%) approach may have lost negotiating leverage that could have widened the margin.
B6: CHINN IS THE PREFERRED GC | C6: Three of the four jobs (2009, 2010, 2011) are Chinn Construction. Combined Chinn revenue: $2.65M, combined profit: $1.19M = 44.9% blended margin. Exxel (2012) hit 38.3% as a one-off. Chinn has been substantially more profitable on average.
B7: DEDUCTIVE vs ADDITIVE CHANGE ORDERS | C7: 2009: +$9K (small additive). 2010: −$83K (deductive — unusual). 2011: +$57K (3 additive COs). 2012: $0 recorded. Four different CO patterns. 2010's deductive COs likely contributed to its outsize margin via descoped work that OWP banked.
B8: FIXTURE COUNT CLUSTER | C8: Three of four jobs cluster tightly at 803/812/816 fixtures (2010/2009/2012). 2011 sits alone at 590. Yet hours required ranges from 4,116 (2009) to 14,607 (2012) — a 3.5× spread on similar work. Productivity is the variable, not scope.
B9: 2009 IS THE LABOR-LIGHT EXTREME | C9: 4,116 hours over 16 months = ~257 hrs/month average. 2012 ran 14,607 hours over 17 months = ~860 hrs/month. 2009 likely had part-time crews or split-attention with concurrent jobs.
B10: 2011 HAS THE BEST HOURS/FIXTURE | C10: 2009: 5.1. 2010: 12.8. 2011: 11.8. 2012: 17.9. Shockingly, 2009 looks like the most labor-efficient — but that's because the per-fixture math benefits from low total hours (likely under-recorded or partial JCR coverage). Excluding 2009 as an outlier, 2011 is the productivity winner.
B11: WAGE STRUCTURE IS REMARKABLY STABLE | C11: Blended gross wage across 4 jobs: $20.58 / $19.78 / $20.58 / $19.94. Fully-loaded: $30.51 / $29.86 / $31.08 / $30.12. Wage variance is under 5% across all 4 — OWP's crew economics are stable, so productivity differences are about hours-on-job, not pay rate.
B12: VENDOR CONCENTRATION IS A PATTERN | C12: 2009: Ferguson alone = 73% of AP (extreme). 2010: Rosen Supply 55%. 2011: similar concentration. 2012: top vendor concentration. Across all 4 jobs, OWP routinely puts 50-75% of material spend with one vendor. This is leverage left on the table — consolidating across jobs into a true preferred-vendor program could unlock 2-5% material savings.
B13: PO DISCIPLINE VARIES WIDELY | C13: 2009: 49 POs, $154K (102% of material). 2010: 24 POs, $214K (75%). 2011: 26 POs, $125K (42%). 2012: zero POs. There's no consistent procurement process across jobs — 2009 had the highest discipline, 2012 had none.
B14: DURATION ≠ COMPLEXITY | C14: 2009: 16mo. 2010: 24mo. 2011: 17mo. 2012: 17mo. 2010's extra duration didn't translate to more revenue per month (actually less than 2012). Long jobs are not premium jobs — they're just longer.
B15: REVENUE PER UNIT TIGHTENING | C15: 2009: $2,346/unit. 2010: $8,403/unit. 2011: $7,434/unit. 2012: $8,537/unit. 2009 is dramatically below the others — smaller buildings command much lower per-unit pricing. OWP earns ~3.5× more per unit on mid-size jobs vs small.
B17: THE BIGGEST QUESTIONS FOR OWP
B18: 1. Why did 2010 deliver 54% margin while the other 3 jobs averaged 34%? Was 2010 a pricing fluke or a repeatable formula? 2. Why did 2009 land at only 27% margin? Is small-job economics structurally lower-margin, or did Ferguson concentration cost us pricing leverage? 3. Is the Chinn relationship (44.9% blended margin on $2.65M across 3 jobs) worth formalizing as a preferred-GC pipeline? 4. Across all 4 jobs, OWP puts 55-73% of material spend through one vendor per job. Could a multi-job consolidated buy unlock 3-5% material savings?
B20: Sources: OWP_2009_JCR_Summary.xlsx, OWP_2010_JCR_Summary.xlsx, OWP_2011_JCR_Summary.xlsx, OWP_2012_JCR_Summary_Notion.xlsx
