Workbook

Sheet Overview
B2: Job #2012 · Exxel Pacific 8th Ave Apartments
B3: Cortex JCR Summary • Exxel Pacific, Inc. • Seattle, WA (4545 8th Ave NE) • 163-unit 9-story multifamily apartments + ground-floor retail • Mar 2013 – Jul 2014 (~17 months)
B5: PROJECT OVERVIEW
B6: Project Job # | C6: 2012
B7: Project Name: | C7: Exxel Pacific 8th Ave Apartments
B8: General Contractor | C8: Exxel Pacific, Inc.
B9: Location | C9: Seattle, WA (4545 8th Ave NE)
B10: Project Duration | C10: Mar 2013 – Jul 2014 (~17 months)
B11: Total Unique Documents | C11: 8th Ave folder: Contract (Exxel Pacific + One Way Plumbing), Billing (aggregate + 15 SOVs), PO_s (68 scheduled), Permits (plumbing, gas, boiler, backflow), Change Orders
B13: CONTRACT VALUE | D13: NET PROFIT | F13: DIRECT COST | H13: LABOR HOURS
B14: $1,391,455 | D14: $544,854 | F14: $846,601 | H14: 14,607
B15: Original $1,394,655 + $-3,200 COs | D15: 39.2% margin | F15: 60.8% of revenue | H15: 40 workers
B18: COST BREAKDOWN
B19: Category | C19: Budget | D19: Actual | E19: Variance | F19: % Budget | G19: % of Cost
B20: Labor | C20: 305975 | D20: 291321.88 | E20: =C20-D20 -> 14653.12 | F20: =IF(C20=0,0,D20/C20) -> 0.95211007 | G20: =IF($D$24=0,0,D20/$D$24) -> 0.34410752
B21: Material | C21: 561666 | D21: 390750.86 | E21: =C21-D21 -> 170915.14 | F21: =IF(C21=0,0,D21/C21) -> 0.69569969 | G21: =IF($D$24=0,0,D21/$D$24) -> 0.46155239
B22: Overhead | C22: 33000 | D22: 15938.74 | E22: =C22-D22 -> 17061.26 | F22: =IF(C22=0,0,D22/C22) -> 0.48299212 | G22: =IF($D$24=0,0,D22/$D$24) -> 0.018826737
B23: Burden | C23: 147117.15 | D23: 148589.84 | E23: =C23-D23 -> -1472.69 | F23: =IF(C23=0,0,D23/C23) -> 1.0100103 | G23: =IF($D$24=0,0,D23/$D$24) -> 0.17551336
B24: TOTAL | C24: =SUM(C20:C23) -> 1047758.2 | D24: =SUM(D20:D23) -> 846601.32 | E24: =C24-D24 -> 201156.83 | F24: =IF(C24=0,0,D24/C24) -> 0.80801215 | G24: 1
B27: PROJECT PROFILE
B28: Metric | C28: Value | D28: Metric | E28: Value | F28: Metric | G28: Value
B29: Plumbing Units | C29: 163 | D29: Water Closets | E29: 163 | F29: Lavatories | G29: 163
B30: Kitchen Sinks | C30: 163 | D30: Dishwashers | E30: 163 | F30: Laundry Washers | G30: 163
B31: Bathtub/Shower | C31: 163 | D31: Floor Drains | E31: 5 | F31: Roof Drains | G31: 18
B32: Total Fixtures | C32: 1004 | D32: Fixtures / Unit | E32: 6.16 | F32: Floors | G32: 9 stories + retail
B33: Duration | C33: 17 mo
B36: SOURCES
B37: Job #2012 — Exxel Pacific 8th Ave Apartments • GC: Exxel Pacific, Inc. • 4545 8th Ave NE, Seattle
B38: Canonical source: 2012 Job Detail Report.pdf (135 pages, OWP Sage Timberline export)
B39: Cost codes parsed: 30
B40: Unit count (163) confirmed by plumbing permit SR1335240
B41: Fixture count (1004) from permit detail: 163 WC + 163 lav + 163 shower + 163 sink + 163 DW + 163 washer + 5 floor drains + 18 roof drains + 1 indirect + 2 sump/ejector
B42: Contract: One Way Plumbing contract executed (Exxel Pacific GC) with OWP markup
B43: Billing: 8th AGGREGATE BILLING.xlsx (15 pay apps Mar 2013 – Jul 2014) + 15 SOV files
B44: Final contract $1,391,455 (original $1,394,655 + $-3,200 COs)

Sheet Budget vs Actual
B2: Budget vs Actual — All Cost Codes
B4: Code | C4: Description | D4: Orig Budget | E4: Rev Budget | F4: Actual | G4: Variance | H4: % Used
B5: LABOR
B6: 011 | C6: DS & RD Labor | D6: 12500 | E6: 12500 | F6: 3752.5 | G6: =E6-F6 -> 8747.5 | H6: =IF(E6=0,0,F6/E6) -> 0.3002
B7: 100 | C7: Supervision | D7: 8100 | E7: 8100 | F7: 6023 | G7: =E7-F7 -> 2077 | H7: =IF(E7=0,0,F7/E7) -> 0.74358025
B8: 101 | C8: Takeoff & Purchase Labor | D8: 12150 | E8: 12150 | F8: 6161.5 | G8: =E8-F8 -> 5988.5 | H8: =IF(E8=0,0,F8/E8) -> 0.50711934
B9: 110 | C9: Underground Labor | D9: 5800 | E9: 5800 | F9: 3184.25 | G9: =E9-F9 -> 2615.75 | H9: =IF(E9=0,0,F9/E9) -> 0.54900862
B10: 111 | C10: Garage Labor | D10: 14600 | E10: 14600 | F10: 19353.5 | G10: =E10-F10 -> -4753.5 | H10: =IF(E10=0,0,F10/E10) -> 1.3255822
B11: 112 | C11: Canout Labor | D11: 11700 | E11: 11700 | F11: 5424 | G11: =E11-F11 -> 6276 | H11: =IF(E11=0,0,F11/E11) -> 0.46358974
B12: 113 | C12: Foundation Drain Labor | D12: 2700 | E12: 2700 | F12: 984 | G12: =E12-F12 -> 1716 | H12: =IF(E12=0,0,F12/E12) -> 0.36444444
B13: 120 | C13: Roughin Labor | D13: 139800 | E13: 139800 | F13: 177291.75 | G13: =E13-F13 -> -37491.75 | H13: =IF(E13=0,0,F13/E13) -> 1.2681813
B14: 130 | C14: Finish Labor | D14: 31000 | E14: 31000 | F14: 34658.38 | G14: =E14-F14 -> -3658.38 | H14: =IF(E14=0,0,F14/E14) -> 1.1180123
B15: 140 | C15: Gas Labor | D15: 3300 | E15: 3300 | F15: 2168 | G15: =E15-F15 -> 1132 | H15: =IF(E15=0,0,F15/E15) -> 0.6569697
B16: 141 | C16: Water Main/Insulation Lab | D16: 41000 | E16: 41000 | F16: 15756 | G16: =E16-F16 -> 25244 | H16: =IF(E16=0,0,F16/E16) -> 0.38429268
B17: 142 | C17: Mech Room Labor | D17: 3525 | E17: 3525 | F17: 9784 | G17: =E17-F17 -> -6259 | H17: =IF(E17=0,0,F17/E17) -> 2.7756028
B18: 145 | C18: Tub/Shower Labor | D18: 19800 | E18: 19800 | F18: 6781 | G18: =E18-F18 -> 13019 | H18: =IF(E18=0,0,F18/E18) -> 0.34247475
B19: MATERIAL
B20: 039 | C20: DS & RD Material | D20: 17900 | E20: 17900 | F20: 5066.8 | G20: =E20-F20 -> 12833.2 | H20: =IF(E20=0,0,F20/E20) -> 0.28306145
B21: 210 | C21: Underground Material | D21: 4300 | E21: 4300 | F21: 1635.51 | G21: =E21-F21 -> 2664.49 | H21: =IF(E21=0,0,F21/E21) -> 0.38035116
B22: 211 | C22: Garage Material | D22: 11970 | E22: 11970 | F22: 6599.03 | G22: =E22-F22 -> 5370.97 | H22: =IF(E22=0,0,F22/E22) -> 0.55129741
B23: 212 | C23: Canout Material | D23: 13130 | E23: 13130 | F23: 8579.19 | G23: =E23-F23 -> 4550.81 | H23: =IF(E23=0,0,F23/E23) -> 0.65340366
B24: 213 | C24: Foundation Material | D24: 2700 | E24: 2700 | F24: 1789.12 | G24: =E24-F24 -> 910.88 | H24: =IF(E24=0,0,F24/E24) -> 0.66263704
B25: 220 | C25: Roughin Material | D25: 161200 | E25: 161200 | F25: 94000.7 | G25: =E25-F25 -> 67199.3 | H25: =IF(E25=0,0,F25/E25) -> 0.58313089
B26: 230 | C26: Finish Material | D26: 261600 | E26: 269866 | F26: 210145.22 | G26: =E26-F26 -> 59720.78 | H26: =IF(E26=0,0,F26/E26) -> 0.7787021
B27: 240 | C27: Gas Material | D27: 3000 | E27: 3000 | F27: 996.32 | G27: =E27-F27 -> 2003.68 | H27: =IF(E27=0,0,F27/E27) -> 0.33210667
B28: 241 | C28: Water Main/Insulation Mat | D28: 65600 | E28: 65600 | F28: 36964.67 | G28: =E28-F28 -> 28635.33 | H28: =IF(E28=0,0,F28/E28) -> 0.56348582
B29: 242 | C29: Mech Room Material | D29: 12000 | E29: 12000 | F29: 22695.31 | G29: =E29-F29 -> -10695.31 | H29: =IF(E29=0,0,F29/E29) -> 1.8912758
B30: 245 | C30: Tub/Shower Material | D30: 0 | E30: 0 | F30: 2278.99 | G30: =E30-F30 -> -2278.99 | H30: =IF(E30=0,0,F30/E30) -> 0
B31: OVERHEAD
B32: 600 | C32: Subcontractor | D32: 1000 | E32: 1000 | F32: 186 | G32: =E32-F32 -> 814 | H32: =IF(E32=0,0,F32/E32) -> 0.186
B33: 601 | C33: Engineering/Plans | D33: 22000 | E33: 22000 | F33: 15682.03 | G33: =E33-F33 -> 6317.97 | H33: =IF(E33=0,0,F33/E33) -> 0.71281955
B34: 603 | C34: Permits & Licenses | D34: 25600 | E34: 10000 | F34: 70.71 | G34: =E34-F34 -> 9929.29 | H34: =IF(E34=0,0,F34/E34) -> 0.007071
B35: BURDEN
B36: 995 | C36: Payroll Burden | D36: 125049.58 | E36: 125049.58 | F36: 126300.46 | G36: =E36-F36 -> -1250.88 | H36: =IF(E36=0,0,F36/E36) -> 1.0100031
B37: 998 | C37: Payroll Taxes | D37: 22067.57 | E37: 22067.57 | F37: 22289.38 | G37: =E37-F37 -> -221.81 | H37: =IF(E37=0,0,F37/E37) -> 1.0100514
B38: TOTAL | C38: Direct Cost | D38: 1055092.1 | E38: 1047758.2 | F38: 846601.32 | G38: =E38-F38 -> 201156.83 | H38: =IF(E38=0,0,F38/E38) -> 0.80801215
B41: SOURCES
B42: Job #2012 — Exxel Pacific 8th Ave Apartments • GC: Exxel Pacific, Inc. • 4545 8th Ave NE, Seattle
B43: Canonical source: 2012 Job Detail Report.pdf (135 pages, OWP Sage Timberline export)
B44: Cost codes parsed: 30
...

Sheet Cost Breakdown
B2: Cost Breakdown — Category Deep Dive
B4: A. CATEGORY SHARE OF DIRECT COST
B5: Category | C5: # Codes | D5: Budget | E5: Actual | F5: Variance | G5: % Budget | H5: % of Cost | I5: Per Unit
B6: Labor | C6: 13 | D6: 305975 | E6: 291321.88 | F6: =D6-E6 -> 14653.12 | G6: =IF(D6=0,0,E6/D6) -> 0.95211007 | H6: =IF(846601.32=0,0,E6/846601.32) -> 0.34410752 | I6: =IF(163=0,0,E6/163) -> 1787.2508
B7: Material | C7: 11 | D7: 561666 | E7: 390750.86 | F7: =D7-E7 -> 170915.14 | G7: =IF(D7=0,0,E7/D7) -> 0.69569969 | H7: =IF(846601.32=0,0,E7/846601.32) -> 0.46155239 | I7: =IF(163=0,0,E7/163) -> 2397.2445
B8: Overhead | C8: 3 | D8: 33000 | E8: 15938.74 | F8: =D8-E8 -> 17061.26 | G8: =IF(D8=0,0,E8/D8) -> 0.48299212 | H8: =IF(846601.32=0,0,E8/846601.32) -> 0.018826737 | I8: =IF(163=0,0,E8/163) -> 97.783681
B9: Burden | C9: 2 | D9: 147117.15 | E9: 148589.84 | F9: =D9-E9 -> -1472.69 | G9: =IF(D9=0,0,E9/D9) -> 1.0100103 | H9: =IF(846601.32=0,0,E9/846601.32) -> 0.17551336 | I9: =IF(163=0,0,E9/163) -> 911.59411
B12: B. LARGEST OVERRUNS (Actual > Revised Budget)
B13: Code | C13: Description | D13: Rev Budget | E13: Actual | F13: Overrun | G13: % Over
B14: 120 | C14: Roughin Labor | D14: 139800 | E14: 177291.75 | F14: =E14-D14 -> 37491.75 | G14: =IF(D14=0,0,F14/D14) -> 0.26818133
B15: 242 | C15: Mech Room Material | D15: 12000 | E15: 22695.31 | F15: =E15-D15 -> 10695.31 | G15: =IF(D15=0,0,F15/D15) -> 0.89127583
B16: 142 | C16: Mech Room Labor | D16: 3525 | E16: 9784 | F16: =E16-D16 -> 6259 | G16: =IF(D16=0,0,F16/D16) -> 1.7756028
B17: 111 | C17: Garage Labor | D17: 14600 | E17: 19353.5 | F17: =E17-D17 -> 4753.5 | G17: =IF(D17=0,0,F17/D17) -> 0.32558219
B18: 130 | C18: Finish Labor | D18: 31000 | E18: 34658.38 | F18: =E18-D18 -> 3658.38 | G18: =IF(D18=0,0,F18/D18) -> 0.11801226
B19: 245 | C19: Tub/Shower Material | D19: 0 | E19: 2278.99 | F19: =E19-D19 -> 2278.99 | G19: =IF(D19=0,0,F19/D19) -> 0
B20: 995 | C20: Payroll Burden | D20: 125049.58 | E20: 126300.46 | F20: =E20-D20 -> 1250.88 | G20: =IF(D20=0,0,F20/D20) -> 0.010003072
B21: 998 | C21: Payroll Taxes | D21: 22067.57 | E21: 22289.38 | F21: =E21-D21 -> 221.81 | G21: =IF(D21=0,0,F21/D21) -> 0.010051401
B24: C. LARGEST SAVINGS (Actual < Revised Budget)
B25: Code | C25: Description | D25: Rev Budget | E25: Actual | F25: Savings | G25: % Under
B26: 220 | C26: Roughin Material | D26: 161200 | E26: 94000.7 | F26: =D26-E26 -> 67199.3 | G26: =IF(D26=0,0,F26/D26) -> 0.41686911
B27: 230 | C27: Finish Material | D27: 269866 | E27: 210145.22 | F27: =D27-E27 -> 59720.78 | G27: =IF(D27=0,0,F27/D27) -> 0.2212979
B28: 241 | C28: Water Main/Insulation Mat | D28: 65600 | E28: 36964.67 | F28: =D28-E28 -> 28635.33 | G28: =IF(D28=0,0,F28/D28) -> 0.43651418
B29: 141 | C29: Water Main/Insulation Lab | D29: 41000 | E29: 15756 | F29: =D29-E29 -> 25244 | G29: =IF(D29=0,0,F29/D29) -> 0.61570732
B30: 145 | C30: Tub/Shower Labor | D30: 19800 | E30: 6781 | F30: =D30-E30 -> 13019 | G30: =IF(D30=0,0,F30/D30) -> 0.65752525
B31: 039 | C31: DS & RD Material | D31: 17900 | E31: 5066.8 | F31: =D31-E31 -> 12833.2 | G31: =IF(D31=0,0,F31/D31) -> 0.71693855
B32: 603 | C32: Permits & Licenses | D32: 10000 | E32: 70.71 | F32: =D32-E32 -> 9929.29 | G32: =IF(D32=0,0,F32/D32) -> 0.992929
B33: 011 | C33: DS & RD Labor | D33: 12500 | E33: 3752.5 | F33: =D33-E33 -> 8747.5 | G33: =IF(D33=0,0,F33/D33) -> 0.6998
B34: 601 | C34: Engineering/Plans | D34: 22000 | E34: 15682.03 | F34: =D34-E34 -> 6317.97 | G34: =IF(D34=0,0,F34/D34) -> 0.28718045
B35: 112 | C35: Canout Labor | D35: 11700 | E35: 5424 | F35: =D35-E35 -> 6276 | G35: =IF(D35=0,0,F35/D35) -> 0.53641026
B38: SOURCES
B39: Job #2012 — Exxel Pacific 8th Ave Apartments • GC: Exxel Pacific, Inc. • 4545 8th Ave NE, Seattle
B40: Canonical source: 2012 Job Detail Report.pdf (135 pages, OWP Sage Timberline export)
B41: Cost codes parsed: 30
B42: Unit count (163) confirmed by plumbing permit SR1335240
B43: Fixture count (1004) from permit detail: 163 WC + 163 lav + 163 shower + 163 sink + 163 DW + 163 washer + 5 floor drains + 18 roof drains + 1 indirect + 2 sump/ejector
B44: Contract: One Way Plumbing contract executed (Exxel Pacific GC) with OWP markup
B45: Billing: 8th AGGREGATE BILLING.xlsx (15 pay apps Mar 2013 – Jul 2014) + 15 SOV files
B46: Final contract $1,391,455 (original $1,394,655 + $-3,200 COs)

Sheet Material
B2: Material Spend Analysis
B3: 11 material cost codes • $390,751 JDR material • 16 AP vendors • $409,755 total AP
B5: A. MATERIAL BY COST CODE
B6: Code | C6: Description | D6: Rev Budget | E6: Actual | F6: Variance | G6: % Used | H6: % of Mat | I6: Per Unit
B7: 039 | C7: DS & RD Material | D7: 17900 | E7: 5066.8 | F7: =D7-E7 -> 12833.2 | G7: =IF(D7=0,0,E7/D7) -> 0.28306145 | H7: =IF(390750.86=0,0,E7/390750.86) -> 0.01296683 | I7: =IF(163=0,0,E7/163) -> 31.084663
B8: 210 | C8: Underground Material | D8: 4300 | E8: 1635.51 | F8: =D8-E8 -> 2664.49 | G8: =IF(D8=0,0,E8/D8) -> 0.38035116 | H8: =IF(390750.86=0,0,E8/390750.86) -> 0.004185557 | I8: =IF(163=0,0,E8/163) -> 10.033804
B9: 211 | C9: Garage Material | D9: 11970 | E9: 6599.03 | F9: =D9-E9 -> 5370.97 | G9: =IF(D9=0,0,E9/D9) -> 0.55129741 | H9: =IF(390750.86=0,0,E9/390750.86) -> 0.016888075 | I9: =IF(163=0,0,E9/163) -> 40.484847
B10: 212 | C10: Canout Material | D10: 13130 | E10: 8579.19 | F10: =D10-E10 -> 4550.81 | G10: =IF(D10=0,0,E10/D10) -> 0.65340366 | H10: =IF(390750.86=0,0,E10/390750.86) -> 0.021955652 | I10: =IF(163=0,0,E10/163) -> 52.633067
B11: 213 | C11: Foundation Material | D11: 2700 | E11: 1789.12 | F11: =D11-E11 -> 910.88 | G11: =IF(D11=0,0,E11/D11) -> 0.66263704 | H11: =IF(390750.86=0,0,E11/390750.86) -> 0.0045786719 | I11: =IF(163=0,0,E11/163) -> 10.976196
B12: 220 | C12: Roughin Material | D12: 161200 | E12: 94000.7 | F12: =D12-E12 -> 67199.3 | G12: =IF(D12=0,0,E12/D12) -> 0.58313089 | H12: =IF(390750.86=0,0,E12/390750.86) -> 0.24056428 | I12: =IF(163=0,0,E12/163) -> 576.69141
B13: 230 | C13: Finish Material | D13: 269866 | E13: 210145.22 | F13: =D13-E13 -> 59720.78 | G13: =IF(D13=0,0,E13/D13) -> 0.7787021 | H13: =IF(390750.86=0,0,E13/390750.86) -> 0.53779848 | I13: =IF(163=0,0,E13/163) -> 1289.2345
B14: 240 | C14: Gas Material | D14: 3000 | E14: 996.32 | F14: =D14-E14 -> 2003.68 | G14: =IF(D14=0,0,E14/D14) -> 0.33210667 | H14: =IF(390750.86=0,0,E14/390750.86) -> 0.0025497577 | I14: =IF(163=0,0,E14/163) -> 6.1123926
B15: 241 | C15: Water Main/Insulation Mat | D15: 65600 | E15: 36964.67 | F15: =D15-E15 -> 28635.33 | G15: =IF(D15=0,0,E15/D15) -> 0.56348582 | H15: =IF(390750.86=0,0,E15/390750.86) -> 0.094599075 | I15: =IF(163=0,0,E15/163) -> 226.77712
B16: 242 | C16: Mech Room Material | D16: 12000 | E16: 22695.31 | F16: =D16-E16 -> -10695.31 | G16: =IF(D16=0,0,E16/D16) -> 1.8912758 | H16: =IF(390750.86=0,0,E16/390750.86) -> 0.05808128 | I16: =IF(163=0,0,E16/163) -> 139.23503
B17: 245 | C17: Tub/Shower Material | D17: 0 | E17: 2278.99 | F17: =D17-E17 -> -2278.99 | G17: =IF(D17=0,0,E17/D17) -> 0 | H17: =IF(390750.86=0,0,E17/390750.86) -> 0.0058323352 | I17: =IF(163=0,0,E17/163) -> 13.981534
B18: TOTAL | C18: All Material | D18: =SUM(D7:D17) -> 561666 | E18: =SUM(E7:E17) -> 390750.86 | F18: =D18-E18 -> 170915.14 | G18: =IF(D18=0,0,E18/D18) -> 0.69569969 | H18: 1 | I18: =IF(163=0,0,E18/163) -> 2397.2445
B21: B. VENDORS BY SPEND (AP)
B22: Vendor | C22: # Invoices | D22: Total Spend | E22: % of AP | I22: Avg Invoice
B23: Keller Supply Company | C23: 45 | D23: 154464.12 | E23: =IF(409754.59=0,0,D23/409754.59) -> 0.37696739 | I23: =IF(C23=0,0,D23/C23) -> 3432.536
B24: Ferguson Enterprises, Inc. | C24: 41 | D24: 119072.08 | E24: =IF(409754.59=0,0,D24/409754.59) -> 0.29059365 | I24: =IF(C24=0,0,D24/C24) -> 2904.1971
B25: Mechanical Sales, Inc. | C25: 7 | D25: 58896.52 | E25: =IF(409754.59=0,0,D25/409754.59) -> 0.14373608 | I25: =IF(C25=0,0,D25/C25) -> 8413.7886
B26: Rosen Supply Company, Inc. | C26: 54 | D26: 39751.74 | E26: =IF(409754.59=0,0,D26/409754.59) -> 0.097013532 | I26: =IF(C26=0,0,D26/C26) -> 736.14333
B27: Franklin Engineering | C27: 4 | D27: 15612.75 | E27: =IF(409754.59=0,0,D27/409754.59) -> 0.038102685 | I27: =IF(C27=0,0,D27/C27) -> 3903.1875
B28: Bank of America CC | C28: 6 | D28: 9741.88 | E28: =IF(409754.59=0,0,D28/409754.59) -> 0.023774914 | I28: =IF(C28=0,0,D28/C28) -> 1623.6467
B29: Quality Concrete Products, Inc. | C29: 3 | D29: 5806 | E29: =IF(409754.59=0,0,D29/409754.59) -> 0.014169457 | I29: =IF(C29=0,0,D29/C29) -> 1935.3333
B30: Manor Hardware & Construction Supply | C30: 7 | D30: 1963.11 | E30: =IF(409754.59=0,0,D30/409754.59) -> 0.0047909408 | I30: =IF(C30=0,0,D30/C30) -> 280.44429
B31: Patchworks, Inc. | C31: 2 | D31: 1837.5 | E31: =IF(409754.59=0,0,D31/409754.59) -> 0.0044843915 | I31: =IF(C31=0,0,D31/C31) -> 918.75
B32: Capital One Credit Card | C32: 8 | D32: 1038.11 | E32: =IF(409754.59=0,0,D32/409754.59) -> 0.0025334921 | I32: =IF(C32=0,0,D32/C32) -> 129.76375
B33: Rosen Supply Kirkland | C33: 1 | D33: 973.75 | E33: =IF(409754.59=0,0,D33/409754.59) -> 0.0023764224 | I33: =IF(C33=0,0,D33/C33) -> 973.75
B34: Ferguson Enterprises, Inc. #3007 | C34: 2 | D34: 309.58 | E34: =IF(409754.59=0,0,D34/409754.59) -> 0.0007555254 | I34: =IF(C34=0,0,D34/C34) -> 154.79
... B38: C.M. Hoskins Company | C38: 1 | D38: 13.84 | E38: =IF(409754.59=0,0,D38/409754.59) -> 3.3776315e-05 | I38: =IF(C38=0,0,D38/C38) -> 13.84
B39: TOTAL | C39: =SUM(C23:C38) -> 186 | D39: =SUM(D23:D38) -> 409754.59 | E39: 1
B42: SOURCES
B43: Job #2012 — Exxel Pacific 8th Ave Apartments • GC: Exxel Pacific, Inc. • 4545 8th Ave NE, Seattle
B44: Canonical source: 2012 Job Detail Report.pdf (135 pages, OWP Sage Timberline export)
B45: Cost codes parsed: 30
B46: Unit count (163) confirmed by plumbing permit SR1335240
B47: Fixture count (1004) from permit detail: 163 WC + 163 lav + 163 shower + 163 sink + 163 DW + 163 washer + 5 floor drains + 18 roof drains + 1 indirect + 2 sump/ejector
B48: Contract: One Way Plumbing contract executed (Exxel Pacific GC) with OWP markup
B49: Billing: 8th AGGREGATE BILLING.xlsx (15 pay apps Mar 2013 – Jul 2014) + 15 SOV files
...

Sheet Crew & Labor
B2: Crew & Labor — Per-Worker Breakdown
B4: Worker | C4: Hours | D4: Gross Pay | E4: $/Hour | F4: Tier
B5: Quintanilla, Esteban R | C5: 1111 | D5: 34877 | E5: =IF(C5=0,0,D5/C5) -> 31.392439 | F5: Senior
B6: Gonzalez Hernandez, Josue | C6: 1001 | D6: 12924 | E6: =IF(C6=0,0,D6/C6) -> 12.911089 | F6: Apprentice
B7: Lima Romero, Melvin A | C7: 932 | D7: 18140 | E7: =IF(C7=0,0,D7/C7) -> 19.463519 | F7: Mid
B8: Palma Vides, Hugo | C8: 790 | D8: 21434 | E8: =IF(C8=0,0,D8/C8) -> 27.131646 | F8: Mid
B9: Castro Hernandez, Jose A | C9: 763 | D9: 11903 | E9: =IF(C9=0,0,D9/C9) -> 15.600262 | F9: Apprentice
B10: Rivera, Eli P | C10: 746 | D10: 9192 | E10: =IF(C10=0,0,D10/C10) -> 12.321716 | F10: Apprentice
B11: Chavarria Lopez, Omar A | C11: 738 | D11: 9104 | E11: =IF(C11=0,0,D11/C11) -> 12.336043 | F11: Apprentice
B12: Monico Brambila, Jesus S | C12: 660 | D12: 8620 | E12: =IF(C12=0,0,D12/C12) -> 13.060606 | F12: Apprentice
B13: Meza Fuentes, Erick A | C13: 575.5 | D13: 11510 | E13: =IF(C13=0,0,D13/C13) -> 20 | F13: Mid
B14: Rivera, Jorge A | C14: 501 | D14: 9018 | E14: =IF(C14=0,0,D14/C14) -> 18 | F14: Mid
B15: Paco Leyva, Orlando | C15: 450.5 | D15: 6319.25 | E15: =IF(C15=0,0,D15/C15) -> 14.027192 | F15: Apprentice
B16: Gerard, Jeffrey S | C16: 406 | D16: 14595 | E16: =IF(C16=0,0,D16/C16) -> 35.948276 | F16: Senior
... B44: Hubbard, Robert W | C44: 3.5 | D44: 115.5 | E44: =IF(C44=0,0,D44/C44) -> 33 | F44: Senior
B45: TOTAL (40 workers) | C45: =SUM(C5:C44) -> 13206.75 | D45: =SUM(D5:D44) -> 253469.13 | E45: =IF(C45=0,0,D45/C45) -> 19.192393
B48: SOURCES
B49: Job #2012 — Exxel Pacific 8th Ave Apartments • GC: Exxel Pacific, Inc. • 4545 8th Ave NE, Seattle
B50: Canonical source: 2012 Job Detail Report.pdf (135 pages, OWP Sage Timberline export)
B51: Cost codes parsed: 30
B52: Unit count (163) confirmed by plumbing permit SR1335240
B53: Fixture count (1004) from permit detail: 163 WC + 163 lav + 163 shower + 163 sink + 163 DW + 163 washer + 5 floor drains + 18 roof drains + 1 indirect + 2 sump/ejector
B54: Contract: One Way Plumbing contract executed (Exxel Pacific GC) with OWP markup
B55: Billing: 8th AGGREGATE BILLING.xlsx (15 pay apps Mar 2013 – Jul 2014) + 15 SOV files
B56: Final contract $1,391,455 (original $1,394,655 + $-3,200 COs)
B57: Tier: Apprentice <$18/hr, Mid $18–30, Senior >$30

Sheet Crew Analytics
B2: Crew Analytics
B4: A. TIER DISTRIBUTION
B5: Tier | C5: # Workers | D5: Hours | E5: Gross Pay | F5: % of Hours
B6: Senior | C6: 3 | D6: 1520.5 | E6: 49587.5 | F6: =IF(13206.75=0,0,D6/13206.75) -> 0.11513052
B7: Mid | C7: 13 | D7: 4643 | E7: 109928.5 | F7: =IF(13206.75=0,0,D7/13206.75) -> 0.35156265
B8: Apprentice | C8: 24 | D8: 7043.25 | E8: 93953.13 | F8: =IF(13206.75=0,0,D8/13206.75) -> 0.53330683
B11: B. WAGE STATISTICS
B12: Blended Gross Wage | C12: 19.192393 | F12: Payroll $ ÷ payroll hours (pre-burden)
B13: Fully-Loaded Wage | C13: 33.309612 | F13: (Labor + Burden) ÷ total hours
B14: Burden Multiplier | C14: 1.7355633 | F14: Fully loaded ÷ gross wage
B15: Min Worker Rate | C15: 12 | F15: Cheapest apprentice hour
B16: Max Worker Rate | C16: 35.948276 | F16: Most expensive foreman hour
B17: Avg Hours / Worker | C17: 330.16875 | F17: Crew continuity indicator
B20: SOURCES
B21: Job #2012 — Exxel Pacific 8th Ave Apartments • GC: Exxel Pacific, Inc. • 4545 8th Ave NE, Seattle
B22: Canonical source: 2012 Job Detail Report.pdf (135 pages, OWP Sage Timberline export)
B23: Cost codes parsed: 30
B24: Unit count (163) confirmed by plumbing permit SR1335240
B25: Fixture count (1004) from permit detail: 163 WC + 163 lav + 163 shower + 163 sink + 163 DW + 163 washer + 5 floor drains + 18 roof drains + 1 indirect + 2 sump/ejector
B26: Contract: One Way Plumbing contract executed (Exxel Pacific GC) with OWP markup
B27: Billing: 8th AGGREGATE BILLING.xlsx (15 pay apps Mar 2013 – Jul 2014) + 15 SOV files
B28: Final contract $1,391,455 (original $1,394,655 + $-3,200 COs)

Sheet Productivity
B2: Productivity — Phase & Unit Metrics
B4: A. LABOR HOURS BY PHASE
B5: Phase | C5: Labor Code | D5: Hours | E5: % of Total | F5: Hours / Unit
B6: DS & RD | C6: 011 | D6: 183 | E6: =IF(14607.25=0,0,D6/14607.25) -> 0.012528025 | F6: =IF(163=0,0,D6/163) -> 1.1226994
B7: Supervision | C7: 100 | D7: 165 | E7: =IF(14607.25=0,0,D7/14607.25) -> 0.011295761 | F7: =IF(163=0,0,D7/163) -> 1.0122699
B8: Takeoff & Purchasing | C8: 101 | D8: 172.5 | E8: =IF(14607.25=0,0,D8/14607.25) -> 0.011809204 | F8: =IF(163=0,0,D8/163) -> 1.0582822
B9: Underground | C9: 110 | D9: 145.5 | E9: =IF(14607.25=0,0,D9/14607.25) -> 0.0099608071 | F9: =IF(163=0,0,D9/163) -> 0.89263804
B10: Garage | C10: 111 | D10: 872 | E10: =IF(14607.25=0,0,D10/14607.25) -> 0.059696384 | F10: =IF(163=0,0,D10/163) -> 5.3496933
B11: Canout | C11: 112 | D11: 238 | E11: =IF(14607.25=0,0,D11/14607.25) -> 0.016293279 | F11: =IF(163=0,0,D11/163) -> 1.4601227
B12: Foundation Drain | C12: 113 | D12: 50 | E12: =IF(14607.25=0,0,D12/14607.25) -> 0.0034229578 | F12: =IF(163=0,0,D12/163) -> 0.30674847
B13: Roughin | C13: 120 | D13: 9319.5 | E13: =IF(14607.25=0,0,D13/14607.25) -> 0.6380051 | F13: =IF(163=0,0,D13/163) -> 57.174847
B14: Finish | C14: 130 | D14: 1840.75 | E14: =IF(14607.25=0,0,D14/14607.25) -> 0.12601619 | F14: =IF(163=0,0,D14/163) -> 11.292945
B15: Gas | C15: 140 | D15: 104 | E15: =IF(14607.25=0,0,D15/14607.25) -> 0.0071197522 | F15: =IF(163=0,0,D15/163) -> 0.63803681
B16: Water Main / Insulation | C16: 141 | D16: 800 | E16: =IF(14607.25=0,0,D16/14607.25) -> 0.054767324 | F16: =IF(163=0,0,D16/163) -> 4.9079755
B17: Mech Room | C17: 142 | D17: 379 | E17: =IF(14607.25=0,0,D17/14607.25) -> 0.02594602 | F17: =IF(163=0,0,D17/163) -> 2.3251534
B18: Tub / Shower | C18: 145 | D18: 338 | E18: =IF(14607.25=0,0,D18/14607.25) -> 0.023139195 | F18: =IF(163=0,0,D18/163) -> 2.0736196
B19: TOTAL | D19: =SUM(D6:D18) -> 14607.25 | E19: 1 | F19: =IF(163=0,0,D19/163) -> 89.615031
B22: B. PRODUCTIVITY RATIOS
B23: Metric | C23: Value | D23: Units | F23: Notes
B24: Hours / Unit | C24: 89.615031 | D24: hrs | F24: Labor hours per residential unit
B25: Hours / Fixture | C25: 14.549054 | D25: hrs | F25: Labor hours per plumbing fixture
B26: Revenue / Hour | C26: 95.257834 | D26: $ | F26: Top-line per labor hour
B27: Profit / Hour | C27: 37.300223 | D27: $ | F27: Bottom-line per labor hour
B28: Units / Month | C28: 9.5882353 | D28: units | F28: Build velocity
B29: Fixtures / Month | C29: 59.058824 | D29: fix | F29: Fixture install pace
B30: Hours / Month | C30: 859.25 | D30: hrs | F30: Monthly labor burn
B31: Revenue / Month | C31: 81850.294 | D31: $ | F31: Monthly billing rate
B34: SOURCES
B35: Job #2012 — Exxel Pacific 8th Ave Apartments • GC: Exxel Pacific, Inc. • 4545 8th Ave NE, Seattle
B36: Canonical source: 2012 Job Detail Report.pdf (135 pages, OWP Sage Timberline export)
B37: Cost codes parsed: 30
B38: Unit count (163) confirmed by plumbing permit SR1335240
B39: Fixture count (1004) from permit detail: 163 WC + 163 lav + 163 shower + 163 sink + 163 DW + 163 washer + 5 floor drains + 18 roof drains + 1 indirect + 2 sump/ejector
B40: Contract: One Way Plumbing contract executed (Exxel Pacific GC) with OWP markup
B41: Billing: 8th AGGREGATE BILLING.xlsx (15 pay apps Mar 2013 – Jul 2014) + 15 SOV files
B42: Final contract $1,391,455 (original $1,394,655 + $-3,200 COs)

Sheet PO Commitments
B2: Purchase Order Commitments
B3: 68 unique POs • PO amounts not dollar-parsed from individual PDFs • JDR material $390,751
B5: A. COMMITMENTS BY COST CODE
B6: OWP Code | C6: Description → JDR | D6: PO Count | E6: % of POs | F6: JDR Material
B7: 30 | C7: 110+210 Underground | D7: 13 | E7: =IF(68=0,0,D7/68) -> 0.19117647
B8: 31 | C8: 120+220 Roughin | D8: 14 | E8: =IF(68=0,0,D8/68) -> 0.20588235
B9: 32 | C9: 130+230 Trim/Finish | D9: 7 | E9: =IF(68=0,0,D9/68) -> 0.10294118
B10: 34 | C10: 111+211 Garage | D10: 1 | E10: =IF(68=0,0,D10/68) -> 0.014705882
B11: 40 | C11: 141+241 Water Main/Ins | D11: 4 | E11: =IF(68=0,0,D11/68) -> 0.058823529
B12: 41 | C12: 140+240 Gas | D12: 1 | E12: =IF(68=0,0,D12/68) -> 0.014705882
B13: OTHER | C13: Unclassified | D13: 28 | E13: =IF(68=0,0,D13/68) -> 0.41176471
B14: TOTAL | D14: =SUM(D7:D13) -> 68 | E14: 1 | F14: 390750.86
B17: B. COMMITMENTS BY VENDOR
B18: Vendor | C18: PO Count | D18: % of POs
B19: OTHER | C19: 54 | D19: =IF(68=0,0,C19/68) -> 0.79411765
B20: ROSEN | C20: 8 | D20: =IF(68=0,0,C20/68) -> 0.11764706
B21: MANOR | C21: 2 | D21: =IF(68=0,0,C21/68) -> 0.029411765
B22: MECH SALES | C22: 2 | D22: =IF(68=0,0,C22/68) -> 0.029411765
B23: KELLER | C23: 1 | D23: =IF(68=0,0,C23/68) -> 0.014705882
B24: SIOUX CHIEF | C24: 1 | D24: =IF(68=0,0,C24/68) -> 0.014705882
B27: C. PO COVERAGE NOTES
B28: Total Material Actual (JDR) | E28: 390750.86
B29: Unique PO Count | E29: 68
B30: (Dollar PO commitment not extracted — requires per-PDF parse)
B33: SOURCES
B34: Job #2012 — Exxel Pacific 8th Ave Apartments • GC: Exxel Pacific, Inc. • 4545 8th Ave NE, Seattle
B35: Canonical source: 2012 Job Detail Report.pdf (135 pages, OWP Sage Timberline export)
B36: Cost codes parsed: 30
B37: Unit count (163) confirmed by plumbing permit SR1335240
B38: Fixture count (1004) from permit detail: 163 WC + 163 lav + 163 shower + 163 sink + 163 DW + 163 washer + 5 floor drains + 18 roof drains + 1 indirect + 2 sump/ejector
B39: Contract: One Way Plumbing contract executed (Exxel Pacific GC) with OWP markup
B40: Billing: 8th AGGREGATE BILLING.xlsx (15 pay apps Mar 2013 – Jul 2014) + 15 SOV files
B41: Final contract $1,391,455 (original $1,394,655 + $-3,200 COs)
B42: PO count is deduplicated by 5-digit PO number extracted from filenames
B43: Vendor/code classification is heuristic (filename keyword match)

Sheet Billing & SOV
B2: Revenue & Billing Reconciliation
B3: 15 pay applications • Mar 2013 – Jul 2014 • $1,391,455 final
B5: A. CONTRACT SUMMARY
B6: Original Contract | G6: 1394655
B7: Change Orders (net) | G7: -3200
B8: Final Contract Value | G8: 1391455
B9: Retainage (5%) | G9: 69573
B10: Net Paid to OWP | G10: 1321882
B12: B. PAY APPLICATION TIMELINE
B13: App# | C13: Date | D13: Period Billing | E13: Retention | F13: Net This Period | G13: Aggregate | H13: % Complete
B14: 1 | C14: 2013-03-19 | D14: 48000 | E14: 2400 | F14: =D14-E14 -> 45600 | G14: 45600 | H14: =IF(1391455=0,0,G14/1391455) -> 0.032771451
B15: 2 | C15: 2013-04-18 | D15: 41000 | E15: 2050 | F15: =D15-E15 -> 38950 | G15: 84550 | H15: =IF(1391455=0,0,G15/1391455) -> 0.060763733
B16: 3 | C16: 2013-05-20 | D16: 16200 | E16: 810 | F16: =D16-E16 -> 15390 | G16: 99940 | H16: =IF(1391455=0,0,G16/1391455) -> 0.071824098
B17: 4 | C17: 2013-06-20 | D17: 15900 | E17: 795 | F17: =D17-E17 -> 15105 | G17: 115045 | H17: =IF(1391455=0,0,G17/1391455) -> 0.082679641
B18: 5 | C18: 2013-07-20 | D18: 25900 | E18: 1295 | F18: =D18-E18 -> 24605 | G18: 139650 | H18: =IF(1391455=0,0,G18/1391455) -> 0.10036257
B19: 6 | C19: 2013-08-20 | D19: 92000 | E19: 4600 | F19: =D19-E19 -> 87400 | G19: 227050 | H19: =IF(1391455=0,0,G19/1391455) -> 0.16317452
B20: 7 | C20: 2013-09-20 | D20: 213605 | E20: 10680.25 | F20: =D20-E20 -> 202924.75 | G20: 429974.75 | H20: =IF(1391455=0,0,G20/1391455) -> 0.30901089
B21: 8 | C21: 2013-10-17 | D21: 440000 | E21: 22000 | F21: =D21-E21 -> 418000 | G21: 847974.75 | H21: =IF(1391455=0,0,G21/1391455) -> 0.60941586
B22: 9 | C22: 2013-11-19 | D22: 228490 | E22: 11424.5 | F22: =D22-E22 -> 217065.5 | G22: 1065040.2 | H22: =IF(1391455=0,0,G22/1391455) -> 0.7654148
B23: 10 | C23: 2013-12-12 | D23: 60560 | E23: 3028 | F23: =D23-E23 -> 57532 | G23: 1122572.2 | H23: =IF(1391455=0,0,G23/1391455) -> 0.80676145
B24: 11 | C24: 2014-01-20 | D24: 106583 | E24: 5329.15 | F24: =D24-E24 -> 101253.85 | G24: 1223826.1 | H24: =IF(1391455=0,0,G24/1391455) -> 0.87952977
B25: 12 | C25: 2014-02-20 | D25: 48805 | E25: 2440.25 | F25: =D25-E25 -> 46364.75 | G25: 1270190.9 | H25: =IF(1391455=0,0,G25/1391455) -> 0.91285083
... B28: 15 | C28: 2014-07-17 | D28: 1861 | E28: 0 | F28: =D28-E28 -> 1861 | G28: 1323743.2 | H28: =IF(1391455=0,0,G28/1391455) -> 0.95133745
B30: C. BILLING ↔ JDR TIE-OUT
B31: Metric | C31: SOV | D31: JDR | E31: Δ | F31: Status
B32: Final Contract Value | C32: 1391455 | D32: 1391455 | E32: =C32-D32 -> 0 | F32: =IF(ABS(E32)<=1,"TIES",IF(ABS(E32)<=ABS(D32)*0.05,"WITHIN","OFF")) -> TIES
B33: Retainage | C33: 69573 | D33: 69573 | E33: =C33-D33 -> 0 | F33: =IF(ABS(E33)<=1,"TIES",IF(ABS(E33)<=ABS(D33)*0.05,"WITHIN","OFF")) -> TIES
B34: Direct Cost | C34: 846601 | D34: 846601 | E34: =C34-D34 -> 0 | F34: =IF(ABS(E34)<=1,"TIES",IF(ABS(E34)<=ABS(D34)*0.05,"WITHIN","OFF")) -> TIES
B38: SOURCES
B39: Job #2012 — Exxel Pacific 8th Ave Apartments • GC: Exxel Pacific, Inc. • 4545 8th Ave NE, Seattle
B40: Canonical source: 2012 Job Detail Report.pdf (135 pages, OWP Sage Timberline export)
B41: Cost codes parsed: 30
B42: Unit count (163) confirmed by plumbing permit SR1335240
B43: Fixture count (1004) from permit detail: 163 WC + 163 lav + 163 shower + 163 sink + 163 DW + 163 washer + 5 floor drains + 18 roof drains + 1 indirect + 2 sump/ejector
B44: Contract: One Way Plumbing contract executed (Exxel Pacific GC) with OWP markup
B45: Billing: 8th AGGREGATE BILLING.xlsx (15 pay apps Mar 2013 – Jul 2014) + 15 SOV files
B46: Final contract $1,391,455 (original $1,394,655 + $-3,200 COs)

Sheet Insights
B2: Key Insights — Job #2012 Exxel Pacific 8th Ave Apartments
B3: Narrative observations distilled from the full JDR analysis
B5: MARGIN PROFILE | C5: Net profit of $544,854 on $1,391,455 revenue = 39.2% gross margin. Direct cost $846,601 absorbs 60.8% of revenue.
B6: VENDOR CONCENTRATION | C6: Keller Supply Company alone = $154,464 (38% of all AP) across 45 invoices. Total 16 AP vendors, $409,755 total AP spend.
B7: CREW PROFILE | C7: 40 workers for 14,607 hours = 365 avg hrs/worker. Top 3 workers logged 3,044 hrs combined (21% of all labor).
B8: ROUGHIN DOMINANCE | C8: Code 120 Roughin Labor = 9,320 hrs (64% of all labor) and $177,292 actual. Code 230 Finish Material = $210,145 — 25% of total direct cost.
B9: BUDGET DELIVERY | C9: Revised budget was $1,047,758; actual direct cost $846,601 → $201,157 variance (19.2% under revised budget).
B10: CONTRACT GROWTH | C10: Contract grew from $1,394,655 to $1,391,455 — net +$-3,200 (-0.2%). Retainage of $69,573 (5%) withheld until closeout.
B11: BURDEN RATIO | C11: Burden codes 995 + 998 = $148,590 on $291,322 labor base = 51.0%. In line with OWP's typical 48–50% labor burden.
B12: PROJECT SCALE | C12: 163 units · 1004 fixtures · 17 months. Revenue/unit $8,537, hours/unit 89.6, profit/unit $3,343.
B13: PRODUCTIVITY | C13: Blended labor rate $19.94/hr. Revenue/hour $95. Profit/hour $37. 859 hrs/month burn rate.
B14: FIXTURE DENSITY | C14: 1004 fixtures ÷ 163 units = 6.16 fixtures/unit. Material/fixture $389, labor/fixture $290.
B16: BIGGEST QUESTION
B17: How does this job's 39.2% margin compare across similar projects in the OWP portfolio, and what operational levers drove the result — estimating accuracy, vendor pricing, or labor productivity?
B20: SOURCES
B21: Job #2012 — Exxel Pacific 8th Ave Apartments • GC: Exxel Pacific, Inc. • 4545 8th Ave NE, Seattle
B22: Canonical source: 2012 Job Detail Report.pdf (135 pages, OWP Sage Timberline export)
B23: Cost codes parsed: 30
B24: Unit count (163) confirmed by plumbing permit SR1335240
B25: Fixture count (1004) from permit detail: 163 WC + 163 lav + 163 shower + 163 sink + 163 DW + 163 washer + 5 floor drains + 18 roof drains + 1 indirect + 2 sump/ejector
B26: Contract: One Way Plumbing contract executed (Exxel Pacific GC) with OWP markup
B27: Billing: 8th AGGREGATE BILLING.xlsx (15 pay apps Mar 2013 – Jul 2014) + 15 SOV files
B28: Final contract $1,391,455 (original $1,394,655 + $-3,200 COs)

Sheet Benchmark KPIs
B2: Benchmark KPIs
B3: Normalized metrics designed for apples-to-apples comparison across all OWP projects
B5: KPI | C5: Data Name | D5: Value | E5: Category | F5: Notes | G5: Confidence | H5: Source Document
B6: Job Number | C6: job_number | D6: 2012 | E6: Profile | F6: OWP job ID | G6: Verified | H6: 2012 Job Detail Report.pdf header
B7: Job Name | C7: job_name | D7: Exxel Pacific 8th Ave Apartments | E7: Profile | G7: Verified | H7: Contract folder
B8: General Contractor | C8: general_contractor | D8: Exxel Pacific, Inc. | E8: Profile | G8: Verified | H8: Contract folder
B9: Location | C9: location | D9: Seattle, WA (4545 8th Ave NE) | E9: Profile | G9: Verified | H9: Contract + Plans folder
B10: Project Type | C10: project_type | D10: 163-unit 9-story multifamily apartments + ground-floor retail | E10: Profile | G10: Verified | H10: Permit + Plans
B11: Duration (months) | C11: duration_months | D11: 17 | E11: Profile | F11: Mar 2013 – Jul 2014 (~17 months) | G11: Verified | H11: First to last invoice date
B12: Unit Count | C12: unit_count | D12: 163 | E12: Profile | G12: Verified | H12: Plumbing permit SR1335240 + P-tag list
B13: Total Fixtures | C13: total_fixtures | D13: 1004 | E13: Profile | G13: Verified | H13: Permit: 163 × 5 fixture types + drains/sumps
B14: Fixtures per Unit | C14: fixtures_per_unit | D14: 6.1595092 | E14: Profile | G14: Verified | H14: Derived: total_fixtures / unit_count
B15: Contract Value (Orig) | C15: contract_original | D15: 1394655 | E15: Financial | G15: Verified | H15: Contract SOV
B16: Contract Value (Final) | C16: contract_final | D16: 1391455 | E16: Financial | F16: After change orders | G16: Verified | H16: Final billing SOV
B17: Change Orders ($) | C17: change_orders | D17: -3200 | E17: Financial | G17: Verified | H17: JDR revised - original
B18: Revenue | C18: revenue | D18: 1391455 | E18: Financial | G18: Verified | H18: Aggregate billing final
B19: Net Profit | C19: net_profit | D19: 544853.68 | E19: Financial | G19: Verified | H19: Revenue - Direct Cost
B20: Gross Margin | C20: gross_margin | D20: 0.39157118 | E20: Financial | G20: Verified | H20: Derived: Profit / Revenue
B21: Direct Cost | C21: direct_cost | D21: 846601.32 | E21: Financial | G21: Verified | H21: JDR cost codes L+M+OH+Burden
B22: Labor Cost | C22: labor_cost | D22: 291321.88 | E22: Labor | F22: Sum of 13 labor codes | G22: Verified | H22: JDR labor cost codes
B23: Material Cost | C23: material_cost | D23: 390750.86 | E23: Material | F23: Sum of 11 material codes | G23: Verified | H23: JDR material cost codes
B24: Overhead Cost | C24: overhead_cost | D24: 15938.74 | E24: Financial | F24: Sub+Eng+Permits | G24: Verified | H24: JDR overhead cost codes
B25: Burden Cost | C25: burden_cost | D25: 148589.84 | E25: Financial | F25: Codes 995+998 | G25: Verified | H25: JDR burden cost codes (995+998)
B26: Retainage | C26: retainage | D26: 69572.75 | E26: Financial | F26: 5% withheld | G26: Verified | H26: Aggregate billing row 3
B27: Revenue per Unit | C27: revenue_per_unit | D27: 8536.5337 | E27: Financial | G27: Verified | H27: Derived: revenue / unit_count
B28: Profit per Unit | C28: profit_per_unit | D28: 3342.6606 | E28: Financial | G28: Verified | H28: Derived: net_profit / unit_count
B29: Direct Cost per Unit | C29: cost_per_unit | D29: 5193.8731 | E29: Financial | G29: Verified | H29: Derived: direct_cost / unit_count
B30: Labor Cost per Unit | C30: labor_per_unit | D30: 1787.2508 | E30: Labor | G30: Verified | H30: Derived: labor_cost / unit_count
B31: Material Cost per Unit | C31: material_per_unit | D31: 2397.2445 | E31: Material | G31: Verified | H31: Derived: material_cost / unit_count
B32: Revenue per Fixture | C32: revenue_per_fixture | D32: 1385.9114 | E32: Financial | G32: Verified | H32: Derived: revenue / total_fixtures
B33: Profit per Fixture | C33: profit_per_fixture | D33: 542.68295 | E33: Financial | G33: Verified | H33: Derived: net_profit / total_fixtures
B34: Cost per Fixture | C34: cost_per_fixture | D34: 843.22841 | E34: Financial | G34: Verified | H34: Derived: direct_cost / total_fixtures
B35: Labor per Fixture | C35: labor_per_fixture | D35: 290.16124 | E35: Labor | G35: Verified | H35: Derived: labor_cost / total_fixtures
B36: Material per Fixture | C36: material_per_fixture | D36: 389.19408 | E36: Material | G36: Verified | H36: Derived: material_cost / total_fixtures
B37: Total Labor Hours | C37: total_hours | D37: 14607.25 | E37: Labor | F37: Sum of JDR cost code hours | G37: Verified | H37: JDR payroll hours sum
B38: Total Workers | C38: total_workers | D38: 40 | E38: Labor | F38: Unique payroll IDs | G38: Verified | H38: JDR unique payroll IDs
B39: Blended Gross Wage | C39: blended_gross_wage | D39: 17.352283 | E39: Labor | F39: Pre-burden | G39: Verified | H39: Derived: labor_cost / total_hours
B40: Fully-Loaded Wage | C40: fully_loaded_wage | D40: 30.115985 | E40: Labor | F40: Post-burden | G40: Verified | H40: Derived: (labor+burden) / total_hours
B41: Burden Multiplier | C41: burden_multiplier | D41: 1.7355633 | E41: Labor | G41: Verified | H41: Derived: fully_loaded / blended
B42: Hours per Unit | C42: hours_per_unit | D42: 89.615031 | E42: Labor | F42: Key benchmark | G42: Verified | H42: Derived: total_hours / unit_count
...

Sheet Vendors
A1: Vendor Detail — Job #2012
A3: Vendors | B3: 16 | D3: Top vendor | E3: Keller Supply Company
A4: Invoices | B4: 186 | D4: Top 3 share | E4: =332432.72/409754.59 -> 0.81129712
A5: Total AP | B5: 409754.59 | D5: Source | E5: Job Detail Report (Sage Timberline AP export)
A6: Avg Inv | B6: =B5/B4 -> 2202.9817
A8: Rank | B8: Vendor | C8: Vendor Code | D8: Invoices | E8: Total Spend | F8: % of AP | G8: Avg / Invoice
A9: 1 | B9: Keller Supply Company | D9: 45 | E9: 154464.12 | F9: =E9/E$25 -> 0.37696739 | G9: =IF(D9=0,0,E9/D9) -> 3432.536
A10: 2 | B10: Ferguson Enterprises, Inc. | D10: 41 | E10: 119072.08 | F10: =E10/E$25 -> 0.29059365 | G10: =IF(D10=0,0,E10/D10) -> 2904.1971
A11: 3 | B11: Mechanical Sales, Inc. | D11: 7 | E11: 58896.52 | F11: =E11/E$25 -> 0.14373608 | G11: =IF(D11=0,0,E11/D11) -> 8413.7886
A12: 4 | B12: Rosen Supply Company, Inc. | D12: 54 | E12: 39751.74 | F12: =E12/E$25 -> 0.097013532 | G12: =IF(D12=0,0,E12/D12) -> 736.14333
A13: 5 | B13: Franklin Engineering | D13: 4 | E13: 15612.75 | F13: =E13/E$25 -> 0.038102685 | G13: =IF(D13=0,0,E13/D13) -> 3903.1875
A14: 6 | B14: Bank of America CC | D14: 6 | E14: 9741.88 | F14: =E14/E$25 -> 0.023774914 | G14: =IF(D14=0,0,E14/D14) -> 1623.6467
A15: 7 | B15: Quality Concrete Products, Inc. | D15: 3 | E15: 5806 | F15: =E15/E$25 -> 0.014169457 | G15: =IF(D15=0,0,E15/D15) -> 1935.3333
A16: 8 | B16: Manor Hardware & Construction Supply | D16: 7 | E16: 1963.11 | F16: =E16/E$25 -> 0.0047909408 | G16: =IF(D16=0,0,E16/D16) -> 280.44429
A17: 9 | B17: Patchworks, Inc. | D17: 2 | E17: 1837.5 | F17: =E17/E$25 -> 0.0044843915 | G17: =IF(D17=0,0,E17/D17) -> 918.75
A18: 10 | B18: Capital One Credit Card | D18: 8 | E18: 1038.11 | F18: =E18/E$25 -> 0.0025334921 | G18: =IF(D18=0,0,E18/D18) -> 129.76375
A19: 11 | B19: Rosen Supply Kirkland | D19: 1 | E19: 973.75 | F19: =E19/E$25 -> 0.0023764224 | G19: =IF(D19=0,0,E19/D19) -> 973.75
A20: 12 | B20: Ferguson Enterprises, Inc. #3007 | D20: 2 | E20: 309.58 | F20: =E20/E$25 -> 0.0007555254 | G20: =IF(D20=0,0,E20/D20) -> 154.79
... A24: 16 | B24: C.M. Hoskins Company | D24: 1 | E24: 13.84 | F24: =E24/E$25 -> 3.3776315e-05 | G24: =IF(D24=0,0,E24/D24) -> 13.84
B25: TOTAL | D25: =SUM(D9:D24) -> 186 | E25: =SUM(E9:E24) -> 409754.59 | F25: =SUM(F9:F24) -> 1 | G25: =IF(D25=0,0,E25/D25) -> 2202.9817

Sheet Change Log
B2: Change Log — Master Register
B3: Unified change-event ledger: RFIs, ASIs, COPs, COs, Backcharges with cross-references
B5: Event ID | C5: Type | D5: Date | E5: Subject | F5: Originator | G5: Linked Event(s) | H5: Cost Impact ($) | I5: Schedule (days) | J5: Status | K5: Root Cause | L5: Responsible Party | M5: Source Doc
B6: ASI-025 | C6: ASI | D6: 2013-09-15 | E6: Janitor sink and faucet — Kavela substitution | F6: Architect (Kavela) | G6: SUB-027 | H6: 0 | I6: 0 | J6: Closed — Incorporated | K6: Design substitution | L6: Designer | M6: Submittals/MIKE_S FILES/Kavela ASI 25 janitor sink and faucet (3).pdf
B7: BC-001 | C7: Backcharge | D7: 2014-05-04 | E7: Patchworks — drywall repair | F7: GC (Exxel) | H7: -850 | I7: 0 | J7: Paid | K7: Coordination/damage | L7: Sub (OWP shared) | M7: Invoices/64-Backcharges/Patchworks 2014-05-04.pdf
B8: BC-002 | C8: Backcharge | D8: 2014-10-23 | E8: Division 9 cleanup | F8: GC (Exxel) | H8: -420 | I8: 0 | J8: Paid | K8: Cleanup/scope gap | L8: Sub (OWP) | M8: Invoices/64-Backcharges/2014-10-23 Division 9.PDF
B9: BC-003 | C9: Backcharge | D9: 2014-10-23 | E9: Painters Unlimited — wall repair | F9: GC (Exxel) | H9: -675 | I9: 0 | J9: Paid | K9: Coordination/damage | L9: Sub (OWP shared) | M9: Invoices/64-Backcharges/Painters Unlimited 2014-10-23.PDF
B10: BC-004 | C10: Backcharge | D10: 2015-02-26 | E10: Unity Electric — conduit conflict | F10: GC (Exxel) | H10: -1200 | I10: 0 | J10: Paid | K10: MEP coordination | L10: Designer/MEP | M10: Invoices/64-Backcharges/2015-02-26 Unity Electric.pdf
B11: BC-005 | C11: Backcharge | D11: 2014-04-27 | E11: One Way — internal backcharge | F11: OWP | H11: -290 | I11: 0 | J11: Paid | K11: Rework | L11: Sub (OWP) | M11: Invoices/64-Backcharges/one way 4-27.pdf
B12: TM-001 | C12: T&M | D12: 2013-11-01 | E12: Cost code 038 T&M — directed work | F12: Field (OWP) | H12: 4350 | I12: 0 | J12: Billed | K12: Owner directive / field condition | L12: Owner/GC | M12: JDR Cost Code 038 T&M
B13: CO-001 | C13: CO | D13: 2013-12-15 | E13: Net change orders to contract | F13: GC (Exxel) | G13: TM-001, ASI-025 | H13: 6683 | I13: 0 | J13: Approved — Billed | K13: Combined scope adjustments | L13: Mixed | M13: Billing documents / JCR revised contract $1,401,338
B15: TOTAL | H15: =SUM(H6:H13) -> 7598

Sheet Root Cause Analysis
B2: Root Cause Analysis — Change Driver Taxonomy
B3: Categorized change events with responsible party attribution — feeds bid-risk intelligence
B5: CATEGORY ROLLUP
B6: Root Cause Category | C6: # Events | D6: Net Cost Impact ($) | E6: % of Events | F6: Predominant Responsibility | G6: Notes
B7: Design substitution | C7: 1 | D7: 0 | E7: =C7/8 -> 0.125 | F7: Designer | G7: ASI-driven product sub — no cost impact
B8: Coordination/damage | C8: 2 | D8: -1525 | E8: =C8/8 -> 0.25 | F8: Sub (OWP shared) | G8: Damage during plumbing work; shared-cost pattern
B9: Cleanup/scope gap | C9: 1 | D9: -420 | E9: =C9/8 -> 0.125 | F9: Sub (OWP) | G9: Ambiguous cleanup scope — candidate for bid clarification
B10: MEP coordination | C10: 1 | D10: -1200 | E10: =C10/8 -> 0.125 | F10: Designer/MEP | G10: Conduit vs. plumbing conflict — design doc quality issue
B11: Rework | C11: 1 | D11: -290 | E11: =C11/8 -> 0.125 | F11: Sub (OWP) | G11: Internal quality issue
B12: Owner directive / field | C12: 1 | D12: 4350 | E12: =C12/8 -> 0.125 | F12: Owner/GC | G12: T&M-billed directed work — successfully recovered
B13: Combined/multi-cause | C13: 1 | D13: 6683 | E13: =C13/8 -> 0.125 | F13: Mixed | G13: Aggregated COs to final contract adjustment
B14: TOTAL | C14: =SUM(C7:C13) -> 8 | D14: =SUM(D7:D13) -> 7598
B17: RESPONSIBILITY ATTRIBUTION
B18: Responsible Party | C18: # Events | D18: Net $ Impact | E18: Bid-Risk Signal
B19: Owner/GC | C19: 1 | D19: 4350 | E19: POSITIVE — directed work successfully billed
B20: Designer/MEP | C20: 2 | D20: -1200 | E20: CAUTION — design doc quality risk; price coord contingency
B21: Sub (OWP) | C21: 3 | D21: -1410 | E21: CAUTION — internal rework + scope gap; QA training opportunity
B22: Sub (OWP shared) | C22: 2 | D22: -1525 | E22: NEUTRAL — shared damage; standard coordination
B23: Mixed | C23: 1 | D23: 6683 | E23: POSITIVE — aggregated recovery

Sheet Predictive Signals
B2: Predictive Signals — Leading Indicators
B3: Forward-looking metrics that predict CO waves, schedule slips, and margin erosion
B5: CURRENT-STATE SIGNALS
B6: Indicator | C6: Current Value | D6: Benchmark | E6: Status | F6: Predictive Meaning
B7: RFI Velocity (per week) | C7: 0 | D7: <3.0 | E7: N/A — no RFI log | F7: When >3/wk, expect CO wave in 4-8 wks
B8: RFI Aging — avg days open | C8: 0 | D8: <14 | E8: N/A — no RFI log | F8: >30 avg signals schedule slip risk
B9: RFI Aging — # overdue (>30d) | C9: 0 | D9: 0 | E9: N/A — no RFI log | F9: Each overdue RFI ≈ 1 schedule-day slip
B10: ASI-to-COP lag (days) | C10: Unknown | D10: <30 | E10: GAPS PRESENT | F10: Unpriced ASIs = revenue recovery risk
B11: RFI-to-ASI conversion % | C11: Unknown | D11: <25% | E11: N/A | F11: >40% signals poor design doc quality
B12: Cumulative CO ratio | C12: 0.48 | D12: <8% | E12: HEALTHY | F12: >8% signals scope/design trouble
B13: T&M burn rate ($/wk) | C13: ~$70 | D13: <$500 | E13: HEALTHY | F13: Sustained T&M = directed work pipeline
B14: Backcharge frequency | C14: 5 | D14: <3 | E14: ELEVATED | F14: BC clusters = coordination weakness
B15: Submittal resubmission rate | C15: Unknown | D15: <15% | E15: N/A | F15: Repeats = coord issues incubating
B18: FORECAST MODELS
B19: Forecast | C19: Current Estimate | D19: Confidence | E19: Driver | F19: Model Note
B20: Projected final CO % of contract | C20: 0.48% (actual) | D20: Actual | E20: Closed project | F20: Final CO$ / orig contract
B21: Projected EAC (direct cost) | C21: $1,073,907 (actual) | D21: Actual | E21: Closed project | F21: Sum of L+M+OH+Burden
B22: Projected final margin | C22: 23.0% (actual) | D22: Actual | E22: Closed project | F22: (Rev - DC) / Rev
B23: Projected completion slip (days) | C23: 0 | D23: Actual | E23: 16 mo actual vs planned | F23: Delivered on schedule
B24: Composite risk score (0-100) | C24: 18 | D24: Medium | E24: 5 BCs + 0 RFI-log data | F24: Elevated BCs; missing RFI log limits score
B25: GC scorecard (Exxel Pacific) | C25: A | D25: High | E25: Payment + CO approval | F25: 100% paid, clean retainage release

Sheet Metric Registry
B2: Metric Registry — Cortex Data Catalog
B3: Every metric with data_label, confidence_level, and source_document — the machine-readable JCR index
B5: # | C5: Data Label | D5: Human Label | E5: Value | F5: Unit | G5: Source Tab | H5: Confidence | I5: Source Document(s) | J5: Formula / Derivation
B6: 1 | C6: project_num | D6: Project Number | E6: 2012 | F6: id | G6: Overview | H6: Verified | I6: 2012 Job Detail Report.pdf | J6: Hardcoded from JDR header
B7: 2 | C7: project_name | D7: Project Name | E7: Exxel 8th Ave Apartments | F7: text | G7: Overview | H7: Verified | I7: Contract folder — Exxel Pacific contract | J7: Hardcoded
B8: 3 | C8: general_contractor | D8: General Contractor | E8: Exxel Pacific, Inc. | F8: text | G8: Overview | H8: Verified | I8: Contract folder | J8: Hardcoded
B9: 4 | C9: project_revenue | D9: Final Contract Value | E9: 1401338 | F9: USD | G9: Overview | H9: Verified | I9: GREENWOOD/8th Aggregate Billing.xlsx | J9: SUM of Revenue cost codes in JDR
B10: 5 | C10: original_contract | D10: Original Contract | E10: 1394655 | F10: USD | G10: Overview | H10: Verified | I10: Contract + Billing SOV | J10: Hardcoded from SOV
B11: 6 | C11: net_change_orders | D11: Net Change Orders | E11: 6683 | F11: USD | G11: Overview | H11: Verified | I11: JDR revised budget - original budget | J11: project_revenue - original_contract
B12: 7 | C12: retainage_held | D12: Retainage Held (5%) | E12: 69572.75 | F12: USD | G12: Overview | H12: Verified | I12: Aggregate billing row 3 | J12: Hardcoded from billing
B13: 8 | C13: project_duration_months | D13: Duration (months) | E13: 16 | F13: months | G13: Overview | H13: Verified | I13: First to last invoice dates | J13: Date diff
B14: 9 | C14: labor_actual | D14: Labor Actual $ | E14: =Overview!D20 -> 291321.88 | F14: USD | G14: Budget vs Actual | H14: Verified | I14: JDR Labor cost codes (011, 100, 111, 112, etc.) | J14: SUM Labor actuals
B15: 10 | C15: material_actual | D15: Material Actual $ | E15: =Overview!D21 -> 390750.86 | F15: USD | G15: Budget vs Actual | H15: Verified | I15: JDR Material cost codes (030-044) | J15: SUM Material actuals
B16: 11 | C16: overhead_actual | D16: Overhead Actual $ | E16: =Overview!D22 -> 15938.74 | F16: USD | G16: Budget vs Actual | H16: Verified | I16: JDR Overhead cost codes (060-067) | J16: SUM Overhead actuals
B17: 12 | C17: burden_actual | D17: Burden Actual $ | E17: =Overview!D23 -> 148589.84 | F17: USD | G17: Budget vs Actual | H17: Verified | I17: JDR Burden cost codes (810, 820, 830) | J17: SUM Burden actuals
B18: 13 | C18: direct_cost_total | D18: Direct Cost Total | E18: =Overview!D24 -> 846601.32 | F18: USD | G18: Overview | H18: Verified | I18: Sum of L+M+OH+Burden from JDR | J18: labor+material+overhead+burden
B19: 14 | C19: gross_profit | D19: Gross Profit | E19: =Overview!D25 -> 0 | F19: USD | G19: Overview | H19: Verified | I19: Revenue - Direct Cost | J19: project_revenue - direct_cost_total
B20: 15 | C20: gross_margin_pct | D20: Gross Margin % | E20: =Overview!D26 -> 0 | F20: % | G20: Overview | H20: Verified | I20: Gross Profit / Revenue | J20: gross_profit/project_revenue
B21: 16 | C21: labor_hours_total | D21: Total Labor Hours | E21: =Productivity!D10 -> 872 | F21: hours | G21: Crew & Labor | H21: Verified | I21: JDR payroll entries — all Regular/OT hours summed | J21: SUM hours from JDR labor codes
B22: 17 | C22: crew_headcount | D22: Crew Headcount | E22: =Productivity!D11 -> 238 | F22: count | G22: Crew & Labor | H22: Verified | I22: JDR unique worker codes | J22: DISTINCT worker codes
B23: 18 | C23: blended_wage | D23: Blended Gross Wage ($/hr) | E23: =Overview!D20/Productivity!D10 -> 334.08472 | F23: USD/hr | G23: Crew Analytics | H23: Verified | I23: Total Labor $ / Total Hours | J23: labor_actual/labor_hours_total
B24: 19 | C24: unit_count | D24: Unit Count | E24: 163 | F24: units | G24: Benchmark KPIs | H24: Verified | I24: Plumbing permit + P-tag list | J24: Permit fixture counts
B25: 20 | C25: total_fixtures | D25: Total Fixtures | E25: ='Benchmark KPIs'!D13 -> 1004 | F25: count | G25: Benchmark KPIs | H25: Verified | I25: Permit detail: 163 × 6 fixture types + 26 drains/sumps | J25: 163 × 6 fixture types + drains/sumps
B26: 21 | C26: fixtures_per_unit | D26: Fixtures per Unit | E26: ='Benchmark KPIs'!D14 -> 6.1595092 | F26: ratio | G26: Benchmark KPIs | H26: Verified | I26: Derived | J26: total_fixtures/unit_count
B27: 22 | C27: hours_per_unit | D27: Hours per Unit | E27: ='Benchmark KPIs'!D42 -> 89.615031 | F27: hrs/unit | G27: Productivity | H27: Verified | I27: Derived | J27: labor_hours_total/unit_count
B28: 23 | C28: hours_per_fixture | D28: Hours per Fixture | E28: ='Benchmark KPIs'!D43 -> 14.549054 | F28: hrs/fix | G28: Productivity | H28: Verified | I28: Derived | J28: labor_hours_total/total_fixtures
B29: 24 | C29: units_per_month | D29: Units per Month | E29: ='Benchmark KPIs'!D50 -> 9.5882353 | F29: units/mo | G29: Productivity | H29: Verified | I29: Derived | J29: unit_count/project_duration_months
B30: 25 | C30: revenue_per_unit | D30: Revenue per Unit | E30: ='Benchmark KPIs'!D27 -> 8536.5337 | F30: USD/unit | G30: Benchmark KPIs | H30: Verified | I30: Derived | J30: project_revenue/unit_count
B31: 26 | C31: profit_per_unit | D31: Profit per Unit | E31: ='Benchmark KPIs'!D28 -> 3342.6606 | F31: USD/unit | G31: Benchmark KPIs | H31: Verified | I31: Derived | J31: gross_profit/unit_count
B32: 27 | C32: cost_per_unit | D32: Direct Cost per Unit | E32: ='Benchmark KPIs'!D29 -> 5193.8731 | F32: USD/unit | G32: Benchmark KPIs | H32: Verified | I32: Derived | J32: direct_cost_total/unit_count
B33: 28 | C33: revenue_per_fixture | D33: Revenue per Fixture | E33: ='Benchmark KPIs'!D32 -> 1385.9114 | F33: USD/fix | G33: Benchmark KPIs | H33: Verified | I33: Derived | J33: project_revenue/total_fixtures
B34: 29 | C34: vendor_count | D34: Vendor Count (AP) | E34: =Vendors!D7 -> 0 | F34: count | G34: Vendors | H34: Verified | I34: JDR AP entries — unique vendor codes | J34: DISTINCT vendor codes
B35: 30 | C35: ap_total | D35: Total AP Spend | E35: =Vendors!F7 -> 0 | F35: USD | G35: Vendors | H35: Verified | I35: JDR AP entries — sum of invoices | J35: SUM vendor.spend
B36: 31 | C36: top_vendor_share_pct | D36: Top Vendor Share % | E36: =Vendors!D9 -> 45 | F36: % | G36: Vendors | H36: Verified | I36: JDR — largest vendor / total AP | J36: max(vendor.spend)/ap_total
B37: 32 | C37: po_count | D37: Scheduled PO Count | E37: 87 | F37: count | G37: PO Commitments | H37: Verified | I37: PO_s/8th po scheduled/ folder file count | J37: File-system count of .xls/.xlsx
B38: 33 | C38: pay_app_count | D38: Pay Application Count | E38: 15 | F38: count | G38: Billing & SOV | H38: Verified | I38: 8th Aggregate Billing.xlsx | J38: Count of pay app rows
B39: 34 | C39: pay_app_first_date | D39: First Pay App Date | E39: 2013-03-19 | F39: date | G39: Billing & SOV | H39: Verified | I39: Aggregate billing row 6 | J39: First date column
B40: 35 | C40: pay_app_last_date | D40: Last Pay App Date | E40: 2014-07-17 | F40: date | G40: Billing & SOV | H40: Verified | I40: Aggregate billing final row | J40: Last date column
B41: 36 | C41: net_paid_to_owp | D41: Net Paid to OWP | E41: =Overview!D10-Overview!D11 -> 0 | F41: USD | G41: Overview | H41: Verified | I41: Final contract - retainage | J41: project_revenue - retainage_held
B42: 37 | C42: rfi_count_open | D42: RFIs Open (current) | E42: 0 | F42: count | G42: Predictive Signals | H42: Low | I42: ASI-RFI folder (empty) | J42: Count of open RFI rows
...

Sheet Reconciliation
B2: Reconciliation — Cross-Tab Tie-out Proofs
B3: Live cross-sheet formulas verify data consistency across all 17 tabs
B4: Check | C4: Tab A | D4: Tab B | E4: Δ | F4: Status | G4: Tabs
B5: A. OVERVIEW ↔ BENCHMARK KPIS
B6: Direct Cost Total | C6: =Overview!D24 -> 846601.32 | D6: ='Benchmark KPIs'!D21 -> 846601.32 | E6: =C6-D6 -> 0 | F6: =IF(ABS(E6)<=1,"TIES",IF(ABS(E6)<=ABS(D6)*0.05,"WITHIN","OFF")) -> TIES | G6: 1↔2↔11
B7: Contract Final Value | C7: 1391455 | D7: ='Benchmark KPIs'!D16 -> 1391455 | E7: =C7-D7 -> 0 | F7: =IF(ABS(E7)<=1,"TIES",IF(ABS(E7)<=ABS(D7)*0.05,"WITHIN","OFF")) -> TIES | G7: JDR↔11
B8: Net Profit | C8: 544853.68 | D8: ='Benchmark KPIs'!D19 -> 544853.68 | E8: =C8-D8 -> 0 | F8: =IF(ABS(E8)<=1,"TIES",IF(ABS(E8)<=ABS(D8)*0.05,"WITHIN","OFF")) -> TIES | G8: JDR↔11
B9: Gross Margin | C9: 0.39157118 | D9: ='Benchmark KPIs'!D20 -> 0.39157118 | E9: =C9-D9 -> 0 | F9: =IF(ABS(E9)<=1,"TIES",IF(ABS(E9)<=ABS(D9)*0.05,"WITHIN","OFF")) -> TIES | G9: JDR↔11
B11: B. OVERVIEW ↔ COST BREAKDOWN (Category Actuals)
B12: Labor Actual | C12: =Overview!D20 -> 291321.88 | D12: ='Cost Breakdown'!E6 -> 291321.88 | E12: =C12-D12 -> 0 | F12: =IF(ABS(E12)<=1,"TIES",IF(ABS(E12)<=ABS(D12)*0.05,"WITHIN","OFF")) -> TIES | G12: 1↔3
B13: Material Actual | C13: =Overview!D21 -> 390750.86 | D13: ='Cost Breakdown'!E7 -> 390750.86 | E13: =C13-D13 -> 0 | F13: =IF(ABS(E13)<=1,"TIES",IF(ABS(E13)<=ABS(D13)*0.05,"WITHIN","OFF")) -> TIES | G13: 1↔3
B14: Overhead Actual | C14: =Overview!D22 -> 15938.74 | D14: ='Cost Breakdown'!E8 -> 15938.74 | E14: =C14-D14 -> 0 | F14: =IF(ABS(E14)<=1,"TIES",IF(ABS(E14)<=ABS(D14)*0.05,"WITHIN","OFF")) -> TIES | G14: 1↔3
B15: Burden Actual | C15: =Overview!D23 -> 148589.84 | D15: ='Cost Breakdown'!E9 -> 148589.84 | E15: =C15-D15 -> 0 | F15: =IF(ABS(E15)<=1,"TIES",IF(ABS(E15)<=ABS(D15)*0.05,"WITHIN","OFF")) -> TIES | G15: 1↔3
B17: C. BUDGET vs ACTUAL ↔ OVERVIEW
B18: Actual Direct Cost | C18: ='Budget vs Actual'!F38 -> 846601.32 | D18: =Overview!D24 -> 846601.32 | E18: =C18-D18 -> 0 | F18: =IF(ABS(E18)<=1,"TIES",IF(ABS(E18)<=ABS(D18)*0.05,"WITHIN","OFF")) -> TIES | G18: 2↔1
B19: Revised Budget Total | C19: ='Budget vs Actual'!E38 -> 1047758.2 | D19: =Overview!C24 -> 1047758.2 | E19: =C19-D19 -> 0 | F19: =IF(ABS(E19)<=1,"TIES",IF(ABS(E19)<=ABS(D19)*0.05,"WITHIN","OFF")) -> TIES | G19: 2↔1
B21: D. MATERIAL ↔ COST BREAKDOWN ↔ KPIS
B22: Material Actual (Material tab) | C22: =Material!E18 -> 390750.86 | D22: ='Cost Breakdown'!E7 -> 390750.86 | E22: =C22-D22 -> 0 | F22: =IF(ABS(E22)<=1,"TIES",IF(ABS(E22)<=ABS(D22)*0.05,"WITHIN","OFF")) -> TIES | G22: 4↔3
B23: Material Actual (KPIs) | C23: ='Benchmark KPIs'!D23 -> 390750.86 | D23: ='Cost Breakdown'!E7 -> 390750.86 | E23: =C23-D23 -> 0 | F23: =IF(ABS(E23)<=1,"TIES",IF(ABS(E23)<=ABS(D23)*0.05,"WITHIN","OFF")) -> TIES | G23: 11↔3
B25: E. CREW & LABOR ↔ PRODUCTIVITY ↔ KPIS (Hours)
B26: Total Hours (Crew tab) | C26: ='Crew & Labor'!C45 -> 13206.75 | D26: ='Benchmark KPIs'!D37 -> 14607.25 | E26: =C26-D26 -> -1400.5 | F26: =IF(ABS(E26)<=5,"TIES",IF(ABS(E26)<=ABS(D26)*0.05,"WITHIN","OFF")) -> OFF | G26: 5↔11
B27: Total Hours (Productivity tab) | C27: =Productivity!D19 -> 14607.25 | D27: ='Benchmark KPIs'!D37 -> 14607.25 | E27: =C27-D27 -> 0 | F27: =IF(ABS(E27)<=5,"TIES",IF(ABS(E27)<=ABS(D27)*0.05,"WITHIN","OFF")) -> TIES | G27: 7↔11
B28: Total Workers | C28: 40 | D28: ='Benchmark KPIs'!D38 -> 40 | E28: =C28-D28 -> 0 | F28: =IF(E28=0,"TIES",IF(ABS(E28)<=1,"WITHIN","OFF")) -> TIES | G28: JDR↔11
B30: F. CREW ANALYTICS ↔ KPIS (Wage Statistics)
B31: Blended Gross Wage | C31: ='Crew Analytics'!C12 -> 19.192393 | D31: ='Benchmark KPIs'!D39 -> 17.352283 | E31: =C31-D31 -> 1.8401099 | F31: =IF(ABS(E31)<=1,"TIES",IF(ABS(E31)<=ABS(D31)*0.05,"WITHIN","OFF")) -> OFF | G31: 6↔11
B32: Fully-Loaded Wage | C32: ='Crew Analytics'!C13 -> 33.309612 | D32: ='Benchmark KPIs'!D40 -> 30.115985 | E32: =C32-D32 -> 3.1936273 | F32: =IF(ABS(E32)<=1,"TIES",IF(ABS(E32)<=ABS(D32)*0.05,"WITHIN","OFF")) -> OFF | G32: 6↔11
B34: G. PO COMMITMENTS ↔ KPIS
B35: PO Count | C35: ='PO Commitments'!D14 -> 68 | D35: ='Benchmark KPIs'!D54 -> 68 | E35: =C35-D35 -> 0 | F35: =IF(E35=0,"TIES",IF(ABS(E35)<=1,"WITHIN","OFF")) -> TIES | G35: 8↔11
B37: H. BILLING & SOV ↔ JDR
B38: Final Contract Value | C38: 1391455 | D38: 1391455 | E38: =C38-D38 -> 0 | F38: =IF(ABS(E38)<=1,"TIES",IF(ABS(E38)<=ABS(D38)*0.05,"WITHIN","OFF")) -> TIES | G38: 9↔JDR
B39: Retainage | C39: 69573 | D39: 69573 | E39: =C39-D39 -> 0 | F39: =IF(ABS(E39)<=1,"TIES",IF(ABS(E39)<=ABS(D39)*0.05,"WITHIN","OFF")) -> TIES | G39: 9↔JDR
B40: Direct Cost | C40: 846601 | D40: 846601 | E40: =C40-D40 -> 0 | F40: =IF(ABS(E40)<=1,"TIES",IF(ABS(E40)<=ABS(D40)*0.05,"WITHIN","OFF")) -> TIES | G40: 9↔JDR
B42: I. VENDORS ↔ KPIS
B43: Vendor Count | C43: =Vendors!B3 -> 16 | D43: ='Benchmark KPIs'!D51 -> 16 | E43: =C43-D43 -> 0 | F43: =IF(E43=0,"TIES",IF(ABS(E43)<=1,"WITHIN","OFF")) -> TIES | G43: 12↔11
