Workbook

Sheet Overview
B2: Job #2009 · Chinn Greenwood Apartments
B3: Cortex JCR Summary • Chinn Construction, LLC • Seattle, WA • 168-unit apartment building • Jul 2012 – Oct 2013 (~16 months)
B5: PROJECT OVERVIEW
B6: Project Job # | C6: 2009
B7: Project Name: | C7: Chinn Greenwood Apartments
B8: General Contractor | C8: Chinn Construction, LLC
B9: Location | C9: Seattle, WA
B10: Project Duration | C10: Jul 2012 – Oct 2013 (~16 months)
B11: Total Unique Documents | C11: Greenwood folder: Contract, Billing (aggregate + 11 SOVs), PO Scheduled (48), Permits, Plans, Submittals
B13: CONTRACT VALUE | D13: NET PROFIT | F13: DIRECT COST | H13: LABOR HOURS
B14: $394,208 | D14: $113,840 | F14: $280,368 | H14: 3,928
B15: Original $384,900 + $9,308 COs | D15: 28.9% margin | F15: 71.1% of revenue | H15: 23 workers
B18: COST BREAKDOWN
B19: Category | C19: Budget | D19: Actual | E19: Variance | F19: % Budget | G19: % of Cost
B20: Labor | C20: 72340 | D20: 80901.5 | E20: =C20-D20 | F20: =IF(C20=0,0,D20/C20) | G20: =IF($D$24=0,0,D20/$D$24)
B21: Material | C21: 195311 | D21: 151064.39 | E21: =C21-D21 | F21: =IF(C21=0,0,D21/C21) | G21: =IF($D$24=0,0,D21/$D$24)
B22: Overhead | C22: 10885 | D22: 7510.52 | E22: =C22-D22 | F22: =IF(C22=0,0,D22/C22) | G22: =IF($D$24=0,0,D22/$D$24)
B23: Burden | C23: 38464.22 | D23: 40891.46 | E23: =C23-D23 | F23: =IF(C23=0,0,D23/C23) | G23: =IF($D$24=0,0,D23/$D$24)
B24: TOTAL | C24: =SUM(C20:C23) | D24: =SUM(D20:D23) | E24: =C24-D24 | F24: =IF(C24=0,0,D24/C24) | G24: 1
B27: PROJECT PROFILE
B28: Metric | C28: Value | D28: Metric | E28: Value | F28: Metric | G28: Value
B29: Plumbing Units | C29: 168 | D29: Water Closets | E29: 168 | F29: Kitchen Sinks | G29: 168
B30: Total Fixtures | C30: 812 | D30: Lavatories | E30: 168 | F30: Tubs | G30: 168
B31: Fixtures / Unit | C31: 4.83 | D31: Auto Washers | E31: 140 | F31: Showers | G31: 0
B32: Stacks | C32: 36 | D32: Duration | E32: 16 mo | F32: Cost Codes | G32: 26
B36: SOURCES
B37: Job #2009 — Chinn Greenwood Apartments • GC: Chinn Construction, LLC • Seattle, WA
B38: Canonical source: 2009 Job Detail Report.pdf (49 pages, OWP Sage Timberline export)
B39: Cost codes parsed: 26
B40: Unit count (168) and fixture count (812) from greenwood h20 stacks.xls and trim POs
B41: 3-level building + lobby: L1 (18 units), L2 (18 units), L3 (18 units), LW (amenity) × south/north stacks
B42: Billing: GREENWOOD AGGREGATE BILLING.xlsx (11 pay apps Jul 2012 – Oct 2013)
B43: Final contract $394,208 (original $384,900 + $9,308 COs)

Sheet Budget vs Actual
B2: Budget vs Actual — All Cost Codes
B4: Code | C4: Description | D4: Orig Budget | E4: Rev Budget | F4: Actual | G4: Variance | H4: % Used
B5: LABOR
B6: 011 | C6: DS & RD Labor | D6: 1250 | E6: 1250 | F6: 1645 | G6: =E6-F6 | H6: =IF(E6=0,0,F6/E6)
B7: 100 | C7: Supervision | D7: 3000 | E7: 3000 | F7: 2992 | G7: =E7-F7 | H7: =IF(E7=0,0,F7/E7)
B8: 101 | C8: Takeoff & Purchase Labor | D8: 2500 | E8: 2500 | F8: 1324 | G8: =E8-F8 | H8: =IF(E8=0,0,F8/E8)
B9: 110 | C9: Underground Labor | D9: 5350 | E9: 5350 | F9: 4209 | G9: =E9-F9 | H9: =IF(E9=0,0,F9/E9)
B10: 111 | C10: Garage Labor | D10: 8960 | E10: 8960 | F10: 9872 | G10: =E10-F10 | H10: =IF(E10=0,0,F10/E10)
B11: 112 | C11: Canout Labor | D11: 2000 | E11: 2000 | F11: 1485.5 | G11: =E11-F11 | H11: =IF(E11=0,0,F11/E11)
B12: 120 | C12: Roughin Labor | D12: 34500 | E12: 37530 | F12: 46114 | G12: =E12-F12 | H12: =IF(E12=0,0,F12/E12)
B13: 130 | C13: Finish Labor | D13: 10250 | E13: 10320 | F13: 11391.5 | G13: =E13-F13 | H13: =IF(E13=0,0,F13/E13)
B14: 141 | C14: Water Main/Insulation Lab | D14: 0 | E14: 0 | F14: 0 | G14: =E14-F14 | H14: =IF(E14=0,0,F14/E14)
B15: 142 | C15: Mech Room Labor | D15: 1430 | E15: 1430 | F15: 1730 | G15: =E15-F15 | H15: =IF(E15=0,0,F15/E15)
B16: 145 | C16: Tub/Shower Labor | D16: 0 | E16: 0 | F16: 138.5 | G16: =E16-F16 | H16: =IF(E16=0,0,F16/E16)
B17: MATERIAL
B18: 039 | C18: DS & RD Material | D18: 1250 | E18: 1250 | F18: 369.06 | G18: =E18-F18 | H18: =IF(E18=0,0,F18/E18)
B19: 210 | C19: Underground Material | D19: 2800 | E19: 2800 | F19: 2613.58 | G19: =E19-F19 | H19: =IF(E19=0,0,F19/E19)
B20: 211 | C20: Garage Material | D20: 10570 | E20: 10570 | F20: 3972.94 | G20: =E20-F20 | H20: =IF(E20=0,0,F20/E20)
B21: 212 | C21: Canout Material | D21: 2800 | E21: 2800 | F21: 2749.23 | G21: =E21-F21 | H21: =IF(E21=0,0,F21/E21)
B22: 220 | C22: Roughin Material | D22: 33560 | E22: 32510 | F22: 30742.47 | G22: =E22-F22 | H22: =IF(E22=0,0,F22/E22)
B23: 230 | C23: Finish Material | D23: 143270 | E23: 143381 | F23: 109975.66 | G23: =E23-F23 | H23: =IF(E23=0,0,F23/E23)
B24: 241 | C24: Water Main/Insulation Mat | D24: 0 | E24: 0 | F24: 0 | G24: =E24-F24 | H24: =IF(E24=0,0,F24/E24)
B25: 242 | C25: Mech Room Material | D25: 2000 | E25: 2000 | F25: 641.45 | G25: =E25-F25 | H25: =IF(E25=0,0,F25/E25)
B26: 245 | C26: Tub/Shower Material | D26: 0 | E26: 0 | F26: 0 | G26: =E26-F26 | H26: =IF(E26=0,0,F26/E26)
B27: OVERHEAD
B28: 600 | C28: Subcontractor | D28: 4800 | E28: 4885 | F28: 2379 | G28: =E28-F28 | H28: =IF(E28=0,0,F28/E28)
B29: 601 | C29: Engineering/Plans | D29: 6000 | E29: 6000 | F29: 4990.08 | G29: =E29-F29 | H29: =IF(E29=0,0,F29/E29)
B30: 603 | C30: Permits & Licenses | D30: 0 | E30: 0 | F30: 141.44 | G30: =E30-F30 | H30: =IF(E30=0,0,F30/E30)
B31: BURDEN
B32: 995 | C32: Payroll Burden | D32: 28928 | E32: 32694.58 | F32: 34412.05 | G32: =E32-F32 | H32: =IF(E32=0,0,F32/E32)
B33: 998 | C33: Payroll Taxes | D33: 5532.48 | E33: 5769.64 | F33: 6479.41 | G33: =E33-F33 | H33: =IF(E33=0,0,F33/E33)
B34: TOTAL | C34: Direct Cost | D34: 310750.48 | E34: 317000.22 | F34: 280367.87 | G34: =E34-F34 | H34: =IF(E34=0,0,F34/E34)
B37: SOURCES
B38: Job #2009 — Chinn Greenwood Apartments • GC: Chinn Construction, LLC • Seattle, WA
B39: Canonical source: 2009 Job Detail Report.pdf (49 pages, OWP Sage Timberline export)
B40: Cost codes parsed: 26
B41: Unit count (168) and fixture count (812) from greenwood h20 stacks.xls and trim POs
B42: 3-level building + lobby: L1 (18 units), L2 (18 units), L3 (18 units), LW (amenity) × south/north stacks
B43: Billing: GREENWOOD AGGREGATE BILLING.xlsx (11 pay apps Jul 2012 – Oct 2013)
B44: Final contract $394,208 (original $384,900 + $9,308 COs)

Sheet Cost Breakdown
B2: Cost Breakdown — Category Deep Dive
B4: A. CATEGORY SHARE OF DIRECT COST
B5: Category | C5: # Codes | D5: Budget | E5: Actual | F5: Variance | G5: % Budget | H5: % of Cost | I5: Per Unit
B6: Labor | C6: 11 | D6: 72340 | E6: 80901.5 | F6: =D6-E6 | G6: =IF(D6=0,0,E6/D6) | H6: =IF(280367.87=0,0,E6/280367.87) | I6: =IF(168=0,0,E6/168)
B7: Material | C7: 9 | D7: 195311 | E7: 151064.39 | F7: =D7-E7 | G7: =IF(D7=0,0,E7/D7) | H7: =IF(280367.87=0,0,E7/280367.87) | I7: =IF(168=0,0,E7/168)
B8: Overhead | C8: 3 | D8: 10885 | E8: 7510.52 | F8: =D8-E8 | G8: =IF(D8=0,0,E8/D8) | H8: =IF(280367.87=0,0,E8/280367.87) | I8: =IF(168=0,0,E8/168)
B9: Burden | C9: 2 | D9: 38464.22 | E9: 40891.46 | F9: =D9-E9 | G9: =IF(D9=0,0,E9/D9) | H9: =IF(280367.87=0,0,E9/280367.87) | I9: =IF(168=0,0,E9/168)
B12: B. LARGEST OVERRUNS (Actual > Revised Budget)
B13: Code | C13: Description | D13: Rev Budget | E13: Actual | F13: Overrun | G13: % Over
B14: 120 | C14: Roughin Labor | D14: 37530 | E14: 46114 | F14: =E14-D14 | G14: =IF(D14=0,0,F14/D14)
B15: 995 | C15: Payroll Burden | D15: 32694.58 | E15: 34412.05 | F15: =E15-D15 | G15: =IF(D15=0,0,F15/D15)
B16: 130 | C16: Finish Labor | D16: 10320 | E16: 11391.5 | F16: =E16-D16 | G16: =IF(D16=0,0,F16/D16)
B17: 111 | C17: Garage Labor | D17: 8960 | E17: 9872 | F17: =E17-D17 | G17: =IF(D17=0,0,F17/D17)
B18: 998 | C18: Payroll Taxes | D18: 5769.64 | E18: 6479.41 | F18: =E18-D18 | G18: =IF(D18=0,0,F18/D18)
B19: 011 | C19: DS & RD Labor | D19: 1250 | E19: 1645 | F19: =E19-D19 | G19: =IF(D19=0,0,F19/D19)
B20: 142 | C20: Mech Room Labor | D20: 1430 | E20: 1730 | F20: =E20-D20 | G20: =IF(D20=0,0,F20/D20)
B21: 603 | C21: Permits & Licenses | D21: 0 | E21: 141.44 | F21: =E21-D21 | G21: =IF(D21=0,0,F21/D21)
B22: 145 | C22: Tub/Shower Labor | D22: 0 | E22: 138.5 | F22: =E22-D22 | G22: =IF(D22=0,0,F22/D22)
B25: C. LARGEST SAVINGS (Actual < Revised Budget)
B26: Code | C26: Description | D26: Rev Budget | E26: Actual | F26: Savings | G26: % Under
B27: 230 | C27: Finish Material | D27: 143381 | E27: 109975.66 | F27: =D27-E27 | G27: =IF(D27=0,0,F27/D27)
B28: 211 | C28: Garage Material | D28: 10570 | E28: 3972.94 | F28: =D28-E28 | G28: =IF(D28=0,0,F28/D28)
B29: 600 | C29: Subcontractor | D29: 4885 | E29: 2379 | F29: =D29-E29 | G29: =IF(D29=0,0,F29/D29)
B30: 220 | C30: Roughin Material | D30: 32510 | E30: 30742.47 | F30: =D30-E30 | G30: =IF(D30=0,0,F30/D30)
B31: 242 | C31: Mech Room Material | D31: 2000 | E31: 641.45 | F31: =D31-E31 | G31: =IF(D31=0,0,F31/D31)
B32: 101 | C32: Takeoff & Purchase Labor | D32: 2500 | E32: 1324 | F32: =D32-E32 | G32: =IF(D32=0,0,F32/D32)
B33: 110 | C33: Underground Labor | D33: 5350 | E33: 4209 | F33: =D33-E33 | G33: =IF(D33=0,0,F33/D33)
B34: 601 | C34: Engineering/Plans | D34: 6000 | E34: 4990.08 | F34: =D34-E34 | G34: =IF(D34=0,0,F34/D34)
B35: 039 | C35: DS & RD Material | D35: 1250 | E35: 369.06 | F35: =D35-E35 | G35: =IF(D35=0,0,F35/D35)
B36: 112 | C36: Canout Labor | D36: 2000 | E36: 1485.5 | F36: =D36-E36 | G36: =IF(D36=0,0,F36/D36)
B39: SOURCES
B40: Job #2009 — Chinn Greenwood Apartments • GC: Chinn Construction, LLC • Seattle, WA
B41: Canonical source: 2009 Job Detail Report.pdf (49 pages, OWP Sage Timberline export)
B42: Cost codes parsed: 26
B43: Unit count (168) and fixture count (812) from greenwood h20 stacks.xls and trim POs
B44: 3-level building + lobby: L1 (18 units), L2 (18 units), L3 (18 units), LW (amenity) × south/north stacks
B45: Billing: GREENWOOD AGGREGATE BILLING.xlsx (11 pay apps Jul 2012 – Oct 2013)
B46: Final contract $394,208 (original $384,900 + $9,308 COs)

Sheet Material
B2: Material Spend Analysis
B3: 9 material cost codes • $151,064 JDR material • 13 AP vendors • $174,470 total AP
B5: A. MATERIAL BY COST CODE
B6: Code | C6: Description | D6: Rev Budget | E6: Actual | F6: Variance | G6: % Used | H6: % of Mat | I6: Per Unit
B7: 039 | C7: DS & RD Material | D7: 1250 | E7: 369.06 | F7: =D7-E7 | G7: =IF(D7=0,0,E7/D7) | H7: =IF(151064.39=0,0,E7/151064.39) | I7: =IF(168=0,0,E7/168)
B8: 210 | C8: Underground Material | D8: 2800 | E8: 2613.58 | F8: =D8-E8 | G8: =IF(D8=0,0,E8/D8) | H8: =IF(151064.39=0,0,E8/151064.39) | I8: =IF(168=0,0,E8/168)
B9: 211 | C9: Garage Material | D9: 10570 | E9: 3972.94 | F9: =D9-E9 | G9: =IF(D9=0,0,E9/D9) | H9: =IF(151064.39=0,0,E9/151064.39) | I9: =IF(168=0,0,E9/168)
B10: 212 | C10: Canout Material | D10: 2800 | E10: 2749.23 | F10: =D10-E10 | G10: =IF(D10=0,0,E10/D10) | H10: =IF(151064.39=0,0,E10/151064.39) | I10: =IF(168=0,0,E10/168)
B11: 220 | C11: Roughin Material | D11: 32510 | E11: 30742.47 | F11: =D11-E11 | G11: =IF(D11=0,0,E11/D11) | H11: =IF(151064.39=0,0,E11/151064.39) | I11: =IF(168=0,0,E11/168)
B12: 230 | C12: Finish Material | D12: 143381 | E12: 109975.66 | F12: =D12-E12 | G12: =IF(D12=0,0,E12/D12) | H12: =IF(151064.39=0,0,E12/151064.39) | I12: =IF(168=0,0,E12/168)
B13: 241 | C13: Water Main/Insulation Mat | D13: 0 | E13: 0 | F13: =D13-E13 | G13: =IF(D13=0,0,E13/D13) | H13: =IF(151064.39=0,0,E13/151064.39) | I13: =IF(168=0,0,E13/168)
B14: 242 | C14: Mech Room Material | D14: 2000 | E14: 641.45 | F14: =D14-E14 | G14: =IF(D14=0,0,E14/D14) | H14: =IF(151064.39=0,0,E14/151064.39) | I14: =IF(168=0,0,E14/168)
B15: 245 | C15: Tub/Shower Material | D15: 0 | E15: 0 | F15: =D15-E15 | G15: =IF(D15=0,0,E15/D15) | H15: =IF(151064.39=0,0,E15/151064.39) | I15: =IF(168=0,0,E15/168)
B16: TOTAL | C16: All Material | D16: =SUM(D7:D15) | E16: =SUM(E7:E15) | F16: =D16-E16 | G16: =IF(D16=0,0,E16/D16) | H16: 1 | I16: =IF(168=0,0,E16/168)
B19: B. VENDORS BY SPEND (AP)
B20: Vendor | C20: # Invoices | D20: Total Spend | E20: % of AP | I20: Avg Invoice
B21: Ferguson Enterprises, Inc. | C21: 65 | D21: 117439.01 | E21: =IF(174470.0499999999=0,0,D21/174470.0499999999) | I21: =IF(C21=0,0,D21/C21)
B22: Keller Supply Company | C22: 14 | D22: 29740.43 | E22: =IF(174470.0499999999=0,0,D22/174470.0499999999) | I22: =IF(C22=0,0,D22/C22)
B23: Mechanical Sales, Inc. | C23: 2 | D23: 16339.3 | E23: =IF(174470.0499999999=0,0,D23/174470.0499999999) | I23: =IF(C23=0,0,D23/C23)
B24: Franklin Engineering | C24: 1 | D24: 4895 | E24: =IF(174470.0499999999=0,0,D24/174470.0499999999) | I24: =IF(C24=0,0,D24/C24)
B25: Mickelo Construction LLC | C25: 1 | D25: 2250 | E25: =IF(174470.0499999999=0,0,D25/174470.0499999999) | I25: =IF(C25=0,0,D25/C25)
B26: Quality Concrete Products, Inc. | C26: 4 | D26: 1821 | E26: =IF(174470.0499999999=0,0,D26/174470.0499999999) | I26: =IF(C26=0,0,D26/C26)
B27: Rosen Supply Company, Inc. | C27: 2 | D27: 1040.84 | E27: =IF(174470.0499999999=0,0,D27/174470.0499999999) | I27: =IF(C27=0,0,D27/C27)
B28: Ferguson Enterprises, Inc. #3007 | C28: 1 | D28: 245.19 | E28: =IF(174470.0499999999=0,0,D28/174470.0499999999) | I28: =IF(C28=0,0,D28/C28)
B29: Bank of America CC | C29: 1 | D29: 210 | E29: =IF(174470.0499999999=0,0,D29/174470.0499999999) | I29: =IF(C29=0,0,D29/C29)
B30: Capital One Credit Card | C30: 3 | D30: 167.8 | E30: =IF(174470.0499999999=0,0,D30/174470.0499999999) | I30: =IF(C30=0,0,D30/C30)
B31: R.A. Brown Backflow Testing | C31: 1 | D31: 129 | E31: =IF(174470.0499999999=0,0,D31/174470.0499999999) | I31: =IF(C31=0,0,D31/C31)
B32: C.M. Hoskins Company | C32: 2 | D32: 97.4 | E32: =IF(174470.0499999999=0,0,D32/174470.0499999999) | I32: =IF(C32=0,0,D32/C32)
B33: DRSi | C33: 1 | D33: 95.08 | E33: =IF(174470.0499999999=0,0,D33/174470.0499999999) | I33: =IF(C33=0,0,D33/C33)
B34: TOTAL | C34: =SUM(C21:C33) | D34: =SUM(D21:D33) | E34: 1
B37: SOURCES
B38: Job #2009 — Chinn Greenwood Apartments • GC: Chinn Construction, LLC • Seattle, WA
B39: Canonical source: 2009 Job Detail Report.pdf (49 pages, OWP Sage Timberline export)
B40: Cost codes parsed: 26
B41: Unit count (168) and fixture count (812) from greenwood h20 stacks.xls and trim POs
B42: 3-level building + lobby: L1 (18 units), L2 (18 units), L3 (18 units), LW (amenity) × south/north stacks
B43: Billing: GREENWOOD AGGREGATE BILLING.xlsx (11 pay apps Jul 2012 – Oct 2013)
B44: Final contract $394,208 (original $384,900 + $9,308 COs)
B45: Vendor AP ties to JDR 'by Source: AP' line (174,470.05)

Sheet Crew & Labor
B2: Crew & Labor — Per-Worker Breakdown
B4: Worker | C4: Hours | D4: Gross Pay | E4: $/Hour | F4: Tier
B5: Quintanilla, Esteban R | C5: 569 | D5: 17070 | E5: =IF(C5=0,0,D5/C5) | F5: Senior
B6: Sanders, Allen O | C6: 432.5 | D6: 10872 | E6: =IF(C6=0,0,D6/C6) | F6: Mid
B7: Mazil, Antonio | C7: 416 | D7: 5264 | E7: =IF(C7=0,0,D7/C7) | F7: Apprentice
B8: Castro Hernandez, Carlos E | C8: 349 | D8: 7678 | E8: =IF(C8=0,0,D8/C8) | F8: Mid
B9: Palma Vides, Hugo | C9: 304 | D9: 7600 | E9: =IF(C9=0,0,D9/C9) | F9: Mid
B10: Ramirez, Lorenzo A | C10: 269 | D10: 3982 | E10: =IF(C10=0,0,D10/C10) | F10: Apprentice
B11: Castro Hernandez, Jose A | C11: 236 | D11: 3304 | E11: =IF(C11=0,0,D11/C11) | F11: Apprentice
B12: Arreola, Israel A | C12: 221 | D12: 2487 | E12: =IF(C12=0,0,D12/C12) | F12: Apprentice
B13: Soto Cruz, Jovani | C13: 210.5 | D13: 2859.5 | E13: =IF(C13=0,0,D13/C13) | F13: Apprentice
B14: Cortes Mendiola, Victor H | C14: 208 | D14: 4136 | E14: =IF(C14=0,0,D14/C14) | F14: Mid
B15: Meza Fuentes, Erick A | C15: 192 | D15: 2880 | E15: =IF(C15=0,0,D15/C15) | F15: Apprentice
B16: Gerard, Jeffrey S | C16: 164 | D16: 5435.2 | E16: =IF(C16=0,0,D16/C16) | F16: Senior
... B27: Lima Romero, Melvin A | C27: 1 | D27: 17 | E27: =IF(C27=0,0,D27/C27) | F27: Apprentice
B28: TOTAL (23 workers) | C28: =SUM(C5:C27) | D28: =SUM(D5:D27) | E28: =IF(C28=0,0,D28/C28)
B31: SOURCES
B32: Job #2009 — Chinn Greenwood Apartments • GC: Chinn Construction, LLC • Seattle, WA
B33: Canonical source: 2009 Job Detail Report.pdf (49 pages, OWP Sage Timberline export)
B34: Cost codes parsed: 26
B35: Unit count (168) and fixture count (812) from greenwood h20 stacks.xls and trim POs
B36: 3-level building + lobby: L1 (18 units), L2 (18 units), L3 (18 units), LW (amenity) × south/north stacks
B37: Billing: GREENWOOD AGGREGATE BILLING.xlsx (11 pay apps Jul 2012 – Oct 2013)
B38: Final contract $394,208 (original $384,900 + $9,308 COs)
B39: Tier: Apprentice <$18/hr, Mid $18–30, Senior >$30

Sheet Crew Analytics
B2: Crew Analytics
B4: A. TIER DISTRIBUTION
B5: Tier | C5: # Workers | D5: Hours | E5: Gross Pay | F5: % of Hours
B6: Senior | C6: 3 | D6: 740 | E6: 22729.2 | F6: =IF(4159.0=0,0,D6/4159.0)
B7: Mid | C7: 9 | D7: 1699.5 | E7: 40217 | F7: =IF(4159.0=0,0,D7/4159.0)
B8: Apprentice | C8: 11 | D8: 1719.5 | E8: 23021.5 | F8: =IF(4159.0=0,0,D8/4159.0)
B11: B. WAGE STATISTICS
B12: Blended Gross Wage | C12: 20.670281 | F12: Payroll $ ÷ payroll hours (pre-burden)
B13: Fully-Loaded Wage | C13: 29.284193 | F13: (Labor + Burden) ÷ total hours
B14: Burden Multiplier | C14: 1.4167293 | F14: Fully loaded ÷ gross wage
B15: Min Worker Rate | C15: 11 | F15: Cheapest apprentice hour
B16: Max Worker Rate | C16: 33.141463 | F16: Most expensive foreman hour
B17: Avg Hours / Worker | C17: 180.82609 | F17: Crew continuity indicator
B20: SOURCES
B21: Job #2009 — Chinn Greenwood Apartments • GC: Chinn Construction, LLC • Seattle, WA
B22: Canonical source: 2009 Job Detail Report.pdf (49 pages, OWP Sage Timberline export)
B23: Cost codes parsed: 26
B24: Unit count (168) and fixture count (812) from greenwood h20 stacks.xls and trim POs
B25: 3-level building + lobby: L1 (18 units), L2 (18 units), L3 (18 units), LW (amenity) × south/north stacks
B26: Billing: GREENWOOD AGGREGATE BILLING.xlsx (11 pay apps Jul 2012 – Oct 2013)
B27: Final contract $394,208 (original $384,900 + $9,308 COs)

Sheet Productivity
B2: Productivity — Phase & Unit Metrics
B4: A. LABOR HOURS BY PHASE
B5: Phase | C5: Labor Code | D5: Hours | E5: % of Total | F5: Hours / Unit
B6: DS & RD | C6: 011 | D6: 76 | E6: =IF(3928.5=0,0,D6/3928.5) | F6: =IF(168=0,0,D6/168)
B7: Supervision | C7: 100 | D7: 90 | E7: =IF(3928.5=0,0,D7/3928.5) | F7: =IF(168=0,0,D7/168)
B8: Takeoff & Purchasing | C8: 101 | D8: 40 | E8: =IF(3928.5=0,0,D8/3928.5) | F8: =IF(168=0,0,D8/168)
B9: Underground | C9: 110 | D9: 213.5 | E9: =IF(3928.5=0,0,D9/3928.5) | F9: =IF(168=0,0,D9/168)
B10: Garage | C10: 111 | D10: 488 | E10: =IF(3928.5=0,0,D10/3928.5) | F10: =IF(168=0,0,D10/168)
B11: Canout | C11: 112 | D11: 69.5 | E11: =IF(3928.5=0,0,D11/3928.5) | F11: =IF(168=0,0,D11/168)
B12: Roughin | C12: 120 | D12: 2311 | E12: =IF(3928.5=0,0,D12/3928.5) | F12: =IF(168=0,0,D12/168)
B13: Finish | C13: 130 | D13: 557.5 | E13: =IF(3928.5=0,0,D13/3928.5) | F13: =IF(168=0,0,D13/168)
B14: Water Main / Insulation | C14: 141 | D14: 16 | E14: =IF(3928.5=0,0,D14/3928.5) | F14: =IF(168=0,0,D14/168)
B15: Mech Room | C15: 142 | D15: 63 | E15: =IF(3928.5=0,0,D15/3928.5) | F15: =IF(168=0,0,D15/168)
B16: Tub / Shower | C16: 145 | D16: 4 | E16: =IF(3928.5=0,0,D16/3928.5) | F16: =IF(168=0,0,D16/168)
B17: TOTAL | D17: =SUM(D6:D16) | E17: 1 | F17: =IF(168=0,0,D17/168)
B20: B. PRODUCTIVITY RATIOS
B21: Metric | C21: Value | D21: Units | F21: Notes
B22: Hours / Unit | C22: 23.383929 | D22: hrs | F22: Labor hours per residential unit
B23: Hours / Fixture | C23: 4.8380542 | D23: hrs | F23: Labor hours per plumbing fixture
B24: Revenue / Hour | C24: 100.34568 | D24: $ | F24: Top-line per labor hour
B25: Profit / Hour | C25: 28.978015 | D25: $ | F25: Bottom-line per labor hour
B26: Units / Month | C26: 10.5 | D26: units | F26: Build velocity
B27: Fixtures / Month | C27: 50.75 | D27: fix | F27: Fixture install pace
B28: Hours / Month | C28: 245.53125 | D28: hrs | F28: Monthly labor burn
B29: Revenue / Month | C29: 24638 | D29: $ | F29: Monthly billing rate
B32: SOURCES
B33: Job #2009 — Chinn Greenwood Apartments • GC: Chinn Construction, LLC • Seattle, WA
B34: Canonical source: 2009 Job Detail Report.pdf (49 pages, OWP Sage Timberline export)
B35: Cost codes parsed: 26
B36: Unit count (168) and fixture count (812) from greenwood h20 stacks.xls and trim POs
B37: 3-level building + lobby: L1 (18 units), L2 (18 units), L3 (18 units), LW (amenity) × south/north stacks
B38: Billing: GREENWOOD AGGREGATE BILLING.xlsx (11 pay apps Jul 2012 – Oct 2013)
B39: Final contract $394,208 (original $384,900 + $9,308 COs)

Sheet PO Commitments
B2: Purchase Order Commitments
B3: 7 unique POs • PO amounts not dollar-parsed from individual PDFs • JDR material $151,064
B5: A. COMMITMENTS BY COST CODE
B6: OWP Code | C6: Description → JDR | D6: PO Count | E6: % of POs | F6: JDR Material
B7: 32 | C7: 130+230 Trim/Finish | D7: 5 | E7: =IF(7=0,0,D7/7)
B8: OTHER | C8: Unclassified | D8: 2 | E8: =IF(7=0,0,D8/7)
B9: TOTAL | D9: =SUM(D7:D8) | E9: 1 | F9: 151064.39
B12: B. COMMITMENTS BY VENDOR
B13: Vendor | C13: PO Count | D13: % of POs
B14: OTHER | C14: 6 | D14: =IF(7=0,0,C14/7)
B15: FEI | C15: 1 | D15: =IF(7=0,0,C15/7)
B18: C. PO COVERAGE NOTES
B19: Total Material Actual (JDR) | E19: 151064.39
B20: Unique PO Count | E20: 7
B21: (Dollar PO commitment not extracted — requires per-PDF parse)
B24: SOURCES
B25: Job #2009 — Chinn Greenwood Apartments • GC: Chinn Construction, LLC • Seattle, WA
B26: Canonical source: 2009 Job Detail Report.pdf (49 pages, OWP Sage Timberline export)
B27: Cost codes parsed: 26
B28: Unit count (168) and fixture count (812) from greenwood h20 stacks.xls and trim POs
B29: 3-level building + lobby: L1 (18 units), L2 (18 units), L3 (18 units), LW (amenity) × south/north stacks
B30: Billing: GREENWOOD AGGREGATE BILLING.xlsx (11 pay apps Jul 2012 – Oct 2013)
B31: Final contract $394,208 (original $384,900 + $9,308 COs)
B32: PO count is deduplicated by 5-digit PO number extracted from filenames
B33: Vendor/code classification is heuristic (filename keyword match)

Sheet Billing & SOV
B2: Revenue & Billing Reconciliation
B3: 11 pay applications • Jul 2012 – Oct 2013 • $394,208 final
B5: A. CONTRACT SUMMARY
B6: Original Contract | G6: 384900
B7: Change Orders (net) | G7: 9308
B8: Final Contract Value | G8: 394208
B9: Retainage (5%) | G9: 19710
B10: Net Paid to OWP | G10: 374498
B12: B. PAY APPLICATION TIMELINE
B13: App# | C13: Date | D13: Period Billing | E13: Retention | F13: Net This Period | G13: Aggregate | H13: % Complete
B14: 1 | C14: 2012-07-20 | D14: 12200 | E14: 610 | F14: =D14-E14 | G14: 11590 | H14: =IF(394208.0=0,0,G14/394208.0)
B15: 2 | C15: 2012-08-20 | D15: 39500 | E15: 1975 | F15: =D15-E15 | G15: 49115 | H15: =IF(394208.0=0,0,G15/394208.0)
B16: 3 | C16: 2012-09-20 | D16: 8300 | E16: 415 | F16: =D16-E16 | G16: 57000 | H16: =IF(394208.0=0,0,G16/394208.0)
B17: 4 | C17: 2012-10-20 | D17: 88500 | E17: 4425 | F17: =D17-E17 | G17: 141075 | H17: =IF(394208.0=0,0,G17/394208.0)
B18: 5 | C18: 2012-11-15 | D18: 112480 | E18: 5624 | F18: =D18-E18 | G18: 247931 | H18: =IF(394208.0=0,0,G18/394208.0)
B19: 6 | C19: 2012-12-20 | D19: 13250 | E19: 662.5 | F19: =D19-E19 | G19: 260518.5 | H19: =IF(394208.0=0,0,G19/394208.0)
B20: 7 | C20: 2013-02-19 | D20: 28485 | E20: 1424.25 | F20: =D20-E20 | G20: 287579.25 | H20: =IF(394208.0=0,0,G20/394208.0)
B21: 8 | C21: 2013-03-19 | D21: 6400 | E21: 320 | F21: =D21-E21 | G21: 293659.25 | H21: =IF(394208.0=0,0,G21/394208.0)
B22: 9 | C22: 2013-04-18 | D22: 48175 | E22: 2408.75 | F22: =D22-E22 | G22: 339425.5 | H22: =IF(394208.0=0,0,G22/394208.0)
B23: 10 | C23: 2013-05-19 | D23: 35494 | E23: 1774.7 | F23: =D23-E23 | G23: 373144.8 | H23: =IF(394208.0=0,0,G23/394208.0)
B24: 11 | C24: 2013-08-13 | D24: 1424 | E24: 71.2 | F24: =D24-E24 | G24: 374497.6 | H24: =IF(394208.0=0,0,G24/394208.0)
B25: 13 | C25: 2013-10-24 | D25: 19710.4 | E25: 0 | F25: =D25-E25 | G25: 392208 | H25: =IF(394208.0=0,0,G25/394208.0)
B27: C. BILLING ↔ JDR TIE-OUT
B28: Metric | C28: SOV | D28: JDR | E28: Δ | F28: Status
B29: Final Contract Value | C29: 394208 | D29: 394208 | E29: =C29-D29 | F29: =IF(ABS(E29)<=1,"TIES",IF(ABS(E29)<=ABS(D29)*0.05,"WITHIN","OFF"))
B30: Retainage | C30: 19710 | D30: 19710 | E30: =C30-D30 | F30: =IF(ABS(E30)<=1,"TIES",IF(ABS(E30)<=ABS(D30)*0.05,"WITHIN","OFF"))
B31: Direct Cost | C31: 280368 | D31: 280368 | E31: =C31-D31 | F31: =IF(ABS(E31)<=1,"TIES",IF(ABS(E31)<=ABS(D31)*0.05,"WITHIN","OFF"))
B35: SOURCES
B36: Job #2009 — Chinn Greenwood Apartments • GC: Chinn Construction, LLC • Seattle, WA
B37: Canonical source: 2009 Job Detail Report.pdf (49 pages, OWP Sage Timberline export)
B38: Cost codes parsed: 26
B39: Unit count (168) and fixture count (812) from greenwood h20 stacks.xls and trim POs
B40: 3-level building + lobby: L1 (18 units), L2 (18 units), L3 (18 units), LW (amenity) × south/north stacks
B41: Billing: GREENWOOD AGGREGATE BILLING.xlsx (11 pay apps Jul 2012 – Oct 2013)
B42: Final contract $394,208 (original $384,900 + $9,308 COs)

Sheet Insights
B2: Key Insights — Job #2009 Chinn Greenwood Apartments
B3: Narrative observations distilled from the full JDR analysis
B5: MARGIN PROFILE | C5: Net profit of $113,840 on $394,208 revenue = 28.9% gross margin. Direct cost $280,368 absorbs 71.1% of revenue.
B6: VENDOR CONCENTRATION | C6: Ferguson Enterprises, Inc. alone = $117,439 (67% of all AP) across 65 invoices. Total 13 AP vendors, $174,470 total AP spend.
B7: CREW PROFILE | C7: 23 workers for 3,928 hours = 171 avg hrs/worker. Top 3 workers logged 1,418 hrs combined (36% of all labor).
B8: ROUGHIN DOMINANCE | C8: Code 120 Roughin Labor = 2,311 hrs (59% of all labor) and $46,114 actual. Code 230 Finish Material = $109,976 — 39% of total direct cost.
B9: BUDGET DELIVERY | C9: Revised budget was $317,000; actual direct cost $280,368 → $36,632 variance (11.6% under revised budget).
B10: CONTRACT GROWTH | C10: Contract grew from $384,900 to $394,208 — net +$9,308 (2.4%). Retainage of $19,710 (5%) withheld until closeout.
B11: BURDEN RATIO | C11: Burden codes 995 + 998 = $40,891 on $80,902 labor base = 50.5%. In line with OWP's typical 48–50% labor burden.
B12: PROJECT SCALE | C12: 168 units · 812 fixtures · 16 months. Revenue/unit $2,346, hours/unit 23.4, profit/unit $678.
B13: PRODUCTIVITY | C13: Blended labor rate $20.59/hr. Revenue/hour $100. Profit/hour $29. 246 hrs/month burn rate.
B14: FIXTURE DENSITY | C14: 812 fixtures ÷ 168 units = 4.83 fixtures/unit. Material/fixture $186, labor/fixture $100.
B16: BIGGEST QUESTION
B17: How does this job's 28.9% margin compare across similar projects in the OWP portfolio, and what operational levers drove the result — estimating accuracy, vendor pricing, or labor productivity?
B20: SOURCES
B21: Job #2009 — Chinn Greenwood Apartments • GC: Chinn Construction, LLC • Seattle, WA
B22: Canonical source: 2009 Job Detail Report.pdf (49 pages, OWP Sage Timberline export)
B23: Cost codes parsed: 26
B24: Unit count (168) and fixture count (812) from greenwood h20 stacks.xls and trim POs
B25: 3-level building + lobby: L1 (18 units), L2 (18 units), L3 (18 units), LW (amenity) × south/north stacks
B26: Billing: GREENWOOD AGGREGATE BILLING.xlsx (11 pay apps Jul 2012 – Oct 2013)
B27: Final contract $394,208 (original $384,900 + $9,308 COs)

Sheet Benchmark KPIs
B2: Benchmark KPIs
B3: Normalized metrics designed for apples-to-apples comparison across all OWP projects
B5: KPI | C5: Data Name | D5: Value | E5: Category | F5: Notes
B6: Job Number | C6: job_number | D6: 2009 | E6: Profile | F6: OWP job ID
B7: Job Name | C7: job_name | D7: Chinn Greenwood Apartments | E7: Profile
B8: General Contractor | C8: general_contractor | D8: Chinn Construction, LLC | E8: Profile
B9: Location | C9: location | D9: Seattle, WA | E9: Profile
B10: Project Type | C10: project_type | D10: 168-unit apartment building | E10: Profile
B11: Duration (months) | C11: duration_months | D11: 16 | E11: Profile | F11: Jul 2012 – Oct 2013 (~16 months)
B12: Unit Count | C12: unit_count | D12: 168 | E12: Profile
B13: Total Fixtures | C13: total_fixtures | D13: 812 | E13: Profile
B14: Fixtures per Unit | C14: fixtures_per_unit | D14: 4.8333333 | E14: Profile
B15: Contract Value (Orig) | C15: contract_original | D15: 384900 | E15: Financial
B16: Contract Value (Final) | C16: contract_final | D16: 394208 | E16: Financial | F16: After change orders
B17: Change Orders ($) | C17: change_orders | D17: 9308 | E17: Financial
B18: Revenue | C18: revenue | D18: 394208 | E18: Financial
B19: Net Profit | C19: net_profit | D19: 113840.13 | E19: Financial
B20: Gross Margin | C20: gross_margin | D20: 0.28878189 | E20: Financial
B21: Direct Cost | C21: direct_cost | D21: 280367.87 | E21: Financial
B22: Labor Cost | C22: labor_cost | D22: 80901.5 | E22: Labor | F22: Sum of 11 labor codes
B23: Material Cost | C23: material_cost | D23: 151064.39 | E23: Material | F23: Sum of 9 material codes
B24: Overhead Cost | C24: overhead_cost | D24: 7510.52 | E24: Financial | F24: Sub+Eng+Permits
B25: Burden Cost | C25: burden_cost | D25: 40891.46 | E25: Financial | F25: Codes 995+998
B26: Retainage | C26: retainage | D26: 19710.4 | E26: Financial | F26: 5% withheld
B27: Revenue per Unit | C27: revenue_per_unit | D27: 2346.4762 | E27: Financial
B28: Profit per Unit | C28: profit_per_unit | D28: 677.61982 | E28: Financial
B29: Direct Cost per Unit | C29: cost_per_unit | D29: 1668.8564 | E29: Financial
B30: Labor Cost per Unit | C30: labor_per_unit | D30: 481.55655 | E30: Labor
B31: Material Cost per Unit | C31: material_per_unit | D31: 899.1928 | E31: Material
B32: Revenue per Fixture | C32: revenue_per_fixture | D32: 485.47783 | E32: Financial
B33: Profit per Fixture | C33: profit_per_fixture | D33: 140.1972 | E33: Financial
B34: Cost per Fixture | C34: cost_per_fixture | D34: 345.28063 | E34: Financial
B35: Labor per Fixture | C35: labor_per_fixture | D35: 99.632389 | E35: Labor
B36: Material per Fixture | C36: material_per_fixture | D36: 186.03989 | E36: Material
B37: Total Labor Hours | C37: total_hours | D37: 3928.5 | E37: Labor | F37: Sum of JDR cost code hours
B38: Total Workers | C38: total_workers | D38: 23 | E38: Labor | F38: Unique payroll IDs
B39: Blended Gross Wage | C39: blended_gross_wage | D39: 21.883085 | E39: Labor | F39: Pre-burden
B40: Fully-Loaded Wage | C40: fully_loaded_wage | D40: 31.002408 | E40: Labor | F40: Post-burden
B41: Burden Multiplier | C41: burden_multiplier | D41: 1.4167293 | E41: Labor
B42: Hours per Unit | C42: hours_per_unit | D42: 23.383929 | E42: Labor | F42: Key benchmark
...

Sheet Vendors
A1: Vendor Detail — Job #2009
A3: Vendors | B3: 13 | D3: Top vendor | E3: Ferguson Enterprises, Inc.
A4: Invoices | B4: 98 | D4: Top 3 share | E4: =163518.73999999993/174470.0499999999
A5: Total AP | B5: 174470.05 | D5: Source | E5: Job Detail Report (Sage Timberline AP export)
A6: Avg Inv | B6: =B5/B4
A8: Rank | B8: Vendor | C8: Vendor Code | D8: Invoices | E8: Total Spend | F8: % of AP | G8: Avg / Invoice
A9: 1 | B9: Ferguson Enterprises, Inc. | D9: 65 | E9: 117439.01 | F9: =E9/E$22 | G9: =IF(D9=0,0,E9/D9)
A10: 2 | B10: Keller Supply Company | D10: 14 | E10: 29740.43 | F10: =E10/E$22 | G10: =IF(D10=0,0,E10/D10)
A11: 3 | B11: Mechanical Sales, Inc. | D11: 2 | E11: 16339.3 | F11: =E11/E$22 | G11: =IF(D11=0,0,E11/D11)
A12: 4 | B12: Franklin Engineering | D12: 1 | E12: 4895 | F12: =E12/E$22 | G12: =IF(D12=0,0,E12/D12)
A13: 5 | B13: Mickelo Construction LLC | D13: 1 | E13: 2250 | F13: =E13/E$22 | G13: =IF(D13=0,0,E13/D13)
A14: 6 | B14: Quality Concrete Products, Inc. | D14: 4 | E14: 1821 | F14: =E14/E$22 | G14: =IF(D14=0,0,E14/D14)
A15: 7 | B15: Rosen Supply Company, Inc. | D15: 2 | E15: 1040.84 | F15: =E15/E$22 | G15: =IF(D15=0,0,E15/D15)
A16: 8 | B16: Ferguson Enterprises, Inc. #3007 | D16: 1 | E16: 245.19 | F16: =E16/E$22 | G16: =IF(D16=0,0,E16/D16)
A17: 9 | B17: Bank of America CC | D17: 1 | E17: 210 | F17: =E17/E$22 | G17: =IF(D17=0,0,E17/D17)
A18: 10 | B18: Capital One Credit Card | D18: 3 | E18: 167.8 | F18: =E18/E$22 | G18: =IF(D18=0,0,E18/D18)
A19: 11 | B19: R.A. Brown Backflow Testing | D19: 1 | E19: 129 | F19: =E19/E$22 | G19: =IF(D19=0,0,E19/D19)
A20: 12 | B20: C.M. Hoskins Company | D20: 2 | E20: 97.4 | F20: =E20/E$22 | G20: =IF(D20=0,0,E20/D20)
A21: 13 | B21: DRSi | D21: 1 | E21: 95.08 | F21: =E21/E$22 | G21: =IF(D21=0,0,E21/D21)
B22: TOTAL | D22: =SUM(D9:D21) | E22: =SUM(E9:E21) | F22: =SUM(F9:F21) | G22: =IF(D22=0,0,E22/D22)

Sheet Reconciliation
B2: Reconciliation — Cross-Tab Tie-out Proofs
B3: Live cross-sheet formulas verify data consistency across all 12 source tabs
B4: Check | C4: Tab A | D4: Tab B | E4: Δ | F4: Status | G4: Tabs
B5: A. OVERVIEW ↔ BENCHMARK KPIS
B6: Direct Cost Total | C6: ='Overview'!D24 | D6: ='Benchmark KPIs'!D21 | E6: =C6-D6 | F6: =IF(ABS(E6)<=1,"TIES",IF(ABS(E6)<=ABS(D6)*0.05,"WITHIN","OFF")) | G6: 1↔2↔11
B7: Contract Final Value | C7: 394208 | D7: ='Benchmark KPIs'!D16 | E7: =C7-D7 | F7: =IF(ABS(E7)<=1,"TIES",IF(ABS(E7)<=ABS(D7)*0.05,"WITHIN","OFF")) | G7: JDR↔11
B8: Net Profit | C8: 113840.13 | D8: ='Benchmark KPIs'!D19 | E8: =C8-D8 | F8: =IF(ABS(E8)<=1,"TIES",IF(ABS(E8)<=ABS(D8)*0.05,"WITHIN","OFF")) | G8: JDR↔11
B9: Gross Margin | C9: 0.28878189 | D9: ='Benchmark KPIs'!D20 | E9: =C9-D9 | F9: =IF(ABS(E9)<=1,"TIES",IF(ABS(E9)<=ABS(D9)*0.05,"WITHIN","OFF")) | G9: JDR↔11
B11: B. OVERVIEW ↔ COST BREAKDOWN (Category Actuals)
B12: Labor Actual | C12: ='Overview'!D20 | D12: ='Cost Breakdown'!E6 | E12: =C12-D12 | F12: =IF(ABS(E12)<=1,"TIES",IF(ABS(E12)<=ABS(D12)*0.05,"WITHIN","OFF")) | G12: 1↔3
B13: Material Actual | C13: ='Overview'!D21 | D13: ='Cost Breakdown'!E7 | E13: =C13-D13 | F13: =IF(ABS(E13)<=1,"TIES",IF(ABS(E13)<=ABS(D13)*0.05,"WITHIN","OFF")) | G13: 1↔3
B14: Overhead Actual | C14: ='Overview'!D22 | D14: ='Cost Breakdown'!E8 | E14: =C14-D14 | F14: =IF(ABS(E14)<=1,"TIES",IF(ABS(E14)<=ABS(D14)*0.05,"WITHIN","OFF")) | G14: 1↔3
B15: Burden Actual | C15: ='Overview'!D23 | D15: ='Cost Breakdown'!E9 | E15: =C15-D15 | F15: =IF(ABS(E15)<=1,"TIES",IF(ABS(E15)<=ABS(D15)*0.05,"WITHIN","OFF")) | G15: 1↔3
B17: C. BUDGET vs ACTUAL ↔ OVERVIEW
B18: Actual Direct Cost | C18: ='Budget vs Actual'!F34 | D18: ='Overview'!D24 | E18: =C18-D18 | F18: =IF(ABS(E18)<=1,"TIES",IF(ABS(E18)<=ABS(D18)*0.05,"WITHIN","OFF")) | G18: 2↔1
B19: Revised Budget Total | C19: ='Budget vs Actual'!E34 | D19: ='Overview'!C24 | E19: =C19-D19 | F19: =IF(ABS(E19)<=1,"TIES",IF(ABS(E19)<=ABS(D19)*0.05,"WITHIN","OFF")) | G19: 2↔1
B21: D. MATERIAL ↔ COST BREAKDOWN ↔ KPIS
B22: Material Actual (Material tab) | C22: ='Material'!E16 | D22: ='Cost Breakdown'!E7 | E22: =C22-D22 | F22: =IF(ABS(E22)<=1,"TIES",IF(ABS(E22)<=ABS(D22)*0.05,"WITHIN","OFF")) | G22: 4↔3
B23: Material Actual (KPIs) | C23: ='Benchmark KPIs'!D23 | D23: ='Cost Breakdown'!E7 | E23: =C23-D23 | F23: =IF(ABS(E23)<=1,"TIES",IF(ABS(E23)<=ABS(D23)*0.05,"WITHIN","OFF")) | G23: 11↔3
B25: E. CREW & LABOR ↔ PRODUCTIVITY ↔ KPIS (Hours)
B26: Total Hours (Crew tab) | C26: ='Crew & Labor'!C28 | D26: ='Benchmark KPIs'!D37 | E26: =C26-D26 | F26: =IF(ABS(E26)<=5,"TIES",IF(ABS(E26)<=ABS(D26)*0.05,"WITHIN","OFF")) | G26: 5↔11
B27: Total Hours (Productivity tab) | C27: ='Productivity'!D17 | D27: ='Benchmark KPIs'!D37 | E27: =C27-D27 | F27: =IF(ABS(E27)<=5,"TIES",IF(ABS(E27)<=ABS(D27)*0.05,"WITHIN","OFF")) | G27: 7↔11
B28: Total Workers | C28: 23 | D28: ='Benchmark KPIs'!D38 | E28: =C28-D28 | F28: =IF(E28=0,"TIES",IF(ABS(E28)<=1,"WITHIN","OFF")) | G28: JDR↔11
B30: F. CREW ANALYTICS ↔ KPIS (Wage Statistics)
B31: Blended Gross Wage | C31: ='Crew Analytics'!C12 | D31: ='Benchmark KPIs'!D39 | E31: =C31-D31 | F31: =IF(ABS(E31)<=1,"TIES",IF(ABS(E31)<=ABS(D31)*0.05,"WITHIN","OFF")) | G31: 6↔11
B32: Fully-Loaded Wage | C32: ='Crew Analytics'!C13 | D32: ='Benchmark KPIs'!D40 | E32: =C32-D32 | F32: =IF(ABS(E32)<=1,"TIES",IF(ABS(E32)<=ABS(D32)*0.05,"WITHIN","OFF")) | G32: 6↔11
B34: G. PO COMMITMENTS ↔ KPIS
B35: PO Count | C35: ='PO Commitments'!D9 | D35: ='Benchmark KPIs'!D54 | E35: =C35-D35 | F35: =IF(E35=0,"TIES",IF(ABS(E35)<=1,"WITHIN","OFF")) | G35: 8↔11
B37: H. BILLING & SOV ↔ JDR
B38: Final Contract Value | C38: 394208 | D38: 394208 | E38: =C38-D38 | F38: =IF(ABS(E38)<=1,"TIES",IF(ABS(E38)<=ABS(D38)*0.05,"WITHIN","OFF")) | G38: 9↔JDR
B39: Retainage | C39: 19710 | D39: 19710 | E39: =C39-D39 | F39: =IF(ABS(E39)<=1,"TIES",IF(ABS(E39)<=ABS(D39)*0.05,"WITHIN","OFF")) | G39: 9↔JDR
B40: Direct Cost | C40: 280368 | D40: 280368 | E40: =C40-D40 | F40: =IF(ABS(E40)<=1,"TIES",IF(ABS(E40)<=ABS(D40)*0.05,"WITHIN","OFF")) | G40: 9↔JDR
B42: I. VENDORS ↔ KPIS
B43: Vendor Count | C43: ='Vendors'!B3 | D43: ='Benchmark KPIs'!D51 | E43: =C43-D43 | F43: =IF(E43=0,"TIES",IF(ABS(E43)<=1,"WITHIN","OFF")) | G43: 12↔11
B44: Total AP Spend | C44: ='Vendors'!E22 | D44: 174470 | E44: =C44-D44 | F44: =IF(ABS(E44)<=1,"TIES",IF(ABS(E44)<=ABS(D44)*0.05,"WITHIN","OFF")) | G44: 12↔JDR
B46: J. INSIGHTS (Narrative Review)
B47: 10 insight cards — narrative text verified at generation time, no formula check applicable
B49: SOURCES
B50: Job #2009 — Chinn Greenwood Apartments • GC: Chinn Construction, LLC • Seattle, WA
B51: Canonical source: 2009 Job Detail Report.pdf (49 pages, OWP Sage Timberline export)
...
