Workbook

Sheet Inputs
B2: Inputs — Canonical Job Data
B3: All values sourced from each job's JCR Summary workbook. Blue = hardcoded input.
B5: Metric | C5: Job #2011 | D5: Job #2012 | E5: Source / Notes
B6: — PROFILE —
B7: Job Name | C7: Chinn Barrett Park | D7: Exxel 8th Ave
B8: General Contractor | C8: Chinn Construction, LLC | D8: Exxel Pacific, Inc.
B9: Location | C9: Seattle, WA | D9: Seattle, WA
B10: Duration (months) | C10: 17 | D10: 17 | E10: Nov 2012–Mar 2014 / Jan 2013–Jun 2014
B11: Unit Count | C11: 117 | D11: 163 | E11: Residential units
B12: Total Fixtures | C12: 590 | D12: 816 | E12: All in-unit plumbing fixtures
B13: — FINANCIAL —
B14: Original Contract | C14: 813050 | D14: 1394655
B15: Final Contract / Revenue | C15: 869824 | D15: 1391455 | E15: Incl. change orders
B16: Change Orders | C16: 56774 | D16: 0 | E16: 2011: 3 COs; 2012: none in JCR
B17: Net Profit | C17: 332960 | D17: 533274
B18: Direct Cost | C18: 536863 | D18: 858181 | E18: Labor + Material + OH + Burden
B19: Retainage | C19: 43491 | D19: 69573 | E19: 5% held by GC
B20: — COST MIX —
B21: Labor Cost | C21: 142883 | D21: 271219 | E21: 2012 labor = avg_rate 18.57 × 14,607h (derived)
B22: Material Cost | C22: 295006 | D22: 408537
B23: Overhead Cost | C23: 26210 | D23: 9697
B24: Burden Cost | C24: 72765 | D24: 168728 | E24: 2012: gross×0.51 burden multiplier
B25: — LABOR —
B26: Total Labor Hours | C26: 6944 | D26: 14607
B27: Total Workers | C27: 31 | D27: 28 | E27: Unique payroll IDs
B28: Blended Gross Wage ($/hr) | C28: 20.58 | D28: 19.94 | E28: Pre-burden
B29: Fully-Loaded Wage ($/hr) | C29: 31.08 | D29: 30.12 | E29: Post-burden
B30: — MATERIAL —
B31: Total PO Committed | C31: 124908 | D31: 0 | E31: 2012 tracks via AP invoices, not POs
B32: Total POs | C32: 26 | D32: 0
B33: Material Vendors | C33: 14 | D33: 17 | E33: Distinct AP vendors
B36: Sources: OWP_2011_JCR_Summary.xlsx (Chinn Barrett Park) + OWP_2012_JCR_Summary_Notion.xlsx (Exxel 8th Ave). Both reconcile exactly to their source JCR PDFs.

Sheet Comparison
B2: Job #2011 vs Job #2012 — Head-to-Head Benchmark
B3: Chinn Barrett Park (117 units) vs Exxel 8th Ave (163 units) • both 17-month Seattle multifamily plumbing jobs
B5: Metric | C5: 2011 Barrett | D5: 2012 Exxel | E5: Δ ($ / #) | F5: Δ % | G5: Leader
B6: A. PROJECT SCALE
B7: Unit Count | C7: =Inputs!C11 -> 117 | D7: =Inputs!D11 -> 163 | E7: =D7-C7 -> 46 | F7: =IF(C7=0,0,(D7-C7)/ABS(C7)) -> 0.39316239 | G7: =IF(ABS(D7-C7)/MAX(ABS(C7),0.0001)<0.02,"Tie",IF(D7>C7,"2012","2011")) -> 2012
B8: Total Fixtures | C8: =Inputs!C12 -> 590 | D8: =Inputs!D12 -> 816 | E8: =D8-C8 -> 226 | F8: =IF(C8=0,0,(D8-C8)/ABS(C8)) -> 0.38305085 | G8: =IF(ABS(D8-C8)/MAX(ABS(C8),0.0001)<0.02,"Tie",IF(D8>C8,"2012","2011")) -> 2012
B9: Duration (months) | C9: =Inputs!C10 -> 17 | D9: =Inputs!D10 -> 17 | E9: =D9-C9 -> 0 | F9: =IF(C9=0,0,(D9-C9)/ABS(C9)) -> 0 | G9: =IF(ABS(D9-C9)/MAX(ABS(C9),0.0001)<0.02,"Tie",IF(D9<C9,"2012","2011")) -> Tie
B10: Fixtures / Unit | C10: =Inputs!C12/Inputs!C11 -> 5.042735 | D10: =Inputs!D12/Inputs!D11 -> 5.006135 | E10: =D10-C10 -> -0.036600073 | F10: =IF(C10=0,0,(D10-C10)/ABS(C10)) -> -0.0072579807 | G10: =IF(ABS(D10-C10)/MAX(ABS(C10),0.0001)<0.02,"Tie",IF(D10>C10,"2012","2011")) -> Tie
B11: B. TOP-LINE FINANCIAL
B12: Revenue (Final Contract) | C12: =Inputs!C15 -> 869824 | D12: =Inputs!D15 -> 1391455 | E12: =D12-C12 -> 521631 | F12: =IF(C12=0,0,(D12-C12)/ABS(C12)) -> 0.59969718 | G12: =IF(ABS(D12-C12)/MAX(ABS(C12),0.0001)<0.02,"Tie",IF(D12>C12,"2012","2011")) -> 2012
B13: Net Profit | C13: =Inputs!C17 -> 332960 | D13: =Inputs!D17 -> 533274 | E13: =D13-C13 -> 200314 | F13: =IF(C13=0,0,(D13-C13)/ABS(C13)) -> 0.60161581 | G13: =IF(ABS(D13-C13)/MAX(ABS(C13),0.0001)<0.02,"Tie",IF(D13>C13,"2012","2011")) -> 2012
B14: Direct Cost | C14: =Inputs!C18 -> 536863 | D14: =Inputs!D18 -> 858181 | E14: =D14-C14 -> 321318 | F14: =IF(C14=0,0,(D14-C14)/ABS(C14)) -> 0.59851023 | G14: =IF(ABS(D14-C14)/MAX(ABS(C14),0.0001)<0.02,"Tie",IF(D14<C14,"2012","2011")) -> 2011
B15: Gross Margin | C15: =Inputs!C17/Inputs!C15 -> 0.38279008 | D15: =Inputs!D17/Inputs!D15 -> 0.38324919 | E15: =D15-C15 -> 0.00045910713 | F15: =IF(C15=0,0,(D15-C15)/ABS(C15)) -> 0.0011993705 | G15: =IF(ABS(D15-C15)/MAX(ABS(C15),0.0001)<0.02,"Tie",IF(D15>C15,"2012","2011")) -> Tie
B16: Change Orders ($) | C16: =Inputs!C16 -> 56774 | D16: =Inputs!D16 -> 0 | E16: =D16-C16 -> -56774 | F16: =IF(C16=0,0,(D16-C16)/ABS(C16)) -> -1 | G16: =IF(ABS(D16-C16)/MAX(ABS(C16),0.0001)<0.02,"Tie",IF(D16>C16,"2012","2011")) -> 2011
B17: Retainage | C17: =Inputs!C19 -> 43491 | D17: =Inputs!D19 -> 69573 | E17: =D17-C17 -> 26082 | F17: =IF(C17=0,0,(D17-C17)/ABS(C17)) -> 0.59971028 | G17: =IF(ABS(D17-C17)/MAX(ABS(C17),0.0001)<0.02,"Tie",IF(D17<C17,"2012","2011")) -> 2011
B18: C. PER-UNIT ECONOMICS
B19: Revenue / Unit | C19: =Inputs!C15/Inputs!C11 -> 7434.3932 | D19: =Inputs!D15/Inputs!D11 -> 8536.5337 | E19: =D19-C19 -> 1102.1406 | F19: =IF(C19=0,0,(D19-C19)/ABS(C19)) -> 0.1482489 | G19: =IF(ABS(D19-C19)/MAX(ABS(C19),0.0001)<0.02,"Tie",IF(D19>C19,"2012","2011")) -> 2012
B20: Profit / Unit | C20: =Inputs!C17/Inputs!C11 -> 2845.812 | D20: =Inputs!D17/Inputs!D11 -> 3271.6196 | E20: =D20-C20 -> 425.80767 | F20: =IF(C20=0,0,(D20-C20)/ABS(C20)) -> 0.14962607 | G20: =IF(ABS(D20-C20)/MAX(ABS(C20),0.0001)<0.02,"Tie",IF(D20>C20,"2012","2011")) -> 2012
B21: Direct Cost / Unit | C21: =Inputs!C18/Inputs!C11 -> 4588.5726 | D21: =Inputs!D18/Inputs!D11 -> 5264.9141 | E21: =D21-C21 -> 676.34146 | F21: =IF(C21=0,0,(D21-C21)/ABS(C21)) -> 0.14739692 | G21: =IF(ABS(D21-C21)/MAX(ABS(C21),0.0001)<0.02,"Tie",IF(D21<C21,"2012","2011")) -> 2011
B22: Labor Cost / Unit | C22: =Inputs!C21/Inputs!C11 -> 1221.2222 | D22: =Inputs!D21/Inputs!D11 -> 1663.9202 | E22: =D22-C22 -> 442.69802 | F22: =IF(C22=0,0,(D22-C22)/ABS(C22)) -> 0.36250407 | G22: =IF(ABS(D22-C22)/MAX(ABS(C22),0.0001)<0.02,"Tie",IF(D22<C22,"2012","2011")) -> 2011
B23: Material Cost / Unit | C23: =Inputs!C22/Inputs!C11 -> 2521.4188 | D23: =Inputs!D22/Inputs!D11 -> 2506.362 | E23: =D23-C23 -> -15.05684 | F23: =IF(C23=0,0,(D23-C23)/ABS(C23)) -> -0.0059715745 | G23: =IF(ABS(D23-C23)/MAX(ABS(C23),0.0001)<0.02,"Tie",IF(D23<C23,"2012","2011")) -> Tie
B24: Hours / Unit | C24: =Inputs!C26/Inputs!C11 -> 59.350427 | D24: =Inputs!D26/Inputs!D11 -> 89.613497 | E24: =D24-C24 -> 30.26307 | F24: =IF(C24=0,0,(D24-C24)/ABS(C24)) -> 0.50990483 | G24: =IF(ABS(D24-C24)/MAX(ABS(C24),0.0001)<0.02,"Tie",IF(D24<C24,"2012","2011")) -> 2011
B25: D. PER-FIXTURE ECONOMICS
B26: Revenue / Fixture | C26: =Inputs!C15/Inputs!C12 -> 1474.278 | D26: =Inputs!D15/Inputs!D12 -> 1705.2145 | E26: =D26-C26 -> 230.93649 | F26: =IF(C26=0,0,(D26-C26)/ABS(C26)) -> 0.15664379 | G26: =IF(ABS(D26-C26)/MAX(ABS(C26),0.0001)<0.02,"Tie",IF(D26>C26,"2012","2011")) -> 2012
B27: Profit / Fixture | C27: =Inputs!C17/Inputs!C12 -> 564.33898 | D27: =Inputs!D17/Inputs!D12 -> 653.52206 | E27: =D27-C27 -> 89.183076 | F27: =IF(C27=0,0,(D27-C27)/ABS(C27)) -> 0.15803104 | G27: =IF(ABS(D27-C27)/MAX(ABS(C27),0.0001)<0.02,"Tie",IF(D27>C27,"2012","2011")) -> 2012
B28: Direct Cost / Fixture | C28: =Inputs!C18/Inputs!C12 -> 909.93729 | D28: =Inputs!D18/Inputs!D12 -> 1051.6924 | E28: =D28-C28 -> 141.75511 | F28: =IF(C28=0,0,(D28-C28)/ABS(C28)) -> 0.15578559 | G28: =IF(ABS(D28-C28)/MAX(ABS(C28),0.0001)<0.02,"Tie",IF(D28<C28,"2012","2011")) -> 2011
B29: Labor / Fixture | C29: =Inputs!C21/Inputs!C12 -> 242.17458 | D29: =Inputs!D21/Inputs!D12 -> 332.37623 | E29: =D29-C29 -> 90.201649 | F29: =IF(C29=0,0,(D29-C29)/ABS(C29)) -> 0.3724654 | G29: =IF(ABS(D29-C29)/MAX(ABS(C29),0.0001)<0.02,"Tie",IF(D29<C29,"2012","2011")) -> 2011
B30: Material / Fixture | C30: =Inputs!C22/Inputs!C12 -> 500.01017 | D30: =Inputs!D22/Inputs!D12 -> 500.65809 | E30: =D30-C30 -> 0.64791874 | F30: =IF(C30=0,0,(D30-C30)/ABS(C30)) -> 0.0012958111 | G30: =IF(ABS(D30-C30)/MAX(ABS(C30),0.0001)<0.02,"Tie",IF(D30<C30,"2012","2011")) -> Tie
B31: Hours / Fixture | C31: =Inputs!C26/Inputs!C12 -> 11.769492 | D31: =Inputs!D26/Inputs!D12 -> 17.900735 | E31: =D31-C31 -> 6.1312438 | F31: =IF(C31=0,0,(D31-C31)/ABS(C31)) -> 0.52094381 | G31: =IF(ABS(D31-C31)/MAX(ABS(C31),0.0001)<0.02,"Tie",IF(D31<C31,"2012","2011")) -> 2011
B32: E. LABOR & PRODUCTIVITY
B33: Total Labor Hours | C33: =Inputs!C26 -> 6944 | D33: =Inputs!D26 -> 14607 | E33: =D33-C33 -> 7663 | F33: =IF(C33=0,0,(D33-C33)/ABS(C33)) -> 1.1035426 | G33: =IF(ABS(D33-C33)/MAX(ABS(C33),0.0001)<0.02,"Tie",IF(D33<C33,"2012","2011")) -> 2011
B34: Total Workers | C34: =Inputs!C27 -> 31 | D34: =Inputs!D27 -> 28 | E34: =D34-C34 -> -3 | F34: =IF(C34=0,0,(D34-C34)/ABS(C34)) -> -0.096774194 | G34: =IF(ABS(D34-C34)/MAX(ABS(C34),0.0001)<0.02,"Tie",IF(D34<C34,"2012","2011")) -> 2012
B35: Blended Gross Wage | C35: =Inputs!C28 -> 20.58 | D35: =Inputs!D28 -> 19.94 | E35: =D35-C35 -> -0.64 | F35: =IF(C35=0,0,(D35-C35)/ABS(C35)) -> -0.031098154 | G35: =IF(ABS(D35-C35)/MAX(ABS(C35),0.0001)<0.02,"Tie",IF(D35<C35,"2012","2011")) -> 2012
B36: Fully-Loaded Wage | C36: =Inputs!C29 -> 31.08 | D36: =Inputs!D29 -> 30.12 | E36: =D36-C36 -> -0.96 | F36: =IF(C36=0,0,(D36-C36)/ABS(C36)) -> -0.030888031 | G36: =IF(ABS(D36-C36)/MAX(ABS(C36),0.0001)<0.02,"Tie",IF(D36<C36,"2012","2011")) -> 2012
B37: Revenue / Hour | C37: =Inputs!C15/Inputs!C26 -> 125.26267 | D37: =Inputs!D15/Inputs!D26 -> 95.259465 | E37: =D37-C37 -> -30.003208 | F37: =IF(C37=0,0,(D37-C37)/ABS(C37)) -> -0.23952234 | G37: =IF(ABS(D37-C37)/MAX(ABS(C37),0.0001)<0.02,"Tie",IF(D37>C37,"2012","2011")) -> 2011
B38: Profit / Hour | C38: =Inputs!C17/Inputs!C26 -> 47.949309 | D38: =Inputs!D17/Inputs!D26 -> 36.508113 | E38: =D38-C38 -> -11.441196 | F38: =IF(C38=0,0,(D38-C38)/ABS(C38)) -> -0.23861024 | G38: =IF(ABS(D38-C38)/MAX(ABS(C38),0.0001)<0.02,"Tie",IF(D38>C38,"2012","2011")) -> 2011
B39: Hours / Worker (avg) | C39: =Inputs!C26/Inputs!C27 -> 224 | D39: =Inputs!D26/Inputs!D27 -> 521.67857 | E39: =D39-C39 -> 297.67857 | F39: =IF(C39=0,0,(D39-C39)/ABS(C39)) -> 1.3289222 | G39: =IF(ABS(D39-C39)/MAX(ABS(C39),0.0001)<0.02,"Tie",IF(D39>C39,"2012","2011")) -> 2012
B40: F. COST MIX
B41: Labor % of Revenue | C41: =Inputs!C21/Inputs!C15 -> 0.16426656 | D41: =Inputs!D21/Inputs!D15 -> 0.19491755 | E41: =D41-C41 -> 0.030650986 | F41: =IF(C41=0,0,(D41-C41)/ABS(C41)) -> 0.18659297 | G41: =IF(ABS(D41-C41)/MAX(ABS(C41),0.0001)<0.02,"Tie",IF(D41<C41,"2012","2011")) -> 2011
B42: Material % of Revenue | C42: =Inputs!C22/Inputs!C15 -> 0.33915597 | D42: =Inputs!D22/Inputs!D15 -> 0.29360418 | E42: =D42-C42 -> -0.04555179 | F42: =IF(C42=0,0,(D42-C42)/ABS(C42)) -> -0.13430927 | G42: =IF(ABS(D42-C42)/MAX(ABS(C42),0.0001)<0.02,"Tie",IF(D42<C42,"2012","2011")) -> 2012
...

Sheet Insights
B2: Key Observations — 2011 vs 2012
B4: IDENTICAL GROSS MARGIN | C4: Both jobs landed at 38.3% gross margin — near-identical profitability despite 60% scale difference. Strongly suggests OWP has a repeatable bidding formula for Seattle multifamily.
B5: 2012 IS 60% LARGER | C5: 163 units vs 117 (+39%) and 816 fixtures vs 590 (+38%). Both completed in exactly 17 months — meaning 2012 absorbed the extra scale via crew density, not duration.
B6: 2012 BURNED 2.1× MORE HOURS | C6: 14,607 hrs vs 6,944 hrs for only 1.4× the units. Hours/unit jumped from 59 to 90 (+51%). 2011 looks more labor-efficient per unit — possibly simpler unit type, fewer stacks/fixture complexity.
B7: 2011 GENERATED MORE $/HOUR | C7: Revenue per labor hour: $125 (2011) vs $95 (2012). Profit per hour: $48 vs $37. 2011 extracted 31% more revenue per hour of crew time — consistent with its lower hour intensity.
B8: IDENTICAL FIXTURES/UNIT (5.0) | C8: Both projects hit ~5 fixtures/unit, the textbook 1-bath multifamily number. Apples-to-apples on fixture complexity, which makes the hours/fixture gap (11.8 vs 17.9) the single most important efficiency insight.
B9: HOURS/FIXTURE — 52% GAP | C9: 2011: 11.8 hrs/fixture. 2012: 17.9 hrs/fixture. This is a huge productivity gap on identical fixture density. Worth investigating: was 2012 a harder building (mid-rise vs low-rise), taller stacks, rework, or crew composition?
B10: SIMILAR WAGE STRUCTURE | C10: Blended gross wage: $20.58 vs $19.94. Fully-loaded: $31.08 vs $30.12. Near-identical crew economics — the hours gap is NOT explained by wage differences.
B11: 2011 HEAVIER ON MATERIAL | C11: Material % of revenue: 33.9% (2011) vs 29.4% (2012). 2011 spent more on materials per unit ($2,521 vs $2,397) but less on labor per unit ($1,221 vs $1,664). Different trade-off: more materials, less labor.
B12: 2012 DID NOT TRACK POS | C12: 2011 committed $125K across 26 POs (42% PO coverage of material). 2012 has no PO log in the source folder — tracked material exclusively via 186 AP invoices. Process difference, not a red flag.
B13: BOTH HAD 38% NET PROFIT | C13: 2011: $332,960 profit on $869,824 revenue. 2012: $533,274 profit on $1,391,455 revenue. Dollar-for-dollar scaling — OWP's margin discipline held across two different GCs (Chinn / Exxel).
B14: CREW DENSITY DIFFERENCE | C14: 31 workers on 117 units = 1 worker per 3.8 units (2011). 28 workers on 163 units = 1 per 5.8 units (2012). 2012 ran a leaner crew per unit but worked them 2× as many hours each (522 vs 224 avg).
B15: 2011 HAD 3 CHANGE ORDERS | C15: CO #1 foundation drains ($25.4K), CO #2 trash chute ($1K), CO #3 fixture change ($30.4K) = $56.8K total (+7% of original). 2012 JCR shows no captured COs — either none occurred, or were embedded in original contract revisions.
B17: BIGGEST QUESTION FOR OWP
B18: Why did 2012 take 52% more labor hours per fixture than 2011, despite identical fixture density (5/unit), identical margin (38.3%), and identical duration (17 months)? If that gap were closed, 2012's profit could have risen by an estimated $230K+ (5,000 hrs × $46 profit/hr).
B20: Sources: OWP_2011_JCR_Summary.xlsx and OWP_2012_JCR_Summary_Notion.xlsx (both reconcile exactly to JCR PDFs)
